//Schematic to java Structure by jajo_11 | inspired by "MITHION'S .SCHEMATIC TO JAVA CONVERTINGTOOL"

package net.minecraft.MoWithers.worldgen;

import static net.minecraft.MoWithers.worldgen.ChestGenHooksWither.WITHER_STATUE_BASE;
import static net.minecraft.MoWithers.worldgen.ChestGenHooksWither.WITHER_STATUE_HEAD_1;
import static net.minecraft.MoWithers.worldgen.ChestGenHooksWither.WITHER_STATUE_HEAD_2;

import java.util.List;
import java.util.Random;

import com.google.common.collect.Lists;

import net.minecraft.block.Block;
import net.minecraft.block.material.Material;
import net.minecraft.init.Blocks;
import net.minecraft.init.Items;
import net.minecraft.item.Item;
import net.minecraft.tileentity.TileEntity;
import net.minecraft.tileentity.TileEntityChest;
import net.minecraft.util.BlockPos;
import net.minecraft.util.WeightedRandomChestContent;
import net.minecraft.world.World;
import net.minecraft.world.gen.feature.WorldGenerator;
import net.minecraftforge.common.ChestGenHooks;

public class Defaultwithersouth extends WorldGenerator
{
    private static final List CHESTCONTENT = Lists.newArrayList(new WeightedRandomChestContent[] {new WeightedRandomChestContent(Items.golden_apple, 0, 1, 1, 5), new WeightedRandomChestContent(Items.saddle, 0, 1, 1, 10), new WeightedRandomChestContent(Items.iron_ingot, 0, 1, 4, 10), new WeightedRandomChestContent(Items.gold_ingot, 0, 1, 2, 5), new WeightedRandomChestContent(Items.bread, 0, 1, 1, 10), new WeightedRandomChestContent(Items.wheat, 0, 1, 4, 10), new WeightedRandomChestContent(Items.gunpowder, 0, 1, 4, 10), new WeightedRandomChestContent(Items.string, 0, 1, 4, 10), new WeightedRandomChestContent(Items.bucket, 0, 1, 1, 10), new WeightedRandomChestContent(Items.golden_apple, 0, 1, 1, 1), new WeightedRandomChestContent(Items.redstone, 0, 1, 4, 10), new WeightedRandomChestContent(Items.record_13, 0, 1, 1, 4), new WeightedRandomChestContent(Items.record_cat, 0, 1, 1, 4), new WeightedRandomChestContent(Items.name_tag, 0, 1, 1, 10), new WeightedRandomChestContent(Items.golden_horse_armor, 0, 1, 1, 2), new WeightedRandomChestContent(Items.iron_horse_armor, 0, 1, 1, 5), new WeightedRandomChestContent(Items.diamond_horse_armor, 0, 1, 1, 1)});
    private static final List DOUBLECHESTCONTENT = Lists.newArrayList(new WeightedRandomChestContent[] {new WeightedRandomChestContent(Items.golden_apple, 1, 1, 1, 1), new WeightedRandomChestContent(Items.bone, 0, 4, 6, 20), new WeightedRandomChestContent(Items.rotten_flesh, 0, 3, 7, 16) , new WeightedRandomChestContent(Items.diamond, 0, 1, 3, 3), new WeightedRandomChestContent(Items.iron_ingot, 0, 1, 5, 10), new WeightedRandomChestContent(Items.gold_ingot, 0, 2, 7, 15), new WeightedRandomChestContent(Items.emerald, 0, 1, 3, 2), new WeightedRandomChestContent(Items.bread, 0, 1, 3, 15), new WeightedRandomChestContent(Items.apple, 0, 1, 3, 15), new WeightedRandomChestContent(Items.iron_pickaxe, 0, 1, 1, 5), new WeightedRandomChestContent(Items.iron_sword, 0, 1, 1, 5), new WeightedRandomChestContent(Items.iron_chestplate, 0, 1, 1, 5), new WeightedRandomChestContent(Items.iron_helmet, 0, 1, 1, 5), new WeightedRandomChestContent(Items.iron_leggings, 0, 1, 1, 5), new WeightedRandomChestContent(Items.iron_boots, 0, 1, 1, 5), new WeightedRandomChestContent(Item.getItemFromBlock(Blocks.obsidian), 0, 3, 7, 5), new WeightedRandomChestContent(Item.getItemFromBlock(Blocks.coal_block), 0, 3, 7, 15), new WeightedRandomChestContent(Items.iron_horse_armor, 0, 1, 1, 1), new WeightedRandomChestContent(Items.golden_horse_armor, 0, 1, 1, 1), new WeightedRandomChestContent(Items.diamond_horse_armor, 0, 1, 1, 1)});

	public boolean generate(World world, Random rand, BlockPos pos)
	{
        if ((world.isAirBlock(pos) || world.getBlockState(pos).getBlock() == Blocks.snow_layer || world.getBlockState(pos).getBlock().getMaterial() == Material.plants) && world.canSeeSky(pos) && world.getBlockState(pos.down()).getBlock().getMaterial().isSolid())
        {
    	    generate_r0(world, rand, pos.getX(), pos.getY(), pos.getZ());
    	    
    	    return true;
        }
        else
        {
            return false;
        }

	}

	public boolean generate_r0(World world, Random rand, int x, int y, int z)
	{
		x -= 14;
		z -= 7;
		
		this.setBlock(world, x + 11, y + 0, z + 7, Blocks.iron_block, 0, 3);
		this.setBlock(world, x + 11, y + 0, z + 6, Blocks.iron_block, 0, 3);
		this.setBlock(world, x + 11, y + 0, z + 5, Blocks.iron_block, 0, 3);
		this.setBlock(world, x + 11, y + 0, z + 4, Blocks.iron_block, 0, 3);
		this.setBlock(world, x + 11, y + 0, z + 3, Blocks.iron_block, 0, 3);
		this.setBlock(world, x + 11, y + 0, z + 2, Blocks.iron_block, 0, 3);
		this.setBlock(world, x + 11, y + 0, z + 1, Blocks.iron_block, 0, 3);
		this.setBlock(world, x + 11, y + 0, z + 0, Blocks.iron_block, 0, 3);
		this.setBlock(world, x + 12, y + 0, z + 7, Blocks.iron_block, 0, 3);
		this.setBlock(world, x + 12, y + 0, z + 6, Blocks.iron_block, 0, 3);
		this.setBlock(world, x + 12, y + 0, z + 5, Blocks.iron_block, 0, 3);
		this.setBlock(world, x + 12, y + 0, z + 4, Blocks.iron_block, 0, 3);
		this.setBlock(world, x + 12, y + 0, z + 3, Blocks.iron_block, 0, 3);
		this.setBlock(world, x + 12, y + 0, z + 2, Blocks.iron_block, 0, 3);
		this.setBlock(world, x + 12, y + 0, z + 1, Blocks.iron_block, 0, 3);
		this.setBlock(world, x + 12, y + 0, z + 0, Blocks.iron_block, 0, 3);
		this.setBlock(world, x + 13, y + 0, z + 7, Blocks.iron_block, 0, 3);
		this.setBlock(world, x + 13, y + 0, z + 6, Blocks.iron_block, 0, 3);
		this.setBlock(world, x + 13, y + 0, z + 5, Blocks.iron_block, 0, 3);
		this.setBlock(world, x + 13, y + 0, z + 4, Blocks.wool, 15, 3);
		this.setBlock(world, x + 13, y + 0, z + 3, Blocks.wool, 15, 3);
		this.setBlock(world, x + 13, y + 0, z + 2, Blocks.wool, 15, 3);
		this.setBlock(world, x + 13, y + 0, z + 1, Blocks.iron_block, 0, 3);
		this.setBlock(world, x + 13, y + 0, z + 0, Blocks.iron_block, 0, 3);
		this.setBlock(world, x + 14, y + 0, z + 7, Blocks.iron_block, 0, 3);
		this.setBlock(world, x + 14, y + 0, z + 6, Blocks.iron_block, 0, 3);
		this.setBlock(world, x + 14, y + 0, z + 5, Blocks.iron_block, 0, 3);
		this.setBlock(world, x + 14, y + 0, z + 4, Blocks.wool, 15, 3);
		this.setBlock(world, x + 14, y + 0, z + 3, Blocks.wool, 15, 3);
		this.setBlock(world, x + 14, y + 0, z + 2, Blocks.wool, 15, 3);
		this.setBlock(world, x + 14, y + 0, z + 1, Blocks.iron_block, 0, 3);
		this.setBlock(world, x + 14, y + 0, z + 0, Blocks.iron_block, 0, 3);
		this.setBlock(world, x + 15, y + 0, z + 7, Blocks.iron_block, 0, 3);
		this.setBlock(world, x + 15, y + 0, z + 6, Blocks.iron_block, 0, 3);
		this.setBlock(world, x + 15, y + 0, z + 5, Blocks.iron_block, 0, 3);
		this.setBlock(world, x + 15, y + 0, z + 4, Blocks.wool, 15, 3);
		this.setBlock(world, x + 15, y + 0, z + 3, Blocks.wool, 15, 3);
		this.setBlock(world, x + 15, y + 0, z + 2, Blocks.wool, 15, 3);
		this.setBlock(world, x + 15, y + 0, z + 1, Blocks.iron_block, 0, 3);
		this.setBlock(world, x + 15, y + 0, z + 0, Blocks.iron_block, 0, 3);
		this.setBlock(world, x + 16, y + 0, z + 7, Blocks.iron_block, 0, 3);
		this.setBlock(world, x + 16, y + 0, z + 6, Blocks.iron_block, 0, 3);
		this.setBlock(world, x + 16, y + 0, z + 5, Blocks.iron_block, 0, 3);
		this.setBlock(world, x + 16, y + 0, z + 4, Blocks.iron_block, 0, 3);
		this.setBlock(world, x + 16, y + 0, z + 3, Blocks.iron_block, 0, 3);
		this.setBlock(world, x + 16, y + 0, z + 2, Blocks.iron_block, 0, 3);
		this.setBlock(world, x + 16, y + 0, z + 1, Blocks.iron_block, 0, 3);
		this.setBlock(world, x + 16, y + 0, z + 0, Blocks.iron_block, 0, 3);
		this.setBlock(world, x + 17, y + 0, z + 7, Blocks.iron_block, 0, 3);
		this.setBlock(world, x + 17, y + 0, z + 6, Blocks.iron_block, 0, 3);
		this.setBlock(world, x + 17, y + 0, z + 5, Blocks.iron_block, 0, 3);
		this.setBlock(world, x + 17, y + 0, z + 4, Blocks.iron_block, 0, 3);
		this.setBlock(world, x + 17, y + 0, z + 3, Blocks.iron_block, 0, 3);
		this.setBlock(world, x + 17, y + 0, z + 2, Blocks.iron_block, 0, 3);
		this.setBlock(world, x + 17, y + 0, z + 1, Blocks.iron_block, 0, 3);
		this.setBlock(world, x + 17, y + 0, z + 0, Blocks.iron_block, 0, 3);
		this.setBlock(world, x + 12, y + 1, z + 6, Blocks.iron_block, 0, 3);
		this.setBlock(world, x + 12, y + 1, z + 5, Blocks.iron_block, 0, 3);
		this.setBlock(world, x + 12, y + 1, z + 4, Blocks.iron_block, 0, 3);
		this.setBlock(world, x + 12, y + 1, z + 3, Blocks.iron_block, 0, 3);
		this.setBlock(world, x + 12, y + 1, z + 2, Blocks.iron_block, 0, 3);
		this.setBlock(world, x + 12, y + 1, z + 1, Blocks.iron_block, 0, 3);
		this.setBlock(world, x + 13, y + 1, z + 6, Blocks.iron_block, 0, 3);
		this.setBlock(world, x + 13, y + 1, z + 5, Blocks.wool, 15, 3);
		this.setBlock(world, x + 13, y + 1, z + 4, Blocks.wool, 15, 3);
		this.setBlock(world, x + 13, y + 1, z + 3, Blocks.wool, 15, 3);
		this.setBlock(world, x + 13, y + 1, z + 2, Blocks.wool, 15, 3);
		this.setBlock(world, x + 13, y + 1, z + 1, Blocks.iron_block, 0, 3);
		this.setBlock(world, x + 14, y + 1, z + 6, Blocks.iron_block, 0, 3);
		this.setBlock(world, x + 14, y + 1, z + 5, Blocks.wool, 7, 3);
		this.setBlock(world, x + 14, y + 1, z + 4, Blocks.wool, 15, 3);
		this.setBlock(world, x + 14, y + 1, z + 3, Blocks.chest, 5, 3);
        TileEntity tileentity1 = world.getTileEntity(new BlockPos(x + 14, y + 1, z + 3));
        if (tileentity1 instanceof TileEntityChest)
        {
            WeightedRandomChestContent.generateChestContents(rand, ChestGenHooks.getItems(WITHER_STATUE_BASE, rand), (TileEntityChest)tileentity1, ChestGenHooks.getCount(WITHER_STATUE_BASE, rand));
        }
		this.setBlock(world, x + 14, y + 1, z + 2, Blocks.wool, 7, 3);
		this.setBlock(world, x + 14, y + 1, z + 1, Blocks.iron_block, 0, 3);
		this.setBlock(world, x + 15, y + 1, z + 6, Blocks.iron_block, 0, 3);
		this.setBlock(world, x + 15, y + 1, z + 5, Blocks.wool, 15, 3);
		this.setBlock(world, x + 15, y + 1, z + 4, Blocks.wool, 15, 3);
		this.setBlock(world, x + 15, y + 1, z + 3, Blocks.wool, 15, 3);
		this.setBlock(world, x + 15, y + 1, z + 2, Blocks.wool, 15, 3);
		this.setBlock(world, x + 15, y + 1, z + 1, Blocks.iron_block, 0, 3);
		this.setBlock(world, x + 16, y + 1, z + 6, Blocks.iron_block, 0, 3);
		this.setBlock(world, x + 16, y + 1, z + 5, Blocks.iron_block, 0, 3);
		this.setBlock(world, x + 16, y + 1, z + 4, Blocks.iron_block, 0, 3);
		this.setBlock(world, x + 16, y + 1, z + 3, Blocks.iron_block, 0, 3);
		this.setBlock(world, x + 16, y + 1, z + 2, Blocks.iron_block, 0, 3);
		this.setBlock(world, x + 16, y + 1, z + 1, Blocks.iron_block, 0, 3);
		this.setBlock(world, x + 13, y + 2, z + 6, Blocks.wool, 15, 3);
		this.setBlock(world, x + 13, y + 2, z + 5, Blocks.wool, 15, 3);
		this.setBlock(world, x + 13, y + 2, z + 4, Blocks.wool, 15, 3);
		this.setBlock(world, x + 13, y + 2, z + 3, Blocks.wool, 15, 3);
		this.setBlock(world, x + 13, y + 2, z + 2, Blocks.wool, 15, 3);
		this.setBlock(world, x + 14, y + 2, z + 6, Blocks.wool, 7, 3);
		this.setBlock(world, x + 14, y + 2, z + 5, Blocks.wool, 15, 3);
		this.setBlock(world, x + 14, y + 2, z + 4, Blocks.wool, 15, 3);
		this.setBlock(world, x + 14, y + 2, z + 3, Blocks.wool, 15, 3);
		this.setBlock(world, x + 14, y + 2, z + 2, Blocks.wool, 15, 3);
		this.setBlock(world, x + 15, y + 2, z + 6, Blocks.wool, 15, 3);
		this.setBlock(world, x + 15, y + 2, z + 5, Blocks.wool, 15, 3);
		this.setBlock(world, x + 15, y + 2, z + 4, Blocks.wool, 15, 3);
		this.setBlock(world, x + 15, y + 2, z + 3, Blocks.wool, 15, 3);
		this.setBlock(world, x + 15, y + 2, z + 2, Blocks.wool, 15, 3);
		this.setBlock(world, x + 13, y + 3, z + 7, Blocks.wool, 15, 3);
		this.setBlock(world, x + 13, y + 3, z + 6, Blocks.wool, 15, 3);
		this.setBlock(world, x + 13, y + 3, z + 5, Blocks.wool, 15, 3);
		this.setBlock(world, x + 13, y + 3, z + 4, Blocks.wool, 15, 3);
		this.setBlock(world, x + 13, y + 3, z + 3, Blocks.wool, 15, 3);
		this.setBlock(world, x + 14, y + 3, z + 7, Blocks.wool, 8, 3);
		this.setBlock(world, x + 14, y + 3, z + 6, Blocks.wool, 15, 3);
		this.setBlock(world, x + 14, y + 3, z + 5, Blocks.wool, 15, 3);
		this.setBlock(world, x + 14, y + 3, z + 4, Blocks.wool, 15, 3);
		this.setBlock(world, x + 14, y + 3, z + 3, Blocks.wool, 7, 3);
		this.setBlock(world, x + 15, y + 3, z + 7, Blocks.wool, 15, 3);
		this.setBlock(world, x + 15, y + 3, z + 6, Blocks.wool, 15, 3);
		this.setBlock(world, x + 15, y + 3, z + 5, Blocks.wool, 15, 3);
		this.setBlock(world, x + 15, y + 3, z + 4, Blocks.wool, 15, 3);
		this.setBlock(world, x + 15, y + 3, z + 3, Blocks.wool, 15, 3);
		this.setBlock(world, x + 13, y + 4, z + 8, Blocks.wool, 15, 3);
		this.setBlock(world, x + 13, y + 4, z + 7, Blocks.wool, 15, 3);
		this.setBlock(world, x + 13, y + 4, z + 6, Blocks.wool, 15, 3);
		this.setBlock(world, x + 13, y + 4, z + 5, Blocks.wool, 15, 3);
		this.setBlock(world, x + 13, y + 4, z + 4, Blocks.wool, 15, 3);
		this.setBlock(world, x + 14, y + 4, z + 8, Blocks.wool, 7, 3);
		this.setBlock(world, x + 14, y + 4, z + 7, Blocks.wool, 15, 3);
		this.setBlock(world, x + 14, y + 4, z + 6, Blocks.wool, 15, 3);
		this.setBlock(world, x + 14, y + 4, z + 5, Blocks.wool, 15, 3);
		this.setBlock(world, x + 14, y + 4, z + 4, Blocks.wool, 7, 3);
		this.setBlock(world, x + 15, y + 4, z + 8, Blocks.wool, 15, 3);
		this.setBlock(world, x + 15, y + 4, z + 7, Blocks.wool, 15, 3);
		this.setBlock(world, x + 15, y + 4, z + 6, Blocks.wool, 15, 3);
		this.setBlock(world, x + 15, y + 4, z + 5, Blocks.wool, 15, 3);
		this.setBlock(world, x + 15, y + 4, z + 4, Blocks.wool, 15, 3);
		this.setBlock(world, x + 13, y + 5, z + 9, Blocks.wool, 15, 3);
		this.setBlock(world, x + 13, y + 5, z + 8, Blocks.wool, 15, 3);
		this.setBlock(world, x + 13, y + 5, z + 7, Blocks.wool, 15, 3);
		this.setBlock(world, x + 13, y + 5, z + 6, Blocks.wool, 15, 3);
		this.setBlock(world, x + 13, y + 5, z + 5, Blocks.wool, 15, 3);
		this.setBlock(world, x + 14, y + 5, z + 9, Blocks.wool, 15, 3);
		this.setBlock(world, x + 14, y + 5, z + 8, Blocks.wool, 15, 3);
		this.setBlock(world, x + 14, y + 5, z + 7, Blocks.wool, 15, 3);
		this.setBlock(world, x + 14, y + 5, z + 6, Blocks.wool, 15, 3);
		this.setBlock(world, x + 14, y + 5, z + 5, Blocks.wool, 8, 3);
		this.setBlock(world, x + 15, y + 5, z + 9, Blocks.wool, 15, 3);
		this.setBlock(world, x + 15, y + 5, z + 8, Blocks.wool, 15, 3);
		this.setBlock(world, x + 15, y + 5, z + 7, Blocks.wool, 15, 3);
		this.setBlock(world, x + 15, y + 5, z + 6, Blocks.wool, 15, 3);
		this.setBlock(world, x + 15, y + 5, z + 5, Blocks.wool, 15, 3);
		this.setBlock(world, x + 13, y + 6, z + 9, Blocks.wool, 15, 3);
		this.setBlock(world, x + 13, y + 6, z + 8, Blocks.wool, 15, 3);
		this.setBlock(world, x + 13, y + 6, z + 7, Blocks.wool, 15, 3);
		this.setBlock(world, x + 13, y + 6, z + 6, Blocks.wool, 15, 3);
		this.setBlock(world, x + 14, y + 6, z + 9, Blocks.wool, 7, 3);
		this.setBlock(world, x + 14, y + 6, z + 8, Blocks.wool, 15, 3);
		this.setBlock(world, x + 14, y + 6, z + 7, Blocks.wool, 15, 3);
		this.setBlock(world, x + 14, y + 6, z + 6, Blocks.wool, 7, 3);
		this.setBlock(world, x + 15, y + 6, z + 9, Blocks.wool, 15, 3);
		this.setBlock(world, x + 15, y + 6, z + 8, Blocks.wool, 15, 3);
		this.setBlock(world, x + 15, y + 6, z + 7, Blocks.wool, 15, 3);
		this.setBlock(world, x + 15, y + 6, z + 6, Blocks.wool, 15, 3);
		this.setBlock(world, x + 9, y + 7, z + 8, Blocks.wool, 8, 3);
		this.setBlock(world, x + 9, y + 7, z + 7, Blocks.wool, 8, 3);
		this.setBlock(world, x + 10, y + 7, z + 8, Blocks.wool, 8, 3);
		this.setBlock(world, x + 10, y + 7, z + 7, Blocks.wool, 8, 3);
		this.setBlock(world, x + 11, y + 7, z + 8, Blocks.wool, 7, 3);
		this.setBlock(world, x + 11, y + 7, z + 7, Blocks.wool, 7, 3);
		this.setBlock(world, x + 12, y + 7, z + 8, Blocks.wool, 7, 3);
		this.setBlock(world, x + 12, y + 7, z + 7, Blocks.wool, 7, 3);
		this.setBlock(world, x + 13, y + 7, z + 9, Blocks.wool, 15, 3);
		this.setBlock(world, x + 13, y + 7, z + 8, Blocks.wool, 15, 3);
		this.setBlock(world, x + 13, y + 7, z + 7, Blocks.wool, 15, 3);
		this.setBlock(world, x + 14, y + 7, z + 9, Blocks.wool, 7, 3);
		this.setBlock(world, x + 14, y + 7, z + 8, Blocks.wool, 15, 3);
		this.setBlock(world, x + 14, y + 7, z + 7, Blocks.wool, 7, 3);
		this.setBlock(world, x + 15, y + 7, z + 9, Blocks.wool, 15, 3);
		this.setBlock(world, x + 15, y + 7, z + 8, Blocks.wool, 15, 3);
		this.setBlock(world, x + 15, y + 7, z + 7, Blocks.wool, 15, 3);
		this.setBlock(world, x + 16, y + 7, z + 8, Blocks.wool, 7, 3);
		this.setBlock(world, x + 16, y + 7, z + 7, Blocks.wool, 7, 3);
		this.setBlock(world, x + 17, y + 7, z + 8, Blocks.wool, 7, 3);
		this.setBlock(world, x + 17, y + 7, z + 7, Blocks.wool, 7, 3);
		this.setBlock(world, x + 18, y + 7, z + 8, Blocks.wool, 8, 3);
		this.setBlock(world, x + 18, y + 7, z + 7, Blocks.wool, 8, 3);
		this.setBlock(world, x + 19, y + 7, z + 8, Blocks.wool, 8, 3);
		this.setBlock(world, x + 19, y + 7, z + 7, Blocks.wool, 8, 3);
		this.setBlock(world, x + 9, y + 8, z + 8, Blocks.wool, 8, 3);
		this.setBlock(world, x + 9, y + 8, z + 7, Blocks.wool, 8, 3);
		this.setBlock(world, x + 10, y + 8, z + 8, Blocks.wool, 8, 3);
		this.setBlock(world, x + 10, y + 8, z + 7, Blocks.wool, 8, 3);
		this.setBlock(world, x + 11, y + 8, z + 8, Blocks.wool, 7, 3);
		this.setBlock(world, x + 11, y + 8, z + 7, Blocks.wool, 7, 3);
		this.setBlock(world, x + 12, y + 8, z + 8, Blocks.wool, 7, 3);
		this.setBlock(world, x + 12, y + 8, z + 7, Blocks.wool, 7, 3);
		this.setBlock(world, x + 13, y + 8, z + 9, Blocks.wool, 15, 3);
		this.setBlock(world, x + 13, y + 8, z + 8, Blocks.wool, 15, 3);
		this.setBlock(world, x + 13, y + 8, z + 7, Blocks.wool, 15, 3);
		this.setBlock(world, x + 14, y + 8, z + 9, Blocks.wool, 8, 3);
		this.setBlock(world, x + 14, y + 8, z + 8, Blocks.wool, 15, 3);
		this.setBlock(world, x + 14, y + 8, z + 7, Blocks.wool, 8, 3);
		this.setBlock(world, x + 15, y + 8, z + 9, Blocks.wool, 15, 3);
		this.setBlock(world, x + 15, y + 8, z + 8, Blocks.wool, 15, 3);
		this.setBlock(world, x + 15, y + 8, z + 7, Blocks.wool, 15, 3);
		this.setBlock(world, x + 16, y + 8, z + 8, Blocks.wool, 7, 3);
		this.setBlock(world, x + 16, y + 8, z + 7, Blocks.wool, 7, 3);
		this.setBlock(world, x + 17, y + 8, z + 8, Blocks.wool, 7, 3);
		this.setBlock(world, x + 17, y + 8, z + 7, Blocks.wool, 7, 3);
		this.setBlock(world, x + 18, y + 8, z + 8, Blocks.wool, 8, 3);
		this.setBlock(world, x + 18, y + 8, z + 7, Blocks.wool, 8, 3);
		this.setBlock(world, x + 19, y + 8, z + 8, Blocks.wool, 8, 3);
		this.setBlock(world, x + 19, y + 8, z + 7, Blocks.wool, 8, 3);
		this.setBlock(world, x + 13, y + 9, z + 9, Blocks.wool, 15, 3);
		this.setBlock(world, x + 13, y + 9, z + 8, Blocks.wool, 15, 3);
		this.setBlock(world, x + 13, y + 9, z + 7, Blocks.wool, 15, 3);
		this.setBlock(world, x + 14, y + 9, z + 9, Blocks.wool, 8, 3);
		this.setBlock(world, x + 14, y + 9, z + 8, Blocks.wool, 15, 3);
		this.setBlock(world, x + 14, y + 9, z + 7, Blocks.wool, 8, 3);
		this.setBlock(world, x + 15, y + 9, z + 9, Blocks.wool, 15, 3);
		this.setBlock(world, x + 15, y + 9, z + 8, Blocks.wool, 15, 3);
		this.setBlock(world, x + 15, y + 9, z + 7, Blocks.wool, 15, 3);
		this.setBlock(world, x + 9, y + 10, z + 8, Blocks.wool, 8, 3);
		this.setBlock(world, x + 9, y + 10, z + 7, Blocks.wool, 8, 3);
		this.setBlock(world, x + 10, y + 10, z + 8, Blocks.wool, 8, 3);
		this.setBlock(world, x + 10, y + 10, z + 7, Blocks.wool, 8, 3);
		this.setBlock(world, x + 11, y + 10, z + 8, Blocks.wool, 7, 3);
		this.setBlock(world, x + 11, y + 10, z + 7, Blocks.wool, 7, 3);
		this.setBlock(world, x + 12, y + 10, z + 8, Blocks.wool, 7, 3);
		this.setBlock(world, x + 12, y + 10, z + 7, Blocks.wool, 7, 3);
		this.setBlock(world, x + 13, y + 10, z + 9, Blocks.wool, 15, 3);
		this.setBlock(world, x + 13, y + 10, z + 8, Blocks.wool, 15, 3);
		this.setBlock(world, x + 13, y + 10, z + 7, Blocks.wool, 15, 3);
		this.setBlock(world, x + 14, y + 10, z + 9, Blocks.wool, 8, 3);
		this.setBlock(world, x + 14, y + 10, z + 8, Blocks.wool, 15, 3);
		this.setBlock(world, x + 14, y + 10, z + 7, Blocks.wool, 8, 3);
		this.setBlock(world, x + 15, y + 10, z + 9, Blocks.wool, 15, 3);
		this.setBlock(world, x + 15, y + 10, z + 8, Blocks.wool, 15, 3);
		this.setBlock(world, x + 15, y + 10, z + 7, Blocks.wool, 15, 3);
		this.setBlock(world, x + 16, y + 10, z + 8, Blocks.wool, 7, 3);
		this.setBlock(world, x + 16, y + 10, z + 7, Blocks.wool, 7, 3);
		this.setBlock(world, x + 17, y + 10, z + 8, Blocks.wool, 7, 3);
		this.setBlock(world, x + 17, y + 10, z + 7, Blocks.wool, 7, 3);
		this.setBlock(world, x + 18, y + 10, z + 8, Blocks.wool, 8, 3);
		this.setBlock(world, x + 18, y + 10, z + 7, Blocks.wool, 8, 3);
		this.setBlock(world, x + 19, y + 10, z + 8, Blocks.wool, 8, 3);
		this.setBlock(world, x + 19, y + 10, z + 7, Blocks.wool, 8, 3);
		this.setBlock(world, x + 9, y + 11, z + 8, Blocks.wool, 8, 3);
		this.setBlock(world, x + 9, y + 11, z + 7, Blocks.wool, 8, 3);
		this.setBlock(world, x + 10, y + 11, z + 8, Blocks.wool, 8, 3);
		this.setBlock(world, x + 10, y + 11, z + 7, Blocks.wool, 8, 3);
		this.setBlock(world, x + 11, y + 11, z + 8, Blocks.wool, 7, 3);
		this.setBlock(world, x + 11, y + 11, z + 7, Blocks.wool, 7, 3);
		this.setBlock(world, x + 12, y + 11, z + 8, Blocks.wool, 7, 3);
		this.setBlock(world, x + 12, y + 11, z + 7, Blocks.wool, 7, 3);
		this.setBlock(world, x + 13, y + 11, z + 9, Blocks.wool, 15, 3);
		this.setBlock(world, x + 13, y + 11, z + 8, Blocks.wool, 15, 3);
		this.setBlock(world, x + 13, y + 11, z + 7, Blocks.wool, 15, 3);
		this.setBlock(world, x + 14, y + 11, z + 9, Blocks.wool, 8, 3);
		this.setBlock(world, x + 14, y + 11, z + 8, Blocks.wool, 15, 3);
		this.setBlock(world, x + 14, y + 11, z + 7, Blocks.wool, 8, 3);
		this.setBlock(world, x + 15, y + 11, z + 9, Blocks.wool, 15, 3);
		this.setBlock(world, x + 15, y + 11, z + 8, Blocks.wool, 15, 3);
		this.setBlock(world, x + 15, y + 11, z + 7, Blocks.wool, 15, 3);
		this.setBlock(world, x + 16, y + 11, z + 8, Blocks.wool, 7, 3);
		this.setBlock(world, x + 16, y + 11, z + 7, Blocks.wool, 7, 3);
		this.setBlock(world, x + 17, y + 11, z + 8, Blocks.wool, 7, 3);
		this.setBlock(world, x + 17, y + 11, z + 7, Blocks.wool, 7, 3);
		this.setBlock(world, x + 18, y + 11, z + 8, Blocks.wool, 8, 3);
		this.setBlock(world, x + 18, y + 11, z + 7, Blocks.wool, 8, 3);
		this.setBlock(world, x + 19, y + 11, z + 8, Blocks.wool, 8, 3);
		this.setBlock(world, x + 19, y + 11, z + 7, Blocks.wool, 8, 3);
		this.setBlock(world, x + 13, y + 12, z + 9, Blocks.wool, 15, 3);
		this.setBlock(world, x + 13, y + 12, z + 8, Blocks.wool, 15, 3);
		this.setBlock(world, x + 13, y + 12, z + 7, Blocks.wool, 15, 3);
		this.setBlock(world, x + 14, y + 12, z + 9, Blocks.wool, 8, 3);
		this.setBlock(world, x + 14, y + 12, z + 8, Blocks.wool, 15, 3);
		this.setBlock(world, x + 14, y + 12, z + 7, Blocks.wool, 8, 3);
		this.setBlock(world, x + 15, y + 12, z + 9, Blocks.wool, 15, 3);
		this.setBlock(world, x + 15, y + 12, z + 8, Blocks.wool, 15, 3);
		this.setBlock(world, x + 15, y + 12, z + 7, Blocks.wool, 15, 3);
		this.setBlock(world, x + 9, y + 13, z + 8, Blocks.wool, 8, 3);
		this.setBlock(world, x + 9, y + 13, z + 7, Blocks.wool, 8, 3);
		this.setBlock(world, x + 10, y + 13, z + 8, Blocks.wool, 8, 3);
		this.setBlock(world, x + 10, y + 13, z + 7, Blocks.wool, 8, 3);
		this.setBlock(world, x + 11, y + 13, z + 8, Blocks.wool, 7, 3);
		this.setBlock(world, x + 11, y + 13, z + 7, Blocks.wool, 7, 3);
		this.setBlock(world, x + 12, y + 13, z + 8, Blocks.wool, 7, 3);
		this.setBlock(world, x + 12, y + 13, z + 7, Blocks.wool, 7, 3);
		this.setBlock(world, x + 13, y + 13, z + 9, Blocks.wool, 15, 3);
		this.setBlock(world, x + 13, y + 13, z + 8, Blocks.wool, 15, 3);
		this.setBlock(world, x + 13, y + 13, z + 7, Blocks.wool, 15, 3);
		this.setBlock(world, x + 14, y + 13, z + 9, Blocks.wool, 7, 3);
		this.setBlock(world, x + 14, y + 13, z + 8, Blocks.wool, 15, 3);
		this.setBlock(world, x + 14, y + 13, z + 7, Blocks.wool, 7, 3);
		this.setBlock(world, x + 15, y + 13, z + 9, Blocks.wool, 15, 3);
		this.setBlock(world, x + 15, y + 13, z + 8, Blocks.wool, 15, 3);
		this.setBlock(world, x + 15, y + 13, z + 7, Blocks.wool, 15, 3);
		this.setBlock(world, x + 16, y + 13, z + 8, Blocks.wool, 7, 3);
		this.setBlock(world, x + 16, y + 13, z + 7, Blocks.wool, 7, 3);
		this.setBlock(world, x + 17, y + 13, z + 8, Blocks.wool, 7, 3);
		this.setBlock(world, x + 17, y + 13, z + 7, Blocks.wool, 7, 3);
		this.setBlock(world, x + 18, y + 13, z + 8, Blocks.wool, 8, 3);
		this.setBlock(world, x + 18, y + 13, z + 7, Blocks.wool, 8, 3);
		this.setBlock(world, x + 19, y + 13, z + 8, Blocks.wool, 8, 3);
		this.setBlock(world, x + 19, y + 13, z + 7, Blocks.wool, 8, 3);
		this.setBlock(world, x + 9, y + 14, z + 8, Blocks.wool, 8, 3);
		this.setBlock(world, x + 9, y + 14, z + 7, Blocks.wool, 8, 3);
		this.setBlock(world, x + 10, y + 14, z + 8, Blocks.wool, 8, 3);
		this.setBlock(world, x + 10, y + 14, z + 7, Blocks.wool, 8, 3);
		this.setBlock(world, x + 11, y + 14, z + 8, Blocks.wool, 7, 3);
		this.setBlock(world, x + 11, y + 14, z + 7, Blocks.wool, 7, 3);
		this.setBlock(world, x + 12, y + 14, z + 8, Blocks.wool, 7, 3);
		this.setBlock(world, x + 12, y + 14, z + 7, Blocks.wool, 7, 3);
		this.setBlock(world, x + 13, y + 14, z + 9, Blocks.wool, 15, 3);
		this.setBlock(world, x + 13, y + 14, z + 8, Blocks.wool, 15, 3);
		this.setBlock(world, x + 13, y + 14, z + 7, Blocks.wool, 15, 3);
		this.setBlock(world, x + 14, y + 14, z + 9, Blocks.wool, 7, 3);
		this.setBlock(world, x + 14, y + 14, z + 8, Blocks.wool, 15, 3);
		this.setBlock(world, x + 14, y + 14, z + 7, Blocks.wool, 7, 3);
		this.setBlock(world, x + 15, y + 14, z + 9, Blocks.wool, 15, 3);
		this.setBlock(world, x + 15, y + 14, z + 8, Blocks.wool, 15, 3);
		this.setBlock(world, x + 15, y + 14, z + 7, Blocks.wool, 15, 3);
		this.setBlock(world, x + 16, y + 14, z + 8, Blocks.wool, 7, 3);
		this.setBlock(world, x + 16, y + 14, z + 7, Blocks.wool, 7, 3);
		this.setBlock(world, x + 17, y + 14, z + 8, Blocks.wool, 7, 3);
		this.setBlock(world, x + 17, y + 14, z + 7, Blocks.wool, 7, 3);
		this.setBlock(world, x + 18, y + 14, z + 8, Blocks.wool, 8, 3);
		this.setBlock(world, x + 18, y + 14, z + 7, Blocks.wool, 8, 3);
		this.setBlock(world, x + 19, y + 14, z + 8, Blocks.wool, 8, 3);
		this.setBlock(world, x + 19, y + 14, z + 7, Blocks.wool, 8, 3);
		this.setBlock(world, x + 13, y + 15, z + 9, Blocks.wool, 15, 3);
		this.setBlock(world, x + 13, y + 15, z + 8, Blocks.wool, 15, 3);
		this.setBlock(world, x + 13, y + 15, z + 7, Blocks.wool, 15, 3);
		this.setBlock(world, x + 14, y + 15, z + 9, Blocks.wool, 15, 3);
		this.setBlock(world, x + 14, y + 15, z + 8, Blocks.wool, 15, 3);
		this.setBlock(world, x + 14, y + 15, z + 7, Blocks.wool, 15, 3);
		this.setBlock(world, x + 15, y + 15, z + 9, Blocks.wool, 15, 3);
		this.setBlock(world, x + 15, y + 15, z + 8, Blocks.wool, 15, 3);
		this.setBlock(world, x + 15, y + 15, z + 7, Blocks.wool, 15, 3);
		this.setBlock(world, x + 5, y + 16, z + 9, Blocks.wool, 15, 3);
		this.setBlock(world, x + 5, y + 16, z + 8, Blocks.wool, 15, 3);
		this.setBlock(world, x + 5, y + 16, z + 7, Blocks.wool, 15, 3);
		this.setBlock(world, x + 6, y + 16, z + 9, Blocks.wool, 15, 3);
		this.setBlock(world, x + 6, y + 16, z + 8, Blocks.wool, 15, 3);
		this.setBlock(world, x + 6, y + 16, z + 7, Blocks.wool, 15, 3);
		this.setBlock(world, x + 7, y + 16, z + 9, Blocks.wool, 15, 3);
		this.setBlock(world, x + 7, y + 16, z + 8, Blocks.wool, 15, 3);
		this.setBlock(world, x + 7, y + 16, z + 7, Blocks.wool, 15, 3);
		this.setBlock(world, x + 8, y + 16, z + 9, Blocks.wool, 15, 3);
		this.setBlock(world, x + 8, y + 16, z + 8, Blocks.wool, 15, 3);
		this.setBlock(world, x + 8, y + 16, z + 7, Blocks.wool, 15, 3);
		this.setBlock(world, x + 9, y + 16, z + 9, Blocks.wool, 15, 3);
		this.setBlock(world, x + 9, y + 16, z + 8, Blocks.wool, 15, 3);
		this.setBlock(world, x + 9, y + 16, z + 7, Blocks.wool, 15, 3);
		this.setBlock(world, x + 10, y + 16, z + 9, Blocks.wool, 15, 3);
		this.setBlock(world, x + 10, y + 16, z + 8, Blocks.wool, 15, 3);
		this.setBlock(world, x + 10, y + 16, z + 7, Blocks.wool, 15, 3);
		this.setBlock(world, x + 11, y + 16, z + 9, Blocks.wool, 15, 3);
		this.setBlock(world, x + 11, y + 16, z + 8, Blocks.wool, 15, 3);
		this.setBlock(world, x + 11, y + 16, z + 7, Blocks.wool, 15, 3);
		this.setBlock(world, x + 12, y + 16, z + 9, Blocks.wool, 15, 3);
		this.setBlock(world, x + 12, y + 16, z + 8, Blocks.wool, 15, 3);
		this.setBlock(world, x + 12, y + 16, z + 7, Blocks.wool, 15, 3);
		this.setBlock(world, x + 13, y + 16, z + 9, Blocks.wool, 15, 3);
		this.setBlock(world, x + 13, y + 16, z + 8, Blocks.wool, 15, 3);
		this.setBlock(world, x + 13, y + 16, z + 7, Blocks.wool, 15, 3);
		this.setBlock(world, x + 14, y + 16, z + 9, Blocks.wool, 15, 3);
		this.setBlock(world, x + 14, y + 16, z + 8, Blocks.wool, 15, 3);
		this.setBlock(world, x + 14, y + 16, z + 7, Blocks.wool, 15, 3);
		this.setBlock(world, x + 15, y + 16, z + 9, Blocks.wool, 15, 3);
		this.setBlock(world, x + 15, y + 16, z + 8, Blocks.wool, 15, 3);
		this.setBlock(world, x + 15, y + 16, z + 7, Blocks.wool, 15, 3);
		this.setBlock(world, x + 16, y + 16, z + 9, Blocks.wool, 15, 3);
		this.setBlock(world, x + 16, y + 16, z + 8, Blocks.wool, 15, 3);
		this.setBlock(world, x + 16, y + 16, z + 7, Blocks.wool, 15, 3);
		this.setBlock(world, x + 17, y + 16, z + 9, Blocks.wool, 15, 3);
		this.setBlock(world, x + 17, y + 16, z + 8, Blocks.wool, 15, 3);
		this.setBlock(world, x + 17, y + 16, z + 7, Blocks.wool, 15, 3);
		this.setBlock(world, x + 18, y + 16, z + 9, Blocks.wool, 15, 3);
		this.setBlock(world, x + 18, y + 16, z + 8, Blocks.wool, 15, 3);
		this.setBlock(world, x + 18, y + 16, z + 7, Blocks.wool, 15, 3);
		this.setBlock(world, x + 19, y + 16, z + 9, Blocks.wool, 15, 3);
		this.setBlock(world, x + 19, y + 16, z + 8, Blocks.wool, 15, 3);
		this.setBlock(world, x + 19, y + 16, z + 7, Blocks.wool, 15, 3);
		this.setBlock(world, x + 20, y + 16, z + 9, Blocks.wool, 15, 3);
		this.setBlock(world, x + 20, y + 16, z + 8, Blocks.wool, 15, 3);
		this.setBlock(world, x + 20, y + 16, z + 7, Blocks.wool, 15, 3);
		this.setBlock(world, x + 21, y + 16, z + 9, Blocks.wool, 15, 3);
		this.setBlock(world, x + 21, y + 16, z + 8, Blocks.wool, 15, 3);
		this.setBlock(world, x + 21, y + 16, z + 7, Blocks.wool, 15, 3);
		this.setBlock(world, x + 22, y + 16, z + 9, Blocks.wool, 15, 3);
		this.setBlock(world, x + 22, y + 16, z + 8, Blocks.wool, 15, 3);
		this.setBlock(world, x + 22, y + 16, z + 7, Blocks.wool, 15, 3);
		this.setBlock(world, x + 23, y + 16, z + 9, Blocks.wool, 15, 3);
		this.setBlock(world, x + 23, y + 16, z + 8, Blocks.wool, 15, 3);
		this.setBlock(world, x + 23, y + 16, z + 7, Blocks.wool, 15, 3);
		this.setBlock(world, x + 1, y + 17, z + 11, Blocks.wool, 15, 3);
		this.setBlock(world, x + 1, y + 17, z + 10, Blocks.wool, 15, 3);
		this.setBlock(world, x + 1, y + 17, z + 9, Blocks.wool, 15, 3);
		this.setBlock(world, x + 1, y + 17, z + 8, Blocks.wool, 15, 3);
		this.setBlock(world, x + 1, y + 17, z + 7, Blocks.wool, 15, 3);
		this.setBlock(world, x + 1, y + 17, z + 6, Blocks.wool, 15, 3);
		this.setBlock(world, x + 2, y + 17, z + 11, Blocks.wool, 15, 3);
		this.setBlock(world, x + 2, y + 17, z + 10, Blocks.wool, 15, 3);
		this.setBlock(world, x + 2, y + 17, z + 9, Blocks.wool, 15, 3);
		this.setBlock(world, x + 2, y + 17, z + 8, Blocks.wool, 15, 3);
		this.setBlock(world, x + 2, y + 17, z + 7, Blocks.wool, 15, 3);
		this.setBlock(world, x + 2, y + 17, z + 6, Blocks.wool, 15, 3);
		this.setBlock(world, x + 3, y + 17, z + 11, Blocks.wool, 15, 3);
		this.setBlock(world, x + 3, y + 17, z + 10, Blocks.wool, 15, 3);
		this.setBlock(world, x + 3, y + 17, z + 9, Blocks.wool, 15, 3);
		this.setBlock(world, x + 3, y + 17, z + 8, Blocks.wool, 15, 3);
		this.setBlock(world, x + 3, y + 17, z + 7, Blocks.wool, 15, 3);
		this.setBlock(world, x + 3, y + 17, z + 6, Blocks.wool, 15, 3);
		this.setBlock(world, x + 4, y + 17, z + 11, Blocks.wool, 15, 3);
		this.setBlock(world, x + 4, y + 17, z + 10, Blocks.wool, 15, 3);
		this.setBlock(world, x + 4, y + 17, z + 9, Blocks.wool, 15, 3);
		this.setBlock(world, x + 4, y + 17, z + 8, Blocks.wool, 15, 3);
		this.setBlock(world, x + 4, y + 17, z + 7, Blocks.wool, 15, 3);
		this.setBlock(world, x + 4, y + 17, z + 6, Blocks.wool, 15, 3);
		this.setBlock(world, x + 5, y + 17, z + 11, Blocks.wool, 15, 3);
		this.setBlock(world, x + 5, y + 17, z + 10, Blocks.wool, 15, 3);
		this.setBlock(world, x + 5, y + 17, z + 9, Blocks.wool, 15, 3);
		this.setBlock(world, x + 5, y + 17, z + 8, Blocks.wool, 15, 3);
		this.setBlock(world, x + 5, y + 17, z + 7, Blocks.wool, 15, 3);
		this.setBlock(world, x + 5, y + 17, z + 6, Blocks.wool, 15, 3);
		this.setBlock(world, x + 6, y + 17, z + 11, Blocks.wool, 15, 3);
		this.setBlock(world, x + 6, y + 17, z + 10, Blocks.wool, 15, 3);
		this.setBlock(world, x + 6, y + 17, z + 9, Blocks.wool, 15, 3);
		this.setBlock(world, x + 6, y + 17, z + 8, Blocks.wool, 15, 3);
		this.setBlock(world, x + 6, y + 17, z + 7, Blocks.wool, 15, 3);
		this.setBlock(world, x + 6, y + 17, z + 6, Blocks.wool, 15, 3);
		this.setBlock(world, x + 7, y + 17, z + 9, Blocks.wool, 15, 3);
		this.setBlock(world, x + 7, y + 17, z + 8, Blocks.wool, 15, 3);
		this.setBlock(world, x + 7, y + 17, z + 7, Blocks.wool, 7, 3);
		this.setBlock(world, x + 8, y + 17, z + 9, Blocks.wool, 15, 3);
		this.setBlock(world, x + 8, y + 17, z + 8, Blocks.wool, 15, 3);
		this.setBlock(world, x + 8, y + 17, z + 7, Blocks.wool, 15, 3);
		this.setBlock(world, x + 9, y + 17, z + 9, Blocks.wool, 15, 3);
		this.setBlock(world, x + 9, y + 17, z + 8, Blocks.wool, 15, 3);
		this.setBlock(world, x + 9, y + 17, z + 7, Blocks.wool, 15, 3);
		this.setBlock(world, x + 10, y + 17, z + 9, Blocks.wool, 7, 3);
		this.setBlock(world, x + 10, y + 17, z + 8, Blocks.wool, 15, 3);
		this.setBlock(world, x + 10, y + 17, z + 7, Blocks.wool, 7, 3);
		this.setBlock(world, x + 11, y + 17, z + 9, Blocks.wool, 8, 3);
		this.setBlock(world, x + 11, y + 17, z + 8, Blocks.wool, 15, 3);
		this.setBlock(world, x + 11, y + 17, z + 7, Blocks.wool, 15, 3);
		this.setBlock(world, x + 12, y + 17, z + 9, Blocks.wool, 7, 3);
		this.setBlock(world, x + 12, y + 17, z + 8, Blocks.wool, 15, 3);
		this.setBlock(world, x + 12, y + 17, z + 7, Blocks.wool, 15, 3);
		this.setBlock(world, x + 13, y + 17, z + 9, Blocks.wool, 15, 3);
		this.setBlock(world, x + 13, y + 17, z + 8, Blocks.wool, 15, 3);
		this.setBlock(world, x + 13, y + 17, z + 7, Blocks.wool, 15, 3);
		this.setBlock(world, x + 14, y + 17, z + 9, Blocks.wool, 15, 3);
		this.setBlock(world, x + 14, y + 17, z + 8, Blocks.wool, 15, 3);
		this.setBlock(world, x + 14, y + 17, z + 7, Blocks.wool, 15, 3);
		this.setBlock(world, x + 15, y + 17, z + 9, Blocks.wool, 15, 3);
		this.setBlock(world, x + 15, y + 17, z + 8, Blocks.wool, 15, 3);
		this.setBlock(world, x + 15, y + 17, z + 7, Blocks.wool, 15, 3);
		this.setBlock(world, x + 16, y + 17, z + 9, Blocks.wool, 7, 3);
		this.setBlock(world, x + 16, y + 17, z + 8, Blocks.wool, 15, 3);
		this.setBlock(world, x + 16, y + 17, z + 7, Blocks.wool, 7, 3);
		this.setBlock(world, x + 17, y + 17, z + 9, Blocks.wool, 8, 3);
		this.setBlock(world, x + 17, y + 17, z + 8, Blocks.wool, 15, 3);
		this.setBlock(world, x + 17, y + 17, z + 7, Blocks.wool, 7, 3);
		this.setBlock(world, x + 18, y + 17, z + 9, Blocks.wool, 8, 3);
		this.setBlock(world, x + 18, y + 17, z + 8, Blocks.wool, 15, 3);
		this.setBlock(world, x + 18, y + 17, z + 7, Blocks.wool, 8, 3);
		this.setBlock(world, x + 19, y + 17, z + 9, Blocks.wool, 7, 3);
		this.setBlock(world, x + 19, y + 17, z + 8, Blocks.wool, 15, 3);
		this.setBlock(world, x + 19, y + 17, z + 7, Blocks.wool, 8, 3);
		this.setBlock(world, x + 20, y + 17, z + 9, Blocks.wool, 15, 3);
		this.setBlock(world, x + 20, y + 17, z + 8, Blocks.wool, 15, 3);
		this.setBlock(world, x + 20, y + 17, z + 7, Blocks.wool, 8, 3);
		this.setBlock(world, x + 21, y + 17, z + 9, Blocks.wool, 15, 3);
		this.setBlock(world, x + 21, y + 17, z + 8, Blocks.wool, 15, 3);
		this.setBlock(world, x + 21, y + 17, z + 7, Blocks.wool, 7, 3);
		this.setBlock(world, x + 22, y + 17, z + 12, Blocks.wool, 15, 3);
		this.setBlock(world, x + 22, y + 17, z + 11, Blocks.wool, 15, 3);
		this.setBlock(world, x + 22, y + 17, z + 10, Blocks.wool, 15, 3);
		this.setBlock(world, x + 22, y + 17, z + 9, Blocks.wool, 15, 3);
		this.setBlock(world, x + 22, y + 17, z + 8, Blocks.wool, 15, 3);
		this.setBlock(world, x + 22, y + 17, z + 7, Blocks.wool, 15, 3);
		this.setBlock(world, x + 23, y + 17, z + 12, Blocks.wool, 15, 3);
		this.setBlock(world, x + 23, y + 17, z + 11, Blocks.wool, 15, 3);
		this.setBlock(world, x + 23, y + 17, z + 10, Blocks.wool, 15, 3);
		this.setBlock(world, x + 23, y + 17, z + 9, Blocks.wool, 15, 3);
		this.setBlock(world, x + 23, y + 17, z + 8, Blocks.wool, 15, 3);
		this.setBlock(world, x + 23, y + 17, z + 7, Blocks.wool, 15, 3);
		this.setBlock(world, x + 24, y + 17, z + 12, Blocks.wool, 15, 3);
		this.setBlock(world, x + 24, y + 17, z + 11, Blocks.wool, 15, 3);
		this.setBlock(world, x + 24, y + 17, z + 10, Blocks.wool, 15, 3);
		this.setBlock(world, x + 24, y + 17, z + 9, Blocks.wool, 15, 3);
		this.setBlock(world, x + 24, y + 17, z + 8, Blocks.wool, 15, 3);
		this.setBlock(world, x + 24, y + 17, z + 7, Blocks.wool, 15, 3);
		this.setBlock(world, x + 25, y + 17, z + 12, Blocks.wool, 15, 3);
		this.setBlock(world, x + 25, y + 17, z + 11, Blocks.wool, 15, 3);
		this.setBlock(world, x + 25, y + 17, z + 10, Blocks.wool, 15, 3);
		this.setBlock(world, x + 25, y + 17, z + 9, Blocks.wool, 15, 3);
		this.setBlock(world, x + 25, y + 17, z + 8, Blocks.wool, 15, 3);
		this.setBlock(world, x + 25, y + 17, z + 7, Blocks.wool, 15, 3);
		this.setBlock(world, x + 26, y + 17, z + 12, Blocks.wool, 15, 3);
		this.setBlock(world, x + 26, y + 17, z + 11, Blocks.wool, 15, 3);
		this.setBlock(world, x + 26, y + 17, z + 10, Blocks.wool, 15, 3);
		this.setBlock(world, x + 26, y + 17, z + 9, Blocks.wool, 15, 3);
		this.setBlock(world, x + 26, y + 17, z + 8, Blocks.wool, 15, 3);
		this.setBlock(world, x + 26, y + 17, z + 7, Blocks.wool, 15, 3);
		this.setBlock(world, x + 27, y + 17, z + 12, Blocks.wool, 15, 3);
		this.setBlock(world, x + 27, y + 17, z + 11, Blocks.wool, 15, 3);
		this.setBlock(world, x + 27, y + 17, z + 10, Blocks.wool, 15, 3);
		this.setBlock(world, x + 27, y + 17, z + 9, Blocks.wool, 15, 3);
		this.setBlock(world, x + 27, y + 17, z + 8, Blocks.wool, 15, 3);
		this.setBlock(world, x + 27, y + 17, z + 7, Blocks.wool, 15, 3);
		this.setBlock(world, x + 1, y + 18, z + 11, Blocks.wool, 15, 3);
		this.setBlock(world, x + 1, y + 18, z + 10, Blocks.wool, 15, 3);
		this.setBlock(world, x + 1, y + 18, z + 9, Blocks.wool, 15, 3);
		this.setBlock(world, x + 1, y + 18, z + 8, Blocks.wool, 15, 3);
		this.setBlock(world, x + 1, y + 18, z + 7, Blocks.wool, 15, 3);
		this.setBlock(world, x + 1, y + 18, z + 6, Blocks.wool, 15, 3);
		this.setBlock(world, x + 2, y + 18, z + 11, Blocks.iron_block, 0, 3);
		this.setBlock(world, x + 2, y + 18, z + 10, Blocks.wool, 15, 3);
		this.setBlock(world, x + 2, y + 18, z + 9, Blocks.wool, 15, 3);
		this.setBlock(world, x + 2, y + 18, z + 8, Blocks.wool, 15, 3);
		this.setBlock(world, x + 2, y + 18, z + 7, Blocks.wool, 15, 3);
		this.setBlock(world, x + 2, y + 18, z + 6, Blocks.wool, 15, 3);
		this.setBlock(world, x + 3, y + 18, z + 11, Blocks.iron_block, 0, 3);
		this.setBlock(world, x + 3, y + 18, z + 10, Blocks.wool, 15, 3);
		this.setBlock(world, x + 3, y + 18, z + 9, Blocks.wool, 15, 3);
		this.setBlock(world, x + 3, y + 18, z + 8, Blocks.wool, 15, 3);
		this.setBlock(world, x + 3, y + 18, z + 7, Blocks.wool, 15, 3);
		this.setBlock(world, x + 3, y + 18, z + 6, Blocks.wool, 15, 3);
		this.setBlock(world, x + 4, y + 18, z + 11, Blocks.iron_block, 0, 3);
		this.setBlock(world, x + 4, y + 18, z + 10, Blocks.wool, 15, 3);
		this.setBlock(world, x + 4, y + 18, z + 9, Blocks.wool, 15, 3);
		this.setBlock(world, x + 4, y + 18, z + 8, Blocks.wool, 15, 3);
		this.setBlock(world, x + 4, y + 18, z + 7, Blocks.wool, 15, 3);
		this.setBlock(world, x + 4, y + 18, z + 6, Blocks.wool, 15, 3);
		this.setBlock(world, x + 5, y + 18, z + 11, Blocks.iron_block, 0, 3);
		this.setBlock(world, x + 5, y + 18, z + 10, Blocks.wool, 15, 3);
		this.setBlock(world, x + 5, y + 18, z + 9, Blocks.wool, 15, 3);
		this.setBlock(world, x + 5, y + 18, z + 8, Blocks.wool, 15, 3);
		this.setBlock(world, x + 5, y + 18, z + 7, Blocks.wool, 15, 3);
		this.setBlock(world, x + 5, y + 18, z + 6, Blocks.wool, 15, 3);
		this.setBlock(world, x + 6, y + 18, z + 11, Blocks.wool, 15, 3);
		this.setBlock(world, x + 6, y + 18, z + 10, Blocks.wool, 15, 3);
		this.setBlock(world, x + 6, y + 18, z + 9, Blocks.wool, 15, 3);
		this.setBlock(world, x + 6, y + 18, z + 8, Blocks.wool, 15, 3);
		this.setBlock(world, x + 6, y + 18, z + 7, Blocks.wool, 15, 3);
		this.setBlock(world, x + 6, y + 18, z + 6, Blocks.wool, 15, 3);
		this.setBlock(world, x + 7, y + 18, z + 9, Blocks.wool, 15, 3);
		this.setBlock(world, x + 7, y + 18, z + 8, Blocks.wool, 15, 3);
		this.setBlock(world, x + 7, y + 18, z + 7, Blocks.wool, 15, 3);
		this.setBlock(world, x + 8, y + 18, z + 9, Blocks.wool, 15, 3);
		this.setBlock(world, x + 8, y + 18, z + 8, Blocks.wool, 15, 3);
		this.setBlock(world, x + 8, y + 18, z + 7, Blocks.wool, 15, 3);
		this.setBlock(world, x + 9, y + 18, z + 9, Blocks.wool, 15, 3);
		this.setBlock(world, x + 9, y + 18, z + 8, Blocks.wool, 15, 3);
		this.setBlock(world, x + 9, y + 18, z + 7, Blocks.wool, 15, 3);
		this.setBlock(world, x + 10, y + 18, z + 9, Blocks.wool, 15, 3);
		this.setBlock(world, x + 10, y + 18, z + 8, Blocks.wool, 15, 3);
		this.setBlock(world, x + 10, y + 18, z + 7, Blocks.wool, 15, 3);
		this.setBlock(world, x + 11, y + 18, z + 9, Blocks.wool, 15, 3);
		this.setBlock(world, x + 11, y + 18, z + 8, Blocks.wool, 15, 3);
		this.setBlock(world, x + 11, y + 18, z + 7, Blocks.wool, 15, 3);
		this.setBlock(world, x + 12, y + 18, z + 9, Blocks.wool, 15, 3);
		this.setBlock(world, x + 12, y + 18, z + 8, Blocks.wool, 15, 3);
		this.setBlock(world, x + 12, y + 18, z + 7, Blocks.wool, 15, 3);
		this.setBlock(world, x + 13, y + 18, z + 9, Blocks.wool, 15, 3);
		this.setBlock(world, x + 13, y + 18, z + 8, Blocks.wool, 15, 3);
		this.setBlock(world, x + 13, y + 18, z + 7, Blocks.wool, 15, 3);
		this.setBlock(world, x + 14, y + 18, z + 9, Blocks.wool, 15, 3);
		this.setBlock(world, x + 14, y + 18, z + 8, Blocks.wool, 15, 3);
		this.setBlock(world, x + 14, y + 18, z + 7, Blocks.wool, 15, 3);
		this.setBlock(world, x + 15, y + 18, z + 9, Blocks.wool, 15, 3);
		this.setBlock(world, x + 15, y + 18, z + 8, Blocks.wool, 15, 3);
		this.setBlock(world, x + 15, y + 18, z + 7, Blocks.wool, 15, 3);
		this.setBlock(world, x + 16, y + 18, z + 9, Blocks.wool, 15, 3);
		this.setBlock(world, x + 16, y + 18, z + 8, Blocks.wool, 15, 3);
		this.setBlock(world, x + 16, y + 18, z + 7, Blocks.wool, 15, 3);
		this.setBlock(world, x + 17, y + 18, z + 9, Blocks.wool, 15, 3);
		this.setBlock(world, x + 17, y + 18, z + 8, Blocks.wool, 15, 3);
		this.setBlock(world, x + 17, y + 18, z + 7, Blocks.wool, 15, 3);
		this.setBlock(world, x + 18, y + 18, z + 9, Blocks.wool, 15, 3);
		this.setBlock(world, x + 18, y + 18, z + 8, Blocks.wool, 15, 3);
		this.setBlock(world, x + 18, y + 18, z + 7, Blocks.wool, 15, 3);
		this.setBlock(world, x + 19, y + 18, z + 9, Blocks.wool, 15, 3);
		this.setBlock(world, x + 19, y + 18, z + 8, Blocks.wool, 15, 3);
		this.setBlock(world, x + 19, y + 18, z + 7, Blocks.wool, 15, 3);
		this.setBlock(world, x + 20, y + 18, z + 9, Blocks.wool, 15, 3);
		this.setBlock(world, x + 20, y + 18, z + 8, Blocks.wool, 15, 3);
		this.setBlock(world, x + 20, y + 18, z + 7, Blocks.wool, 15, 3);
		this.setBlock(world, x + 21, y + 18, z + 9, Blocks.wool, 15, 3);
		this.setBlock(world, x + 21, y + 18, z + 8, Blocks.wool, 15, 3);
		this.setBlock(world, x + 21, y + 18, z + 7, Blocks.wool, 15, 3);
		this.setBlock(world, x + 22, y + 18, z + 12, Blocks.wool, 15, 3);
		this.setBlock(world, x + 22, y + 18, z + 11, Blocks.wool, 15, 3);
		this.setBlock(world, x + 22, y + 18, z + 10, Blocks.wool, 15, 3);
		this.setBlock(world, x + 22, y + 18, z + 9, Blocks.wool, 15, 3);
		this.setBlock(world, x + 22, y + 18, z + 8, Blocks.wool, 15, 3);
		this.setBlock(world, x + 22, y + 18, z + 7, Blocks.wool, 15, 3);
		this.setBlock(world, x + 23, y + 18, z + 12, Blocks.iron_block, 0, 3);
		this.setBlock(world, x + 23, y + 18, z + 11, Blocks.wool, 15, 3);
		this.setBlock(world, x + 23, y + 18, z + 10, Blocks.wool, 15, 3);
		this.setBlock(world, x + 23, y + 18, z + 9, Blocks.wool, 15, 3);
		this.setBlock(world, x + 23, y + 18, z + 8, Blocks.wool, 15, 3);
		this.setBlock(world, x + 23, y + 18, z + 7, Blocks.wool, 15, 3);
		this.setBlock(world, x + 24, y + 18, z + 12, Blocks.iron_block, 0, 3);
		this.setBlock(world, x + 24, y + 18, z + 11, Blocks.wool, 15, 3);
		this.setBlock(world, x + 24, y + 18, z + 10, Blocks.wool, 15, 3);
		this.setBlock(world, x + 24, y + 18, z + 9, Blocks.wool, 15, 3);
		this.setBlock(world, x + 24, y + 18, z + 8, Blocks.wool, 15, 3);
		this.setBlock(world, x + 24, y + 18, z + 7, Blocks.wool, 15, 3);
		this.setBlock(world, x + 25, y + 18, z + 12, Blocks.iron_block, 0, 3);
		this.setBlock(world, x + 25, y + 18, z + 11, Blocks.wool, 15, 3);
		this.setBlock(world, x + 25, y + 18, z + 10, Blocks.wool, 15, 3);
		this.setBlock(world, x + 25, y + 18, z + 9, Blocks.wool, 15, 3);
		this.setBlock(world, x + 25, y + 18, z + 8, Blocks.wool, 15, 3);
		this.setBlock(world, x + 25, y + 18, z + 7, Blocks.wool, 15, 3);
		this.setBlock(world, x + 26, y + 18, z + 12, Blocks.iron_block, 0, 3);
		this.setBlock(world, x + 26, y + 18, z + 11, Blocks.wool, 15, 3);
		this.setBlock(world, x + 26, y + 18, z + 10, Blocks.wool, 15, 3);
		this.setBlock(world, x + 26, y + 18, z + 9, Blocks.wool, 15, 3);
		this.setBlock(world, x + 26, y + 18, z + 8, Blocks.wool, 15, 3);
		this.setBlock(world, x + 26, y + 18, z + 7, Blocks.wool, 15, 3);
		this.setBlock(world, x + 27, y + 18, z + 12, Blocks.wool, 15, 3);
		this.setBlock(world, x + 27, y + 18, z + 11, Blocks.wool, 15, 3);
		this.setBlock(world, x + 27, y + 18, z + 10, Blocks.wool, 15, 3);
		this.setBlock(world, x + 27, y + 18, z + 9, Blocks.wool, 15, 3);
		this.setBlock(world, x + 27, y + 18, z + 8, Blocks.wool, 15, 3);
		this.setBlock(world, x + 27, y + 18, z + 7, Blocks.wool, 15, 3);
		this.setBlock(world, x + 1, y + 19, z + 11, Blocks.wool, 15, 3);
		this.setBlock(world, x + 1, y + 19, z + 10, Blocks.wool, 15, 3);
		this.setBlock(world, x + 1, y + 19, z + 9, Blocks.wool, 15, 3);
		this.setBlock(world, x + 1, y + 19, z + 8, Blocks.wool, 15, 3);
		this.setBlock(world, x + 1, y + 19, z + 7, Blocks.wool, 15, 3);
		this.setBlock(world, x + 1, y + 19, z + 6, Blocks.wool, 15, 3);
		this.setBlock(world, x + 2, y + 19, z + 11, Blocks.wool, 15, 3);
		this.setBlock(world, x + 2, y + 19, z + 10, Blocks.wool, 15, 3);
		this.setBlock(world, x + 2, y + 19, z + 9, Blocks.wool, 15, 3);
		this.setBlock(world, x + 2, y + 19, z + 8, Blocks.wool, 15, 3);
		this.setBlock(world, x + 2, y + 19, z + 7, Blocks.wool, 15, 3);
		this.setBlock(world, x + 2, y + 19, z + 6, Blocks.wool, 15, 3);
		this.setBlock(world, x + 3, y + 19, z + 11, Blocks.wool, 15, 3);
		this.setBlock(world, x + 3, y + 19, z + 10, Blocks.wool, 15, 3);
		this.setBlock(world, x + 3, y + 19, z + 9, Blocks.wool, 15, 3);
		this.setBlock(world, x + 3, y + 19, z + 8, Blocks.wool, 15, 3);
		this.setBlock(world, x + 3, y + 19, z + 7, Blocks.wool, 15, 3);
		this.setBlock(world, x + 3, y + 19, z + 6, Blocks.wool, 15, 3);
		this.setBlock(world, x + 4, y + 19, z + 11, Blocks.wool, 15, 3);
		this.setBlock(world, x + 4, y + 19, z + 10, Blocks.wool, 15, 3);
		this.setBlock(world, x + 4, y + 19, z + 9, Blocks.wool, 15, 3);
		this.setBlock(world, x + 4, y + 19, z + 8, Blocks.wool, 15, 3);
		this.setBlock(world, x + 4, y + 19, z + 7, Blocks.wool, 15, 3);
		this.setBlock(world, x + 4, y + 19, z + 6, Blocks.wool, 15, 3);
		this.setBlock(world, x + 5, y + 19, z + 11, Blocks.wool, 15, 3);
		this.setBlock(world, x + 5, y + 19, z + 10, Blocks.wool, 15, 3);
		this.setBlock(world, x + 5, y + 19, z + 9, Blocks.wool, 15, 3);
		this.setBlock(world, x + 5, y + 19, z + 8, Blocks.wool, 15, 3);
		this.setBlock(world, x + 5, y + 19, z + 7, Blocks.wool, 15, 3);
		this.setBlock(world, x + 5, y + 19, z + 6, Blocks.wool, 15, 3);
		this.setBlock(world, x + 6, y + 19, z + 11, Blocks.wool, 15, 3);
		this.setBlock(world, x + 6, y + 19, z + 10, Blocks.wool, 15, 3);
		this.setBlock(world, x + 6, y + 19, z + 9, Blocks.wool, 15, 3);
		this.setBlock(world, x + 6, y + 19, z + 8, Blocks.wool, 15, 3);
		this.setBlock(world, x + 6, y + 19, z + 7, Blocks.wool, 15, 3);
		this.setBlock(world, x + 6, y + 19, z + 6, Blocks.wool, 15, 3);
		this.setBlock(world, x + 11, y + 19, z + 12, Blocks.wool, 15, 3);
		this.setBlock(world, x + 11, y + 19, z + 11, Blocks.wool, 15, 3);
		this.setBlock(world, x + 11, y + 19, z + 10, Blocks.wool, 15, 3);
		this.setBlock(world, x + 11, y + 19, z + 9, Blocks.wool, 15, 3);
		this.setBlock(world, x + 11, y + 19, z + 8, Blocks.wool, 15, 3);
		this.setBlock(world, x + 11, y + 19, z + 7, Blocks.wool, 15, 3);
		this.setBlock(world, x + 11, y + 19, z + 6, Blocks.wool, 15, 3);
		this.setBlock(world, x + 11, y + 19, z + 5, Blocks.wool, 15, 3);
		this.setBlock(world, x + 12, y + 19, z + 12, Blocks.wool, 15, 3);
		this.setBlock(world, x + 12, y + 19, z + 11, Blocks.wool, 15, 3);
		this.setBlock(world, x + 12, y + 19, z + 10, Blocks.wool, 15, 3);
		this.setBlock(world, x + 12, y + 19, z + 9, Blocks.wool, 15, 3);
		this.setBlock(world, x + 12, y + 19, z + 8, Blocks.wool, 15, 3);
		this.setBlock(world, x + 12, y + 19, z + 7, Blocks.wool, 15, 3);
		this.setBlock(world, x + 12, y + 19, z + 6, Blocks.wool, 15, 3);
		this.setBlock(world, x + 12, y + 19, z + 5, Blocks.wool, 15, 3);
		this.setBlock(world, x + 13, y + 19, z + 12, Blocks.wool, 15, 3);
		this.setBlock(world, x + 13, y + 19, z + 11, Blocks.wool, 15, 3);
		this.setBlock(world, x + 13, y + 19, z + 10, Blocks.wool, 15, 3);
		this.setBlock(world, x + 13, y + 19, z + 9, Blocks.wool, 15, 3);
		this.setBlock(world, x + 13, y + 19, z + 8, Blocks.wool, 15, 3);
		this.setBlock(world, x + 13, y + 19, z + 7, Blocks.wool, 15, 3);
		this.setBlock(world, x + 13, y + 19, z + 6, Blocks.wool, 15, 3);
		this.setBlock(world, x + 13, y + 19, z + 5, Blocks.wool, 15, 3);
		this.setBlock(world, x + 14, y + 19, z + 12, Blocks.wool, 15, 3);
		this.setBlock(world, x + 14, y + 19, z + 11, Blocks.wool, 15, 3);
		this.setBlock(world, x + 14, y + 19, z + 10, Blocks.wool, 15, 3);
		this.setBlock(world, x + 14, y + 19, z + 9, Blocks.wool, 15, 3);
		this.setBlock(world, x + 14, y + 19, z + 8, Blocks.wool, 15, 3);
		this.setBlock(world, x + 14, y + 19, z + 7, Blocks.wool, 15, 3);
		this.setBlock(world, x + 14, y + 19, z + 6, Blocks.wool, 15, 3);
		this.setBlock(world, x + 14, y + 19, z + 5, Blocks.wool, 15, 3);
		this.setBlock(world, x + 15, y + 19, z + 12, Blocks.wool, 15, 3);
		this.setBlock(world, x + 15, y + 19, z + 11, Blocks.wool, 15, 3);
		this.setBlock(world, x + 15, y + 19, z + 10, Blocks.wool, 15, 3);
		this.setBlock(world, x + 15, y + 19, z + 9, Blocks.wool, 15, 3);
		this.setBlock(world, x + 15, y + 19, z + 8, Blocks.wool, 15, 3);
		this.setBlock(world, x + 15, y + 19, z + 7, Blocks.wool, 15, 3);
		this.setBlock(world, x + 15, y + 19, z + 6, Blocks.wool, 15, 3);
		this.setBlock(world, x + 15, y + 19, z + 5, Blocks.wool, 15, 3);
		this.setBlock(world, x + 16, y + 19, z + 12, Blocks.wool, 15, 3);
		this.setBlock(world, x + 16, y + 19, z + 11, Blocks.wool, 15, 3);
		this.setBlock(world, x + 16, y + 19, z + 10, Blocks.wool, 15, 3);
		this.setBlock(world, x + 16, y + 19, z + 9, Blocks.wool, 15, 3);
		this.setBlock(world, x + 16, y + 19, z + 8, Blocks.wool, 15, 3);
		this.setBlock(world, x + 16, y + 19, z + 7, Blocks.wool, 15, 3);
		this.setBlock(world, x + 16, y + 19, z + 6, Blocks.wool, 15, 3);
		this.setBlock(world, x + 16, y + 19, z + 5, Blocks.wool, 15, 3);
		this.setBlock(world, x + 17, y + 19, z + 12, Blocks.wool, 15, 3);
		this.setBlock(world, x + 17, y + 19, z + 11, Blocks.wool, 15, 3);
		this.setBlock(world, x + 17, y + 19, z + 10, Blocks.wool, 15, 3);
		this.setBlock(world, x + 17, y + 19, z + 9, Blocks.wool, 15, 3);
		this.setBlock(world, x + 17, y + 19, z + 8, Blocks.wool, 15, 3);
		this.setBlock(world, x + 17, y + 19, z + 7, Blocks.wool, 15, 3);
		this.setBlock(world, x + 17, y + 19, z + 6, Blocks.wool, 15, 3);
		this.setBlock(world, x + 17, y + 19, z + 5, Blocks.wool, 15, 3);
		this.setBlock(world, x + 18, y + 19, z + 12, Blocks.wool, 15, 3);
		this.setBlock(world, x + 18, y + 19, z + 11, Blocks.wool, 15, 3);
		this.setBlock(world, x + 18, y + 19, z + 10, Blocks.wool, 15, 3);
		this.setBlock(world, x + 18, y + 19, z + 9, Blocks.wool, 15, 3);
		this.setBlock(world, x + 18, y + 19, z + 8, Blocks.wool, 15, 3);
		this.setBlock(world, x + 18, y + 19, z + 7, Blocks.wool, 15, 3);
		this.setBlock(world, x + 18, y + 19, z + 6, Blocks.wool, 15, 3);
		this.setBlock(world, x + 18, y + 19, z + 5, Blocks.wool, 15, 3);
		this.setBlock(world, x + 22, y + 19, z + 12, Blocks.wool, 15, 3);
		this.setBlock(world, x + 22, y + 19, z + 11, Blocks.wool, 15, 3);
		this.setBlock(world, x + 22, y + 19, z + 10, Blocks.wool, 15, 3);
		this.setBlock(world, x + 22, y + 19, z + 9, Blocks.wool, 15, 3);
		this.setBlock(world, x + 22, y + 19, z + 8, Blocks.wool, 15, 3);
		this.setBlock(world, x + 22, y + 19, z + 7, Blocks.wool, 15, 3);
		this.setBlock(world, x + 23, y + 19, z + 12, Blocks.wool, 15, 3);
		this.setBlock(world, x + 23, y + 19, z + 11, Blocks.wool, 15, 3);
		this.setBlock(world, x + 23, y + 19, z + 10, Blocks.wool, 15, 3);
		this.setBlock(world, x + 23, y + 19, z + 9, Blocks.wool, 15, 3);
		this.setBlock(world, x + 23, y + 19, z + 8, Blocks.wool, 15, 3);
		this.setBlock(world, x + 23, y + 19, z + 7, Blocks.wool, 15, 3);
		this.setBlock(world, x + 24, y + 19, z + 12, Blocks.wool, 15, 3);
		this.setBlock(world, x + 24, y + 19, z + 11, Blocks.wool, 15, 3);
		this.setBlock(world, x + 24, y + 19, z + 10, Blocks.wool, 15, 3);
		this.setBlock(world, x + 24, y + 19, z + 9, Blocks.wool, 15, 3);
		this.setBlock(world, x + 24, y + 19, z + 8, Blocks.wool, 15, 3);
		this.setBlock(world, x + 24, y + 19, z + 7, Blocks.wool, 15, 3);
		this.setBlock(world, x + 25, y + 19, z + 12, Blocks.wool, 15, 3);
		this.setBlock(world, x + 25, y + 19, z + 11, Blocks.wool, 15, 3);
		this.setBlock(world, x + 25, y + 19, z + 10, Blocks.wool, 15, 3);
		this.setBlock(world, x + 25, y + 19, z + 9, Blocks.wool, 15, 3);
		this.setBlock(world, x + 25, y + 19, z + 8, Blocks.wool, 15, 3);
		this.setBlock(world, x + 25, y + 19, z + 7, Blocks.wool, 15, 3);
		this.setBlock(world, x + 26, y + 19, z + 12, Blocks.wool, 15, 3);
		this.setBlock(world, x + 26, y + 19, z + 11, Blocks.wool, 15, 3);
		this.setBlock(world, x + 26, y + 19, z + 10, Blocks.wool, 15, 3);
		this.setBlock(world, x + 26, y + 19, z + 9, Blocks.wool, 15, 3);
		this.setBlock(world, x + 26, y + 19, z + 8, Blocks.wool, 15, 3);
		this.setBlock(world, x + 26, y + 19, z + 7, Blocks.wool, 15, 3);
		this.setBlock(world, x + 27, y + 19, z + 12, Blocks.wool, 15, 3);
		this.setBlock(world, x + 27, y + 19, z + 11, Blocks.wool, 15, 3);
		this.setBlock(world, x + 27, y + 19, z + 10, Blocks.wool, 15, 3);
		this.setBlock(world, x + 27, y + 19, z + 9, Blocks.wool, 15, 3);
		this.setBlock(world, x + 27, y + 19, z + 8, Blocks.wool, 15, 3);
		this.setBlock(world, x + 27, y + 19, z + 7, Blocks.wool, 15, 3);
		this.setBlock(world, x + 1, y + 20, z + 11, Blocks.iron_block, 0, 3);
		this.setBlock(world, x + 1, y + 20, z + 10, Blocks.wool, 15, 3);
		this.setBlock(world, x + 1, y + 20, z + 9, Blocks.wool, 15, 3);
		this.setBlock(world, x + 1, y + 20, z + 8, Blocks.wool, 15, 3);
		this.setBlock(world, x + 1, y + 20, z + 7, Blocks.wool, 15, 3);
		this.setBlock(world, x + 1, y + 20, z + 6, Blocks.wool, 15, 3);
		this.setBlock(world, x + 2, y + 20, z + 11, Blocks.iron_block, 0, 3);
		this.setBlock(world, x + 2, y + 20, z + 10, Blocks.wool, 15, 3);
		this.setBlock(world, x + 2, y + 20, z + 9, Blocks.wool, 15, 3);
		this.setBlock(world, x + 2, y + 20, z + 8, Blocks.wool, 15, 3);
		this.setBlock(world, x + 2, y + 20, z + 7, Blocks.wool, 15, 3);
		this.setBlock(world, x + 2, y + 20, z + 6, Blocks.wool, 15, 3);
		this.setBlock(world, x + 3, y + 20, z + 11, Blocks.wool, 15, 3);
		this.setBlock(world, x + 3, y + 20, z + 10, Blocks.wool, 15, 3);
		this.setBlock(world, x + 3, y + 20, z + 9, Blocks.wool, 15, 3);
		this.setBlock(world, x + 3, y + 20, z + 8, Blocks.wool, 15, 3);
		this.setBlock(world, x + 3, y + 20, z + 7, Blocks.wool, 15, 3);
		this.setBlock(world, x + 3, y + 20, z + 6, Blocks.wool, 15, 3);
		this.setBlock(world, x + 4, y + 20, z + 11, Blocks.wool, 15, 3);
		this.setBlock(world, x + 4, y + 20, z + 10, Blocks.wool, 15, 3);
		this.setBlock(world, x + 4, y + 20, z + 9, Blocks.wool, 15, 3);
		this.setBlock(world, x + 4, y + 20, z + 8, Blocks.wool, 15, 3);
		this.setBlock(world, x + 4, y + 20, z + 7, Blocks.wool, 15, 3);
		this.setBlock(world, x + 4, y + 20, z + 6, Blocks.wool, 15, 3);
		this.setBlock(world, x + 5, y + 20, z + 11, Blocks.iron_block, 0, 3);
		this.setBlock(world, x + 5, y + 20, z + 10, Blocks.wool, 15, 3);
		this.setBlock(world, x + 5, y + 20, z + 9, Blocks.wool, 15, 3);
		this.setBlock(world, x + 5, y + 20, z + 8, Blocks.wool, 15, 3);
		this.setBlock(world, x + 5, y + 20, z + 7, Blocks.wool, 15, 3);
		this.setBlock(world, x + 5, y + 20, z + 6, Blocks.wool, 15, 3);
		this.setBlock(world, x + 6, y + 20, z + 11, Blocks.iron_block, 0, 3);
		this.setBlock(world, x + 6, y + 20, z + 10, Blocks.wool, 15, 3);
		this.setBlock(world, x + 6, y + 20, z + 9, Blocks.wool, 15, 3);
		this.setBlock(world, x + 6, y + 20, z + 8, Blocks.wool, 15, 3);
		this.setBlock(world, x + 6, y + 20, z + 7, Blocks.wool, 15, 3);
		this.setBlock(world, x + 6, y + 20, z + 6, Blocks.wool, 15, 3);
		this.setBlock(world, x + 11, y + 20, z + 12, Blocks.wool, 15, 3);
		this.setBlock(world, x + 11, y + 20, z + 11, Blocks.wool, 15, 3);
		this.setBlock(world, x + 11, y + 20, z + 10, Blocks.wool, 15, 3);
		this.setBlock(world, x + 11, y + 20, z + 9, Blocks.wool, 15, 3);
		this.setBlock(world, x + 11, y + 20, z + 8, Blocks.wool, 15, 3);
		this.setBlock(world, x + 11, y + 20, z + 7, Blocks.obsidian, 0, 3);
		this.setBlock(world, x + 11, y + 20, z + 6, Blocks.wool, 15, 3);
		this.setBlock(world, x + 11, y + 20, z + 5, Blocks.wool, 15, 3);
		this.setBlock(world, x + 12, y + 20, z + 12, Blocks.wool, 15, 3);
		this.setBlock(world, x + 12, y + 20, z + 11, Blocks.wool, 15, 3);
		this.setBlock(world, x + 12, y + 20, z + 10, Blocks.wool, 15, 3);
		this.setBlock(world, x + 12, y + 20, z + 9, Blocks.wool, 15, 3);
		this.setBlock(world, x + 12, y + 20, z + 8, Blocks.wool, 15, 3);
		this.setBlock(world, x + 12, y + 20, z + 7, Blocks.wool, 15, 3);
		this.setBlock(world, x + 12, y + 20, z + 6, Blocks.wool, 15, 3);
		this.setBlock(world, x + 12, y + 20, z + 5, Blocks.wool, 15, 3);
		this.setBlock(world, x + 13, y + 20, z + 12, Blocks.iron_block, 0, 3);
		this.setBlock(world, x + 13, y + 20, z + 11, Blocks.iron_block, 0, 3);
		this.setBlock(world, x + 13, y + 20, z + 10, Blocks.iron_block, 0, 3);
		this.setBlock(world, x + 13, y + 20, z + 9, Blocks.wool, 15, 3);
		this.setBlock(world, x + 13, y + 20, z + 8, Blocks.wool, 15, 3);
		this.setBlock(world, x + 13, y + 20, z + 7, Blocks.wool, 15, 3);
		this.setBlock(world, x + 13, y + 20, z + 6, Blocks.wool, 15, 3);
		this.setBlock(world, x + 13, y + 20, z + 5, Blocks.wool, 15, 3);
		this.setBlock(world, x + 14, y + 20, z + 12, Blocks.iron_block, 0, 3);
		this.setBlock(world, x + 14, y + 20, z + 11, Blocks.wool, 15, 3);
		this.setBlock(world, x + 14, y + 20, z + 10, Blocks.iron_block, 0, 3);
		this.setBlock(world, x + 14, y + 20, z + 9, Blocks.iron_block, 0, 3);
		this.setBlock(world, x + 14, y + 20, z + 8, Blocks.wool, 15, 3);
		this.setBlock(world, x + 14, y + 20, z + 7, Blocks.wool, 15, 3);
		this.setBlock(world, x + 14, y + 20, z + 6, Blocks.wool, 15, 3);
		this.setBlock(world, x + 14, y + 20, z + 5, Blocks.wool, 15, 3);
		this.setBlock(world, x + 15, y + 20, z + 12, Blocks.iron_block, 0, 3);
		this.setBlock(world, x + 15, y + 20, z + 11, Blocks.wool, 15, 3);
		this.setBlock(world, x + 15, y + 20, z + 10, Blocks.iron_block, 0, 3);
		this.setBlock(world, x + 15, y + 20, z + 9, Blocks.iron_block, 0, 3);
		this.setBlock(world, x + 15, y + 20, z + 8, Blocks.wool, 15, 3);
		this.setBlock(world, x + 15, y + 20, z + 7, Blocks.wool, 15, 3);
		this.setBlock(world, x + 15, y + 20, z + 6, Blocks.wool, 15, 3);
		this.setBlock(world, x + 15, y + 20, z + 5, Blocks.wool, 15, 3);
		this.setBlock(world, x + 16, y + 20, z + 12, Blocks.iron_block, 0, 3);
		this.setBlock(world, x + 16, y + 20, z + 11, Blocks.iron_block, 0, 3);
		this.setBlock(world, x + 16, y + 20, z + 10, Blocks.iron_block, 0, 3);
		this.setBlock(world, x + 16, y + 20, z + 9, Blocks.wool, 15, 3);
		this.setBlock(world, x + 16, y + 20, z + 8, Blocks.wool, 15, 3);
		this.setBlock(world, x + 16, y + 20, z + 7, Blocks.wool, 15, 3);
		this.setBlock(world, x + 16, y + 20, z + 6, Blocks.wool, 15, 3);
		this.setBlock(world, x + 16, y + 20, z + 5, Blocks.wool, 15, 3);
		this.setBlock(world, x + 17, y + 20, z + 12, Blocks.wool, 15, 3);
		this.setBlock(world, x + 17, y + 20, z + 11, Blocks.wool, 15, 3);
		this.setBlock(world, x + 17, y + 20, z + 10, Blocks.wool, 15, 3);
		this.setBlock(world, x + 17, y + 20, z + 9, Blocks.wool, 15, 3);
		this.setBlock(world, x + 17, y + 20, z + 8, Blocks.wool, 15, 3);
		this.setBlock(world, x + 17, y + 20, z + 7, Blocks.wool, 15, 3);
		this.setBlock(world, x + 17, y + 20, z + 6, Blocks.wool, 15, 3);
		this.setBlock(world, x + 17, y + 20, z + 5, Blocks.wool, 15, 3);
		this.setBlock(world, x + 18, y + 20, z + 12, Blocks.wool, 15, 3);
		this.setBlock(world, x + 18, y + 20, z + 11, Blocks.wool, 15, 3);
		this.setBlock(world, x + 18, y + 20, z + 10, Blocks.wool, 15, 3);
		this.setBlock(world, x + 18, y + 20, z + 9, Blocks.wool, 15, 3);
		this.setBlock(world, x + 18, y + 20, z + 8, Blocks.wool, 15, 3);
		this.setBlock(world, x + 18, y + 20, z + 7, Blocks.obsidian, 0, 3);
		this.setBlock(world, x + 18, y + 20, z + 6, Blocks.wool, 15, 3);
		this.setBlock(world, x + 18, y + 20, z + 5, Blocks.wool, 15, 3);
		this.setBlock(world, x + 22, y + 20, z + 12, Blocks.iron_block, 0, 3);
		this.setBlock(world, x + 22, y + 20, z + 11, Blocks.wool, 15, 3);
		this.setBlock(world, x + 22, y + 20, z + 10, Blocks.wool, 15, 3);
		this.setBlock(world, x + 22, y + 20, z + 9, Blocks.wool, 15, 3);
		this.setBlock(world, x + 22, y + 20, z + 8, Blocks.wool, 15, 3);
		this.setBlock(world, x + 22, y + 20, z + 7, Blocks.wool, 15, 3);
		this.setBlock(world, x + 23, y + 20, z + 12, Blocks.iron_block, 0, 3);
		this.setBlock(world, x + 23, y + 20, z + 11, Blocks.wool, 15, 3);
		this.setBlock(world, x + 23, y + 20, z + 10, Blocks.wool, 15, 3);
		this.setBlock(world, x + 23, y + 20, z + 9, Blocks.wool, 15, 3);
		this.setBlock(world, x + 23, y + 20, z + 8, Blocks.wool, 15, 3);
		this.setBlock(world, x + 23, y + 20, z + 7, Blocks.wool, 15, 3);
		this.setBlock(world, x + 24, y + 20, z + 12, Blocks.wool, 15, 3);
		this.setBlock(world, x + 24, y + 20, z + 11, Blocks.wool, 15, 3);
		this.setBlock(world, x + 24, y + 20, z + 10, Blocks.wool, 15, 3);
		this.setBlock(world, x + 24, y + 20, z + 9, Blocks.wool, 15, 3);
		this.setBlock(world, x + 24, y + 20, z + 8, Blocks.wool, 15, 3);
		this.setBlock(world, x + 24, y + 20, z + 7, Blocks.wool, 15, 3);
		this.setBlock(world, x + 25, y + 20, z + 12, Blocks.wool, 15, 3);
		this.setBlock(world, x + 25, y + 20, z + 11, Blocks.wool, 15, 3);
		this.setBlock(world, x + 25, y + 20, z + 10, Blocks.wool, 15, 3);
		this.setBlock(world, x + 25, y + 20, z + 9, Blocks.wool, 15, 3);
		this.setBlock(world, x + 25, y + 20, z + 8, Blocks.wool, 15, 3);
		this.setBlock(world, x + 25, y + 20, z + 7, Blocks.wool, 15, 3);
		this.setBlock(world, x + 26, y + 20, z + 12, Blocks.iron_block, 0, 3);
		this.setBlock(world, x + 26, y + 20, z + 11, Blocks.wool, 15, 3);
		this.setBlock(world, x + 26, y + 20, z + 10, Blocks.wool, 15, 3);
		this.setBlock(world, x + 26, y + 20, z + 9, Blocks.wool, 15, 3);
		this.setBlock(world, x + 26, y + 20, z + 8, Blocks.wool, 15, 3);
		this.setBlock(world, x + 26, y + 20, z + 7, Blocks.wool, 15, 3);
		this.setBlock(world, x + 27, y + 20, z + 12, Blocks.iron_block, 0, 3);
		this.setBlock(world, x + 27, y + 20, z + 11, Blocks.wool, 15, 3);
		this.setBlock(world, x + 27, y + 20, z + 10, Blocks.wool, 15, 3);
		this.setBlock(world, x + 27, y + 20, z + 9, Blocks.wool, 15, 3);
		this.setBlock(world, x + 27, y + 20, z + 8, Blocks.wool, 15, 3);
		this.setBlock(world, x + 27, y + 20, z + 7, Blocks.wool, 15, 3);
		this.setBlock(world, x + 1, y + 21, z + 11, Blocks.obsidian, 0, 3);
		this.setBlock(world, x + 1, y + 21, z + 10, Blocks.wool, 15, 3);
		this.setBlock(world, x + 1, y + 21, z + 9, Blocks.wool, 15, 3);
		this.setBlock(world, x + 1, y + 21, z + 8, Blocks.wool, 15, 3);
		this.setBlock(world, x + 1, y + 21, z + 7, Blocks.wool, 15, 3);
		this.setBlock(world, x + 1, y + 21, z + 6, Blocks.wool, 15, 3);
		this.setBlock(world, x + 2, y + 21, z + 11, Blocks.obsidian, 0, 3);
		this.setBlock(world, x + 2, y + 21, z + 10, Blocks.wool, 15, 3);
		this.setBlock(world, x + 2, y + 21, z + 9, Blocks.wool, 15, 3);
		this.setBlock(world, x + 2, y + 21, z + 8, Blocks.wool, 15, 3);
		this.setBlock(world, x + 2, y + 21, z + 7, Blocks.wool, 15, 3);
		this.setBlock(world, x + 2, y + 21, z + 6, Blocks.wool, 15, 3);
		this.setBlock(world, x + 3, y + 21, z + 11, Blocks.wool, 15, 3);
		this.setBlock(world, x + 3, y + 21, z + 10, Blocks.wool, 15, 3);
		this.setBlock(world, x + 3, y + 21, z + 9, Blocks.wool, 15, 3);
		this.setBlock(world, x + 3, y + 21, z + 8, Blocks.wool, 15, 3);
		this.setBlock(world, x + 3, y + 21, z + 7, Blocks.wool, 15, 3);
		this.setBlock(world, x + 3, y + 21, z + 6, Blocks.wool, 15, 3);
		this.setBlock(world, x + 4, y + 21, z + 11, Blocks.wool, 15, 3);
		this.setBlock(world, x + 4, y + 21, z + 10, Blocks.wool, 15, 3);
		this.setBlock(world, x + 4, y + 21, z + 9, Blocks.wool, 15, 3);
		this.setBlock(world, x + 4, y + 21, z + 8, Blocks.wool, 15, 3);
		this.setBlock(world, x + 4, y + 21, z + 7, Blocks.wool, 15, 3);
		this.setBlock(world, x + 4, y + 21, z + 6, Blocks.wool, 15, 3);
		this.setBlock(world, x + 5, y + 21, z + 11, Blocks.obsidian, 0, 3);
		this.setBlock(world, x + 5, y + 21, z + 10, Blocks.wool, 15, 3);
		this.setBlock(world, x + 5, y + 21, z + 9, Blocks.wool, 15, 3);
		this.setBlock(world, x + 5, y + 21, z + 8, Blocks.wool, 15, 3);
		this.setBlock(world, x + 5, y + 21, z + 7, Blocks.wool, 15, 3);
		this.setBlock(world, x + 5, y + 21, z + 6, Blocks.wool, 15, 3);
		this.setBlock(world, x + 6, y + 21, z + 11, Blocks.obsidian, 0, 3);
		this.setBlock(world, x + 6, y + 21, z + 10, Blocks.wool, 15, 3);
		this.setBlock(world, x + 6, y + 21, z + 9, Blocks.wool, 15, 3);
		this.setBlock(world, x + 6, y + 21, z + 8, Blocks.wool, 15, 3);
		this.setBlock(world, x + 6, y + 21, z + 7, Blocks.wool, 15, 3);
		this.setBlock(world, x + 6, y + 21, z + 6, Blocks.wool, 15, 3);
		this.setBlock(world, x + 11, y + 21, z + 12, Blocks.wool, 15, 3);
		this.setBlock(world, x + 11, y + 21, z + 11, Blocks.wool, 15, 3);
		this.setBlock(world, x + 11, y + 21, z + 10, Blocks.wool, 15, 3);
		this.setBlock(world, x + 11, y + 21, z + 9, Blocks.wool, 15, 3);
		this.setBlock(world, x + 11, y + 21, z + 8, Blocks.wool, 15, 3);
		this.setBlock(world, x + 11, y + 21, z + 7, Blocks.wool, 15, 3);
		this.setBlock(world, x + 11, y + 21, z + 6, Blocks.wool, 15, 3);
		this.setBlock(world, x + 11, y + 21, z + 5, Blocks.wool, 15, 3);
		this.setBlock(world, x + 12, y + 21, z + 12, Blocks.wool, 15, 3);
		this.setBlock(world, x + 12, y + 21, z + 11, Blocks.wool, 15, 3);
		this.setBlock(world, x + 12, y + 21, z + 10, Blocks.wool, 15, 3);
		this.setBlock(world, x + 12, y + 21, z + 9, Blocks.wool, 15, 3);
		this.setBlock(world, x + 12, y + 21, z + 8, Blocks.wool, 15, 3);
		this.setBlock(world, x + 12, y + 21, z + 7, Blocks.wool, 15, 3);
		this.setBlock(world, x + 12, y + 21, z + 6, Blocks.wool, 15, 3);
		this.setBlock(world, x + 12, y + 21, z + 5, Blocks.wool, 15, 3);
		this.setBlock(world, x + 13, y + 21, z + 12, Blocks.wool, 15, 3);
		this.setBlock(world, x + 13, y + 21, z + 11, Blocks.wool, 15, 3);
		this.setBlock(world, x + 13, y + 21, z + 10, Blocks.wool, 15, 3);
		this.setBlock(world, x + 13, y + 21, z + 9, Blocks.wool, 15, 3);
		this.setBlock(world, x + 13, y + 21, z + 8, Blocks.wool, 15, 3);
		this.setBlock(world, x + 13, y + 21, z + 7, Blocks.wool, 15, 3);
		this.setBlock(world, x + 13, y + 21, z + 6, Blocks.wool, 15, 3);
		this.setBlock(world, x + 13, y + 21, z + 5, Blocks.wool, 15, 3);
		this.setBlock(world, x + 14, y + 21, z + 12, Blocks.wool, 15, 3);
		this.setBlock(world, x + 14, y + 21, z + 11, Blocks.wool, 15, 3);
		this.setBlock(world, x + 14, y + 21, z + 10, Blocks.wool, 15, 3);
		this.setBlock(world, x + 14, y + 21, z + 9, Blocks.wool, 15, 3);
		this.setBlock(world, x + 14, y + 21, z + 8, Blocks.beacon, 0, 3);
		this.setBlock(world, x + 14, y + 21, z + 7, Blocks.beacon, 0, 3);
		this.setBlock(world, x + 14, y + 21, z + 6, Blocks.wool, 15, 3);
		this.setBlock(world, x + 14, y + 21, z + 5, Blocks.wool, 15, 3);
		this.setBlock(world, x + 15, y + 21, z + 12, Blocks.wool, 15, 3);
		this.setBlock(world, x + 15, y + 21, z + 11, Blocks.wool, 15, 3);
		this.setBlock(world, x + 15, y + 21, z + 10, Blocks.wool, 15, 3);
		this.setBlock(world, x + 15, y + 21, z + 9, Blocks.wool, 15, 3);
		this.setBlock(world, x + 15, y + 21, z + 8, Blocks.beacon, 0, 3);
		this.setBlock(world, x + 15, y + 21, z + 7, Blocks.beacon, 0, 3);
		this.setBlock(world, x + 15, y + 21, z + 6, Blocks.wool, 15, 3);
		this.setBlock(world, x + 15, y + 21, z + 5, Blocks.wool, 15, 3);
		this.setBlock(world, x + 16, y + 21, z + 12, Blocks.wool, 15, 3);
		this.setBlock(world, x + 16, y + 21, z + 11, Blocks.wool, 15, 3);
		this.setBlock(world, x + 16, y + 21, z + 10, Blocks.wool, 15, 3);
		this.setBlock(world, x + 16, y + 21, z + 9, Blocks.wool, 15, 3);
		this.setBlock(world, x + 16, y + 21, z + 8, Blocks.wool, 15, 3);
		this.setBlock(world, x + 16, y + 21, z + 7, Blocks.wool, 15, 3);
		this.setBlock(world, x + 16, y + 21, z + 6, Blocks.wool, 15, 3);
		this.setBlock(world, x + 16, y + 21, z + 5, Blocks.wool, 15, 3);
		this.setBlock(world, x + 17, y + 21, z + 12, Blocks.wool, 15, 3);
		this.setBlock(world, x + 17, y + 21, z + 11, Blocks.wool, 15, 3);
		this.setBlock(world, x + 17, y + 21, z + 10, Blocks.wool, 15, 3);
		this.setBlock(world, x + 17, y + 21, z + 9, Blocks.wool, 15, 3);
		this.setBlock(world, x + 17, y + 21, z + 8, Blocks.wool, 15, 3);
		this.setBlock(world, x + 17, y + 21, z + 7, Blocks.wool, 15, 3);
		this.setBlock(world, x + 17, y + 21, z + 6, Blocks.wool, 15, 3);
		this.setBlock(world, x + 17, y + 21, z + 5, Blocks.wool, 15, 3);
		this.setBlock(world, x + 18, y + 21, z + 12, Blocks.wool, 15, 3);
		this.setBlock(world, x + 18, y + 21, z + 11, Blocks.wool, 15, 3);
		this.setBlock(world, x + 18, y + 21, z + 10, Blocks.wool, 15, 3);
		this.setBlock(world, x + 18, y + 21, z + 9, Blocks.wool, 15, 3);
		this.setBlock(world, x + 18, y + 21, z + 8, Blocks.wool, 15, 3);
		this.setBlock(world, x + 18, y + 21, z + 7, Blocks.wool, 15, 3);
		this.setBlock(world, x + 18, y + 21, z + 6, Blocks.wool, 15, 3);
		this.setBlock(world, x + 18, y + 21, z + 5, Blocks.wool, 15, 3);
		this.setBlock(world, x + 22, y + 21, z + 12, Blocks.obsidian, 0, 3);
		this.setBlock(world, x + 22, y + 21, z + 11, Blocks.wool, 15, 3);
		this.setBlock(world, x + 22, y + 21, z + 10, Blocks.wool, 15, 3);
		this.setBlock(world, x + 22, y + 21, z + 9, Blocks.wool, 15, 3);
		this.setBlock(world, x + 22, y + 21, z + 8, Blocks.wool, 15, 3);
		this.setBlock(world, x + 22, y + 21, z + 7, Blocks.wool, 15, 3);
		this.setBlock(world, x + 23, y + 21, z + 12, Blocks.obsidian, 0, 3);
		this.setBlock(world, x + 23, y + 21, z + 11, Blocks.wool, 15, 3);
		this.setBlock(world, x + 23, y + 21, z + 10, Blocks.wool, 15, 3);
		this.setBlock(world, x + 23, y + 21, z + 9, Blocks.wool, 15, 3);
		this.setBlock(world, x + 23, y + 21, z + 8, Blocks.wool, 15, 3);
		this.setBlock(world, x + 23, y + 21, z + 7, Blocks.wool, 15, 3);
		this.setBlock(world, x + 24, y + 21, z + 12, Blocks.wool, 15, 3);
		this.setBlock(world, x + 24, y + 21, z + 11, Blocks.wool, 15, 3);
		this.setBlock(world, x + 24, y + 21, z + 10, Blocks.wool, 15, 3);
		this.setBlock(world, x + 24, y + 21, z + 9, Blocks.wool, 15, 3);
		this.setBlock(world, x + 24, y + 21, z + 8, Blocks.wool, 15, 3);
		this.setBlock(world, x + 24, y + 21, z + 7, Blocks.wool, 15, 3);
		this.setBlock(world, x + 25, y + 21, z + 12, Blocks.wool, 15, 3);
		this.setBlock(world, x + 25, y + 21, z + 11, Blocks.wool, 15, 3);
		this.setBlock(world, x + 25, y + 21, z + 10, Blocks.wool, 15, 3);
		this.setBlock(world, x + 25, y + 21, z + 9, Blocks.wool, 15, 3);
		this.setBlock(world, x + 25, y + 21, z + 8, Blocks.wool, 15, 3);
		this.setBlock(world, x + 25, y + 21, z + 7, Blocks.wool, 15, 3);
		this.setBlock(world, x + 26, y + 21, z + 12, Blocks.obsidian, 0, 3);
		this.setBlock(world, x + 26, y + 21, z + 11, Blocks.wool, 15, 3);
		this.setBlock(world, x + 26, y + 21, z + 10, Blocks.wool, 15, 3);
		this.setBlock(world, x + 26, y + 21, z + 9, Blocks.wool, 15, 3);
		this.setBlock(world, x + 26, y + 21, z + 8, Blocks.wool, 15, 3);
		this.setBlock(world, x + 26, y + 21, z + 7, Blocks.wool, 15, 3);
		this.setBlock(world, x + 27, y + 21, z + 12, Blocks.obsidian, 0, 3);
		this.setBlock(world, x + 27, y + 21, z + 11, Blocks.wool, 15, 3);
		this.setBlock(world, x + 27, y + 21, z + 10, Blocks.wool, 15, 3);
		this.setBlock(world, x + 27, y + 21, z + 9, Blocks.wool, 15, 3);
		this.setBlock(world, x + 27, y + 21, z + 8, Blocks.wool, 15, 3);
		this.setBlock(world, x + 27, y + 21, z + 7, Blocks.wool, 15, 3);
		this.setBlock(world, x + 1, y + 22, z + 11, Blocks.wool, 15, 3);
		this.setBlock(world, x + 1, y + 22, z + 10, Blocks.wool, 15, 3);
		this.setBlock(world, x + 1, y + 22, z + 9, Blocks.wool, 15, 3);
		this.setBlock(world, x + 1, y + 22, z + 8, Blocks.wool, 15, 3);
		this.setBlock(world, x + 1, y + 22, z + 7, Blocks.wool, 15, 3);
		this.setBlock(world, x + 1, y + 22, z + 6, Blocks.wool, 15, 3);
		this.setBlock(world, x + 2, y + 22, z + 11, Blocks.wool, 8, 3);
		this.setBlock(world, x + 2, y + 22, z + 10, Blocks.wool, 15, 3);
		this.setBlock(world, x + 2, y + 22, z + 9, Blocks.wool, 15, 3);
		this.setBlock(world, x + 2, y + 22, z + 8, Blocks.wool, 15, 3);
		this.setBlock(world, x + 2, y + 22, z + 7, Blocks.wool, 15, 3);
		this.setBlock(world, x + 2, y + 22, z + 6, Blocks.wool, 15, 3);
		this.setBlock(world, x + 3, y + 22, z + 11, Blocks.wool, 8, 3);
		this.setBlock(world, x + 3, y + 22, z + 10, Blocks.wool, 15, 3);
		this.setBlock(world, x + 3, y + 22, z + 9, Blocks.wool, 15, 3);
		this.setBlock(world, x + 3, y + 22, z + 8, Blocks.wool, 15, 3);
		this.setBlock(world, x + 3, y + 22, z + 7, Blocks.wool, 15, 3);
		this.setBlock(world, x + 3, y + 22, z + 6, Blocks.wool, 15, 3);
		this.setBlock(world, x + 4, y + 22, z + 11, Blocks.wool, 8, 3);
		this.setBlock(world, x + 4, y + 22, z + 10, Blocks.wool, 15, 3);
		this.setBlock(world, x + 4, y + 22, z + 9, Blocks.wool, 15, 3);
		this.setBlock(world, x + 4, y + 22, z + 8, Blocks.wool, 15, 3);
		this.setBlock(world, x + 4, y + 22, z + 7, Blocks.wool, 15, 3);
		this.setBlock(world, x + 4, y + 22, z + 6, Blocks.wool, 15, 3);
		this.setBlock(world, x + 5, y + 22, z + 11, Blocks.wool, 15, 3);
		this.setBlock(world, x + 5, y + 22, z + 10, Blocks.wool, 15, 3);
		this.setBlock(world, x + 5, y + 22, z + 9, Blocks.wool, 15, 3);
		this.setBlock(world, x + 5, y + 22, z + 8, Blocks.wool, 15, 3);
		this.setBlock(world, x + 5, y + 22, z + 7, Blocks.wool, 15, 3);
		this.setBlock(world, x + 5, y + 22, z + 6, Blocks.wool, 15, 3);
		this.setBlock(world, x + 6, y + 22, z + 11, Blocks.wool, 15, 3);
		this.setBlock(world, x + 6, y + 22, z + 10, Blocks.wool, 15, 3);
		this.setBlock(world, x + 6, y + 22, z + 9, Blocks.wool, 15, 3);
		this.setBlock(world, x + 6, y + 22, z + 8, Blocks.wool, 15, 3);
		this.setBlock(world, x + 6, y + 22, z + 7, Blocks.wool, 15, 3);
		this.setBlock(world, x + 6, y + 22, z + 6, Blocks.wool, 15, 3);
		this.setBlock(world, x + 11, y + 22, z + 12, Blocks.wool, 15, 3);
		this.setBlock(world, x + 11, y + 22, z + 11, Blocks.wool, 15, 3);
		this.setBlock(world, x + 11, y + 22, z + 10, Blocks.wool, 15, 3);
		this.setBlock(world, x + 11, y + 22, z + 9, Blocks.wool, 15, 3);
		this.setBlock(world, x + 11, y + 22, z + 8, Blocks.wool, 15, 3);
		this.setBlock(world, x + 11, y + 22, z + 7, Blocks.wool, 15, 3);
		this.setBlock(world, x + 11, y + 22, z + 6, Blocks.wool, 15, 3);
		this.setBlock(world, x + 11, y + 22, z + 5, Blocks.wool, 15, 3);
		this.setBlock(world, x + 12, y + 22, z + 12, Blocks.iron_block, 0, 3);
		this.setBlock(world, x + 12, y + 22, z + 11, Blocks.iron_block, 0, 3);
		this.setBlock(world, x + 12, y + 22, z + 10, Blocks.iron_block, 0, 3);
		this.setBlock(world, x + 12, y + 22, z + 9, Blocks.wool, 15, 3);
		this.setBlock(world, x + 12, y + 22, z + 8, Blocks.wool, 15, 3);
		this.setBlock(world, x + 12, y + 22, z + 7, Blocks.wool, 15, 3);
		this.setBlock(world, x + 12, y + 22, z + 6, Blocks.wool, 15, 3);
		this.setBlock(world, x + 12, y + 22, z + 5, Blocks.wool, 15, 3);
		this.setBlock(world, x + 13, y + 22, z + 12, Blocks.iron_block, 0, 3);
		this.setBlock(world, x + 13, y + 22, z + 11, Blocks.wool, 15, 3);
		this.setBlock(world, x + 13, y + 22, z + 10, Blocks.iron_block, 0, 3);
		this.setBlock(world, x + 13, y + 22, z + 9, Blocks.iron_block, 0, 3);
		this.setBlock(world, x + 13, y + 22, z + 8, Blocks.iron_block, 0, 3);
		this.setBlock(world, x + 13, y + 22, z + 7, Blocks.iron_block, 0, 3);
		this.setBlock(world, x + 13, y + 22, z + 6, Blocks.wool, 15, 3);
		this.setBlock(world, x + 13, y + 22, z + 5, Blocks.wool, 15, 3);
		this.setBlock(world, x + 14, y + 22, z + 12, Blocks.wool, 15, 3);
		this.setBlock(world, x + 14, y + 22, z + 11, Blocks.wool, 15, 3);
		this.setBlock(world, x + 14, y + 22, z + 10, Blocks.wool, 15, 3);
		this.setBlock(world, x + 14, y + 22, z + 9, Blocks.wool, 15, 3);
		this.setBlock(world, x + 14, y + 22, z + 8, Blocks.chest, 4, 3);
        TileEntity tileentity2 = world.getTileEntity(new BlockPos(x + 14, y + 22, z + 5));
        if (tileentity2 instanceof TileEntityChest)
        {
            WeightedRandomChestContent.generateChestContents(rand, ChestGenHooks.getItems(WITHER_STATUE_HEAD_1, rand), (TileEntityChest)tileentity2, ChestGenHooks.getCount(WITHER_STATUE_HEAD_1, rand));
        }
		this.setBlock(world, x + 14, y + 22, z + 7, Blocks.beacon, 0, 3);
		this.setBlock(world, x + 14, y + 22, z + 6, Blocks.wool, 15, 3);
		this.setBlock(world, x + 14, y + 22, z + 5, Blocks.wool, 15, 3);
		this.setBlock(world, x + 15, y + 22, z + 12, Blocks.wool, 15, 3);
		this.setBlock(world, x + 15, y + 22, z + 11, Blocks.wool, 15, 3);
		this.setBlock(world, x + 15, y + 22, z + 10, Blocks.wool, 15, 3);
		this.setBlock(world, x + 15, y + 22, z + 9, Blocks.wool, 15, 3);
		this.setBlock(world, x + 15, y + 22, z + 8, Blocks.chest, 4, 3);
        TileEntity tileentity3 = world.getTileEntity(new BlockPos(x + 15, y + 22, z + 8));
        if (tileentity3 instanceof TileEntityChest)
        {
            WeightedRandomChestContent.generateChestContents(rand, ChestGenHooks.getItems(WITHER_STATUE_HEAD_2, rand), (TileEntityChest)tileentity3, ChestGenHooks.getCount(WITHER_STATUE_HEAD_2, rand));
        }
		this.setBlock(world, x + 15, y + 22, z + 7, Blocks.beacon, 0, 3);
		this.setBlock(world, x + 15, y + 22, z + 6, Blocks.wool, 15, 3);
		this.setBlock(world, x + 15, y + 22, z + 5, Blocks.wool, 15, 3);
		this.setBlock(world, x + 16, y + 22, z + 12, Blocks.iron_block, 0, 3);
		this.setBlock(world, x + 16, y + 22, z + 11, Blocks.wool, 15, 3);
		this.setBlock(world, x + 16, y + 22, z + 10, Blocks.wool, 15, 3);
		this.setBlock(world, x + 16, y + 22, z + 9, Blocks.iron_block, 0, 3);
		this.setBlock(world, x + 16, y + 22, z + 8, Blocks.iron_block, 0, 3);
		this.setBlock(world, x + 16, y + 22, z + 7, Blocks.iron_block, 0, 3);
		this.setBlock(world, x + 16, y + 22, z + 6, Blocks.wool, 15, 3);
		this.setBlock(world, x + 16, y + 22, z + 5, Blocks.wool, 15, 3);
		this.setBlock(world, x + 17, y + 22, z + 12, Blocks.iron_block, 0, 3);
		this.setBlock(world, x + 17, y + 22, z + 11, Blocks.iron_block, 0, 3);
		this.setBlock(world, x + 17, y + 22, z + 10, Blocks.iron_block, 0, 3);
		this.setBlock(world, x + 17, y + 22, z + 9, Blocks.iron_block, 0, 3);
		this.setBlock(world, x + 17, y + 22, z + 8, Blocks.wool, 15, 3);
		this.setBlock(world, x + 17, y + 22, z + 7, Blocks.wool, 15, 3);
		this.setBlock(world, x + 17, y + 22, z + 6, Blocks.wool, 15, 3);
		this.setBlock(world, x + 17, y + 22, z + 5, Blocks.wool, 15, 3);
		this.setBlock(world, x + 18, y + 22, z + 12, Blocks.wool, 15, 3);
		this.setBlock(world, x + 18, y + 22, z + 11, Blocks.wool, 15, 3);
		this.setBlock(world, x + 18, y + 22, z + 10, Blocks.wool, 15, 3);
		this.setBlock(world, x + 18, y + 22, z + 9, Blocks.wool, 15, 3);
		this.setBlock(world, x + 18, y + 22, z + 8, Blocks.wool, 15, 3);
		this.setBlock(world, x + 18, y + 22, z + 7, Blocks.wool, 15, 3);
		this.setBlock(world, x + 18, y + 22, z + 6, Blocks.wool, 15, 3);
		this.setBlock(world, x + 18, y + 22, z + 5, Blocks.wool, 15, 3);
		this.setBlock(world, x + 22, y + 22, z + 12, Blocks.wool, 15, 3);
		this.setBlock(world, x + 22, y + 22, z + 11, Blocks.wool, 15, 3);
		this.setBlock(world, x + 22, y + 22, z + 10, Blocks.wool, 15, 3);
		this.setBlock(world, x + 22, y + 22, z + 9, Blocks.wool, 15, 3);
		this.setBlock(world, x + 22, y + 22, z + 8, Blocks.wool, 15, 3);
		this.setBlock(world, x + 22, y + 22, z + 7, Blocks.wool, 15, 3);
		this.setBlock(world, x + 23, y + 22, z + 12, Blocks.wool, 8, 3);
		this.setBlock(world, x + 23, y + 22, z + 11, Blocks.wool, 15, 3);
		this.setBlock(world, x + 23, y + 22, z + 10, Blocks.wool, 15, 3);
		this.setBlock(world, x + 23, y + 22, z + 9, Blocks.wool, 15, 3);
		this.setBlock(world, x + 23, y + 22, z + 8, Blocks.wool, 15, 3);
		this.setBlock(world, x + 23, y + 22, z + 7, Blocks.wool, 15, 3);
		this.setBlock(world, x + 24, y + 22, z + 12, Blocks.wool, 8, 3);
		this.setBlock(world, x + 24, y + 22, z + 11, Blocks.wool, 15, 3);
		this.setBlock(world, x + 24, y + 22, z + 10, Blocks.wool, 15, 3);
		this.setBlock(world, x + 24, y + 22, z + 9, Blocks.wool, 15, 3);
		this.setBlock(world, x + 24, y + 22, z + 8, Blocks.wool, 15, 3);
		this.setBlock(world, x + 24, y + 22, z + 7, Blocks.wool, 15, 3);
		this.setBlock(world, x + 25, y + 22, z + 12, Blocks.wool, 8, 3);
		this.setBlock(world, x + 25, y + 22, z + 11, Blocks.wool, 15, 3);
		this.setBlock(world, x + 25, y + 22, z + 10, Blocks.wool, 15, 3);
		this.setBlock(world, x + 25, y + 22, z + 9, Blocks.wool, 15, 3);
		this.setBlock(world, x + 25, y + 22, z + 8, Blocks.wool, 15, 3);
		this.setBlock(world, x + 25, y + 22, z + 7, Blocks.wool, 15, 3);
		this.setBlock(world, x + 26, y + 22, z + 12, Blocks.wool, 15, 3);
		this.setBlock(world, x + 26, y + 22, z + 11, Blocks.wool, 15, 3);
		this.setBlock(world, x + 26, y + 22, z + 10, Blocks.wool, 15, 3);
		this.setBlock(world, x + 26, y + 22, z + 9, Blocks.wool, 15, 3);
		this.setBlock(world, x + 26, y + 22, z + 8, Blocks.wool, 15, 3);
		this.setBlock(world, x + 26, y + 22, z + 7, Blocks.wool, 15, 3);
		this.setBlock(world, x + 27, y + 22, z + 12, Blocks.wool, 15, 3);
		this.setBlock(world, x + 27, y + 22, z + 11, Blocks.wool, 15, 3);
		this.setBlock(world, x + 27, y + 22, z + 10, Blocks.wool, 15, 3);
		this.setBlock(world, x + 27, y + 22, z + 9, Blocks.wool, 15, 3);
		this.setBlock(world, x + 27, y + 22, z + 8, Blocks.wool, 15, 3);
		this.setBlock(world, x + 27, y + 22, z + 7, Blocks.wool, 15, 3);
		this.setBlock(world, x + 11, y + 23, z + 12, Blocks.obsidian, 0, 3);
		this.setBlock(world, x + 11, y + 23, z + 11, Blocks.wool, 15, 3);
		this.setBlock(world, x + 11, y + 23, z + 10, Blocks.wool, 15, 3);
		this.setBlock(world, x + 11, y + 23, z + 9, Blocks.wool, 15, 3);
		this.setBlock(world, x + 11, y + 23, z + 8, Blocks.wool, 15, 3);
		this.setBlock(world, x + 11, y + 23, z + 7, Blocks.wool, 15, 3);
		this.setBlock(world, x + 11, y + 23, z + 6, Blocks.wool, 15, 3);
		this.setBlock(world, x + 11, y + 23, z + 5, Blocks.wool, 15, 3);
		this.setBlock(world, x + 12, y + 23, z + 12, Blocks.obsidian, 0, 3);
		this.setBlock(world, x + 12, y + 23, z + 11, Blocks.wool, 15, 3);
		this.setBlock(world, x + 12, y + 23, z + 10, Blocks.wool, 15, 3);
		this.setBlock(world, x + 12, y + 23, z + 9, Blocks.wool, 15, 3);
		this.setBlock(world, x + 12, y + 23, z + 8, Blocks.wool, 15, 3);
		this.setBlock(world, x + 12, y + 23, z + 7, Blocks.wool, 15, 3);
		this.setBlock(world, x + 12, y + 23, z + 6, Blocks.wool, 15, 3);
		this.setBlock(world, x + 12, y + 23, z + 5, Blocks.wool, 15, 3);
		this.setBlock(world, x + 13, y + 23, z + 12, Blocks.obsidian, 0, 3);
		this.setBlock(world, x + 13, y + 23, z + 11, Blocks.wool, 15, 3);
		this.setBlock(world, x + 13, y + 23, z + 10, Blocks.wool, 15, 3);
		this.setBlock(world, x + 13, y + 23, z + 9, Blocks.wool, 15, 3);
		this.setBlock(world, x + 13, y + 23, z + 8, Blocks.wool, 15, 3);
		this.setBlock(world, x + 13, y + 23, z + 7, Blocks.wool, 15, 3);
		this.setBlock(world, x + 13, y + 23, z + 6, Blocks.wool, 15, 3);
		this.setBlock(world, x + 13, y + 23, z + 5, Blocks.wool, 15, 3);
		this.setBlock(world, x + 14, y + 23, z + 12, Blocks.wool, 15, 3);
		this.setBlock(world, x + 14, y + 23, z + 11, Blocks.wool, 15, 3);
		this.setBlock(world, x + 14, y + 23, z + 10, Blocks.wool, 15, 3);
		this.setBlock(world, x + 14, y + 23, z + 9, Blocks.wool, 15, 3);
		this.setBlock(world, x + 14, y + 23, z + 8, Blocks.wool, 15, 3);
		this.setBlock(world, x + 14, y + 23, z + 7, Blocks.wool, 15, 3);
		this.setBlock(world, x + 14, y + 23, z + 6, Blocks.wool, 15, 3);
		this.setBlock(world, x + 14, y + 23, z + 5, Blocks.wool, 15, 3);
		this.setBlock(world, x + 15, y + 23, z + 12, Blocks.wool, 15, 3);
		this.setBlock(world, x + 15, y + 23, z + 11, Blocks.wool, 15, 3);
		this.setBlock(world, x + 15, y + 23, z + 10, Blocks.wool, 15, 3);
		this.setBlock(world, x + 15, y + 23, z + 9, Blocks.wool, 15, 3);
		this.setBlock(world, x + 15, y + 23, z + 8, Blocks.wool, 15, 3);
		this.setBlock(world, x + 15, y + 23, z + 7, Blocks.wool, 15, 3);
		this.setBlock(world, x + 15, y + 23, z + 6, Blocks.wool, 15, 3);
		this.setBlock(world, x + 15, y + 23, z + 5, Blocks.wool, 15, 3);
		this.setBlock(world, x + 16, y + 23, z + 12, Blocks.obsidian, 0, 3);
		this.setBlock(world, x + 16, y + 23, z + 11, Blocks.wool, 15, 3);
		this.setBlock(world, x + 16, y + 23, z + 10, Blocks.wool, 15, 3);
		this.setBlock(world, x + 16, y + 23, z + 9, Blocks.wool, 15, 3);
		this.setBlock(world, x + 16, y + 23, z + 8, Blocks.wool, 15, 3);
		this.setBlock(world, x + 16, y + 23, z + 7, Blocks.wool, 15, 3);
		this.setBlock(world, x + 16, y + 23, z + 6, Blocks.wool, 15, 3);
		this.setBlock(world, x + 16, y + 23, z + 5, Blocks.wool, 15, 3);
		this.setBlock(world, x + 17, y + 23, z + 12, Blocks.obsidian, 0, 3);
		this.setBlock(world, x + 17, y + 23, z + 11, Blocks.wool, 15, 3);
		this.setBlock(world, x + 17, y + 23, z + 10, Blocks.wool, 15, 3);
		this.setBlock(world, x + 17, y + 23, z + 9, Blocks.wool, 15, 3);
		this.setBlock(world, x + 17, y + 23, z + 8, Blocks.wool, 15, 3);
		this.setBlock(world, x + 17, y + 23, z + 7, Blocks.wool, 15, 3);
		this.setBlock(world, x + 17, y + 23, z + 6, Blocks.wool, 15, 3);
		this.setBlock(world, x + 17, y + 23, z + 5, Blocks.wool, 15, 3);
		this.setBlock(world, x + 18, y + 23, z + 12, Blocks.obsidian, 0, 3);
		this.setBlock(world, x + 18, y + 23, z + 11, Blocks.wool, 15, 3);
		this.setBlock(world, x + 18, y + 23, z + 10, Blocks.wool, 15, 3);
		this.setBlock(world, x + 18, y + 23, z + 9, Blocks.wool, 15, 3);
		this.setBlock(world, x + 18, y + 23, z + 8, Blocks.wool, 15, 3);
		this.setBlock(world, x + 18, y + 23, z + 7, Blocks.wool, 15, 3);
		this.setBlock(world, x + 18, y + 23, z + 6, Blocks.wool, 15, 3);
		this.setBlock(world, x + 18, y + 23, z + 5, Blocks.wool, 15, 3);
		this.setBlock(world, x + 11, y + 24, z + 12, Blocks.wool, 15, 3);
		this.setBlock(world, x + 11, y + 24, z + 11, Blocks.wool, 15, 3);
		this.setBlock(world, x + 11, y + 24, z + 10, Blocks.wool, 15, 3);
		this.setBlock(world, x + 11, y + 24, z + 9, Blocks.wool, 15, 3);
		this.setBlock(world, x + 11, y + 24, z + 8, Blocks.wool, 15, 3);
		this.setBlock(world, x + 11, y + 24, z + 7, Blocks.wool, 15, 3);
		this.setBlock(world, x + 11, y + 24, z + 6, Blocks.wool, 15, 3);
		this.setBlock(world, x + 11, y + 24, z + 5, Blocks.wool, 15, 3);
		this.setBlock(world, x + 12, y + 24, z + 12, Blocks.wool, 7, 3);
		this.setBlock(world, x + 12, y + 24, z + 11, Blocks.wool, 15, 3);
		this.setBlock(world, x + 12, y + 24, z + 10, Blocks.wool, 15, 3);
		this.setBlock(world, x + 12, y + 24, z + 9, Blocks.wool, 15, 3);
		this.setBlock(world, x + 12, y + 24, z + 8, Blocks.wool, 15, 3);
		this.setBlock(world, x + 12, y + 24, z + 7, Blocks.wool, 15, 3);
		this.setBlock(world, x + 12, y + 24, z + 6, Blocks.wool, 15, 3);
		this.setBlock(world, x + 12, y + 24, z + 5, Blocks.wool, 15, 3);
		this.setBlock(world, x + 13, y + 24, z + 12, Blocks.wool, 8, 3);
		this.setBlock(world, x + 13, y + 24, z + 11, Blocks.wool, 15, 3);
		this.setBlock(world, x + 13, y + 24, z + 10, Blocks.wool, 15, 3);
		this.setBlock(world, x + 13, y + 24, z + 9, Blocks.wool, 15, 3);
		this.setBlock(world, x + 13, y + 24, z + 8, Blocks.wool, 15, 3);
		this.setBlock(world, x + 13, y + 24, z + 7, Blocks.wool, 15, 3);
		this.setBlock(world, x + 13, y + 24, z + 6, Blocks.wool, 15, 3);
		this.setBlock(world, x + 13, y + 24, z + 5, Blocks.wool, 15, 3);
		this.setBlock(world, x + 14, y + 24, z + 12, Blocks.wool, 8, 3);
		this.setBlock(world, x + 14, y + 24, z + 11, Blocks.wool, 15, 3);
		this.setBlock(world, x + 14, y + 24, z + 10, Blocks.wool, 15, 3);
		this.setBlock(world, x + 14, y + 24, z + 9, Blocks.wool, 15, 3);
		this.setBlock(world, x + 14, y + 24, z + 8, Blocks.wool, 15, 3);
		this.setBlock(world, x + 14, y + 24, z + 7, Blocks.wool, 15, 3);
		this.setBlock(world, x + 14, y + 24, z + 6, Blocks.wool, 15, 3);
		this.setBlock(world, x + 14, y + 24, z + 5, Blocks.wool, 15, 3);
		this.setBlock(world, x + 15, y + 24, z + 12, Blocks.wool, 8, 3);
		this.setBlock(world, x + 15, y + 24, z + 11, Blocks.wool, 15, 3);
		this.setBlock(world, x + 15, y + 24, z + 10, Blocks.wool, 15, 3);
		this.setBlock(world, x + 15, y + 24, z + 9, Blocks.wool, 15, 3);
		this.setBlock(world, x + 15, y + 24, z + 8, Blocks.wool, 15, 3);
		this.setBlock(world, x + 15, y + 24, z + 7, Blocks.wool, 15, 3);
		this.setBlock(world, x + 15, y + 24, z + 6, Blocks.wool, 15, 3);
		this.setBlock(world, x + 15, y + 24, z + 5, Blocks.wool, 15, 3);
		this.setBlock(world, x + 16, y + 24, z + 12, Blocks.wool, 8, 3);
		this.setBlock(world, x + 16, y + 24, z + 11, Blocks.wool, 15, 3);
		this.setBlock(world, x + 16, y + 24, z + 10, Blocks.wool, 15, 3);
		this.setBlock(world, x + 16, y + 24, z + 9, Blocks.wool, 15, 3);
		this.setBlock(world, x + 16, y + 24, z + 8, Blocks.wool, 15, 3);
		this.setBlock(world, x + 16, y + 24, z + 7, Blocks.wool, 15, 3);
		this.setBlock(world, x + 16, y + 24, z + 6, Blocks.wool, 15, 3);
		this.setBlock(world, x + 16, y + 24, z + 5, Blocks.wool, 15, 3);
		this.setBlock(world, x + 17, y + 24, z + 12, Blocks.wool, 15, 3);
		this.setBlock(world, x + 17, y + 24, z + 11, Blocks.wool, 15, 3);
		this.setBlock(world, x + 17, y + 24, z + 10, Blocks.wool, 15, 3);
		this.setBlock(world, x + 17, y + 24, z + 9, Blocks.wool, 15, 3);
		this.setBlock(world, x + 17, y + 24, z + 8, Blocks.wool, 15, 3);
		this.setBlock(world, x + 17, y + 24, z + 7, Blocks.wool, 15, 3);
		this.setBlock(world, x + 17, y + 24, z + 6, Blocks.wool, 15, 3);
		this.setBlock(world, x + 17, y + 24, z + 5, Blocks.wool, 15, 3);
		this.setBlock(world, x + 18, y + 24, z + 12, Blocks.wool, 15, 3);
		this.setBlock(world, x + 18, y + 24, z + 11, Blocks.wool, 15, 3);
		this.setBlock(world, x + 18, y + 24, z + 10, Blocks.wool, 15, 3);
		this.setBlock(world, x + 18, y + 24, z + 9, Blocks.wool, 15, 3);
		this.setBlock(world, x + 18, y + 24, z + 8, Blocks.wool, 15, 3);
		this.setBlock(world, x + 18, y + 24, z + 7, Blocks.wool, 15, 3);
		this.setBlock(world, x + 18, y + 24, z + 6, Blocks.wool, 15, 3);
		this.setBlock(world, x + 18, y + 24, z + 5, Blocks.wool, 15, 3);
		this.setBlock(world, x + 11, y + 25, z + 12, Blocks.wool, 15, 3);
		this.setBlock(world, x + 11, y + 25, z + 11, Blocks.wool, 15, 3);
		this.setBlock(world, x + 11, y + 25, z + 10, Blocks.wool, 15, 3);
		this.setBlock(world, x + 11, y + 25, z + 9, Blocks.wool, 15, 3);
		this.setBlock(world, x + 11, y + 25, z + 8, Blocks.wool, 15, 3);
		this.setBlock(world, x + 11, y + 25, z + 7, Blocks.wool, 15, 3);
		this.setBlock(world, x + 11, y + 25, z + 6, Blocks.wool, 15, 3);
		this.setBlock(world, x + 11, y + 25, z + 5, Blocks.wool, 15, 3);
		this.setBlock(world, x + 12, y + 25, z + 12, Blocks.wool, 15, 3);
		this.setBlock(world, x + 12, y + 25, z + 11, Blocks.wool, 15, 3);
		this.setBlock(world, x + 12, y + 25, z + 10, Blocks.wool, 15, 3);
		this.setBlock(world, x + 12, y + 25, z + 9, Blocks.wool, 15, 3);
		this.setBlock(world, x + 12, y + 25, z + 8, Blocks.wool, 15, 3);
		this.setBlock(world, x + 12, y + 25, z + 7, Blocks.wool, 15, 3);
		this.setBlock(world, x + 12, y + 25, z + 6, Blocks.wool, 15, 3);
		this.setBlock(world, x + 12, y + 25, z + 5, Blocks.wool, 15, 3);
		this.setBlock(world, x + 13, y + 25, z + 12, Blocks.wool, 15, 3);
		this.setBlock(world, x + 13, y + 25, z + 11, Blocks.wool, 15, 3);
		this.setBlock(world, x + 13, y + 25, z + 10, Blocks.wool, 15, 3);
		this.setBlock(world, x + 13, y + 25, z + 9, Blocks.wool, 15, 3);
		this.setBlock(world, x + 13, y + 25, z + 8, Blocks.wool, 15, 3);
		this.setBlock(world, x + 13, y + 25, z + 7, Blocks.wool, 15, 3);
		this.setBlock(world, x + 13, y + 25, z + 6, Blocks.wool, 15, 3);
		this.setBlock(world, x + 13, y + 25, z + 5, Blocks.wool, 15, 3);
		this.setBlock(world, x + 14, y + 25, z + 12, Blocks.wool, 15, 3);
		this.setBlock(world, x + 14, y + 25, z + 11, Blocks.wool, 15, 3);
		this.setBlock(world, x + 14, y + 25, z + 10, Blocks.wool, 15, 3);
		this.setBlock(world, x + 14, y + 25, z + 9, Blocks.wool, 15, 3);
		this.setBlock(world, x + 14, y + 25, z + 8, Blocks.wool, 15, 3);
		this.setBlock(world, x + 14, y + 25, z + 7, Blocks.wool, 15, 3);
		this.setBlock(world, x + 14, y + 25, z + 6, Blocks.wool, 15, 3);
		this.setBlock(world, x + 14, y + 25, z + 5, Blocks.wool, 15, 3);
		this.setBlock(world, x + 15, y + 25, z + 12, Blocks.wool, 15, 3);
		this.setBlock(world, x + 15, y + 25, z + 11, Blocks.wool, 15, 3);
		this.setBlock(world, x + 15, y + 25, z + 10, Blocks.wool, 15, 3);
		this.setBlock(world, x + 15, y + 25, z + 9, Blocks.wool, 15, 3);
		this.setBlock(world, x + 15, y + 25, z + 8, Blocks.wool, 15, 3);
		this.setBlock(world, x + 15, y + 25, z + 7, Blocks.wool, 15, 3);
		this.setBlock(world, x + 15, y + 25, z + 6, Blocks.wool, 15, 3);
		this.setBlock(world, x + 15, y + 25, z + 5, Blocks.wool, 15, 3);
		this.setBlock(world, x + 16, y + 25, z + 12, Blocks.wool, 15, 3);
		this.setBlock(world, x + 16, y + 25, z + 11, Blocks.wool, 15, 3);
		this.setBlock(world, x + 16, y + 25, z + 10, Blocks.wool, 15, 3);
		this.setBlock(world, x + 16, y + 25, z + 9, Blocks.wool, 15, 3);
		this.setBlock(world, x + 16, y + 25, z + 8, Blocks.wool, 15, 3);
		this.setBlock(world, x + 16, y + 25, z + 7, Blocks.wool, 15, 3);
		this.setBlock(world, x + 16, y + 25, z + 6, Blocks.wool, 15, 3);
		this.setBlock(world, x + 16, y + 25, z + 5, Blocks.wool, 15, 3);
		this.setBlock(world, x + 17, y + 25, z + 12, Blocks.wool, 15, 3);
		this.setBlock(world, x + 17, y + 25, z + 11, Blocks.wool, 15, 3);
		this.setBlock(world, x + 17, y + 25, z + 10, Blocks.wool, 15, 3);
		this.setBlock(world, x + 17, y + 25, z + 9, Blocks.wool, 15, 3);
		this.setBlock(world, x + 17, y + 25, z + 8, Blocks.wool, 15, 3);
		this.setBlock(world, x + 17, y + 25, z + 7, Blocks.wool, 15, 3);
		this.setBlock(world, x + 17, y + 25, z + 6, Blocks.wool, 15, 3);
		this.setBlock(world, x + 17, y + 25, z + 5, Blocks.wool, 15, 3);
		this.setBlock(world, x + 18, y + 25, z + 12, Blocks.wool, 15, 3);
		this.setBlock(world, x + 18, y + 25, z + 11, Blocks.wool, 15, 3);
		this.setBlock(world, x + 18, y + 25, z + 10, Blocks.wool, 15, 3);
		this.setBlock(world, x + 18, y + 25, z + 9, Blocks.wool, 15, 3);
		this.setBlock(world, x + 18, y + 25, z + 8, Blocks.wool, 15, 3);
		this.setBlock(world, x + 18, y + 25, z + 7, Blocks.wool, 15, 3);
		this.setBlock(world, x + 18, y + 25, z + 6, Blocks.wool, 15, 3);
		this.setBlock(world, x + 18, y + 25, z + 5, Blocks.wool, 15, 3);
		this.setBlock(world, x + 11, y + 26, z + 12, Blocks.wool, 15, 3);
		this.setBlock(world, x + 11, y + 26, z + 11, Blocks.wool, 15, 3);
		this.setBlock(world, x + 11, y + 26, z + 10, Blocks.wool, 15, 3);
		this.setBlock(world, x + 11, y + 26, z + 9, Blocks.wool, 15, 3);
		this.setBlock(world, x + 11, y + 26, z + 8, Blocks.wool, 15, 3);
		this.setBlock(world, x + 11, y + 26, z + 7, Blocks.wool, 15, 3);
		this.setBlock(world, x + 11, y + 26, z + 6, Blocks.wool, 15, 3);
		this.setBlock(world, x + 11, y + 26, z + 5, Blocks.wool, 15, 3);
		this.setBlock(world, x + 12, y + 26, z + 12, Blocks.wool, 15, 3);
		this.setBlock(world, x + 12, y + 26, z + 11, Blocks.wool, 15, 3);
		this.setBlock(world, x + 12, y + 26, z + 10, Blocks.wool, 15, 3);
		this.setBlock(world, x + 12, y + 26, z + 9, Blocks.wool, 15, 3);
		this.setBlock(world, x + 12, y + 26, z + 8, Blocks.wool, 15, 3);
		this.setBlock(world, x + 12, y + 26, z + 7, Blocks.wool, 15, 3);
		this.setBlock(world, x + 12, y + 26, z + 6, Blocks.wool, 15, 3);
		this.setBlock(world, x + 12, y + 26, z + 5, Blocks.wool, 15, 3);
		this.setBlock(world, x + 13, y + 26, z + 12, Blocks.wool, 15, 3);
		this.setBlock(world, x + 13, y + 26, z + 11, Blocks.wool, 15, 3);
		this.setBlock(world, x + 13, y + 26, z + 10, Blocks.wool, 15, 3);
		this.setBlock(world, x + 13, y + 26, z + 9, Blocks.wool, 15, 3);
		this.setBlock(world, x + 13, y + 26, z + 8, Blocks.wool, 15, 3);
		this.setBlock(world, x + 13, y + 26, z + 7, Blocks.wool, 15, 3);
		this.setBlock(world, x + 13, y + 26, z + 6, Blocks.wool, 15, 3);
		this.setBlock(world, x + 13, y + 26, z + 5, Blocks.wool, 15, 3);
		this.setBlock(world, x + 14, y + 26, z + 12, Blocks.wool, 15, 3);
		this.setBlock(world, x + 14, y + 26, z + 11, Blocks.wool, 15, 3);
		this.setBlock(world, x + 14, y + 26, z + 10, Blocks.wool, 15, 3);
		this.setBlock(world, x + 14, y + 26, z + 9, Blocks.wool, 15, 3);
		this.setBlock(world, x + 14, y + 26, z + 8, Blocks.wool, 15, 3);
		this.setBlock(world, x + 14, y + 26, z + 7, Blocks.wool, 15, 3);
		this.setBlock(world, x + 14, y + 26, z + 6, Blocks.wool, 15, 3);
		this.setBlock(world, x + 14, y + 26, z + 5, Blocks.wool, 15, 3);
		this.setBlock(world, x + 15, y + 26, z + 12, Blocks.wool, 15, 3);
		this.setBlock(world, x + 15, y + 26, z + 11, Blocks.wool, 15, 3);
		this.setBlock(world, x + 15, y + 26, z + 10, Blocks.wool, 15, 3);
		this.setBlock(world, x + 15, y + 26, z + 9, Blocks.wool, 15, 3);
		this.setBlock(world, x + 15, y + 26, z + 8, Blocks.wool, 15, 3);
		this.setBlock(world, x + 15, y + 26, z + 7, Blocks.wool, 15, 3);
		this.setBlock(world, x + 15, y + 26, z + 6, Blocks.wool, 15, 3);
		this.setBlock(world, x + 15, y + 26, z + 5, Blocks.wool, 15, 3);
		this.setBlock(world, x + 16, y + 26, z + 12, Blocks.wool, 15, 3);
		this.setBlock(world, x + 16, y + 26, z + 11, Blocks.wool, 15, 3);
		this.setBlock(world, x + 16, y + 26, z + 10, Blocks.wool, 15, 3);
		this.setBlock(world, x + 16, y + 26, z + 9, Blocks.wool, 15, 3);
		this.setBlock(world, x + 16, y + 26, z + 8, Blocks.wool, 15, 3);
