//Schematic to java Structure by jajo_11 | inspired by "MITHION'S .SCHEMATIC TO JAVA CONVERTINGTOOL"

package net.minecraft.MoWithers.worldgen;

import static net.minecraft.MoWithers.worldgen.ChestGenHooksWither.WITHER_STATUE_BASE;
import static net.minecraft.MoWithers.worldgen.ChestGenHooksWither.WITHER_STATUE_HEAD_1;
import static net.minecraft.MoWithers.worldgen.ChestGenHooksWither.WITHER_STATUE_HEAD_2;

import java.util.List;
import java.util.Random;

import com.google.common.collect.Lists;

import net.minecraft.block.Block;
import net.minecraft.block.material.Material;
import net.minecraft.init.Blocks;
import net.minecraft.init.Items;
import net.minecraft.item.Item;
import net.minecraft.item.ItemStack;
import net.minecraft.tileentity.TileEntity;
import net.minecraft.tileentity.TileEntityChest;
import net.minecraft.util.BlockPos;
import net.minecraft.util.WeightedRandomChestContent;
import net.minecraft.world.World;
import net.minecraft.world.gen.feature.WorldGenerator;
import net.minecraftforge.common.ChestGenHooks;

public class Defaultwithereast extends WorldGenerator
{
    private static final List CHESTCONTENT = Lists.newArrayList(new WeightedRandomChestContent[] {new WeightedRandomChestContent(Items.golden_apple, 0, 1, 1, 5), new WeightedRandomChestContent(Items.saddle, 0, 1, 1, 10), new WeightedRandomChestContent(Items.iron_ingot, 0, 1, 4, 10), new WeightedRandomChestContent(Items.gold_ingot, 0, 1, 2, 5), new WeightedRandomChestContent(Items.bread, 0, 1, 1, 10), new WeightedRandomChestContent(Items.wheat, 0, 1, 4, 10), new WeightedRandomChestContent(Items.gunpowder, 0, 1, 4, 10), new WeightedRandomChestContent(Items.string, 0, 1, 4, 10), new WeightedRandomChestContent(Items.bucket, 0, 1, 1, 10), new WeightedRandomChestContent(Items.golden_apple, 0, 1, 1, 1), new WeightedRandomChestContent(Items.redstone, 0, 1, 4, 10), new WeightedRandomChestContent(Items.record_13, 0, 1, 1, 4), new WeightedRandomChestContent(Items.record_cat, 0, 1, 1, 4), new WeightedRandomChestContent(Items.name_tag, 0, 1, 1, 10), new WeightedRandomChestContent(Items.golden_horse_armor, 0, 1, 1, 2), new WeightedRandomChestContent(Items.iron_horse_armor, 0, 1, 1, 5), new WeightedRandomChestContent(Items.diamond_horse_armor, 0, 1, 1, 1)});
    private static final List DOUBLECHESTCONTENT = Lists.newArrayList(new WeightedRandomChestContent[] {new WeightedRandomChestContent(Items.golden_apple, 1, 1, 1, 1), new WeightedRandomChestContent(Items.bone, 0, 4, 6, 20), new WeightedRandomChestContent(Items.rotten_flesh, 0, 3, 7, 16) , new WeightedRandomChestContent(Items.diamond, 0, 1, 3, 3), new WeightedRandomChestContent(Items.iron_ingot, 0, 1, 5, 10), new WeightedRandomChestContent(Items.gold_ingot, 0, 2, 7, 15), new WeightedRandomChestContent(Items.emerald, 0, 1, 3, 2), new WeightedRandomChestContent(Items.bread, 0, 1, 3, 15), new WeightedRandomChestContent(Items.apple, 0, 1, 3, 15), new WeightedRandomChestContent(Items.iron_pickaxe, 0, 1, 1, 5), new WeightedRandomChestContent(Items.iron_sword, 0, 1, 1, 5), new WeightedRandomChestContent(Items.iron_chestplate, 0, 1, 1, 5), new WeightedRandomChestContent(Items.iron_helmet, 0, 1, 1, 5), new WeightedRandomChestContent(Items.iron_leggings, 0, 1, 1, 5), new WeightedRandomChestContent(Items.iron_boots, 0, 1, 1, 5), new WeightedRandomChestContent(Item.getItemFromBlock(Blocks.obsidian), 0, 3, 7, 5), new WeightedRandomChestContent(Item.getItemFromBlock(Blocks.coal_block), 0, 3, 7, 15), new WeightedRandomChestContent(Items.iron_horse_armor, 0, 1, 1, 1), new WeightedRandomChestContent(Items.golden_horse_armor, 0, 1, 1, 1), new WeightedRandomChestContent(Items.diamond_horse_armor, 0, 1, 1, 1)});

	public boolean generate(World world, Random rand, BlockPos pos)
	{
        if ((world.isAirBlock(pos) || world.getBlockState(pos).getBlock() == Blocks.snow_layer || world.getBlockState(pos).getBlock().getMaterial() == Material.plants) && world.canSeeSky(pos) && world.getBlockState(pos.down()).getBlock().getMaterial().isSolid())
        {
    	    generate_r0(world, rand, pos.getX(), pos.getY(), pos.getZ());
    	    
    	    return true;
        }
        else
        {
            return false;
        }
	}

	public boolean generate_r0(World world, Random rand, int x, int y, int z)
	{
		x -= 7;
		z -= 14;
		
		this.setBlock(world, x + 7, y + 0, z + 17, Blocks.iron_block, 0, 3);
		this.setBlock(world, x + 6, y + 0, z + 17, Blocks.iron_block, 0, 3);
		this.setBlock(world, x + 5, y + 0, z + 17, Blocks.iron_block, 0, 3);
		this.setBlock(world, x + 4, y + 0, z + 17, Blocks.iron_block, 0, 3);
		this.setBlock(world, x + 3, y + 0, z + 17, Blocks.iron_block, 0, 3);
		this.setBlock(world, x + 2, y + 0, z + 17, Blocks.iron_block, 0, 3);
		this.setBlock(world, x + 1, y + 0, z + 17, Blocks.iron_block, 0, 3);
		this.setBlock(world, x + 0, y + 0, z + 17, Blocks.iron_block, 0, 3);
		this.setBlock(world, x + 7, y + 0, z + 16, Blocks.iron_block, 0, 3);
		this.setBlock(world, x + 6, y + 0, z + 16, Blocks.iron_block, 0, 3);
		this.setBlock(world, x + 5, y + 0, z + 16, Blocks.iron_block, 0, 3);
		this.setBlock(world, x + 4, y + 0, z + 16, Blocks.iron_block, 0, 3);
		this.setBlock(world, x + 3, y + 0, z + 16, Blocks.iron_block, 0, 3);
		this.setBlock(world, x + 2, y + 0, z + 16, Blocks.iron_block, 0, 3);
		this.setBlock(world, x + 1, y + 0, z + 16, Blocks.iron_block, 0, 3);
		this.setBlock(world, x + 0, y + 0, z + 16, Blocks.iron_block, 0, 3);
		this.setBlock(world, x + 7, y + 0, z + 15, Blocks.iron_block, 0, 3);
		this.setBlock(world, x + 6, y + 0, z + 15, Blocks.iron_block, 0, 3);
		this.setBlock(world, x + 5, y + 0, z + 15, Blocks.iron_block, 0, 3);
		this.setBlock(world, x + 4, y + 0, z + 15, Blocks.wool, 15, 3);
		this.setBlock(world, x + 3, y + 0, z + 15, Blocks.wool, 15, 3);
		this.setBlock(world, x + 2, y + 0, z + 15, Blocks.wool, 15, 3);
		this.setBlock(world, x + 1, y + 0, z + 15, Blocks.iron_block, 0, 3);
		this.setBlock(world, x + 0, y + 0, z + 15, Blocks.iron_block, 0, 3);
		this.setBlock(world, x + 7, y + 0, z + 14, Blocks.iron_block, 0, 3);
		this.setBlock(world, x + 6, y + 0, z + 14, Blocks.iron_block, 0, 3);
		this.setBlock(world, x + 5, y + 0, z + 14, Blocks.iron_block, 0, 3);
		this.setBlock(world, x + 4, y + 0, z + 14, Blocks.wool, 15, 3);
		this.setBlock(world, x + 3, y + 0, z + 14, Blocks.wool, 15, 3);
		this.setBlock(world, x + 2, y + 0, z + 14, Blocks.wool, 15, 3);
		this.setBlock(world, x + 1, y + 0, z + 14, Blocks.iron_block, 0, 3);
		this.setBlock(world, x + 0, y + 0, z + 14, Blocks.iron_block, 0, 3);
		this.setBlock(world, x + 7, y + 0, z + 13, Blocks.iron_block, 0, 3);
		this.setBlock(world, x + 6, y + 0, z + 13, Blocks.iron_block, 0, 3);
		this.setBlock(world, x + 5, y + 0, z + 13, Blocks.iron_block, 0, 3);
		this.setBlock(world, x + 4, y + 0, z + 13, Blocks.wool, 15, 3);
		this.setBlock(world, x + 3, y + 0, z + 13, Blocks.wool, 15, 3);
		this.setBlock(world, x + 2, y + 0, z + 13, Blocks.wool, 15, 3);
		this.setBlock(world, x + 1, y + 0, z + 13, Blocks.iron_block, 0, 3);
		this.setBlock(world, x + 0, y + 0, z + 13, Blocks.iron_block, 0, 3);
		this.setBlock(world, x + 7, y + 0, z + 12, Blocks.iron_block, 0, 3);
		this.setBlock(world, x + 6, y + 0, z + 12, Blocks.iron_block, 0, 3);
		this.setBlock(world, x + 5, y + 0, z + 12, Blocks.iron_block, 0, 3);
		this.setBlock(world, x + 4, y + 0, z + 12, Blocks.iron_block, 0, 3);
		this.setBlock(world, x + 3, y + 0, z + 12, Blocks.iron_block, 0, 3);
		this.setBlock(world, x + 2, y + 0, z + 12, Blocks.iron_block, 0, 3);
		this.setBlock(world, x + 1, y + 0, z + 12, Blocks.iron_block, 0, 3);
		this.setBlock(world, x + 0, y + 0, z + 12, Blocks.iron_block, 0, 3);
		this.setBlock(world, x + 7, y + 0, z + 11, Blocks.iron_block, 0, 3);
		this.setBlock(world, x + 6, y + 0, z + 11, Blocks.iron_block, 0, 3);
		this.setBlock(world, x + 5, y + 0, z + 11, Blocks.iron_block, 0, 3);
		this.setBlock(world, x + 4, y + 0, z + 11, Blocks.iron_block, 0, 3);
		this.setBlock(world, x + 3, y + 0, z + 11, Blocks.iron_block, 0, 3);
		this.setBlock(world, x + 2, y + 0, z + 11, Blocks.iron_block, 0, 3);
		this.setBlock(world, x + 1, y + 0, z + 11, Blocks.iron_block, 0, 3);
		this.setBlock(world, x + 0, y + 0, z + 11, Blocks.iron_block, 0, 3);
		this.setBlock(world, x + 6, y + 1, z + 16, Blocks.iron_block, 0, 3);
		this.setBlock(world, x + 5, y + 1, z + 16, Blocks.iron_block, 0, 3);
		this.setBlock(world, x + 4, y + 1, z + 16, Blocks.iron_block, 0, 3);
		this.setBlock(world, x + 3, y + 1, z + 16, Blocks.iron_block, 0, 3);
		this.setBlock(world, x + 2, y + 1, z + 16, Blocks.iron_block, 0, 3);
		this.setBlock(world, x + 1, y + 1, z + 16, Blocks.iron_block, 0, 3);
		this.setBlock(world, x + 6, y + 1, z + 15, Blocks.iron_block, 0, 3);
		this.setBlock(world, x + 5, y + 1, z + 15, Blocks.wool, 15, 3);
		this.setBlock(world, x + 4, y + 1, z + 15, Blocks.wool, 15, 3);
		this.setBlock(world, x + 3, y + 1, z + 15, Blocks.wool, 15, 3);
		this.setBlock(world, x + 2, y + 1, z + 15, Blocks.wool, 15, 3);
		this.setBlock(world, x + 1, y + 1, z + 15, Blocks.iron_block, 0, 3);
		this.setBlock(world, x + 6, y + 1, z + 14, Blocks.iron_block, 0, 3);
		this.setBlock(world, x + 5, y + 1, z + 14, Blocks.wool, 7, 3);
		this.setBlock(world, x + 4, y + 1, z + 14, Blocks.wool, 15, 3);
		this.setBlock(world, x + 3, y + 1, z + 14, Blocks.chest, 5, 3);
        TileEntity tileentity1 = world.getTileEntity(new BlockPos(x + 3, y + 1, z + 14));
        if (tileentity1 instanceof TileEntityChest)
        {
            WeightedRandomChestContent.generateChestContents(rand, ChestGenHooks.getItems(WITHER_STATUE_BASE, rand), (TileEntityChest)tileentity1, ChestGenHooks.getCount(WITHER_STATUE_BASE, rand));
        }
		this.setBlock(world, x + 2, y + 1, z + 14, Blocks.wool, 7, 3);
		this.setBlock(world, x + 1, y + 1, z + 14, Blocks.iron_block, 0, 3);
		this.setBlock(world, x + 6, y + 1, z + 13, Blocks.iron_block, 0, 3);
		this.setBlock(world, x + 5, y + 1, z + 13, Blocks.wool, 15, 3);
		this.setBlock(world, x + 4, y + 1, z + 13, Blocks.wool, 15, 3);
		this.setBlock(world, x + 3, y + 1, z + 13, Blocks.wool, 15, 3);
		this.setBlock(world, x + 2, y + 1, z + 13, Blocks.wool, 15, 3);
		this.setBlock(world, x + 1, y + 1, z + 13, Blocks.iron_block, 0, 3);
		this.setBlock(world, x + 6, y + 1, z + 12, Blocks.iron_block, 0, 3);
		this.setBlock(world, x + 5, y + 1, z + 12, Blocks.iron_block, 0, 3);
		this.setBlock(world, x + 4, y + 1, z + 12, Blocks.iron_block, 0, 3);
		this.setBlock(world, x + 3, y + 1, z + 12, Blocks.iron_block, 0, 3);
		this.setBlock(world, x + 2, y + 1, z + 12, Blocks.iron_block, 0, 3);
		this.setBlock(world, x + 1, y + 1, z + 12, Blocks.iron_block, 0, 3);
		this.setBlock(world, x + 6, y + 2, z + 15, Blocks.wool, 15, 3);
		this.setBlock(world, x + 5, y + 2, z + 15, Blocks.wool, 15, 3);
		this.setBlock(world, x + 4, y + 2, z + 15, Blocks.wool, 15, 3);
		this.setBlock(world, x + 3, y + 2, z + 15, Blocks.wool, 15, 3);
		this.setBlock(world, x + 2, y + 2, z + 15, Blocks.wool, 15, 3);
		this.setBlock(world, x + 6, y + 2, z + 14, Blocks.wool, 7, 3);
		this.setBlock(world, x + 5, y + 2, z + 14, Blocks.wool, 15, 3);
		this.setBlock(world, x + 4, y + 2, z + 14, Blocks.wool, 15, 3);
		this.setBlock(world, x + 3, y + 2, z + 14, Blocks.wool, 15, 3);
		this.setBlock(world, x + 2, y + 2, z + 14, Blocks.wool, 15, 3);
		this.setBlock(world, x + 6, y + 2, z + 13, Blocks.wool, 15, 3);
		this.setBlock(world, x + 5, y + 2, z + 13, Blocks.wool, 15, 3);
		this.setBlock(world, x + 4, y + 2, z + 13, Blocks.wool, 15, 3);
		this.setBlock(world, x + 3, y + 2, z + 13, Blocks.wool, 15, 3);
		this.setBlock(world, x + 2, y + 2, z + 13, Blocks.wool, 15, 3);
		this.setBlock(world, x + 7, y + 3, z + 15, Blocks.wool, 15, 3);
		this.setBlock(world, x + 6, y + 3, z + 15, Blocks.wool, 15, 3);
		this.setBlock(world, x + 5, y + 3, z + 15, Blocks.wool, 15, 3);
		this.setBlock(world, x + 4, y + 3, z + 15, Blocks.wool, 15, 3);
		this.setBlock(world, x + 3, y + 3, z + 15, Blocks.wool, 15, 3);
		this.setBlock(world, x + 7, y + 3, z + 14, Blocks.wool, 8, 3);
		this.setBlock(world, x + 6, y + 3, z + 14, Blocks.wool, 15, 3);
		this.setBlock(world, x + 5, y + 3, z + 14, Blocks.wool, 15, 3);
		this.setBlock(world, x + 4, y + 3, z + 14, Blocks.wool, 15, 3);
		this.setBlock(world, x + 3, y + 3, z + 14, Blocks.wool, 7, 3);
		this.setBlock(world, x + 7, y + 3, z + 13, Blocks.wool, 15, 3);
		this.setBlock(world, x + 6, y + 3, z + 13, Blocks.wool, 15, 3);
		this.setBlock(world, x + 5, y + 3, z + 13, Blocks.wool, 15, 3);
		this.setBlock(world, x + 4, y + 3, z + 13, Blocks.wool, 15, 3);
		this.setBlock(world, x + 3, y + 3, z + 13, Blocks.wool, 15, 3);
		this.setBlock(world, x + 8, y + 4, z + 15, Blocks.wool, 15, 3);
		this.setBlock(world, x + 7, y + 4, z + 15, Blocks.wool, 15, 3);
		this.setBlock(world, x + 6, y + 4, z + 15, Blocks.wool, 15, 3);
		this.setBlock(world, x + 5, y + 4, z + 15, Blocks.wool, 15, 3);
		this.setBlock(world, x + 4, y + 4, z + 15, Blocks.wool, 15, 3);
		this.setBlock(world, x + 8, y + 4, z + 14, Blocks.wool, 7, 3);
		this.setBlock(world, x + 7, y + 4, z + 14, Blocks.wool, 15, 3);
		this.setBlock(world, x + 6, y + 4, z + 14, Blocks.wool, 15, 3);
		this.setBlock(world, x + 5, y + 4, z + 14, Blocks.wool, 15, 3);
		this.setBlock(world, x + 4, y + 4, z + 14, Blocks.wool, 7, 3);
		this.setBlock(world, x + 8, y + 4, z + 13, Blocks.wool, 15, 3);
		this.setBlock(world, x + 7, y + 4, z + 13, Blocks.wool, 15, 3);
		this.setBlock(world, x + 6, y + 4, z + 13, Blocks.wool, 15, 3);
		this.setBlock(world, x + 5, y + 4, z + 13, Blocks.wool, 15, 3);
		this.setBlock(world, x + 4, y + 4, z + 13, Blocks.wool, 15, 3);
		this.setBlock(world, x + 9, y + 5, z + 15, Blocks.wool, 15, 3);
		this.setBlock(world, x + 8, y + 5, z + 15, Blocks.wool, 15, 3);
		this.setBlock(world, x + 7, y + 5, z + 15, Blocks.wool, 15, 3);
		this.setBlock(world, x + 6, y + 5, z + 15, Blocks.wool, 15, 3);
		this.setBlock(world, x + 5, y + 5, z + 15, Blocks.wool, 15, 3);
		this.setBlock(world, x + 9, y + 5, z + 14, Blocks.wool, 15, 3);
		this.setBlock(world, x + 8, y + 5, z + 14, Blocks.wool, 15, 3);
		this.setBlock(world, x + 7, y + 5, z + 14, Blocks.wool, 15, 3);
		this.setBlock(world, x + 6, y + 5, z + 14, Blocks.wool, 15, 3);
		this.setBlock(world, x + 5, y + 5, z + 14, Blocks.wool, 8, 3);
		this.setBlock(world, x + 9, y + 5, z + 13, Blocks.wool, 15, 3);
		this.setBlock(world, x + 8, y + 5, z + 13, Blocks.wool, 15, 3);
		this.setBlock(world, x + 7, y + 5, z + 13, Blocks.wool, 15, 3);
		this.setBlock(world, x + 6, y + 5, z + 13, Blocks.wool, 15, 3);
		this.setBlock(world, x + 5, y + 5, z + 13, Blocks.wool, 15, 3);
		this.setBlock(world, x + 9, y + 6, z + 15, Blocks.wool, 15, 3);
		this.setBlock(world, x + 8, y + 6, z + 15, Blocks.wool, 15, 3);
		this.setBlock(world, x + 7, y + 6, z + 15, Blocks.wool, 15, 3);
		this.setBlock(world, x + 6, y + 6, z + 15, Blocks.wool, 15, 3);
		this.setBlock(world, x + 9, y + 6, z + 14, Blocks.wool, 7, 3);
		this.setBlock(world, x + 8, y + 6, z + 14, Blocks.wool, 15, 3);
		this.setBlock(world, x + 7, y + 6, z + 14, Blocks.wool, 15, 3);
		this.setBlock(world, x + 6, y + 6, z + 14, Blocks.wool, 7, 3);
		this.setBlock(world, x + 9, y + 6, z + 13, Blocks.wool, 15, 3);
		this.setBlock(world, x + 8, y + 6, z + 13, Blocks.wool, 15, 3);
		this.setBlock(world, x + 7, y + 6, z + 13, Blocks.wool, 15, 3);
		this.setBlock(world, x + 6, y + 6, z + 13, Blocks.wool, 15, 3);
		this.setBlock(world, x + 8, y + 7, z + 19, Blocks.wool, 8, 3);
		this.setBlock(world, x + 7, y + 7, z + 19, Blocks.wool, 8, 3);
		this.setBlock(world, x + 8, y + 7, z + 18, Blocks.wool, 8, 3);
		this.setBlock(world, x + 7, y + 7, z + 18, Blocks.wool, 8, 3);
		this.setBlock(world, x + 8, y + 7, z + 17, Blocks.wool, 7, 3);
		this.setBlock(world, x + 7, y + 7, z + 17, Blocks.wool, 7, 3);
		this.setBlock(world, x + 8, y + 7, z + 16, Blocks.wool, 7, 3);
		this.setBlock(world, x + 7, y + 7, z + 16, Blocks.wool, 7, 3);
		this.setBlock(world, x + 9, y + 7, z + 15, Blocks.wool, 15, 3);
		this.setBlock(world, x + 8, y + 7, z + 15, Blocks.wool, 15, 3);
		this.setBlock(world, x + 7, y + 7, z + 15, Blocks.wool, 15, 3);
		this.setBlock(world, x + 9, y + 7, z + 14, Blocks.wool, 7, 3);
		this.setBlock(world, x + 8, y + 7, z + 14, Blocks.wool, 15, 3);
		this.setBlock(world, x + 7, y + 7, z + 14, Blocks.wool, 7, 3);
		this.setBlock(world, x + 9, y + 7, z + 13, Blocks.wool, 15, 3);
		this.setBlock(world, x + 8, y + 7, z + 13, Blocks.wool, 15, 3);
		this.setBlock(world, x + 7, y + 7, z + 13, Blocks.wool, 15, 3);
		this.setBlock(world, x + 8, y + 7, z + 12, Blocks.wool, 7, 3);
		this.setBlock(world, x + 7, y + 7, z + 12, Blocks.wool, 7, 3);
		this.setBlock(world, x + 8, y + 7, z + 11, Blocks.wool, 7, 3);
		this.setBlock(world, x + 7, y + 7, z + 11, Blocks.wool, 7, 3);
		this.setBlock(world, x + 8, y + 7, z + 10, Blocks.wool, 8, 3);
		this.setBlock(world, x + 7, y + 7, z + 10, Blocks.wool, 8, 3);
		this.setBlock(world, x + 8, y + 7, z + 9, Blocks.wool, 8, 3);
		this.setBlock(world, x + 7, y + 7, z + 9, Blocks.wool, 8, 3);
		this.setBlock(world, x + 8, y + 8, z + 19, Blocks.wool, 8, 3);
		this.setBlock(world, x + 7, y + 8, z + 19, Blocks.wool, 8, 3);
		this.setBlock(world, x + 8, y + 8, z + 18, Blocks.wool, 8, 3);
		this.setBlock(world, x + 7, y + 8, z + 18, Blocks.wool, 8, 3);
		this.setBlock(world, x + 8, y + 8, z + 17, Blocks.wool, 7, 3);
		this.setBlock(world, x + 7, y + 8, z + 17, Blocks.wool, 7, 3);
		this.setBlock(world, x + 8, y + 8, z + 16, Blocks.wool, 7, 3);
		this.setBlock(world, x + 7, y + 8, z + 16, Blocks.wool, 7, 3);
		this.setBlock(world, x + 9, y + 8, z + 15, Blocks.wool, 15, 3);
		this.setBlock(world, x + 8, y + 8, z + 15, Blocks.wool, 15, 3);
		this.setBlock(world, x + 7, y + 8, z + 15, Blocks.wool, 15, 3);
		this.setBlock(world, x + 9, y + 8, z + 14, Blocks.wool, 8, 3);
		this.setBlock(world, x + 8, y + 8, z + 14, Blocks.wool, 15, 3);
		this.setBlock(world, x + 7, y + 8, z + 14, Blocks.wool, 8, 3);
		this.setBlock(world, x + 9, y + 8, z + 13, Blocks.wool, 15, 3);
		this.setBlock(world, x + 8, y + 8, z + 13, Blocks.wool, 15, 3);
		this.setBlock(world, x + 7, y + 8, z + 13, Blocks.wool, 15, 3);
		this.setBlock(world, x + 8, y + 8, z + 12, Blocks.wool, 7, 3);
		this.setBlock(world, x + 7, y + 8, z + 12, Blocks.wool, 7, 3);
		this.setBlock(world, x + 8, y + 8, z + 11, Blocks.wool, 7, 3);
		this.setBlock(world, x + 7, y + 8, z + 11, Blocks.wool, 7, 3);
		this.setBlock(world, x + 8, y + 8, z + 10, Blocks.wool, 8, 3);
		this.setBlock(world, x + 7, y + 8, z + 10, Blocks.wool, 8, 3);
		this.setBlock(world, x + 8, y + 8, z + 9, Blocks.wool, 8, 3);
		this.setBlock(world, x + 7, y + 8, z + 9, Blocks.wool, 8, 3);
		this.setBlock(world, x + 9, y + 9, z + 15, Blocks.wool, 15, 3);
		this.setBlock(world, x + 8, y + 9, z + 15, Blocks.wool, 15, 3);
		this.setBlock(world, x + 7, y + 9, z + 15, Blocks.wool, 15, 3);
		this.setBlock(world, x + 9, y + 9, z + 14, Blocks.wool, 8, 3);
		this.setBlock(world, x + 8, y + 9, z + 14, Blocks.wool, 15, 3);
		this.setBlock(world, x + 7, y + 9, z + 14, Blocks.wool, 8, 3);
		this.setBlock(world, x + 9, y + 9, z + 13, Blocks.wool, 15, 3);
		this.setBlock(world, x + 8, y + 9, z + 13, Blocks.wool, 15, 3);
		this.setBlock(world, x + 7, y + 9, z + 13, Blocks.wool, 15, 3);
		this.setBlock(world, x + 8, y + 10, z + 19, Blocks.wool, 8, 3);
		this.setBlock(world, x + 7, y + 10, z + 19, Blocks.wool, 8, 3);
		this.setBlock(world, x + 8, y + 10, z + 18, Blocks.wool, 8, 3);
		this.setBlock(world, x + 7, y + 10, z + 18, Blocks.wool, 8, 3);
		this.setBlock(world, x + 8, y + 10, z + 17, Blocks.wool, 7, 3);
		this.setBlock(world, x + 7, y + 10, z + 17, Blocks.wool, 7, 3);
		this.setBlock(world, x + 8, y + 10, z + 16, Blocks.wool, 7, 3);
		this.setBlock(world, x + 7, y + 10, z + 16, Blocks.wool, 7, 3);
		this.setBlock(world, x + 9, y + 10, z + 15, Blocks.wool, 15, 3);
		this.setBlock(world, x + 8, y + 10, z + 15, Blocks.wool, 15, 3);
		this.setBlock(world, x + 7, y + 10, z + 15, Blocks.wool, 15, 3);
		this.setBlock(world, x + 9, y + 10, z + 14, Blocks.wool, 8, 3);
		this.setBlock(world, x + 8, y + 10, z + 14, Blocks.wool, 15, 3);
		this.setBlock(world, x + 7, y + 10, z + 14, Blocks.wool, 8, 3);
		this.setBlock(world, x + 9, y + 10, z + 13, Blocks.wool, 15, 3);
		this.setBlock(world, x + 8, y + 10, z + 13, Blocks.wool, 15, 3);
		this.setBlock(world, x + 7, y + 10, z + 13, Blocks.wool, 15, 3);
		this.setBlock(world, x + 8, y + 10, z + 12, Blocks.wool, 7, 3);
		this.setBlock(world, x + 7, y + 10, z + 12, Blocks.wool, 7, 3);
		this.setBlock(world, x + 8, y + 10, z + 11, Blocks.wool, 7, 3);
		this.setBlock(world, x + 7, y + 10, z + 11, Blocks.wool, 7, 3);
		this.setBlock(world, x + 8, y + 10, z + 10, Blocks.wool, 8, 3);
		this.setBlock(world, x + 7, y + 10, z + 10, Blocks.wool, 8, 3);
		this.setBlock(world, x + 8, y + 10, z + 9, Blocks.wool, 8, 3);
		this.setBlock(world, x + 7, y + 10, z + 9, Blocks.wool, 8, 3);
		this.setBlock(world, x + 8, y + 11, z + 19, Blocks.wool, 8, 3);
		this.setBlock(world, x + 7, y + 11, z + 19, Blocks.wool, 8, 3);
		this.setBlock(world, x + 8, y + 11, z + 18, Blocks.wool, 8, 3);
		this.setBlock(world, x + 7, y + 11, z + 18, Blocks.wool, 8, 3);
		this.setBlock(world, x + 8, y + 11, z + 17, Blocks.wool, 7, 3);
		this.setBlock(world, x + 7, y + 11, z + 17, Blocks.wool, 7, 3);
		this.setBlock(world, x + 8, y + 11, z + 16, Blocks.wool, 7, 3);
		this.setBlock(world, x + 7, y + 11, z + 16, Blocks.wool, 7, 3);
		this.setBlock(world, x + 9, y + 11, z + 15, Blocks.wool, 15, 3);
		this.setBlock(world, x + 8, y + 11, z + 15, Blocks.wool, 15, 3);
		this.setBlock(world, x + 7, y + 11, z + 15, Blocks.wool, 15, 3);
		this.setBlock(world, x + 9, y + 11, z + 14, Blocks.wool, 8, 3);
		this.setBlock(world, x + 8, y + 11, z + 14, Blocks.wool, 15, 3);
		this.setBlock(world, x + 7, y + 11, z + 14, Blocks.wool, 8, 3);
		this.setBlock(world, x + 9, y + 11, z + 13, Blocks.wool, 15, 3);
		this.setBlock(world, x + 8, y + 11, z + 13, Blocks.wool, 15, 3);
		this.setBlock(world, x + 7, y + 11, z + 13, Blocks.wool, 15, 3);
		this.setBlock(world, x + 8, y + 11, z + 12, Blocks.wool, 7, 3);
		this.setBlock(world, x + 7, y + 11, z + 12, Blocks.wool, 7, 3);
		this.setBlock(world, x + 8, y + 11, z + 11, Blocks.wool, 7, 3);
		this.setBlock(world, x + 7, y + 11, z + 11, Blocks.wool, 7, 3);
		this.setBlock(world, x + 8, y + 11, z + 10, Blocks.wool, 8, 3);
		this.setBlock(world, x + 7, y + 11, z + 10, Blocks.wool, 8, 3);
		this.setBlock(world, x + 8, y + 11, z + 9, Blocks.wool, 8, 3);
		this.setBlock(world, x + 7, y + 11, z + 9, Blocks.wool, 8, 3);
		this.setBlock(world, x + 9, y + 12, z + 15, Blocks.wool, 15, 3);
		this.setBlock(world, x + 8, y + 12, z + 15, Blocks.wool, 15, 3);
		this.setBlock(world, x + 7, y + 12, z + 15, Blocks.wool, 15, 3);
		this.setBlock(world, x + 9, y + 12, z + 14, Blocks.wool, 8, 3);
		this.setBlock(world, x + 8, y + 12, z + 14, Blocks.wool, 15, 3);
		this.setBlock(world, x + 7, y + 12, z + 14, Blocks.wool, 8, 3);
		this.setBlock(world, x + 9, y + 12, z + 13, Blocks.wool, 15, 3);
		this.setBlock(world, x + 8, y + 12, z + 13, Blocks.wool, 15, 3);
		this.setBlock(world, x + 7, y + 12, z + 13, Blocks.wool, 15, 3);
		this.setBlock(world, x + 8, y + 13, z + 19, Blocks.wool, 8, 3);
		this.setBlock(world, x + 7, y + 13, z + 19, Blocks.wool, 8, 3);
		this.setBlock(world, x + 8, y + 13, z + 18, Blocks.wool, 8, 3);
		this.setBlock(world, x + 7, y + 13, z + 18, Blocks.wool, 8, 3);
		this.setBlock(world, x + 8, y + 13, z + 17, Blocks.wool, 7, 3);
		this.setBlock(world, x + 7, y + 13, z + 17, Blocks.wool, 7, 3);
		this.setBlock(world, x + 8, y + 13, z + 16, Blocks.wool, 7, 3);
		this.setBlock(world, x + 7, y + 13, z + 16, Blocks.wool, 7, 3);
		this.setBlock(world, x + 9, y + 13, z + 15, Blocks.wool, 15, 3);
		this.setBlock(world, x + 8, y + 13, z + 15, Blocks.wool, 15, 3);
		this.setBlock(world, x + 7, y + 13, z + 15, Blocks.wool, 15, 3);
		this.setBlock(world, x + 9, y + 13, z + 14, Blocks.wool, 7, 3);
		this.setBlock(world, x + 8, y + 13, z + 14, Blocks.wool, 15, 3);
		this.setBlock(world, x + 7, y + 13, z + 14, Blocks.wool, 7, 3);
		this.setBlock(world, x + 9, y + 13, z + 13, Blocks.wool, 15, 3);
		this.setBlock(world, x + 8, y + 13, z + 13, Blocks.wool, 15, 3);
		this.setBlock(world, x + 7, y + 13, z + 13, Blocks.wool, 15, 3);
		this.setBlock(world, x + 8, y + 13, z + 12, Blocks.wool, 7, 3);
		this.setBlock(world, x + 7, y + 13, z + 12, Blocks.wool, 7, 3);
		this.setBlock(world, x + 8, y + 13, z + 11, Blocks.wool, 7, 3);
		this.setBlock(world, x + 7, y + 13, z + 11, Blocks.wool, 7, 3);
		this.setBlock(world, x + 8, y + 13, z + 10, Blocks.wool, 8, 3);
		this.setBlock(world, x + 7, y + 13, z + 10, Blocks.wool, 8, 3);
		this.setBlock(world, x + 8, y + 13, z + 9, Blocks.wool, 8, 3);
		this.setBlock(world, x + 7, y + 13, z + 9, Blocks.wool, 8, 3);
		this.setBlock(world, x + 8, y + 14, z + 19, Blocks.wool, 8, 3);
		this.setBlock(world, x + 7, y + 14, z + 19, Blocks.wool, 8, 3);
		this.setBlock(world, x + 8, y + 14, z + 18, Blocks.wool, 8, 3);
		this.setBlock(world, x + 7, y + 14, z + 18, Blocks.wool, 8, 3);
		this.setBlock(world, x + 8, y + 14, z + 17, Blocks.wool, 7, 3);
		this.setBlock(world, x + 7, y + 14, z + 17, Blocks.wool, 7, 3);
		this.setBlock(world, x + 8, y + 14, z + 16, Blocks.wool, 7, 3);
		this.setBlock(world, x + 7, y + 14, z + 16, Blocks.wool, 7, 3);
		this.setBlock(world, x + 9, y + 14, z + 15, Blocks.wool, 15, 3);
		this.setBlock(world, x + 8, y + 14, z + 15, Blocks.wool, 15, 3);
		this.setBlock(world, x + 7, y + 14, z + 15, Blocks.wool, 15, 3);
		this.setBlock(world, x + 9, y + 14, z + 14, Blocks.wool, 7, 3);
		this.setBlock(world, x + 8, y + 14, z + 14, Blocks.wool, 15, 3);
		this.setBlock(world, x + 7, y + 14, z + 14, Blocks.wool, 7, 3);
		this.setBlock(world, x + 9, y + 14, z + 13, Blocks.wool, 15, 3);
		this.setBlock(world, x + 8, y + 14, z + 13, Blocks.wool, 15, 3);
		this.setBlock(world, x + 7, y + 14, z + 13, Blocks.wool, 15, 3);
		this.setBlock(world, x + 8, y + 14, z + 12, Blocks.wool, 7, 3);
		this.setBlock(world, x + 7, y + 14, z + 12, Blocks.wool, 7, 3);
		this.setBlock(world, x + 8, y + 14, z + 11, Blocks.wool, 7, 3);
		this.setBlock(world, x + 7, y + 14, z + 11, Blocks.wool, 7, 3);
		this.setBlock(world, x + 8, y + 14, z + 10, Blocks.wool, 8, 3);
		this.setBlock(world, x + 7, y + 14, z + 10, Blocks.wool, 8, 3);
		this.setBlock(world, x + 8, y + 14, z + 9, Blocks.wool, 8, 3);
		this.setBlock(world, x + 7, y + 14, z + 9, Blocks.wool, 8, 3);
		this.setBlock(world, x + 9, y + 15, z + 15, Blocks.wool, 15, 3);
		this.setBlock(world, x + 8, y + 15, z + 15, Blocks.wool, 15, 3);
		this.setBlock(world, x + 7, y + 15, z + 15, Blocks.wool, 15, 3);
		this.setBlock(world, x + 9, y + 15, z + 14, Blocks.wool, 15, 3);
		this.setBlock(world, x + 8, y + 15, z + 14, Blocks.wool, 15, 3);
		this.setBlock(world, x + 7, y + 15, z + 14, Blocks.wool, 15, 3);
		this.setBlock(world, x + 9, y + 15, z + 13, Blocks.wool, 15, 3);
		this.setBlock(world, x + 8, y + 15, z + 13, Blocks.wool, 15, 3);
		this.setBlock(world, x + 7, y + 15, z + 13, Blocks.wool, 15, 3);
		this.setBlock(world, x + 9, y + 16, z + 23, Blocks.wool, 15, 3);
		this.setBlock(world, x + 8, y + 16, z + 23, Blocks.wool, 15, 3);
		this.setBlock(world, x + 7, y + 16, z + 23, Blocks.wool, 15, 3);
		this.setBlock(world, x + 9, y + 16, z + 22, Blocks.wool, 15, 3);
		this.setBlock(world, x + 8, y + 16, z + 22, Blocks.wool, 15, 3);
		this.setBlock(world, x + 7, y + 16, z + 22, Blocks.wool, 15, 3);
		this.setBlock(world, x + 9, y + 16, z + 21, Blocks.wool, 15, 3);
		this.setBlock(world, x + 8, y + 16, z + 21, Blocks.wool, 15, 3);
		this.setBlock(world, x + 7, y + 16, z + 21, Blocks.wool, 15, 3);
		this.setBlock(world, x + 9, y + 16, z + 20, Blocks.wool, 15, 3);
		this.setBlock(world, x + 8, y + 16, z + 20, Blocks.wool, 15, 3);
		this.setBlock(world, x + 7, y + 16, z + 20, Blocks.wool, 15, 3);
		this.setBlock(world, x + 9, y + 16, z + 19, Blocks.wool, 15, 3);
		this.setBlock(world, x + 8, y + 16, z + 19, Blocks.wool, 15, 3);
		this.setBlock(world, x + 7, y + 16, z + 19, Blocks.wool, 15, 3);
		this.setBlock(world, x + 9, y + 16, z + 18, Blocks.wool, 15, 3);
		this.setBlock(world, x + 8, y + 16, z + 18, Blocks.wool, 15, 3);
		this.setBlock(world, x + 7, y + 16, z + 18, Blocks.wool, 15, 3);
		this.setBlock(world, x + 9, y + 16, z + 17, Blocks.wool, 15, 3);
		this.setBlock(world, x + 8, y + 16, z + 17, Blocks.wool, 15, 3);
		this.setBlock(world, x + 7, y + 16, z + 17, Blocks.wool, 15, 3);
		this.setBlock(world, x + 9, y + 16, z + 16, Blocks.wool, 15, 3);
		this.setBlock(world, x + 8, y + 16, z + 16, Blocks.wool, 15, 3);
		this.setBlock(world, x + 7, y + 16, z + 16, Blocks.wool, 15, 3);
		this.setBlock(world, x + 9, y + 16, z + 15, Blocks.wool, 15, 3);
		this.setBlock(world, x + 8, y + 16, z + 15, Blocks.wool, 15, 3);
		this.setBlock(world, x + 7, y + 16, z + 15, Blocks.wool, 15, 3);
		this.setBlock(world, x + 9, y + 16, z + 14, Blocks.wool, 15, 3);
		this.setBlock(world, x + 8, y + 16, z + 14, Blocks.wool, 15, 3);
		this.setBlock(world, x + 7, y + 16, z + 14, Blocks.wool, 15, 3);
		this.setBlock(world, x + 9, y + 16, z + 13, Blocks.wool, 15, 3);
		this.setBlock(world, x + 8, y + 16, z + 13, Blocks.wool, 15, 3);
		this.setBlock(world, x + 7, y + 16, z + 13, Blocks.wool, 15, 3);
		this.setBlock(world, x + 9, y + 16, z + 12, Blocks.wool, 15, 3);
		this.setBlock(world, x + 8, y + 16, z + 12, Blocks.wool, 15, 3);
		this.setBlock(world, x + 7, y + 16, z + 12, Blocks.wool, 15, 3);
		this.setBlock(world, x + 9, y + 16, z + 11, Blocks.wool, 15, 3);
		this.setBlock(world, x + 8, y + 16, z + 11, Blocks.wool, 15, 3);
		this.setBlock(world, x + 7, y + 16, z + 11, Blocks.wool, 15, 3);
		this.setBlock(world, x + 9, y + 16, z + 10, Blocks.wool, 15, 3);
		this.setBlock(world, x + 8, y + 16, z + 10, Blocks.wool, 15, 3);
		this.setBlock(world, x + 7, y + 16, z + 10, Blocks.wool, 15, 3);
		this.setBlock(world, x + 9, y + 16, z + 9, Blocks.wool, 15, 3);
		this.setBlock(world, x + 8, y + 16, z + 9, Blocks.wool, 15, 3);
		this.setBlock(world, x + 7, y + 16, z + 9, Blocks.wool, 15, 3);
		this.setBlock(world, x + 9, y + 16, z + 8, Blocks.wool, 15, 3);
		this.setBlock(world, x + 8, y + 16, z + 8, Blocks.wool, 15, 3);
		this.setBlock(world, x + 7, y + 16, z + 8, Blocks.wool, 15, 3);
		this.setBlock(world, x + 9, y + 16, z + 7, Blocks.wool, 15, 3);
		this.setBlock(world, x + 8, y + 16, z + 7, Blocks.wool, 15, 3);
		this.setBlock(world, x + 7, y + 16, z + 7, Blocks.wool, 15, 3);
		this.setBlock(world, x + 9, y + 16, z + 6, Blocks.wool, 15, 3);
		this.setBlock(world, x + 8, y + 16, z + 6, Blocks.wool, 15, 3);
		this.setBlock(world, x + 7, y + 16, z + 6, Blocks.wool, 15, 3);
		this.setBlock(world, x + 9, y + 16, z + 5, Blocks.wool, 15, 3);
		this.setBlock(world, x + 8, y + 16, z + 5, Blocks.wool, 15, 3);
		this.setBlock(world, x + 7, y + 16, z + 5, Blocks.wool, 15, 3);
		this.setBlock(world, x + 11, y + 17, z + 27, Blocks.wool, 15, 3);
		this.setBlock(world, x + 10, y + 17, z + 27, Blocks.wool, 15, 3);
		this.setBlock(world, x + 9, y + 17, z + 27, Blocks.wool, 15, 3);
		this.setBlock(world, x + 8, y + 17, z + 27, Blocks.wool, 15, 3);
		this.setBlock(world, x + 7, y + 17, z + 27, Blocks.wool, 15, 3);
		this.setBlock(world, x + 6, y + 17, z + 27, Blocks.wool, 15, 3);
		this.setBlock(world, x + 11, y + 17, z + 26, Blocks.wool, 15, 3);
		this.setBlock(world, x + 10, y + 17, z + 26, Blocks.wool, 15, 3);
		this.setBlock(world, x + 9, y + 17, z + 26, Blocks.wool, 15, 3);
		this.setBlock(world, x + 8, y + 17, z + 26, Blocks.wool, 15, 3);
		this.setBlock(world, x + 7, y + 17, z + 26, Blocks.wool, 15, 3);
		this.setBlock(world, x + 6, y + 17, z + 26, Blocks.wool, 15, 3);
		this.setBlock(world, x + 11, y + 17, z + 25, Blocks.wool, 15, 3);
		this.setBlock(world, x + 10, y + 17, z + 25, Blocks.wool, 15, 3);
		this.setBlock(world, x + 9, y + 17, z + 25, Blocks.wool, 15, 3);
		this.setBlock(world, x + 8, y + 17, z + 25, Blocks.wool, 15, 3);
		this.setBlock(world, x + 7, y + 17, z + 25, Blocks.wool, 15, 3);
		this.setBlock(world, x + 6, y + 17, z + 25, Blocks.wool, 15, 3);
		this.setBlock(world, x + 11, y + 17, z + 24, Blocks.wool, 15, 3);
		this.setBlock(world, x + 10, y + 17, z + 24, Blocks.wool, 15, 3);
		this.setBlock(world, x + 9, y + 17, z + 24, Blocks.wool, 15, 3);
		this.setBlock(world, x + 8, y + 17, z + 24, Blocks.wool, 15, 3);
		this.setBlock(world, x + 7, y + 17, z + 24, Blocks.wool, 15, 3);
		this.setBlock(world, x + 6, y + 17, z + 24, Blocks.wool, 15, 3);
		this.setBlock(world, x + 11, y + 17, z + 23, Blocks.wool, 15, 3);
		this.setBlock(world, x + 10, y + 17, z + 23, Blocks.wool, 15, 3);
		this.setBlock(world, x + 9, y + 17, z + 23, Blocks.wool, 15, 3);
		this.setBlock(world, x + 8, y + 17, z + 23, Blocks.wool, 15, 3);
		this.setBlock(world, x + 7, y + 17, z + 23, Blocks.wool, 15, 3);
		this.setBlock(world, x + 6, y + 17, z + 23, Blocks.wool, 15, 3);
		this.setBlock(world, x + 11, y + 17, z + 22, Blocks.wool, 15, 3);
		this.setBlock(world, x + 10, y + 17, z + 22, Blocks.wool, 15, 3);
		this.setBlock(world, x + 9, y + 17, z + 22, Blocks.wool, 15, 3);
		this.setBlock(world, x + 8, y + 17, z + 22, Blocks.wool, 15, 3);
		this.setBlock(world, x + 7, y + 17, z + 22, Blocks.wool, 15, 3);
		this.setBlock(world, x + 6, y + 17, z + 22, Blocks.wool, 15, 3);
		this.setBlock(world, x + 9, y + 17, z + 21, Blocks.wool, 15, 3);
		this.setBlock(world, x + 8, y + 17, z + 21, Blocks.wool, 15, 3);
		this.setBlock(world, x + 7, y + 17, z + 21, Blocks.wool, 7, 3);
		this.setBlock(world, x + 9, y + 17, z + 20, Blocks.wool, 15, 3);
		this.setBlock(world, x + 8, y + 17, z + 20, Blocks.wool, 15, 3);
		this.setBlock(world, x + 7, y + 17, z + 20, Blocks.wool, 15, 3);
		this.setBlock(world, x + 9, y + 17, z + 19, Blocks.wool, 15, 3);
		this.setBlock(world, x + 8, y + 17, z + 19, Blocks.wool, 15, 3);
		this.setBlock(world, x + 7, y + 17, z + 19, Blocks.wool, 15, 3);
		this.setBlock(world, x + 9, y + 17, z + 18, Blocks.wool, 7, 3);
		this.setBlock(world, x + 8, y + 17, z + 18, Blocks.wool, 15, 3);
		this.setBlock(world, x + 7, y + 17, z + 18, Blocks.wool, 7, 3);
		this.setBlock(world, x + 9, y + 17, z + 17, Blocks.wool, 8, 3);
		this.setBlock(world, x + 8, y + 17, z + 17, Blocks.wool, 15, 3);
		this.setBlock(world, x + 7, y + 17, z + 17, Blocks.wool, 15, 3);
		this.setBlock(world, x + 9, y + 17, z + 16, Blocks.wool, 7, 3);
		this.setBlock(world, x + 8, y + 17, z + 16, Blocks.wool, 15, 3);
		this.setBlock(world, x + 7, y + 17, z + 16, Blocks.wool, 15, 3);
		this.setBlock(world, x + 9, y + 17, z + 15, Blocks.wool, 15, 3);
		this.setBlock(world, x + 8, y + 17, z + 15, Blocks.wool, 15, 3);
		this.setBlock(world, x + 7, y + 17, z + 15, Blocks.wool, 15, 3);
		this.setBlock(world, x + 9, y + 17, z + 14, Blocks.wool, 15, 3);
		this.setBlock(world, x + 8, y + 17, z + 14, Blocks.wool, 15, 3);
		this.setBlock(world, x + 7, y + 17, z + 14, Blocks.wool, 15, 3);
		this.setBlock(world, x + 9, y + 17, z + 13, Blocks.wool, 15, 3);
		this.setBlock(world, x + 8, y + 17, z + 13, Blocks.wool, 15, 3);
		this.setBlock(world, x + 7, y + 17, z + 13, Blocks.wool, 15, 3);
		this.setBlock(world, x + 9, y + 17, z + 12, Blocks.wool, 7, 3);
		this.setBlock(world, x + 8, y + 17, z + 12, Blocks.wool, 15, 3);
		this.setBlock(world, x + 7, y + 17, z + 12, Blocks.wool, 7, 3);
		this.setBlock(world, x + 9, y + 17, z + 11, Blocks.wool, 8, 3);
		this.setBlock(world, x + 8, y + 17, z + 11, Blocks.wool, 15, 3);
		this.setBlock(world, x + 7, y + 17, z + 11, Blocks.wool, 7, 3);
		this.setBlock(world, x + 9, y + 17, z + 10, Blocks.wool, 8, 3);
		this.setBlock(world, x + 8, y + 17, z + 10, Blocks.wool, 15, 3);
		this.setBlock(world, x + 7, y + 17, z + 10, Blocks.wool, 8, 3);
		this.setBlock(world, x + 9, y + 17, z + 9, Blocks.wool, 7, 3);
		this.setBlock(world, x + 8, y + 17, z + 9, Blocks.wool, 15, 3);
		this.setBlock(world, x + 7, y + 17, z + 9, Blocks.wool, 8, 3);
		this.setBlock(world, x + 9, y + 17, z + 8, Blocks.wool, 15, 3);
		this.setBlock(world, x + 8, y + 17, z + 8, Blocks.wool, 15, 3);
		this.setBlock(world, x + 7, y + 17, z + 8, Blocks.wool, 8, 3);
		this.setBlock(world, x + 9, y + 17, z + 7, Blocks.wool, 15, 3);
		this.setBlock(world, x + 8, y + 17, z + 7, Blocks.wool, 15, 3);
		this.setBlock(world, x + 7, y + 17, z + 7, Blocks.wool, 7, 3);
		this.setBlock(world, x + 12, y + 17, z + 6, Blocks.wool, 15, 3);
		this.setBlock(world, x + 11, y + 17, z + 6, Blocks.wool, 15, 3);
		this.setBlock(world, x + 10, y + 17, z + 6, Blocks.wool, 15, 3);
		this.setBlock(world, x + 9, y + 17, z + 6, Blocks.wool, 15, 3);
		this.setBlock(world, x + 8, y + 17, z + 6, Blocks.wool, 15, 3);
		this.setBlock(world, x + 7, y + 17, z + 6, Blocks.wool, 15, 3);
		this.setBlock(world, x + 12, y + 17, z + 5, Blocks.wool, 15, 3);
		this.setBlock(world, x + 11, y + 17, z + 5, Blocks.wool, 15, 3);
		this.setBlock(world, x + 10, y + 17, z + 5, Blocks.wool, 15, 3);
		this.setBlock(world, x + 9, y + 17, z + 5, Blocks.wool, 15, 3);
		this.setBlock(world, x + 8, y + 17, z + 5, Blocks.wool, 15, 3);
		this.setBlock(world, x + 7, y + 17, z + 5, Blocks.wool, 15, 3);
		this.setBlock(world, x + 12, y + 17, z + 4, Blocks.wool, 15, 3);
		this.setBlock(world, x + 11, y + 17, z + 4, Blocks.wool, 15, 3);
		this.setBlock(world, x + 10, y + 17, z + 4, Blocks.wool, 15, 3);
		this.setBlock(world, x + 9, y + 17, z + 4, Blocks.wool, 15, 3);
		this.setBlock(world, x + 8, y + 17, z + 4, Blocks.wool, 15, 3);
		this.setBlock(world, x + 7, y + 17, z + 4, Blocks.wool, 15, 3);
		this.setBlock(world, x + 12, y + 17, z + 3, Blocks.wool, 15, 3);
		this.setBlock(world, x + 11, y + 17, z + 3, Blocks.wool, 15, 3);
		this.setBlock(world, x + 10, y + 17, z + 3, Blocks.wool, 15, 3);
		this.setBlock(world, x + 9, y + 17, z + 3, Blocks.wool, 15, 3);
		this.setBlock(world, x + 8, y + 17, z + 3, Blocks.wool, 15, 3);
		this.setBlock(world, x + 7, y + 17, z + 3, Blocks.wool, 15, 3);
		this.setBlock(world, x + 12, y + 17, z + 2, Blocks.wool, 15, 3);
		this.setBlock(world, x + 11, y + 17, z + 2, Blocks.wool, 15, 3);
		this.setBlock(world, x + 10, y + 17, z + 2, Blocks.wool, 15, 3);
		this.setBlock(world, x + 9, y + 17, z + 2, Blocks.wool, 15, 3);
		this.setBlock(world, x + 8, y + 17, z + 2, Blocks.wool, 15, 3);
		this.setBlock(world, x + 7, y + 17, z + 2, Blocks.wool, 15, 3);
		this.setBlock(world, x + 12, y + 17, z + 1, Blocks.wool, 15, 3);
		this.setBlock(world, x + 11, y + 17, z + 1, Blocks.wool, 15, 3);
		this.setBlock(world, x + 10, y + 17, z + 1, Blocks.wool, 15, 3);
		this.setBlock(world, x + 9, y + 17, z + 1, Blocks.wool, 15, 3);
		this.setBlock(world, x + 8, y + 17, z + 1, Blocks.wool, 15, 3);
		this.setBlock(world, x + 7, y + 17, z + 1, Blocks.wool, 15, 3);
		this.setBlock(world, x + 11, y + 18, z + 27, Blocks.wool, 15, 3);
		this.setBlock(world, x + 10, y + 18, z + 27, Blocks.wool, 15, 3);
		this.setBlock(world, x + 9, y + 18, z + 27, Blocks.wool, 15, 3);
		this.setBlock(world, x + 8, y + 18, z + 27, Blocks.wool, 15, 3);
		this.setBlock(world, x + 7, y + 18, z + 27, Blocks.wool, 15, 3);
		this.setBlock(world, x + 6, y + 18, z + 27, Blocks.wool, 15, 3);
		this.setBlock(world, x + 11, y + 18, z + 26, Blocks.iron_block, 0, 3);
		this.setBlock(world, x + 10, y + 18, z + 26, Blocks.wool, 15, 3);
		this.setBlock(world, x + 9, y + 18, z + 26, Blocks.wool, 15, 3);
		this.setBlock(world, x + 8, y + 18, z + 26, Blocks.wool, 15, 3);
		this.setBlock(world, x + 7, y + 18, z + 26, Blocks.wool, 15, 3);
		this.setBlock(world, x + 6, y + 18, z + 26, Blocks.wool, 15, 3);
		this.setBlock(world, x + 11, y + 18, z + 25, Blocks.iron_block, 0, 3);
		this.setBlock(world, x + 10, y + 18, z + 25, Blocks.wool, 15, 3);
		this.setBlock(world, x + 9, y + 18, z + 25, Blocks.wool, 15, 3);
		this.setBlock(world, x + 8, y + 18, z + 25, Blocks.wool, 15, 3);
		this.setBlock(world, x + 7, y + 18, z + 25, Blocks.wool, 15, 3);
		this.setBlock(world, x + 6, y + 18, z + 25, Blocks.wool, 15, 3);
		this.setBlock(world, x + 11, y + 18, z + 24, Blocks.iron_block, 0, 3);
		this.setBlock(world, x + 10, y + 18, z + 24, Blocks.wool, 15, 3);
		this.setBlock(world, x + 9, y + 18, z + 24, Blocks.wool, 15, 3);
		this.setBlock(world, x + 8, y + 18, z + 24, Blocks.wool, 15, 3);
		this.setBlock(world, x + 7, y + 18, z + 24, Blocks.wool, 15, 3);
		this.setBlock(world, x + 6, y + 18, z + 24, Blocks.wool, 15, 3);
		this.setBlock(world, x + 11, y + 18, z + 23, Blocks.iron_block, 0, 3);
		this.setBlock(world, x + 10, y + 18, z + 23, Blocks.wool, 15, 3);
		this.setBlock(world, x + 9, y + 18, z + 23, Blocks.wool, 15, 3);
		this.setBlock(world, x + 8, y + 18, z + 23, Blocks.wool, 15, 3);
		this.setBlock(world, x + 7, y + 18, z + 23, Blocks.wool, 15, 3);
		this.setBlock(world, x + 6, y + 18, z + 23, Blocks.wool, 15, 3);
		this.setBlock(world, x + 11, y + 18, z + 22, Blocks.wool, 15, 3);
		this.setBlock(world, x + 10, y + 18, z + 22, Blocks.wool, 15, 3);
		this.setBlock(world, x + 9, y + 18, z + 22, Blocks.wool, 15, 3);
		this.setBlock(world, x + 8, y + 18, z + 22, Blocks.wool, 15, 3);
		this.setBlock(world, x + 7, y + 18, z + 22, Blocks.wool, 15, 3);
		this.setBlock(world, x + 6, y + 18, z + 22, Blocks.wool, 15, 3);
		this.setBlock(world, x + 9, y + 18, z + 21, Blocks.wool, 15, 3);
		this.setBlock(world, x + 8, y + 18, z + 21, Blocks.wool, 15, 3);
		this.setBlock(world, x + 7, y + 18, z + 21, Blocks.wool, 15, 3);
		this.setBlock(world, x + 9, y + 18, z + 20, Blocks.wool, 15, 3);
		this.setBlock(world, x + 8, y + 18, z + 20, Blocks.wool, 15, 3);
		this.setBlock(world, x + 7, y + 18, z + 20, Blocks.wool, 15, 3);
		this.setBlock(world, x + 9, y + 18, z + 19, Blocks.wool, 15, 3);
		this.setBlock(world, x + 8, y + 18, z + 19, Blocks.wool, 15, 3);
		this.setBlock(world, x + 7, y + 18, z + 19, Blocks.wool, 15, 3);
		this.setBlock(world, x + 9, y + 18, z + 18, Blocks.wool, 15, 3);
		this.setBlock(world, x + 8, y + 18, z + 18, Blocks.wool, 15, 3);
		this.setBlock(world, x + 7, y + 18, z + 18, Blocks.wool, 15, 3);
		this.setBlock(world, x + 9, y + 18, z + 17, Blocks.wool, 15, 3);
		this.setBlock(world, x + 8, y + 18, z + 17, Blocks.wool, 15, 3);
		this.setBlock(world, x + 7, y + 18, z + 17, Blocks.wool, 15, 3);
		this.setBlock(world, x + 9, y + 18, z + 16, Blocks.wool, 15, 3);
		this.setBlock(world, x + 8, y + 18, z + 16, Blocks.wool, 15, 3);
		this.setBlock(world, x + 7, y + 18, z + 16, Blocks.wool, 15, 3);
		this.setBlock(world, x + 9, y + 18, z + 15, Blocks.wool, 15, 3);
		this.setBlock(world, x + 8, y + 18, z + 15, Blocks.wool, 15, 3);
		this.setBlock(world, x + 7, y + 18, z + 15, Blocks.wool, 15, 3);
		this.setBlock(world, x + 9, y + 18, z + 14, Blocks.wool, 15, 3);
		this.setBlock(world, x + 8, y + 18, z + 14, Blocks.wool, 15, 3);
		this.setBlock(world, x + 7, y + 18, z + 14, Blocks.wool, 15, 3);
		this.setBlock(world, x + 9, y + 18, z + 13, Blocks.wool, 15, 3);
		this.setBlock(world, x + 8, y + 18, z + 13, Blocks.wool, 15, 3);
		this.setBlock(world, x + 7, y + 18, z + 13, Blocks.wool, 15, 3);
		this.setBlock(world, x + 9, y + 18, z + 12, Blocks.wool, 15, 3);
		this.setBlock(world, x + 8, y + 18, z + 12, Blocks.wool, 15, 3);
		this.setBlock(world, x + 7, y + 18, z + 12, Blocks.wool, 15, 3);
		this.setBlock(world, x + 9, y + 18, z + 11, Blocks.wool, 15, 3);
		this.setBlock(world, x + 8, y + 18, z + 11, Blocks.wool, 15, 3);
		this.setBlock(world, x + 7, y + 18, z + 11, Blocks.wool, 15, 3);
		this.setBlock(world, x + 9, y + 18, z + 10, Blocks.wool, 15, 3);
		this.setBlock(world, x + 8, y + 18, z + 10, Blocks.wool, 15, 3);
		this.setBlock(world, x + 7, y + 18, z + 10, Blocks.wool, 15, 3);
		this.setBlock(world, x + 9, y + 18, z + 9, Blocks.wool, 15, 3);
		this.setBlock(world, x + 8, y + 18, z + 9, Blocks.wool, 15, 3);
		this.setBlock(world, x + 7, y + 18, z + 9, Blocks.wool, 15, 3);
		this.setBlock(world, x + 9, y + 18, z + 8, Blocks.wool, 15, 3);
		this.setBlock(world, x + 8, y + 18, z + 8, Blocks.wool, 15, 3);
		this.setBlock(world, x + 7, y + 18, z + 8, Blocks.wool, 15, 3);
		this.setBlock(world, x + 9, y + 18, z + 7, Blocks.wool, 15, 3);
		this.setBlock(world, x + 8, y + 18, z + 7, Blocks.wool, 15, 3);
		this.setBlock(world, x + 7, y + 18, z + 7, Blocks.wool, 15, 3);
		this.setBlock(world, x + 12, y + 18, z + 6, Blocks.wool, 15, 3);
		this.setBlock(world, x + 11, y + 18, z + 6, Blocks.wool, 15, 3);
		this.setBlock(world, x + 10, y + 18, z + 6, Blocks.wool, 15, 3);
		this.setBlock(world, x + 9, y + 18, z + 6, Blocks.wool, 15, 3);
		this.setBlock(world, x + 8, y + 18, z + 6, Blocks.wool, 15, 3);
		this.setBlock(world, x + 7, y + 18, z + 6, Blocks.wool, 15, 3);
		this.setBlock(world, x + 12, y + 18, z + 5, Blocks.iron_block, 0, 3);
		this.setBlock(world, x + 11, y + 18, z + 5, Blocks.wool, 15, 3);
		this.setBlock(world, x + 10, y + 18, z + 5, Blocks.wool, 15, 3);
		this.setBlock(world, x + 9, y + 18, z + 5, Blocks.wool, 15, 3);
		this.setBlock(world, x + 8, y + 18, z + 5, Blocks.wool, 15, 3);
		this.setBlock(world, x + 7, y + 18, z + 5, Blocks.wool, 15, 3);
		this.setBlock(world, x + 12, y + 18, z + 4, Blocks.iron_block, 0, 3);
		this.setBlock(world, x + 11, y + 18, z + 4, Blocks.wool, 15, 3);
		this.setBlock(world, x + 10, y + 18, z + 4, Blocks.wool, 15, 3);
		this.setBlock(world, x + 9, y + 18, z + 4, Blocks.wool, 15, 3);
		this.setBlock(world, x + 8, y + 18, z + 4, Blocks.wool, 15, 3);
		this.setBlock(world, x + 7, y + 18, z + 4, Blocks.wool, 15, 3);
		this.setBlock(world, x + 12, y + 18, z + 3, Blocks.iron_block, 0, 3);
		this.setBlock(world, x + 11, y + 18, z + 3, Blocks.wool, 15, 3);
		this.setBlock(world, x + 10, y + 18, z + 3, Blocks.wool, 15, 3);
		this.setBlock(world, x + 9, y + 18, z + 3, Blocks.wool, 15, 3);
		this.setBlock(world, x + 8, y + 18, z + 3, Blocks.wool, 15, 3);
		this.setBlock(world, x + 7, y + 18, z + 3, Blocks.wool, 15, 3);
		this.setBlock(world, x + 12, y + 18, z + 2, Blocks.iron_block, 0, 3);
		this.setBlock(world, x + 11, y + 18, z + 2, Blocks.wool, 15, 3);
		this.setBlock(world, x + 10, y + 18, z + 2, Blocks.wool, 15, 3);
		this.setBlock(world, x + 9, y + 18, z + 2, Blocks.wool, 15, 3);
		this.setBlock(world, x + 8, y + 18, z + 2, Blocks.wool, 15, 3);
		this.setBlock(world, x + 7, y + 18, z + 2, Blocks.wool, 15, 3);
		this.setBlock(world, x + 12, y + 18, z + 1, Blocks.wool, 15, 3);
		this.setBlock(world, x + 11, y + 18, z + 1, Blocks.wool, 15, 3);
		this.setBlock(world, x + 10, y + 18, z + 1, Blocks.wool, 15, 3);
		this.setBlock(world, x + 9, y + 18, z + 1, Blocks.wool, 15, 3);
		this.setBlock(world, x + 8, y + 18, z + 1, Blocks.wool, 15, 3);
		this.setBlock(world, x + 7, y + 18, z + 1, Blocks.wool, 15, 3);
		this.setBlock(world, x + 11, y + 19, z + 27, Blocks.wool, 15, 3);
		this.setBlock(world, x + 10, y + 19, z + 27, Blocks.wool, 15, 3);
		this.setBlock(world, x + 9, y + 19, z + 27, Blocks.wool, 15, 3);
		this.setBlock(world, x + 8, y + 19, z + 27, Blocks.wool, 15, 3);
		this.setBlock(world, x + 7, y + 19, z + 27, Blocks.wool, 15, 3);
		this.setBlock(world, x + 6, y + 19, z + 27, Blocks.wool, 15, 3);
		this.setBlock(world, x + 11, y + 19, z + 26, Blocks.wool, 15, 3);
		this.setBlock(world, x + 10, y + 19, z + 26, Blocks.wool, 15, 3);
		this.setBlock(world, x + 9, y + 19, z + 26, Blocks.wool, 15, 3);
		this.setBlock(world, x + 8, y + 19, z + 26, Blocks.wool, 15, 3);
		this.setBlock(world, x + 7, y + 19, z + 26, Blocks.wool, 15, 3);
		this.setBlock(world, x + 6, y + 19, z + 26, Blocks.wool, 15, 3);
		this.setBlock(world, x + 11, y + 19, z + 25, Blocks.wool, 15, 3);
		this.setBlock(world, x + 10, y + 19, z + 25, Blocks.wool, 15, 3);
		this.setBlock(world, x + 9, y + 19, z + 25, Blocks.wool, 15, 3);
		this.setBlock(world, x + 8, y + 19, z + 25, Blocks.wool, 15, 3);
		this.setBlock(world, x + 7, y + 19, z + 25, Blocks.wool, 15, 3);
		this.setBlock(world, x + 6, y + 19, z + 25, Blocks.wool, 15, 3);
		this.setBlock(world, x + 11, y + 19, z + 24, Blocks.wool, 15, 3);
		this.setBlock(world, x + 10, y + 19, z + 24, Blocks.wool, 15, 3);
		this.setBlock(world, x + 9, y + 19, z + 24, Blocks.wool, 15, 3);
		this.setBlock(world, x + 8, y + 19, z + 24, Blocks.wool, 15, 3);
		this.setBlock(world, x + 7, y + 19, z + 24, Blocks.wool, 15, 3);
		this.setBlock(world, x + 6, y + 19, z + 24, Blocks.wool, 15, 3);
		this.setBlock(world, x + 11, y + 19, z + 23, Blocks.wool, 15, 3);
		this.setBlock(world, x + 10, y + 19, z + 23, Blocks.wool, 15, 3);
		this.setBlock(world, x + 9, y + 19, z + 23, Blocks.wool, 15, 3);
		this.setBlock(world, x + 8, y + 19, z + 23, Blocks.wool, 15, 3);
		this.setBlock(world, x + 7, y + 19, z + 23, Blocks.wool, 15, 3);
		this.setBlock(world, x + 6, y + 19, z + 23, Blocks.wool, 15, 3);
		this.setBlock(world, x + 11, y + 19, z + 22, Blocks.wool, 15, 3);
		this.setBlock(world, x + 10, y + 19, z + 22, Blocks.wool, 15, 3);
		this.setBlock(world, x + 9, y + 19, z + 22, Blocks.wool, 15, 3);
		this.setBlock(world, x + 8, y + 19, z + 22, Blocks.wool, 15, 3);
		this.setBlock(world, x + 7, y + 19, z + 22, Blocks.wool, 15, 3);
		this.setBlock(world, x + 6, y + 19, z + 22, Blocks.wool, 15, 3);
		this.setBlock(world, x + 12, y + 19, z + 17, Blocks.wool, 15, 3);
		this.setBlock(world, x + 11, y + 19, z + 17, Blocks.wool, 15, 3);
		this.setBlock(world, x + 10, y + 19, z + 17, Blocks.wool, 15, 3);
		this.setBlock(world, x + 9, y + 19, z + 17, Blocks.wool, 15, 3);
		this.setBlock(world, x + 8, y + 19, z + 17, Blocks.wool, 15, 3);
		this.setBlock(world, x + 7, y + 19, z + 17, Blocks.wool, 15, 3);
		this.setBlock(world, x + 6, y + 19, z + 17, Blocks.wool, 15, 3);
		this.setBlock(world, x + 5, y + 19, z + 17, Blocks.wool, 15, 3);
		this.setBlock(world, x + 12, y + 19, z + 16, Blocks.wool, 15, 3);
		this.setBlock(world, x + 11, y + 19, z + 16, Blocks.wool, 15, 3);
		this.setBlock(world, x + 10, y + 19, z + 16, Blocks.wool, 15, 3);
		this.setBlock(world, x + 9, y + 19, z + 16, Blocks.wool, 15, 3);
		this.setBlock(world, x + 8, y + 19, z + 16, Blocks.wool, 15, 3);
		this.setBlock(world, x + 7, y + 19, z + 16, Blocks.wool, 15, 3);
		this.setBlock(world, x + 6, y + 19, z + 16, Blocks.wool, 15, 3);
		this.setBlock(world, x + 5, y + 19, z + 16, Blocks.wool, 15, 3);
		this.setBlock(world, x + 12, y + 19, z + 15, Blocks.wool, 15, 3);
		this.setBlock(world, x + 11, y + 19, z + 15, Blocks.wool, 15, 3);
		this.setBlock(world, x + 10, y + 19, z + 15, Blocks.wool, 15, 3);
		this.setBlock(world, x + 9, y + 19, z + 15, Blocks.wool, 15, 3);
		this.setBlock(world, x + 8, y + 19, z + 15, Blocks.wool, 15, 3);
		this.setBlock(world, x + 7, y + 19, z + 15, Blocks.wool, 15, 3);
		this.setBlock(world, x + 6, y + 19, z + 15, Blocks.wool, 15, 3);
		this.setBlock(world, x + 5, y + 19, z + 15, Blocks.wool, 15, 3);
		this.setBlock(world, x + 12, y + 19, z + 14, Blocks.wool, 15, 3);
		this.setBlock(world, x + 11, y + 19, z + 14, Blocks.wool, 15, 3);
		this.setBlock(world, x + 10, y + 19, z + 14, Blocks.wool, 15, 3);
		this.setBlock(world, x + 9, y + 19, z + 14, Blocks.wool, 15, 3);
		this.setBlock(world, x + 8, y + 19, z + 14, Blocks.wool, 15, 3);
		this.setBlock(world, x + 7, y + 19, z + 14, Blocks.wool, 15, 3);
		this.setBlock(world, x + 6, y + 19, z + 14, Blocks.wool, 15, 3);
		this.setBlock(world, x + 5, y + 19, z + 14, Blocks.wool, 15, 3);
		this.setBlock(world, x + 12, y + 19, z + 13, Blocks.wool, 15, 3);
		this.setBlock(world, x + 11, y + 19, z + 13, Blocks.wool, 15, 3);
		this.setBlock(world, x + 10, y + 19, z + 13, Blocks.wool, 15, 3);
		this.setBlock(world, x + 9, y + 19, z + 13, Blocks.wool, 15, 3);
		this.setBlock(world, x + 8, y + 19, z + 13, Blocks.wool, 15, 3);
		this.setBlock(world, x + 7, y + 19, z + 13, Blocks.wool, 15, 3);
		this.setBlock(world, x + 6, y + 19, z + 13, Blocks.wool, 15, 3);
		this.setBlock(world, x + 5, y + 19, z + 13, Blocks.wool, 15, 3);
		this.setBlock(world, x + 12, y + 19, z + 12, Blocks.wool, 15, 3);
		this.setBlock(world, x + 11, y + 19, z + 12, Blocks.wool, 15, 3);
		this.setBlock(world, x + 10, y + 19, z + 12, Blocks.wool, 15, 3);
		this.setBlock(world, x + 9, y + 19, z + 12, Blocks.wool, 15, 3);
		this.setBlock(world, x + 8, y + 19, z + 12, Blocks.wool, 15, 3);
		this.setBlock(world, x + 7, y + 19, z + 12, Blocks.wool, 15, 3);
		this.setBlock(world, x + 6, y + 19, z + 12, Blocks.wool, 15, 3);
		this.setBlock(world, x + 5, y + 19, z + 12, Blocks.wool, 15, 3);
		this.setBlock(world, x + 12, y + 19, z + 11, Blocks.wool, 15, 3);
		this.setBlock(world, x + 11, y + 19, z + 11, Blocks.wool, 15, 3);
		this.setBlock(world, x + 10, y + 19, z + 11, Blocks.wool, 15, 3);
		this.setBlock(world, x + 9, y + 19, z + 11, Blocks.wool, 15, 3);
		this.setBlock(world, x + 8, y + 19, z + 11, Blocks.wool, 15, 3);
		this.setBlock(world, x + 7, y + 19, z + 11, Blocks.wool, 15, 3);
		this.setBlock(world, x + 6, y + 19, z + 11, Blocks.wool, 15, 3);
		this.setBlock(world, x + 5, y + 19, z + 11, Blocks.wool, 15, 3);
		this.setBlock(world, x + 12, y + 19, z + 10, Blocks.wool, 15, 3);
		this.setBlock(world, x + 11, y + 19, z + 10, Blocks.wool, 15, 3);
		this.setBlock(world, x + 10, y + 19, z + 10, Blocks.wool, 15, 3);
		this.setBlock(world, x + 9, y + 19, z + 10, Blocks.wool, 15, 3);
		this.setBlock(world, x + 8, y + 19, z + 10, Blocks.wool, 15, 3);
		this.setBlock(world, x + 7, y + 19, z + 10, Blocks.wool, 15, 3);
		this.setBlock(world, x + 6, y + 19, z + 10, Blocks.wool, 15, 3);
		this.setBlock(world, x + 5, y + 19, z + 10, Blocks.wool, 15, 3);
		this.setBlock(world, x + 12, y + 19, z + 6, Blocks.wool, 15, 3);
		this.setBlock(world, x + 11, y + 19, z + 6, Blocks.wool, 15, 3);
		this.setBlock(world, x + 10, y + 19, z + 6, Blocks.wool, 15, 3);
		this.setBlock(world, x + 9, y + 19, z + 6, Blocks.wool, 15, 3);
		this.setBlock(world, x + 8, y + 19, z + 6, Blocks.wool, 15, 3);
		this.setBlock(world, x + 7, y + 19, z + 6, Blocks.wool, 15, 3);
		this.setBlock(world, x + 12, y + 19, z + 5, Blocks.wool, 15, 3);
		this.setBlock(world, x + 11, y + 19, z + 5, Blocks.wool, 15, 3);
		this.setBlock(world, x + 10, y + 19, z + 5, Blocks.wool, 15, 3);
		this.setBlock(world, x + 9, y + 19, z + 5, Blocks.wool, 15, 3);
		this.setBlock(world, x + 8, y + 19, z + 5, Blocks.wool, 15, 3);
		this.setBlock(world, x + 7, y + 19, z + 5, Blocks.wool, 15, 3);
		this.setBlock(world, x + 12, y + 19, z + 4, Blocks.wool, 15, 3);
		this.setBlock(world, x + 11, y + 19, z + 4, Blocks.wool, 15, 3);
		this.setBlock(world, x + 10, y + 19, z + 4, Blocks.wool, 15, 3);
		this.setBlock(world, x + 9, y + 19, z + 4, Blocks.wool, 15, 3);
		this.setBlock(world, x + 8, y + 19, z + 4, Blocks.wool, 15, 3);
		this.setBlock(world, x + 7, y + 19, z + 4, Blocks.wool, 15, 3);
		this.setBlock(world, x + 12, y + 19, z + 3, Blocks.wool, 15, 3);
		this.setBlock(world, x + 11, y + 19, z + 3, Blocks.wool, 15, 3);
		this.setBlock(world, x + 10, y + 19, z + 3, Blocks.wool, 15, 3);
		this.setBlock(world, x + 9, y + 19, z + 3, Blocks.wool, 15, 3);
		this.setBlock(world, x + 8, y + 19, z + 3, Blocks.wool, 15, 3);
		this.setBlock(world, x + 7, y + 19, z + 3, Blocks.wool, 15, 3);
		this.setBlock(world, x + 12, y + 19, z + 2, Blocks.wool, 15, 3);
		this.setBlock(world, x + 11, y + 19, z + 2, Blocks.wool, 15, 3);
		this.setBlock(world, x + 10, y + 19, z + 2, Blocks.wool, 15, 3);
		this.setBlock(world, x + 9, y + 19, z + 2, Blocks.wool, 15, 3);
		this.setBlock(world, x + 8, y + 19, z + 2, Blocks.wool, 15, 3);
		this.setBlock(world, x + 7, y + 19, z + 2, Blocks.wool, 15, 3);
		this.setBlock(world, x + 12, y + 19, z + 1, Blocks.wool, 15, 3);
		this.setBlock(world, x + 11, y + 19, z + 1, Blocks.wool, 15, 3);
		this.setBlock(world, x + 10, y + 19, z + 1, Blocks.wool, 15, 3);
		this.setBlock(world, x + 9, y + 19, z + 1, Blocks.wool, 15, 3);
		this.setBlock(world, x + 8, y + 19, z + 1, Blocks.wool, 15, 3);
		this.setBlock(world, x + 7, y + 19, z + 1, Blocks.wool, 15, 3);
		this.setBlock(world, x + 11, y + 20, z + 27, Blocks.iron_block, 0, 3);
		this.setBlock(world, x + 10, y + 20, z + 27, Blocks.wool, 15, 3);
		this.setBlock(world, x + 9, y + 20, z + 27, Blocks.wool, 15, 3);
		this.setBlock(world, x + 8, y + 20, z + 27, Blocks.wool, 15, 3);
		this.setBlock(world, x + 7, y + 20, z + 27, Blocks.wool, 15, 3);
		this.setBlock(world, x + 6, y + 20, z + 27, Blocks.wool, 15, 3);
		this.setBlock(world, x + 11, y + 20, z + 26, Blocks.iron_block, 0, 3);
		this.setBlock(world, x + 10, y + 20, z + 26, Blocks.wool, 15, 3);
		this.setBlock(world, x + 9, y + 20, z + 26, Blocks.wool, 15, 3);
		this.setBlock(world, x + 8, y + 20, z + 26, Blocks.wool, 15, 3);
		this.setBlock(world, x + 7, y + 20, z + 26, Blocks.wool, 15, 3);
		this.setBlock(world, x + 6, y + 20, z + 26, Blocks.wool, 15, 3);
		this.setBlock(world, x + 11, y + 20, z + 25, Blocks.wool, 15, 3);
		this.setBlock(world, x + 10, y + 20, z + 25, Blocks.wool, 15, 3);
		this.setBlock(world, x + 9, y + 20, z + 25, Blocks.wool, 15, 3);
		this.setBlock(world, x + 8, y + 20, z + 25, Blocks.wool, 15, 3);
		this.setBlock(world, x + 7, y + 20, z + 25, Blocks.wool, 15, 3);
		this.setBlock(world, x + 6, y + 20, z + 25, Blocks.wool, 15, 3);
		this.setBlock(world, x + 11, y + 20, z + 24, Blocks.wool, 15, 3);
		this.setBlock(world, x + 10, y + 20, z + 24, Blocks.wool, 15, 3);
		this.setBlock(world, x + 9, y + 20, z + 24, Blocks.wool, 15, 3);
		this.setBlock(world, x + 8, y + 20, z + 24, Blocks.wool, 15, 3);
		this.setBlock(world, x + 7, y + 20, z + 24, Blocks.wool, 15, 3);
		this.setBlock(world, x + 6, y + 20, z + 24, Blocks.wool, 15, 3);
		this.setBlock(world, x + 11, y + 20, z + 23, Blocks.iron_block, 0, 3);
		this.setBlock(world, x + 10, y + 20, z + 23, Blocks.wool, 15, 3);
		this.setBlock(world, x + 9, y + 20, z + 23, Blocks.wool, 15, 3);
		this.setBlock(world, x + 8, y + 20, z + 23, Blocks.wool, 15, 3);
		this.setBlock(world, x + 7, y + 20, z + 23, Blocks.wool, 15, 3);
		this.setBlock(world, x + 6, y + 20, z + 23, Blocks.wool, 15, 3);
		this.setBlock(world, x + 11, y + 20, z + 22, Blocks.iron_block, 0, 3);
		this.setBlock(world, x + 10, y + 20, z + 22, Blocks.wool, 15, 3);
		this.setBlock(world, x + 9, y + 20, z + 22, Blocks.wool, 15, 3);
		this.setBlock(world, x + 8, y + 20, z + 22, Blocks.wool, 15, 3);
		this.setBlock(world, x + 7, y + 20, z + 22, Blocks.wool, 15, 3);
		this.setBlock(world, x + 6, y + 20, z + 22, Blocks.wool, 15, 3);
		this.setBlock(world, x + 12, y + 20, z + 17, Blocks.wool, 15, 3);
		this.setBlock(world, x + 11, y + 20, z + 17, Blocks.wool, 15, 3);
		this.setBlock(world, x + 10, y + 20, z + 17, Blocks.wool, 15, 3);
		this.setBlock(world, x + 9, y + 20, z + 17, Blocks.wool, 15, 3);
		this.setBlock(world, x + 8, y + 20, z + 17, Blocks.wool, 15, 3);
		this.setBlock(world, x + 7, y + 20, z + 17, Blocks.obsidian, 0, 3);
		this.setBlock(world, x + 6, y + 20, z + 17, Blocks.wool, 15, 3);
		this.setBlock(world, x + 5, y + 20, z + 17, Blocks.wool, 15, 3);
		this.setBlock(world, x + 12, y + 20, z + 16, Blocks.wool, 15, 3);
		this.setBlock(world, x + 11, y + 20, z + 16, Blocks.wool, 15, 3);
		this.setBlock(world, x + 10, y + 20, z + 16, Blocks.wool, 15, 3);
		this.setBlock(world, x + 9, y + 20, z + 16, Blocks.wool, 15, 3);
		this.setBlock(world, x + 8, y + 20, z + 16, Blocks.wool, 15, 3);
		this.setBlock(world, x + 7, y + 20, z + 16, Blocks.wool, 15, 3);
		this.setBlock(world, x + 6, y + 20, z + 16, Blocks.wool, 15, 3);
		this.setBlock(world, x + 5, y + 20, z + 16, Blocks.wool, 15, 3);
		this.setBlock(world, x + 12, y + 20, z + 15, Blocks.iron_block, 0, 3);
		this.setBlock(world, x + 11, y + 20, z + 15, Blocks.iron_block, 0, 3);
		this.setBlock(world, x + 10, y + 20, z + 15, Blocks.iron_block, 0, 3);
		this.setBlock(world, x + 9, y + 20, z + 15, Blocks.wool, 15, 3);
		this.setBlock(world, x + 8, y + 20, z + 15, Blocks.wool, 15, 3);
		this.setBlock(world, x + 7, y + 20, z + 15, Blocks.wool, 15, 3);
		this.setBlock(world, x + 6, y + 20, z + 15, Blocks.wool, 15, 3);
		this.setBlock(world, x + 5, y + 20, z + 15, Blocks.wool, 15, 3);
		this.setBlock(world, x + 12, y + 20, z + 14, Blocks.iron_block, 0, 3);
		this.setBlock(world, x + 11, y + 20, z + 14, Blocks.wool, 15, 3);
		this.setBlock(world, x + 10, y + 20, z + 14, Blocks.iron_block, 0, 3);
		this.setBlock(world, x + 9, y + 20, z + 14, Blocks.iron_block, 0, 3);
		this.setBlock(world, x + 8, y + 20, z + 14, Blocks.wool, 15, 3);
		this.setBlock(world, x + 7, y + 20, z + 14, Blocks.wool, 15, 3);
		this.setBlock(world, x + 6, y + 20, z + 14, Blocks.wool, 15, 3);
		this.setBlock(world, x + 5, y + 20, z + 14, Blocks.wool, 15, 3);
		this.setBlock(world, x + 12, y + 20, z + 13, Blocks.iron_block, 0, 3);
		this.setBlock(world, x + 11, y + 20, z + 13, Blocks.wool, 15, 3);
		this.setBlock(world, x + 10, y + 20, z + 13, Blocks.iron_block, 0, 3);
		this.setBlock(world, x + 9, y + 20, z + 13, Blocks.iron_block, 0, 3);
		this.setBlock(world, x + 8, y + 20, z + 13, Blocks.wool, 15, 3);
		this.setBlock(world, x + 7, y + 20, z + 13, Blocks.wool, 15, 3);
		this.setBlock(world, x + 6, y + 20, z + 13, Blocks.wool, 15, 3);
		this.setBlock(world, x + 5, y + 20, z + 13, Blocks.wool, 15, 3);
		this.setBlock(world, x + 12, y + 20, z + 12, Blocks.iron_block, 0, 3);
		this.setBlock(world, x + 11, y + 20, z + 12, Blocks.iron_block, 0, 3);
		this.setBlock(world, x + 10, y + 20, z + 12, Blocks.iron_block, 0, 3);
		this.setBlock(world, x + 9, y + 20, z + 12, Blocks.wool, 15, 3);
		this.setBlock(world, x + 8, y + 20, z + 12, Blocks.wool, 15, 3);
		this.setBlock(world, x + 7, y + 20, z + 12, Blocks.wool, 15, 3);
		this.setBlock(world, x + 6, y + 20, z + 12, Blocks.wool, 15, 3);
		this.setBlock(world, x + 5, y + 20, z + 12, Blocks.wool, 15, 3);
		this.setBlock(world, x + 12, y + 20, z + 11, Blocks.wool, 15, 3);
		this.setBlock(world, x + 11, y + 20, z + 11, Blocks.wool, 15, 3);
		this.setBlock(world, x + 10, y + 20, z + 11, Blocks.wool, 15, 3);
		this.setBlock(world, x + 9, y + 20, z + 11, Blocks.wool, 15, 3);
		this.setBlock(world, x + 8, y + 20, z + 11, Blocks.wool, 15, 3);
		this.setBlock(world, x + 7, y + 20, z + 11, Blocks.wool, 15, 3);
		this.setBlock(world, x + 6, y + 20, z + 11, Blocks.wool, 15, 3);
		this.setBlock(world, x + 5, y + 20, z + 11, Blocks.wool, 15, 3);
		this.setBlock(world, x + 12, y + 20, z + 10, Blocks.wool, 15, 3);
		this.setBlock(world, x + 11, y + 20, z + 10, Blocks.wool, 15, 3);
		this.setBlock(world, x + 10, y + 20, z + 10, Blocks.wool, 15, 3);
		this.setBlock(world, x + 9, y + 20, z + 10, Blocks.wool, 15, 3);
		this.setBlock(world, x + 8, y + 20, z + 10, Blocks.wool, 15, 3);
		this.setBlock(world, x + 7, y + 20, z + 10, Blocks.obsidian, 0, 3);
		this.setBlock(world, x + 6, y + 20, z + 10, Blocks.wool, 15, 3);
		this.setBlock(world, x + 5, y + 20, z + 10, Blocks.wool, 15, 3);
		this.setBlock(world, x + 12, y + 20, z + 6, Blocks.iron_block, 0, 3);
		this.setBlock(world, x + 11, y + 20, z + 6, Blocks.wool, 15, 3);
		this.setBlock(world, x + 10, y + 20, z + 6, Blocks.wool, 15, 3);
		this.setBlock(world, x + 9, y + 20, z + 6, Blocks.wool, 15, 3);
		this.setBlock(world, x + 8, y + 20, z + 6, Blocks.wool, 15, 3);
		this.setBlock(world, x + 7, y + 20, z + 6, Blocks.wool, 15, 3);
		this.setBlock(world, x + 12, y + 20, z + 5, Blocks.iron_block, 0, 3);
		this.setBlock(world, x + 11, y + 20, z + 5, Blocks.wool, 15, 3);
		this.setBlock(world, x + 10, y + 20, z + 5, Blocks.wool, 15, 3);
		this.setBlock(world, x + 9, y + 20, z + 5, Blocks.wool, 15, 3);
		this.setBlock(world, x + 8, y + 20, z + 5, Blocks.wool, 15, 3);
		this.setBlock(world, x + 7, y + 20, z + 5, Blocks.wool, 15, 3);
		this.setBlock(world, x + 12, y + 20, z + 4, Blocks.wool, 15, 3);
		this.setBlock(world, x + 11, y + 20, z + 4, Blocks.wool, 15, 3);
		this.setBlock(world, x + 10, y + 20, z + 4, Blocks.wool, 15, 3);
		this.setBlock(world, x + 9, y + 20, z + 4, Blocks.wool, 15, 3);
		this.setBlock(world, x + 8, y + 20, z + 4, Blocks.wool, 15, 3);
		this.setBlock(world, x + 7, y + 20, z + 4, Blocks.wool, 15, 3);
		this.setBlock(world, x + 12, y + 20, z + 3, Blocks.wool, 15, 3);
		this.setBlock(world, x + 11, y + 20, z + 3, Blocks.wool, 15, 3);
		this.setBlock(world, x + 10, y + 20, z + 3, Blocks.wool, 15, 3);
		this.setBlock(world, x + 9, y + 20, z + 3, Blocks.wool, 15, 3);
		this.setBlock(world, x + 8, y + 20, z + 3, Blocks.wool, 15, 3);
		this.setBlock(world, x + 7, y + 20, z + 3, Blocks.wool, 15, 3);
		this.setBlock(world, x + 12, y + 20, z + 2, Blocks.iron_block, 0, 3);
		this.setBlock(world, x + 11, y + 20, z + 2, Blocks.wool, 15, 3);
		this.setBlock(world, x + 10, y + 20, z + 2, Blocks.wool, 15, 3);
		this.setBlock(world, x + 9, y + 20, z + 2, Blocks.wool, 15, 3);
		this.setBlock(world, x + 8, y + 20, z + 2, Blocks.wool, 15, 3);
		this.setBlock(world, x + 7, y + 20, z + 2, Blocks.wool, 15, 3);
		this.setBlock(world, x + 12, y + 20, z + 1, Blocks.iron_block, 0, 3);
		this.setBlock(world, x + 11, y + 20, z + 1, Blocks.wool, 15, 3);
		this.setBlock(world, x + 10, y + 20, z + 1, Blocks.wool, 15, 3);
		this.setBlock(world, x + 9, y + 20, z + 1, Blocks.wool, 15, 3);
		this.setBlock(world, x + 8, y + 20, z + 1, Blocks.wool, 15, 3);
		this.setBlock(world, x + 7, y + 20, z + 1, Blocks.wool, 15, 3);
		this.setBlock(world, x + 11, y + 21, z + 27, Blocks.obsidian, 0, 3);
		this.setBlock(world, x + 10, y + 21, z + 27, Blocks.wool, 15, 3);
		this.setBlock(world, x + 9, y + 21, z + 27, Blocks.wool, 15, 3);
		this.setBlock(world, x + 8, y + 21, z + 27, Blocks.wool, 15, 3);
		this.setBlock(world, x + 7, y + 21, z + 27, Blocks.wool, 15, 3);
		this.setBlock(world, x + 6, y + 21, z + 27, Blocks.wool, 15, 3);
		this.setBlock(world, x + 11, y + 21, z + 26, Blocks.obsidian, 0, 3);
		this.setBlock(world, x + 10, y + 21, z + 26, Blocks.wool, 15, 3);
		this.setBlock(world, x + 9, y + 21, z + 26, Blocks.wool, 15, 3);
		this.setBlock(world, x + 8, y + 21, z + 26, Blocks.wool, 15, 3);
		this.setBlock(world, x + 7, y + 21, z + 26, Blocks.wool, 15, 3);
		this.setBlock(world, x + 6, y + 21, z + 26, Blocks.wool, 15, 3);
		this.setBlock(world, x + 11, y + 21, z + 25, Blocks.wool, 15, 3);
		this.setBlock(world, x + 10, y + 21, z + 25, Blocks.wool, 15, 3);
		this.setBlock(world, x + 9, y + 21, z + 25, Blocks.wool, 15, 3);
		this.setBlock(world, x + 8, y + 21, z + 25, Blocks.wool, 15, 3);
		this.setBlock(world, x + 7, y + 21, z + 25, Blocks.wool, 15, 3);
		this.setBlock(world, x + 6, y + 21, z + 25, Blocks.wool, 15, 3);
		this.setBlock(world, x + 11, y + 21, z + 24, Blocks.wool, 15, 3);
		this.setBlock(world, x + 10, y + 21, z + 24, Blocks.wool, 15, 3);
		this.setBlock(world, x + 9, y + 21, z + 24, Blocks.wool, 15, 3);
		this.setBlock(world, x + 8, y + 21, z + 24, Blocks.wool, 15, 3);
		this.setBlock(world, x + 7, y + 21, z + 24, Blocks.wool, 15, 3);
		this.setBlock(world, x + 6, y + 21, z + 24, Blocks.wool, 15, 3);
		this.setBlock(world, x + 11, y + 21, z + 23, Blocks.obsidian, 0, 3);
		this.setBlock(world, x + 10, y + 21, z + 23, Blocks.wool, 15, 3);
		this.setBlock(world, x + 9, y + 21, z + 23, Blocks.wool, 15, 3);
		this.setBlock(world, x + 8, y + 21, z + 23, Blocks.wool, 15, 3);
		this.setBlock(world, x + 7, y + 21, z + 23, Blocks.wool, 15, 3);
		this.setBlock(world, x + 6, y + 21, z + 23, Blocks.wool, 15, 3);
		this.setBlock(world, x + 11, y + 21, z + 22, Blocks.obsidian, 0, 3);
		this.setBlock(world, x + 10, y + 21, z + 22, Blocks.wool, 15, 3);
		this.setBlock(world, x + 9, y + 21, z + 22, Blocks.wool, 15, 3);
		this.setBlock(world, x + 8, y + 21, z + 22, Blocks.wool, 15, 3);
		this.setBlock(world, x + 7, y + 21, z + 22, Blocks.wool, 15, 3);
		this.setBlock(world, x + 6, y + 21, z + 22, Blocks.wool, 15, 3);
		this.setBlock(world, x + 12, y + 21, z + 17, Blocks.wool, 15, 3);
		this.setBlock(world, x + 11, y + 21, z + 17, Blocks.wool, 15, 3);
		this.setBlock(world, x + 10, y + 21, z + 17, Blocks.wool, 15, 3);
		this.setBlock(world, x + 9, y + 21, z + 17, Blocks.wool, 15, 3);
		this.setBlock(world, x + 8, y + 21, z + 17, Blocks.wool, 15, 3);
		this.setBlock(world, x + 7, y + 21, z + 17, Blocks.wool, 15, 3);
		this.setBlock(world, x + 6, y + 21, z + 17, Blocks.wool, 15, 3);
		this.setBlock(world, x + 5, y + 21, z + 17, Blocks.wool, 15, 3);
		this.setBlock(world, x + 12, y + 21, z + 16, Blocks.wool, 15, 3);
		this.setBlock(world, x + 11, y + 21, z + 16, Blocks.wool, 15, 3);
		this.setBlock(world, x + 10, y + 21, z + 16, Blocks.wool, 15, 3);
		this.setBlock(world, x + 9, y + 21, z + 16, Blocks.wool, 15, 3);
		this.setBlock(world, x + 8, y + 21, z + 16, Blocks.wool, 15, 3);
		this.setBlock(world, x + 7, y + 21, z + 16, Blocks.wool, 15, 3);
		this.setBlock(world, x + 6, y + 21, z + 16, Blocks.wool, 15, 3);
		this.setBlock(world, x + 5, y + 21, z + 16, Blocks.wool, 15, 3);
		this.setBlock(world, x + 12, y + 21, z + 15, Blocks.wool, 15, 3);
		this.setBlock(world, x + 11, y + 21, z + 15, Blocks.wool, 15, 3);
		this.setBlock(world, x + 10, y + 21, z + 15, Blocks.wool, 15, 3);
		this.setBlock(world, x + 9, y + 21, z + 15, Blocks.wool, 15, 3);
		this.setBlock(world, x + 8, y + 21, z + 15, Blocks.wool, 15, 3);
		this.setBlock(world, x + 7, y + 21, z + 15, Blocks.wool, 15, 3);
		this.setBlock(world, x + 6, y + 21, z + 15, Blocks.wool, 15, 3);
		this.setBlock(world, x + 5, y + 21, z + 15, Blocks.wool, 15, 3);
		this.setBlock(world, x + 12, y + 21, z + 14, Blocks.wool, 15, 3);
		this.setBlock(world, x + 11, y + 21, z + 14, Blocks.wool, 15, 3);
		this.setBlock(world, x + 10, y + 21, z + 14, Blocks.wool, 15, 3);
		this.setBlock(world, x + 9, y + 21, z + 14, Blocks.wool, 15, 3);
		this.setBlock(world, x + 8, y + 21, z + 14, Blocks.beacon, 0, 3);
		this.setBlock(world, x + 7, y + 21, z + 14, Blocks.beacon, 0, 3);
		this.setBlock(world, x + 6, y + 21, z + 14, Blocks.wool, 15, 3);
		this.setBlock(world, x + 5, y + 21, z + 14, Blocks.wool, 15, 3);
		this.setBlock(world, x + 12, y + 21, z + 13, Blocks.wool, 15, 3);
		this.setBlock(world, x + 11, y + 21, z + 13, Blocks.wool, 15, 3);
		this.setBlock(world, x + 10, y + 21, z + 13, Blocks.wool, 15, 3);
		this.setBlock(world, x + 9, y + 21, z + 13, Blocks.wool, 15, 3);
		this.setBlock(world, x + 8, y + 21, z + 13, Blocks.beacon, 0, 3);
		this.setBlock(world, x + 7, y + 21, z + 13, Blocks.beacon, 0, 3);
		this.setBlock(world, x + 6, y + 21, z + 13, Blocks.wool, 15, 3);
		this.setBlock(world, x + 5, y + 21, z + 13, Blocks.wool, 15, 3);
		this.setBlock(world, x + 12, y + 21, z + 12, Blocks.wool, 15, 3);
		this.setBlock(world, x + 11, y + 21, z + 12, Blocks.wool, 15, 3);
		this.setBlock(world, x + 10, y + 21, z + 12, Blocks.wool, 15, 3);
		this.setBlock(world, x + 9, y + 21, z + 12, Blocks.wool, 15, 3);
		this.setBlock(world, x + 8, y + 21, z + 12, Blocks.wool, 15, 3);
		this.setBlock(world, x + 7, y + 21, z + 12, Blocks.wool, 15, 3);
		this.setBlock(world, x + 6, y + 21, z + 12, Blocks.wool, 15, 3);
		this.setBlock(world, x + 5, y + 21, z + 12, Blocks.wool, 15, 3);
		this.setBlock(world, x + 12, y + 21, z + 11, Blocks.wool, 15, 3);
		this.setBlock(world, x + 11, y + 21, z + 11, Blocks.wool, 15, 3);
		this.setBlock(world, x + 10, y + 21, z + 11, Blocks.wool, 15, 3);
		this.setBlock(world, x + 9, y + 21, z + 11, Blocks.wool, 15, 3);
		this.setBlock(world, x + 8, y + 21, z + 11, Blocks.wool, 15, 3);
		this.setBlock(world, x + 7, y + 21, z + 11, Blocks.wool, 15, 3);
		this.setBlock(world, x + 6, y + 21, z + 11, Blocks.wool, 15, 3);
		this.setBlock(world, x + 5, y + 21, z + 11, Blocks.wool, 15, 3);
		this.setBlock(world, x + 12, y + 21, z + 10, Blocks.wool, 15, 3);
		this.setBlock(world, x + 11, y + 21, z + 10, Blocks.wool, 15, 3);
		this.setBlock(world, x + 10, y + 21, z + 10, Blocks.wool, 15, 3);
		this.setBlock(world, x + 9, y + 21, z + 10, Blocks.wool, 15, 3);
		this.setBlock(world, x + 8, y + 21, z + 10, Blocks.wool, 15, 3);
		this.setBlock(world, x + 7, y + 21, z + 10, Blocks.wool, 15, 3);
		this.setBlock(world, x + 6, y + 21, z + 10, Blocks.wool, 15, 3);
		this.setBlock(world, x + 5, y + 21, z + 10, Blocks.wool, 15, 3);
		this.setBlock(world, x + 12, y + 21, z + 6, Blocks.obsidian, 0, 3);
		this.setBlock(world, x + 11, y + 21, z + 6, Blocks.wool, 15, 3);
		this.setBlock(world, x + 10, y + 21, z + 6, Blocks.wool, 15, 3);
		this.setBlock(world, x + 9, y + 21, z + 6, Blocks.wool, 15, 3);
		this.setBlock(world, x + 8, y + 21, z + 6, Blocks.wool, 15, 3);
		this.setBlock(world, x + 7, y + 21, z + 6, Blocks.wool, 15, 3);
		this.setBlock(world, x + 12, y + 21, z + 5, Blocks.obsidian, 0, 3);
		this.setBlock(world, x + 11, y + 21, z + 5, Blocks.wool, 15, 3);
		this.setBlock(world, x + 10, y + 21, z + 5, Blocks.wool, 15, 3);
		this.setBlock(world, x + 9, y + 21, z + 5, Blocks.wool, 15, 3);
		this.setBlock(world, x + 8, y + 21, z + 5, Blocks.wool, 15, 3);
		this.setBlock(world, x + 7, y + 21, z + 5, Blocks.wool, 15, 3);
		this.setBlock(world, x + 12, y + 21, z + 4, Blocks.wool, 15, 3);
		this.setBlock(world, x + 11, y + 21, z + 4, Blocks.wool, 15, 3);
		this.setBlock(world, x + 10, y + 21, z + 4, Blocks.wool, 15, 3);
		this.setBlock(world, x + 9, y + 21, z + 4, Blocks.wool, 15, 3);
		this.setBlock(world, x + 8, y + 21, z + 4, Blocks.wool, 15, 3);
		this.setBlock(world, x + 7, y + 21, z + 4, Blocks.wool, 15, 3);
		this.setBlock(world, x + 12, y + 21, z + 3, Blocks.wool, 15, 3);
		this.setBlock(world, x + 11, y + 21, z + 3, Blocks.wool, 15, 3);
		this.setBlock(world, x + 10, y + 21, z + 3, Blocks.wool, 15, 3);
		this.setBlock(world, x + 9, y + 21, z + 3, Blocks.wool, 15, 3);
		this.setBlock(world, x + 8, y + 21, z + 3, Blocks.wool, 15, 3);
		this.setBlock(world, x + 7, y + 21, z + 3, Blocks.wool, 15, 3);
		this.setBlock(world, x + 12, y + 21, z + 2, Blocks.obsidian, 0, 3);
		this.setBlock(world, x + 11, y + 21, z + 2, Blocks.wool, 15, 3);
		this.setBlock(world, x + 10, y + 21, z + 2, Blocks.wool, 15, 3);
		this.setBlock(world, x + 9, y + 21, z + 2, Blocks.wool, 15, 3);
		this.setBlock(world, x + 8, y + 21, z + 2, Blocks.wool, 15, 3);
		this.setBlock(world, x + 7, y + 21, z + 2, Blocks.wool, 15, 3);
		this.setBlock(world, x + 12, y + 21, z + 1, Blocks.obsidian, 0, 3);
		this.setBlock(world, x + 11, y + 21, z + 1, Blocks.wool, 15, 3);
		this.setBlock(world, x + 10, y + 21, z + 1, Blocks.wool, 15, 3);
		this.setBlock(world, x + 9, y + 21, z + 1, Blocks.wool, 15, 3);
		this.setBlock(world, x + 8, y + 21, z + 1, Blocks.wool, 15, 3);
		this.setBlock(world, x + 7, y + 21, z + 1, Blocks.wool, 15, 3);
		this.setBlock(world, x + 11, y + 22, z + 27, Blocks.wool, 15, 3);
		this.setBlock(world, x + 10, y + 22, z + 27, Blocks.wool, 15, 3);
		this.setBlock(world, x + 9, y + 22, z + 27, Blocks.wool, 15, 3);
		this.setBlock(world, x + 8, y + 22, z + 27, Blocks.wool, 15, 3);
		this.setBlock(world, x + 7, y + 22, z + 27, Blocks.wool, 15, 3);
		this.setBlock(world, x + 6, y + 22, z + 27, Blocks.wool, 15, 3);
		this.setBlock(world, x + 11, y + 22, z + 26, Blocks.wool, 8, 3);
		this.setBlock(world, x + 10, y + 22, z + 26, Blocks.wool, 15, 3);
		this.setBlock(world, x + 9, y + 22, z + 26, Blocks.wool, 15, 3);
		this.setBlock(world, x + 8, y + 22, z + 26, Blocks.wool, 15, 3);
		this.setBlock(world, x + 7, y + 22, z + 26, Blocks.wool, 15, 3);
		this.setBlock(world, x + 6, y + 22, z + 26, Blocks.wool, 15, 3);
		this.setBlock(world, x + 11, y + 22, z + 25, Blocks.wool, 8, 3);
		this.setBlock(world, x + 10, y + 22, z + 25, Blocks.wool, 15, 3);
		this.setBlock(world, x + 9, y + 22, z + 25, Blocks.wool, 15, 3);
		this.setBlock(world, x + 8, y + 22, z + 25, Blocks.wool, 15, 3);
		this.setBlock(world, x + 7, y + 22, z + 25, Blocks.wool, 15, 3);
		this.setBlock(world, x + 6, y + 22, z + 25, Blocks.wool, 15, 3);
		this.setBlock(world, x + 11, y + 22, z + 24, Blocks.wool, 8, 3);
		this.setBlock(world, x + 10, y + 22, z + 24, Blocks.wool, 15, 3);
		this.setBlock(world, x + 9, y + 22, z + 24, Blocks.wool, 15, 3);
		this.setBlock(world, x + 8, y + 22, z + 24, Blocks.wool, 15, 3);
		this.setBlock(world, x + 7, y + 22, z + 24, Blocks.wool, 15, 3);
		this.setBlock(world, x + 6, y + 22, z + 24, Blocks.wool, 15, 3);
		this.setBlock(world, x + 11, y + 22, z + 23, Blocks.wool, 15, 3);
		this.setBlock(world, x + 10, y + 22, z + 23, Blocks.wool, 15, 3);
		this.setBlock(world, x + 9, y + 22, z + 23, Blocks.wool, 15, 3);
		this.setBlock(world, x + 8, y + 22, z + 23, Blocks.wool, 15, 3);
		this.setBlock(world, x + 7, y + 22, z + 23, Blocks.wool, 15, 3);
		this.setBlock(world, x + 6, y + 22, z + 23, Blocks.wool, 15, 3);
		this.setBlock(world, x + 11, y + 22, z + 22, Blocks.wool, 15, 3);
		this.setBlock(world, x + 10, y + 22, z + 22, Blocks.wool, 15, 3);
		this.setBlock(world, x + 9, y + 22, z + 22, Blocks.wool, 15, 3);
		this.setBlock(world, x + 8, y + 22, z + 22, Blocks.wool, 15, 3);
		this.setBlock(world, x + 7, y + 22, z + 22, Blocks.wool, 15, 3);
		this.setBlock(world, x + 6, y + 22, z + 22, Blocks.wool, 15, 3);
		this.setBlock(world, x + 12, y + 22, z + 17, Blocks.wool, 15, 3);
		this.setBlock(world, x + 11, y + 22, z + 17, Blocks.wool, 15, 3);
		this.setBlock(world, x + 10, y + 22, z + 17, Blocks.wool, 15, 3);
		this.setBlock(world, x + 9, y + 22, z + 17, Blocks.wool, 15, 3);
		this.setBlock(world, x + 8, y + 22, z + 17, Blocks.wool, 15, 3);
		this.setBlock(world, x + 7, y + 22, z + 17, Blocks.wool, 15, 3);
		this.setBlock(world, x + 6, y + 22, z + 17, Blocks.wool, 15, 3);
		this.setBlock(world, x + 5, y + 22, z + 17, Blocks.wool, 15, 3);
		this.setBlock(world, x + 12, y + 22, z + 16, Blocks.iron_block, 0, 3);
		this.setBlock(world, x + 11, y + 22, z + 16, Blocks.iron_block, 0, 3);
		this.setBlock(world, x + 10, y + 22, z + 16, Blocks.iron_block, 0, 3);
		this.setBlock(world, x + 9, y + 22, z + 16, Blocks.wool, 15, 3);
		this.setBlock(world, x + 8, y + 22, z + 16, Blocks.wool, 15, 3);
		this.setBlock(world, x + 7, y + 22, z + 16, Blocks.wool, 15, 3);
		this.setBlock(world, x + 6, y + 22, z + 16, Blocks.wool, 15, 3);
		this.setBlock(world, x + 5, y + 22, z + 16, Blocks.wool, 15, 3);
		this.setBlock(world, x + 12, y + 22, z + 15, Blocks.iron_block, 0, 3);
		this.setBlock(world, x + 11, y + 22, z + 15, Blocks.wool, 15, 3);
		this.setBlock(world, x + 10, y + 22, z + 15, Blocks.iron_block, 0, 3);
		this.setBlock(world, x + 9, y + 22, z + 15, Blocks.iron_block, 0, 3);
		this.setBlock(world, x + 8, y + 22, z + 15, Blocks.iron_block, 0, 3);
		this.setBlock(world, x + 7, y + 22, z + 15, Blocks.iron_block, 0, 3);
		this.setBlock(world, x + 6, y + 22, z + 15, Blocks.wool, 15, 3);
		this.setBlock(world, x + 5, y + 22, z + 15, Blocks.wool, 15, 3);
		this.setBlock(world, x + 12, y + 22, z + 14, Blocks.wool, 15, 3);
		this.setBlock(world, x + 11, y + 22, z + 14, Blocks.wool, 15, 3);
		this.setBlock(world, x + 10, y + 22, z + 14, Blocks.wool, 15, 3);
		this.setBlock(world, x + 9, y + 22, z + 14, Blocks.wool, 15, 3);
		this.setBlock(world, x + 8, y + 22, z + 14, Blocks.chest, 4, 3);
        TileEntity tileentity2 = world.getTileEntity(new BlockPos(x + 8, y + 22, z + 14));
        if (tileentity2 instanceof TileEntityChest)
        {
            WeightedRandomChestContent.generateChestContents(rand, ChestGenHooks.getItems(WITHER_STATUE_HEAD_1, rand), (TileEntityChest)tileentity2, ChestGenHooks.getCount(WITHER_STATUE_HEAD_1, rand));
        }
		this.setBlock(world, x + 7, y + 22, z + 14, Blocks.beacon, 0, 3);
		this.setBlock(world, x + 6, y + 22, z + 14, Blocks.wool, 15, 3);
		this.setBlock(world, x + 5, y + 22, z + 14, Blocks.wool, 15, 3);
		this.setBlock(world, x + 12, y + 22, z + 13, Blocks.wool, 15, 3);
		this.setBlock(world, x + 11, y + 22, z + 13, Blocks.wool, 15, 3);
		this.setBlock(world, x + 10, y + 22, z + 13, Blocks.wool, 15, 3);
		this.setBlock(world, x + 9, y + 22, z + 13, Blocks.wool, 15, 3);
		this.setBlock(world, x + 8, y + 22, z + 13, Blocks.chest, 4, 3);
        TileEntity tileentity3 = world.getTileEntity(new BlockPos(x + 8, y + 22, z + 13));
        if (tileentity3 instanceof TileEntityChest)
        {
            WeightedRandomChestContent.generateChestContents(rand, ChestGenHooks.getItems(WITHER_STATUE_HEAD_2, rand), (TileEntityChest)tileentity3, ChestGenHooks.getCount(WITHER_STATUE_HEAD_2, rand));
        }
		this.setBlock(world, x + 7, y + 22, z + 13, Blocks.beacon, 0, 3);
		this.setBlock(world, x + 6, y + 22, z + 13, Blocks.wool, 15, 3);
		this.setBlock(world, x + 5, y + 22, z + 13, Blocks.wool, 15, 3);
		this.setBlock(world, x + 12, y + 22, z + 12, Blocks.iron_block, 0, 3);
		this.setBlock(world, x + 11, y + 22, z + 12, Blocks.wool, 15, 3);
		this.setBlock(world, x + 10, y + 22, z + 12, Blocks.wool, 15, 3);
		this.setBlock(world, x + 9, y + 22, z + 12, Blocks.iron_block, 0, 3);
		this.setBlock(world, x + 8, y + 22, z + 12, Blocks.iron_block, 0, 3);
		this.setBlock(world, x + 7, y + 22, z + 12, Blocks.iron_block, 0, 3);
		this.setBlock(world, x + 6, y + 22, z + 12, Blocks.wool, 15, 3);
		this.setBlock(world, x + 5, y + 22, z + 12, Blocks.wool, 15, 3);
		this.setBlock(world, x + 12, y + 22, z + 11, Blocks.iron_block, 0, 3);
		this.setBlock(world, x + 11, y + 22, z + 11, Blocks.iron_block, 0, 3);
		this.setBlock(world, x + 10, y + 22, z + 11, Blocks.iron_block, 0, 3);
		this.setBlock(world, x + 9, y + 22, z + 11, Blocks.iron_block, 0, 3);
		this.setBlock(world, x + 8, y + 22, z + 11, Blocks.wool, 15, 3);
		this.setBlock(world, x + 7, y + 22, z + 11, Blocks.wool, 15, 3);
		this.setBlock(world, x + 6, y + 22, z + 11, Blocks.wool, 15, 3);
		this.setBlock(world, x + 5, y + 22, z + 11, Blocks.wool, 15, 3);
		this.setBlock(world, x + 12, y + 22, z + 10, Blocks.wool, 15, 3);
		this.setBlock(world, x + 11, y + 22, z + 10, Blocks.wool, 15, 3);
		this.setBlock(world, x + 10, y + 22, z + 10, Blocks.wool, 15, 3);
		this.setBlock(world, x + 9, y + 22, z + 10, Blocks.wool, 15, 3);
		this.setBlock(world, x + 8, y + 22, z + 10, Blocks.wool, 15, 3);
		this.setBlock(world, x + 7, y + 22, z + 10, Blocks.wool, 15, 3);
		this.setBlock(world, x + 6, y + 22, z + 10, Blocks.wool, 15, 3);
		this.setBlock(world, x + 5, y + 22, z + 10, Blocks.wool, 15, 3);
		this.setBlock(world, x + 12, y + 22, z + 6, Blocks.wool, 15, 3);
		this.setBlock(world, x + 11, y + 22, z + 6, Blocks.wool, 15, 3);
		this.setBlock(world, x + 10, y + 22, z + 6, Blocks.wool, 15, 3);
		this.setBlock(world, x + 9, y + 22, z + 6, Blocks.wool, 15, 3);
		this.setBlock(world, x + 8, y + 22, z + 6, Blocks.wool, 15, 3);
		this.setBlock(world, x + 7, y + 22, z + 6, Blocks.wool, 15, 3);
		this.setBlock(world, x + 12, y + 22, z + 5, Blocks.wool, 8, 3);
		this.setBlock(world, x + 11, y + 22, z + 5, Blocks.wool, 15, 3);
		this.setBlock(world, x + 10, y + 22, z + 5, Blocks.wool, 15, 3);
		this.setBlock(world, x + 9, y + 22, z + 5, Blocks.wool, 15, 3);
		this.setBlock(world, x + 8, y + 22, z + 5, Blocks.wool, 15, 3);
		this.setBlock(world, x + 7, y + 22, z + 5, Blocks.wool, 15, 3);
		this.setBlock(world, x + 12, y + 22, z + 4, Blocks.wool, 8, 3);
		this.setBlock(world, x + 11, y + 22, z + 4, Blocks.wool, 15, 3);
		this.setBlock(world, x + 10, y + 22, z + 4, Blocks.wool, 15, 3);
		this.setBlock(world, x + 9, y + 22, z + 4, Blocks.wool, 15, 3);
		this.setBlock(world, x + 8, y + 22, z + 4, Blocks.wool, 15, 3);
		this.setBlock(world, x + 7, y + 22, z + 4, Blocks.wool, 15, 3);
		this.setBlock(world, x + 12, y + 22, z + 3, Blocks.wool, 8, 3);
		this.setBlock(world, x + 11, y + 22, z + 3, Blocks.wool, 15, 3);
		this.setBlock(world, x + 10, y + 22, z + 3, Blocks.wool, 15, 3);
		this.setBlock(world, x + 9, y + 22, z + 3, Blocks.wool, 15, 3);
		this.setBlock(world, x + 8, y + 22, z + 3, Blocks.wool, 15, 3);
		this.setBlock(world, x + 7, y + 22, z + 3, Blocks.wool, 15, 3);
		this.setBlock(world, x + 12, y + 22, z + 2, Blocks.wool, 15, 3);
		this.setBlock(world, x + 11, y + 22, z + 2, Blocks.wool, 15, 3);
		this.setBlock(world, x + 10, y + 22, z + 2, Blocks.wool, 15, 3);
		this.setBlock(world, x + 9, y + 22, z + 2, Blocks.wool, 15, 3);
		this.setBlock(world, x + 8, y + 22, z + 2, Blocks.wool, 15, 3);
		this.setBlock(world, x + 7, y + 22, z + 2, Blocks.wool, 15, 3);
		this.setBlock(world, x + 12, y + 22, z + 1, Blocks.wool, 15, 3);
		this.setBlock(world, x + 11, y + 22, z + 1, Blocks.wool, 15, 3);
		this.setBlock(world, x + 10, y + 22, z + 1, Blocks.wool, 15, 3);
		this.setBlock(world, x + 9, y + 22, z + 1, Blocks.wool, 15, 3);
		this.setBlock(world, x + 8, y + 22, z + 1, Blocks.wool, 15, 3);
		this.setBlock(world, x + 7, y + 22, z + 1, Blocks.wool, 15, 3);
		this.setBlock(world, x + 12, y + 23, z + 17, Blocks.obsidian, 0, 3);
		this.setBlock(world, x + 11, y + 23, z + 17, Blocks.wool, 15, 3);
		this.setBlock(world, x + 10, y + 23, z + 17, Blocks.wool, 15, 3);
		this.setBlock(world, x + 9, y + 23, z + 17, Blocks.wool, 15, 3);
		this.setBlock(world, x + 8, y + 23, z + 17, Blocks.wool, 15, 3);
		this.setBlock(world, x + 7, y + 23, z + 17, Blocks.wool, 15, 3);
		this.setBlock(world, x + 6, y + 23, z + 17, Blocks.wool, 15, 3);
		this.setBlock(world, x + 5, y + 23, z + 17, Blocks.wool, 15, 3);
		this.setBlock(world, x + 12, y + 23, z + 16, Blocks.obsidian, 0, 3);
		this.setBlock(world, x + 11, y + 23, z + 16, Blocks.wool, 15, 3);
		this.setBlock(world, x + 10, y + 23, z + 16, Blocks.wool, 15, 3);
		this.setBlock(world, x + 9, y + 23, z + 16, Blocks.wool, 15, 3);
		this.setBlock(world, x + 8, y + 23, z + 16, Blocks.wool, 15, 3);
		this.setBlock(world, x + 7, y + 23, z + 16, Blocks.wool, 15, 3);
		this.setBlock(world, x + 6, y + 23, z + 16, Blocks.wool, 15, 3);
		this.setBlock(world, x + 5, y + 23, z + 16, Blocks.wool, 15, 3);
		this.setBlock(world, x + 12, y + 23, z + 15, Blocks.obsidian, 0, 3);
		this.setBlock(world, x + 11, y + 23, z + 15, Blocks.wool, 15, 3);
		this.setBlock(world, x + 10, y + 23, z + 15, Blocks.wool, 15, 3);
		this.setBlock(world, x + 9, y + 23, z + 15, Blocks.wool, 15, 3);
		this.setBlock(world, x + 8, y + 23, z + 15, Blocks.wool, 15, 3);
		this.setBlock(world, x + 7, y + 23, z + 15, Blocks.wool, 15, 3);
		this.setBlock(world, x + 6, y + 23, z + 15, Blocks.wool, 15, 3);
		this.setBlock(world, x + 5, y + 23, z + 15, Blocks.wool, 15, 3);
		this.setBlock(world, x + 12, y + 23, z + 14, Blocks.wool, 15, 3);
		this.setBlock(world, x + 11, y + 23, z + 14, Blocks.wool, 15, 3);
		this.setBlock(world, x + 10, y + 23, z + 14, Blocks.wool, 15, 3);
		this.setBlock(world, x + 9, y + 23, z + 14, Blocks.wool, 15, 3);
		this.setBlock(world, x + 8, y + 23, z + 14, Blocks.wool, 15, 3);
		this.setBlock(world, x + 7, y + 23, z + 14, Blocks.wool, 15, 3);
		this.setBlock(world, x + 6, y + 23, z + 14, Blocks.wool, 15, 3);
		this.setBlock(world, x + 5, y + 23, z + 14, Blocks.wool, 15, 3);
		this.setBlock(world, x + 12, y + 23, z + 13, Blocks.wool, 15, 3);
		this.setBlock(world, x + 11, y + 23, z + 13, Blocks.wool, 15, 3);
		this.setBlock(world, x + 10, y + 23, z + 13, Blocks.wool, 15, 3);
		this.setBlock(world, x + 9, y + 23, z + 13, Blocks.wool, 15, 3);
		this.setBlock(world, x + 8, y + 23, z + 13, Blocks.wool, 15, 3);
		this.setBlock(world, x + 7, y + 23, z + 13, Blocks.wool, 15, 3);
		this.setBlock(world, x + 6, y + 23, z + 13, Blocks.wool, 15, 3);
		this.setBlock(world, x + 5, y + 23, z + 13, Blocks.wool, 15, 3);
		this.setBlock(world, x + 12, y + 23, z + 12, Blocks.obsidian, 0, 3);
		this.setBlock(world, x + 11, y + 23, z + 12, Blocks.wool, 15, 3);
		this.setBlock(world, x + 10, y + 23, z + 12, Blocks.wool, 15, 3);
		this.setBlock(world, x + 9, y + 23, z + 12, Blocks.wool, 15, 3);
		this.setBlock(world, x + 8, y + 23, z + 12, Blocks.wool, 15, 3);
		this.setBlock(world, x + 7, y + 23, z + 12, Blocks.wool, 15, 3);
		this.setBlock(world, x + 6, y + 23, z + 12, Blocks.wool, 15, 3);
		this.setBlock(world, x + 5, y + 23, z + 12, Blocks.wool, 15, 3);
		this.setBlock(world, x + 12, y + 23, z + 11, Blocks.obsidian, 0, 3);
		this.setBlock(world, x + 11, y + 23, z + 11, Blocks.wool, 15, 3);
		this.setBlock(world, x + 10, y + 23, z + 11, Blocks.wool, 15, 3);
		this.setBlock(world, x + 9, y + 23, z + 11, Blocks.wool, 15, 3);
		this.setBlock(world, x + 8, y + 23, z + 11, Blocks.wool, 15, 3);
		this.setBlock(world, x + 7, y + 23, z + 11, Blocks.wool, 15, 3);
		this.setBlock(world, x + 6, y + 23, z + 11, Blocks.wool, 15, 3);
		this.setBlock(world, x + 5, y + 23, z + 11, Blocks.wool, 15, 3);
		this.setBlock(world, x + 12, y + 23, z + 10, Blocks.obsidian, 0, 3);
		this.setBlock(world, x + 11, y + 23, z + 10, Blocks.wool, 15, 3);
		this.setBlock(world, x + 10, y + 23, z + 10, Blocks.wool, 15, 3);
		this.setBlock(world, x + 9, y + 23, z + 10, Blocks.wool, 15, 3);
		this.setBlock(world, x + 8, y + 23, z + 10, Blocks.wool, 15, 3);
		this.setBlock(world, x + 7, y + 23, z + 10, Blocks.wool, 15, 3);
		this.setBlock(world, x + 6, y + 23, z + 10, Blocks.wool, 15, 3);
		this.setBlock(world, x + 5, y + 23, z + 10, Blocks.wool, 15, 3);
		this.setBlock(world, x + 12, y + 24, z + 17, Blocks.wool, 15, 3);
		this.setBlock(world, x + 11, y + 24, z + 17, Blocks.wool, 15, 3);
		this.setBlock(world, x + 10, y + 24, z + 17, Blocks.wool, 15, 3);
		this.setBlock(world, x + 9, y + 24, z + 17, Blocks.wool, 15, 3);
		this.setBlock(world, x + 8, y + 24, z + 17, Blocks.wool, 15, 3);
		this.setBlock(world, x + 7, y + 24, z + 17, Blocks.wool, 15, 3);
		this.setBlock(world, x + 6, y + 24, z + 17, Blocks.wool, 15, 3);
		this.setBlock(world, x + 5, y + 24, z + 17, Blocks.wool, 15, 3);
		this.setBlock(world, x + 12, y + 24, z + 16, Blocks.wool, 7, 3);
		this.setBlock(world, x + 11, y + 24, z + 16, Blocks.wool, 15, 3);
		this.setBlock(world, x + 10, y + 24, z + 16, Blocks.wool, 15, 3);
		this.setBlock(world, x + 9, y + 24, z + 16, Blocks.wool, 15, 3);
		this.setBlock(world, x + 8, y + 24, z + 16, Blocks.wool, 15, 3);
		this.setBlock(world, x + 7, y + 24, z + 16, Blocks.wool, 15, 3);
		this.setBlock(world, x + 6, y + 24, z + 16, Blocks.wool, 15, 3);
		this.setBlock(world, x + 5, y + 24, z + 16, Blocks.wool, 15, 3);
		this.setBlock(world, x + 12, y + 24, z + 15, Blocks.wool, 8, 3);
		this.setBlock(world, x + 11, y + 24, z + 15, Blocks.wool, 15, 3);
		this.setBlock(world, x + 10, y + 24, z + 15, Blocks.wool, 15, 3);
		this.setBlock(world, x + 9, y + 24, z + 15, Blocks.wool, 15, 3);
		this.setBlock(world, x + 8, y + 24, z + 15, Blocks.wool, 15, 3);
		this.setBlock(world, x + 7, y + 24, z + 15, Blocks.wool, 15, 3);
		this.setBlock(world, x + 6, y + 24, z + 15, Blocks.wool, 15, 3);
		this.setBlock(world, x + 5, y + 24, z + 15, Blocks.wool, 15, 3);
		this.setBlock(world, x + 12, y + 24, z + 14, Blocks.wool, 8, 3);
		this.setBlock(world, x + 11, y + 24, z + 14, Blocks.wool, 15, 3);
		this.setBlock(world, x + 10, y + 24, z + 14, Blocks.wool, 15, 3);
		this.setBlock(world, x + 9, y + 24, z + 14, Blocks.wool, 15, 3);
		this.setBlock(world, x + 8, y + 24, z + 14, Blocks.wool, 15, 3);
		this.setBlock(world, x + 7, y + 24, z + 14, Blocks.wool, 15, 3);
		this.setBlock(world, x + 6, y + 24, z + 14, Blocks.wool, 15, 3);
		this.setBlock(world, x + 5, y + 24, z + 14, Blocks.wool, 15, 3);
		this.setBlock(world, x + 12, y + 24, z + 13, Blocks.wool, 8, 3);
		this.setBlock(world, x + 11, y + 24, z + 13, Blocks.wool, 15, 3);
		this.setBlock(world, x + 10, y + 24, z + 13, Blocks.wool, 15, 3);
		this.setBlock(world, x + 9, y + 24, z + 13, Blocks.wool, 15, 3);
		this.setBlock(world, x + 8, y + 24, z + 13, Blocks.wool, 15, 3);
		this.setBlock(world, x + 7, y + 24, z + 13, Blocks.wool, 15, 3);
		this.setBlock(world, x + 6, y + 24, z + 13, Blocks.wool, 15, 3);
		this.setBlock(world, x + 5, y + 24, z + 13, Blocks.wool, 15, 3);
		this.setBlock(world, x + 12, y + 24, z + 12, Blocks.wool, 8, 3);
		this.setBlock(world, x + 11, y + 24, z + 12, Blocks.wool, 15, 3);
		this.setBlock(world, x + 10, y + 24, z + 12, Blocks.wool, 15, 3);
		this.setBlock(world, x + 9, y + 24, z + 12, Blocks.wool, 15, 3);
		this.setBlock(world, x + 8, y + 24, z + 12, Blocks.wool, 15, 3);
		this.setBlock(world, x + 7, y + 24, z + 12, Blocks.wool, 15, 3);
		this.setBlock(world, x + 6, y + 24, z + 12, Blocks.wool, 15, 3);
		this.setBlock(world, x + 5, y + 24, z + 12, Blocks.wool, 15, 3);
		this.setBlock(world, x + 12, y + 24, z + 11, Blocks.wool, 15, 3);
		this.setBlock(world, x + 11, y + 24, z + 11, Blocks.wool, 15, 3);
		this.setBlock(world, x + 10, y + 24, z + 11, Blocks.wool, 15, 3);
		this.setBlock(world, x + 9, y + 24, z + 11, Blocks.wool, 15, 3);
		this.setBlock(world, x + 8, y + 24, z + 11, Blocks.wool, 15, 3);
		this.setBlock(world, x + 7, y + 24, z + 11, Blocks.wool, 15, 3);
		this.setBlock(world, x + 6, y + 24, z + 11, Blocks.wool, 15, 3);
		this.setBlock(world, x + 5, y + 24, z + 11, Blocks.wool, 15, 3);
		this.setBlock(world, x + 12, y + 24, z + 10, Blocks.wool, 15, 3);
		this.setBlock(world, x + 11, y + 24, z + 10, Blocks.wool, 15, 3);
		this.setBlock(world, x + 10, y + 24, z + 10, Blocks.wool, 15, 3);
		this.setBlock(world, x + 9, y + 24, z + 10, Blocks.wool, 15, 3);
		this.setBlock(world, x + 8, y + 24, z + 10, Blocks.wool, 15, 3);
		this.setBlock(world, x + 7, y + 24, z + 10, Blocks.wool, 15, 3);
		this.setBlock(world, x + 6, y + 24, z + 10, Blocks.wool, 15, 3);
		this.setBlock(world, x + 5, y + 24, z + 10, Blocks.wool, 15, 3);
		this.setBlock(world, x + 12, y + 25, z + 17, Blocks.wool, 15, 3);
		this.setBlock(world, x + 11, y + 25, z + 17, Blocks.wool, 15, 3);
		this.setBlock(world, x + 10, y + 25, z + 17, Blocks.wool, 15, 3);
		this.setBlock(world, x + 9, y + 25, z + 17, Blocks.wool, 15, 3);
		this.setBlock(world, x + 8, y + 25, z + 17, Blocks.wool, 15, 3);
		this.setBlock(world, x + 7, y + 25, z + 17, Blocks.wool, 15, 3);
		this.setBlock(world, x + 6, y + 25, z + 17, Blocks.wool, 15, 3);
		this.setBlock(world, x + 5, y + 25, z + 17, Blocks.wool, 15, 3);
		this.setBlock(world, x + 12, y + 25, z + 16, Blocks.wool, 15, 3);
		this.setBlock(world, x + 11, y + 25, z + 16, Blocks.wool, 15, 3);
		this.setBlock(world, x + 10, y + 25, z + 16, Blocks.wool, 15, 3);
		this.setBlock(world, x + 9, y + 25, z + 16, Blocks.wool, 15, 3);
		this.setBlock(world, x + 8, y + 25, z + 16, Blocks.wool, 15, 3);
		this.setBlock(world, x + 7, y + 25, z + 16, Blocks.wool, 15, 3);
		this.setBlock(world, x + 6, y + 25, z + 16, Blocks.wool, 15, 3);
		this.setBlock(world, x + 5, y + 25, z + 16, Blocks.wool, 15, 3);
		this.setBlock(world, x + 12, y + 25, z + 15, Blocks.wool, 15, 3);
		this.setBlock(world, x + 11, y + 25, z + 15, Blocks.wool, 15, 3);
		this.setBlock(world, x + 10, y + 25, z + 15, Blocks.wool, 15, 3);
		this.setBlock(world, x + 9, y + 25, z + 15, Blocks.wool, 15, 3);
		this.setBlock(world, x + 8, y + 25, z + 15, Blocks.wool, 15, 3);
		this.setBlock(world, x + 7, y + 25, z + 15, Blocks.wool, 15, 3);
		this.setBlock(world, x + 6, y + 25, z + 15, Blocks.wool, 15, 3);
		this.setBlock(world, x + 5, y + 25, z + 15, Blocks.wool, 15, 3);
		this.setBlock(world, x + 12, y + 25, z + 14, Blocks.wool, 15, 3);
		this.setBlock(world, x + 11, y + 25, z + 14, Blocks.wool, 15, 3);
		this.setBlock(world, x + 10, y + 25, z + 14, Blocks.wool, 15, 3);
		this.setBlock(world, x + 9, y + 25, z + 14, Blocks.wool, 15, 3);
		this.setBlock(world, x + 8, y + 25, z + 14, Blocks.wool, 15, 3);
		this.setBlock(world, x + 7, y + 25, z + 14, Blocks.wool, 15, 3);
		this.setBlock(world, x + 6, y + 25, z + 14, Blocks.wool, 15, 3);
		this.setBlock(world, x + 5, y + 25, z + 14, Blocks.wool, 15, 3);
		this.setBlock(world, x + 12, y + 25, z + 13, Blocks.wool, 15, 3);
		this.setBlock(world, x + 11, y + 25, z + 13, Blocks.wool, 15, 3);
		this.setBlock(world, x + 10, y + 25, z + 13, Blocks.wool, 15, 3);
		this.setBlock(world, x + 9, y + 25, z + 13, Blocks.wool, 15, 3);
		this.setBlock(world, x + 8, y + 25, z + 13, Blocks.wool, 15, 3);
		this.setBlock(world, x + 7, y + 25, z + 13, Blocks.wool, 15, 3);
		this.setBlock(world, x + 6, y + 25, z + 13, Blocks.wool, 15, 3);
		this.setBlock(world, x + 5, y + 25, z + 13, Blocks.wool, 15, 3);
		this.setBlock(world, x + 12, y + 25, z + 12, Blocks.wool, 15, 3);
		this.setBlock(world, x + 11, y + 25, z + 12, Blocks.wool, 15, 3);
		this.setBlock(world, x + 10, y + 25, z + 12, Blocks.wool, 15, 3);
		this.setBlock(world, x + 9, y + 25, z + 12, Blocks.wool, 15, 3);
		this.setBlock(world, x + 8, y + 25, z + 12, Blocks.wool, 15, 3);
		this.setBlock(world, x + 7, y + 25, z + 12, Blocks.wool, 15, 3);
		this.setBlock(world, x + 6, y + 25, z + 12, Blocks.wool, 15, 3);
		this.setBlock(world, x + 5, y + 25, z + 12, Blocks.wool, 15, 3);
		this.setBlock(world, x + 12, y + 25, z + 11, Blocks.wool, 15, 3);
		this.setBlock(world, x + 11, y + 25, z + 11, Blocks.wool, 15, 3);
		this.setBlock(world, x + 10, y + 25, z + 11, Blocks.wool, 15, 3);
		this.setBlock(world, x + 9, y + 25, z + 11, Blocks.wool, 15, 3);
		this.setBlock(world, x + 8, y + 25, z + 11, Blocks.wool, 15, 3);
		this.setBlock(world, x + 7, y + 25, z + 11, Blocks.wool, 15, 3);
		this.setBlock(world, x + 6, y + 25, z + 11, Blocks.wool, 15, 3);
		this.setBlock(world, x + 5, y + 25, z + 11, Blocks.wool, 15, 3);
		this.setBlock(world, x + 12, y + 25, z + 10, Blocks.wool, 15, 3);
		this.setBlock(world, x + 11, y + 25, z + 10, Blocks.wool, 15, 3);
		this.setBlock(world, x + 10, y + 25, z + 10, Blocks.wool, 15, 3);
		this.setBlock(world, x + 9, y + 25, z + 10, Blocks.wool, 15, 3);
		this.setBlock(world, x + 8, y + 25, z + 10, Blocks.wool, 15, 3);
		this.setBlock(world, x + 7, y + 25, z + 10, Blocks.wool, 15, 3);
		this.setBlock(world, x + 6, y + 25, z + 10, Blocks.wool, 15, 3);
		this.setBlock(world, x + 5, y + 25, z + 10, Blocks.wool, 15, 3);
		this.setBlock(world, x + 12, y + 26, z + 17, Blocks.wool, 15, 3);
		this.setBlock(world, x + 11, y + 26, z + 17, Blocks.wool, 15, 3);
		this.setBlock(world, x + 10, y + 26, z + 17, Blocks.wool, 15, 3);
		this.setBlock(world, x + 9, y + 26, z + 17, Blocks.wool, 15, 3);
		this.setBlock(world, x + 8, y + 26, z + 17, Blocks.wool, 15, 3);
		this.setBlock(world, x + 7, y + 26, z + 17, Blocks.wool, 15, 3);
		this.setBlock(world, x + 6, y + 26, z + 17, Blocks.wool, 15, 3);
		this.setBlock(world, x + 5, y + 26, z + 17, Blocks.wool, 15, 3);
		this.setBlock(world, x + 12, y + 26, z + 16, Blocks.wool, 15, 3);
		this.setBlock(world, x + 11, y + 26, z + 16, Blocks.wool, 15, 3);
		this.setBlock(world, x + 10, y + 26, z + 16, Blocks.wool, 15, 3);
		this.setBlock(world, x + 9, y + 26, z + 16, Blocks.wool, 15, 3);
		this.setBlock(world, x + 8, y + 26, z + 16, Blocks.wool, 15, 3);
		this.setBlock(world, x + 7, y + 26, z + 16, Blocks.wool, 15, 3);
		this.setBlock(world, x + 6, y + 26, z + 16, Blocks.wool, 15, 3);
		this.setBlock(world, x + 5, y + 26, z + 16, Blocks.wool, 15, 3);
		this.setBlock(world, x + 12, y + 26, z + 15, Blocks.wool, 15, 3);
		this.setBlock(world, x + 11, y + 26, z + 15, Blocks.wool, 15, 3);
		this.setBlock(world, x + 10, y + 26, z + 15, Blocks.wool, 15, 3);
		this.setBlock(world, x + 9, y + 26, z + 15, Blocks.wool, 15, 3);
		this.setBlock(world, x + 8, y + 26, z + 15, Blocks.wool, 15, 3);
		this.setBlock(world, x + 7, y + 26, z + 15, Blocks.wool, 15, 3);
		this.setBlock(world, x + 6, y + 26, z + 15, Blocks.wool, 15, 3);
		this.setBlock(world, x + 5, y + 26, z + 15, Blocks.wool, 15, 3);
		this.setBlock(world, x + 12, y + 26, z + 14, Blocks.wool, 15, 3);
		this.setBlock(world, x + 11, y + 26, z + 14, Blocks.wool, 15, 3);
		this.setBlock(world, x + 10, y + 26, z + 14, Blocks.wool, 15, 3);
		this.setBlock(world, x + 9, y + 26, z + 14, Blocks.wool, 15, 3);
		this.setBlock(world, x + 8, y + 26, z + 14, Blocks.wool, 15, 3);
		this.setBlock(world, x + 7, y + 26, z + 14, Blocks.wool, 15, 3);
		this.setBlock(world, x + 6, y + 26, z + 14, Blocks.wool, 15, 3);
		this.setBlock(world, x + 5, y + 26, z + 14, Blocks.wool, 15, 3);
		this.setBlock(world, x + 12, y + 26, z + 13, Blocks.wool, 15, 3);
		this.setBlock(world, x + 11, y + 26, z + 13, Blocks.wool, 15, 3);
		this.setBlock(world, x + 10, y + 26, z + 13, Blocks.wool, 15, 3);
		this.setBlock(world, x + 9, y + 26, z + 13, Blocks.wool, 15, 3);
		this.setBlock(world, x + 8, y + 26, z + 13, Blocks.wool, 15, 3);
		this.setBlock(world, x + 7, y + 26, z + 13, Blocks.wool, 15, 3);
		this.setBlock(world, x + 6, y + 26, z + 13, Blocks.wool, 15, 3);
		this.setBlock(world, x + 5, y + 26, z + 13, Blocks.wool, 15, 3);
		this.setBlock(world, x + 12, y + 26, z + 12, Blocks.wool, 15, 3);
		this.setBlock(world, x + 11, y + 26, z + 12, Blocks.wool, 15, 3);
		this.setBlock(world, x + 10, y + 26, z + 12, Blocks.wool, 15, 3);
		this.setBlock(world, x + 9, y + 26, z + 12, Blocks.wool, 15, 3);
		this.setBlock(world, x + 8, y + 26, z + 12, Blocks.wool, 15, 3);
