//Schematic to java Structure by jajo_11 | inspired by "MITHION'S .SCHEMATIC TO JAVA CONVERTINGTOOL"

package net.minecraft.MoWithers.worldgen;

import static net.minecraft.MoWithers.worldgen.ChestGenHooksWither.FORTRESS_MAIN;
import static net.minecraft.MoWithers.worldgen.ChestGenHooksWither.BARRACKS;
import static net.minecraft.MoWithers.worldgen.ChestGenHooksWither.FORGE;
import static net.minecraft.MoWithers.worldgen.ChestGenHooksWither.DISPENSERS;
import static net.minecraft.MoWithers.worldgen.ChestGenHooksWither.RATHOLE;
import static net.minecraft.MoWithers.worldgen.ChestGenHooksWither.SPECIALTREASURE;

import java.util.List;
import java.util.Random;

import com.google.common.collect.Lists;

import net.minecraft.block.Block;
import net.minecraft.block.material.Material;
import net.minecraft.entity.item.EntityArmorStand;
import net.minecraft.init.Blocks;
import net.minecraft.init.Items;
import net.minecraft.item.ItemStack;
import net.minecraft.tileentity.TileEntity;
import net.minecraft.tileentity.TileEntityChest;
import net.minecraft.tileentity.TileEntityDispenser;
import net.minecraft.tileentity.TileEntityMobSpawner;
import net.minecraft.tileentity.TileEntitySkull;
import net.minecraft.util.BlockPos;
import net.minecraft.util.WeightedRandomChestContent;
import net.minecraft.world.World;
import net.minecraft.world.gen.feature.WorldGenerator;
import net.minecraftforge.common.ChestGenHooks;

public class Fortress extends WorldGenerator
{
	private static final List DISPENSERARROWS = Lists.newArrayList(new WeightedRandomChestContent[] {new WeightedRandomChestContent(Items.arrow, 0, 12, 18, 50)});
    private static final List CHESTCONTENTMAIN = Lists.newArrayList(new WeightedRandomChestContent[] {new WeightedRandomChestContent(Items.diamond, 0, 1, 3, 3), new WeightedRandomChestContent(Items.iron_ingot, 0, 1, 5, 10), new WeightedRandomChestContent(Items.gold_ingot, 0, 2, 7, 10), new WeightedRandomChestContent(Items.emerald, 0, 1, 3, 2), new WeightedRandomChestContent(Items.bone, 0, 4, 6, 20), new WeightedRandomChestContent(Items.rotten_flesh, 0, 3, 7, 16), new WeightedRandomChestContent(Items.saddle, 0, 1, 1, 3), new WeightedRandomChestContent(Items.iron_horse_armor, 0, 1, 1, 1), new WeightedRandomChestContent(Items.golden_horse_armor, 0, 1, 1, 1), new WeightedRandomChestContent(Items.diamond_horse_armor, 0, 1, 1, 1), new WeightedRandomChestContent(Items.saddle, 0, 1, 1, 10), new WeightedRandomChestContent(Items.iron_ingot, 0, 1, 4, 10), new WeightedRandomChestContent(Items.bread, 0, 1, 1, 10), new WeightedRandomChestContent(Items.baked_potato, 0, 1, 4, 10), new WeightedRandomChestContent(Items.gunpowder, 0, 1, 4, 10), new WeightedRandomChestContent(Items.arrow, 0, 1, 4, 10), new WeightedRandomChestContent(Items.bucket, 0, 1, 1, 10), new WeightedRandomChestContent(Items.golden_apple, 1, 1, 1, 1), new WeightedRandomChestContent(Items.redstone, 0, 1, 4, 10), new WeightedRandomChestContent(Items.record_13, 0, 1, 1, 4), new WeightedRandomChestContent(Items.record_cat, 0, 1, 1, 4), new WeightedRandomChestContent(Items.name_tag, 0, 1, 1, 10), new WeightedRandomChestContent(Items.golden_horse_armor, 0, 1, 1, 2), new WeightedRandomChestContent(Items.iron_horse_armor, 0, 1, 1, 5), new WeightedRandomChestContent(Items.diamond_horse_armor, 0, 1, 1, 1)});
    private static final List CHESTCONTENTBARRACKS = Lists.newArrayList(new WeightedRandomChestContent[] {new WeightedRandomChestContent(Items.diamond, 0, 1, 3, 3), new WeightedRandomChestContent(Items.iron_ingot, 0, 1, 3, 10), new WeightedRandomChestContent(Items.gold_ingot, 0, 2, 7, 5), new WeightedRandomChestContent(Items.emerald, 0, 1, 3, 2), new WeightedRandomChestContent(Items.bone, 0, 4, 6, 20), new WeightedRandomChestContent(Items.rotten_flesh, 0, 3, 7, 16), new WeightedRandomChestContent(Items.saddle, 0, 1, 1, 3), new WeightedRandomChestContent(Items.iron_horse_armor, 0, 1, 1, 1), new WeightedRandomChestContent(Items.golden_horse_armor, 0, 1, 1, 1), new WeightedRandomChestContent(Items.diamond_horse_armor, 0, 1, 1, 1), new WeightedRandomChestContent(Items.saddle, 0, 1, 1, 10), new WeightedRandomChestContent(Items.iron_axe, 0, 1, 1, 10), new WeightedRandomChestContent(Items.iron_sword, 0, 1, 1, 10), new WeightedRandomChestContent(Items.cooked_beef, 0, 1, 4, 10), new WeightedRandomChestContent(Items.stick, 0, 1, 4, 10), new WeightedRandomChestContent(Items.bow, 0, 1, 1, 5), new WeightedRandomChestContent(Items.arrow, 0, 2, 6, 10), new WeightedRandomChestContent(Items.golden_apple, 0, 1, 1, 1), new WeightedRandomChestContent(Items.redstone, 0, 1, 4, 10), new WeightedRandomChestContent(Items.record_13, 0, 1, 1, 4), new WeightedRandomChestContent(Items.record_cat, 0, 1, 1, 4), new WeightedRandomChestContent(Items.name_tag, 0, 1, 1, 10), new WeightedRandomChestContent(Items.golden_horse_armor, 0, 1, 1, 2), new WeightedRandomChestContent(Items.iron_horse_armor, 0, 1, 1, 5), new WeightedRandomChestContent(Items.diamond_horse_armor, 0, 1, 1, 1)});
    private static final List CHESTCONTENTFORGE = Lists.newArrayList(new WeightedRandomChestContent[] {new WeightedRandomChestContent(Items.diamond, 0, 1, 3, 3), new WeightedRandomChestContent(Items.iron_ingot, 0, 2, 5, 15), new WeightedRandomChestContent(Items.gold_ingot, 0, 2, 7, 15), new WeightedRandomChestContent(Items.emerald, 0, 1, 3, 2), new WeightedRandomChestContent(Items.bone, 0, 4, 6, 20), new WeightedRandomChestContent(Items.rotten_flesh, 0, 3, 7, 16), new WeightedRandomChestContent(Items.saddle, 0, 1, 1, 3), new WeightedRandomChestContent(Items.iron_horse_armor, 0, 1, 1, 1), new WeightedRandomChestContent(Items.golden_horse_armor, 0, 1, 1, 1), new WeightedRandomChestContent(Items.diamond_horse_armor, 0, 1, 1, 1), new WeightedRandomChestContent(Items.saddle, 0, 1, 1, 10), new WeightedRandomChestContent(Items.iron_pickaxe, 0, 1, 1, 10), new WeightedRandomChestContent(Items.diamond_pickaxe, 0, 1, 1, 3), new WeightedRandomChestContent(Items.flint_and_steel, 0, 1, 1, 5), new WeightedRandomChestContent(Items.gunpowder, 0, 1, 4, 10), new WeightedRandomChestContent(Items.string, 0, 1, 4, 10), new WeightedRandomChestContent(Items.bucket, 0, 1, 1, 10), new WeightedRandomChestContent(Items.golden_apple, 0, 1, 1, 1), new WeightedRandomChestContent(Items.redstone, 0, 1, 4, 10), new WeightedRandomChestContent(Items.record_13, 0, 1, 1, 4), new WeightedRandomChestContent(Items.record_cat, 0, 1, 1, 4), new WeightedRandomChestContent(Items.name_tag, 0, 1, 1, 10), new WeightedRandomChestContent(Items.golden_horse_armor, 0, 1, 1, 2), new WeightedRandomChestContent(Items.iron_horse_armor, 0, 1, 1, 5), new WeightedRandomChestContent(Items.diamond_horse_armor, 0, 1, 1, 1)});
    private static final List CHESTCONTENTRATHOLE = Lists.newArrayList(new WeightedRandomChestContent[] {new WeightedRandomChestContent(Items.iron_ingot, 0, 1, 5, 10), new WeightedRandomChestContent(Items.gold_ingot, 0, 2, 7, 15), new WeightedRandomChestContent(Items.bone, 0, 6, 12, 30), new WeightedRandomChestContent(Items.rotten_flesh, 0, 6, 12, 30), new WeightedRandomChestContent(Items.saddle, 0, 1, 1, 10), new WeightedRandomChestContent(Items.iron_ingot, 0, 1, 4, 10), new WeightedRandomChestContent(Items.bread, 0, 1, 1, 10), new WeightedRandomChestContent(Items.wheat, 0, 1, 4, 10), new WeightedRandomChestContent(Items.gunpowder, 0, 1, 4, 10), new WeightedRandomChestContent(Items.string, 0, 1, 4, 10), new WeightedRandomChestContent(Items.bucket, 0, 1, 1, 10), new WeightedRandomChestContent(Items.golden_apple, 0, 1, 1, 1), new WeightedRandomChestContent(Items.redstone, 0, 1, 4, 10), new WeightedRandomChestContent(Items.record_13, 0, 1, 1, 4), new WeightedRandomChestContent(Items.record_cat, 0, 1, 1, 4), new WeightedRandomChestContent(Items.name_tag, 0, 1, 1, 10), new WeightedRandomChestContent(Items.golden_horse_armor, 0, 1, 1, 2), new WeightedRandomChestContent(Items.iron_horse_armor, 0, 1, 1, 5), new WeightedRandomChestContent(Items.diamond_horse_armor, 0, 1, 1, 1)});
    private static final List CHESTCONTENTPUZZEL = Lists.newArrayList(new WeightedRandomChestContent[] {new WeightedRandomChestContent(Items.diamond, 0, 2, 4, 10), new WeightedRandomChestContent(Items.iron_ingot, 0, 5, 10, 30), new WeightedRandomChestContent(Items.gold_ingot, 0, 3, 7, 20), new WeightedRandomChestContent(Items.emerald, 0, 1, 3, 5), new WeightedRandomChestContent(Items.cooked_beef, 0, 5, 10, 30), new WeightedRandomChestContent(Items.baked_potato, 0, 8, 8, 10), new WeightedRandomChestContent(Items.golden_apple, 1, 1, 1, 1), new WeightedRandomChestContent(Items.redstone, 0, 8, 16, 20), new WeightedRandomChestContent(Items.name_tag, 0, 1, 1, 10)});
    
	public boolean generate(World world, Random rand, BlockPos pos)
	{
        if ((world.isAirBlock(pos) || world.getBlockState(pos).getBlock() == Blocks.snow_layer || world.getBlockState(pos).getBlock().getMaterial() == Material.plants) && world.canSeeSky(pos.up()) && world.getBlockState(pos.down()).getBlock().getMaterial().isSolid())
        {
        	this.generate_r0(world, rand, pos.getX(), pos.getY(), pos.getZ());

    	    return true;
        }
        else
        {
            return false;
        }
	}

	public boolean generate_r0(World world, Random rand, int x, int y, int z)
	{
		x -= 14;
		z -= 14;
		--y;
		
		this.setBlock(world, x + 1, y + 0, z + 1, Blocks.stonebrick, 0, 3);
		this.setBlock(world, x + 2, y + 0, z + 1, Blocks.stonebrick, 0, 3);
		this.setBlock(world, x + 3, y + 0, z + 1, Blocks.stonebrick, 0, 3);
		this.setBlock(world, x + 4, y + 0, z + 1, Blocks.stonebrick, 0, 3);
		this.setBlock(world, x + 5, y + 0, z + 1, Blocks.stonebrick, 0, 3);
		this.setBlock(world, x + 6, y + 0, z + 1, Blocks.stonebrick, 0, 3);
		this.setBlock(world, x + 7, y + 0, z + 1, Blocks.stonebrick, 0, 3);
		this.setBlock(world, x + 8, y + 0, z + 1, Blocks.stonebrick, 0, 3);
		this.setBlock(world, x + 9, y + 0, z + 1, Blocks.stonebrick, 0, 3);
		this.setBlock(world, x + 10, y + 0, z + 1, Blocks.stonebrick, 0, 3);
		this.setBlock(world, x + 11, y + 0, z + 1, Blocks.stonebrick, 0, 3);
		this.setBlock(world, x + 12, y + 0, z + 1, Blocks.stonebrick, 0, 3);
		this.setBlock(world, x + 13, y + 0, z + 1, Blocks.stonebrick, 0, 3);
		this.setBlock(world, x + 14, y + 0, z + 1, Blocks.stonebrick, 0, 3);
		this.setBlock(world, x + 15, y + 0, z + 1, Blocks.stonebrick, 0, 3);
		this.setBlock(world, x + 16, y + 0, z + 1, Blocks.stonebrick, 0, 3);
		this.setBlock(world, x + 17, y + 0, z + 1, Blocks.stonebrick, 0, 3);
		this.setBlock(world, x + 18, y + 0, z + 1, Blocks.stonebrick, 0, 3);
		this.setBlock(world, x + 19, y + 0, z + 1, Blocks.stonebrick, 0, 3);
		this.setBlock(world, x + 20, y + 0, z + 1, Blocks.stonebrick, 0, 3);
		this.setBlock(world, x + 21, y + 0, z + 1, Blocks.stonebrick, 0, 3);
		this.setBlock(world, x + 22, y + 0, z + 1, Blocks.stonebrick, 0, 3);
		this.setBlock(world, x + 23, y + 0, z + 1, Blocks.stonebrick, 0, 3);
		this.setBlock(world, x + 24, y + 0, z + 1, Blocks.stonebrick, 0, 3);
		this.setBlock(world, x + 25, y + 0, z + 1, Blocks.stonebrick, 0, 3);
		this.setBlock(world, x + 26, y + 0, z + 1, Blocks.stonebrick, 0, 3);
		this.setBlock(world, x + 27, y + 0, z + 1, Blocks.stonebrick, 0, 3);
		this.setBlock(world, x + 28, y + 0, z + 1, Blocks.stonebrick, 0, 3);
		this.setBlock(world, x + 29, y + 0, z + 1, Blocks.stonebrick, 0, 3);
		this.setBlock(world, x + 1, y + 0, z + 2, Blocks.stonebrick, 0, 3);
		this.setBlock(world, x + 2, y + 0, z + 2, Blocks.stonebrick, 0, 3);
		this.setBlock(world, x + 3, y + 0, z + 2, Blocks.stonebrick, 0, 3);
		this.setBlock(world, x + 4, y + 0, z + 2, Blocks.stonebrick, 0, 3);
		this.setBlock(world, x + 5, y + 0, z + 2, Blocks.stonebrick, 0, 3);
		this.setBlock(world, x + 6, y + 0, z + 2, Blocks.stonebrick, 0, 3);
		this.setBlock(world, x + 7, y + 0, z + 2, Blocks.stonebrick, 0, 3);
		this.setBlock(world, x + 8, y + 0, z + 2, Blocks.stonebrick, 0, 3);
		this.setBlock(world, x + 9, y + 0, z + 2, Blocks.stonebrick, 0, 3);
		this.setBlock(world, x + 10, y + 0, z + 2, Blocks.stonebrick, 0, 3);
		this.setBlock(world, x + 11, y + 0, z + 2, Blocks.stonebrick, 0, 3);
		this.setBlock(world, x + 12, y + 0, z + 2, Blocks.stonebrick, 0, 3);
		this.setBlock(world, x + 13, y + 0, z + 2, Blocks.stonebrick, 0, 3);
		this.setBlock(world, x + 14, y + 0, z + 2, Blocks.stonebrick, 0, 3);
		this.setBlock(world, x + 15, y + 0, z + 2, Blocks.stonebrick, 0, 3);
		this.setBlock(world, x + 16, y + 0, z + 2, Blocks.stonebrick, 0, 3);
		this.setBlock(world, x + 17, y + 0, z + 2, Blocks.stonebrick, 0, 3);
		this.setBlock(world, x + 18, y + 0, z + 2, Blocks.stonebrick, 0, 3);
		this.setBlock(world, x + 19, y + 0, z + 2, Blocks.stonebrick, 0, 3);
		this.setBlock(world, x + 20, y + 0, z + 2, Blocks.stonebrick, 0, 3);
		this.setBlock(world, x + 21, y + 0, z + 2, Blocks.stonebrick, 0, 3);
		this.setBlock(world, x + 22, y + 0, z + 2, Blocks.stonebrick, 0, 3);
		this.setBlock(world, x + 23, y + 0, z + 2, Blocks.stonebrick, 0, 3);
		this.setBlock(world, x + 24, y + 0, z + 2, Blocks.stonebrick, 0, 3);
		this.setBlock(world, x + 25, y + 0, z + 2, Blocks.stonebrick, 0, 3);
		this.setBlock(world, x + 26, y + 0, z + 2, Blocks.stonebrick, 0, 3);
		this.setBlock(world, x + 27, y + 0, z + 2, Blocks.stonebrick, 0, 3);
		this.setBlock(world, x + 28, y + 0, z + 2, Blocks.stonebrick, 0, 3);
		this.setBlock(world, x + 29, y + 0, z + 2, Blocks.stonebrick, 0, 3);
		this.setBlock(world, x + 1, y + 0, z + 3, Blocks.stonebrick, 0, 3);
		this.setBlock(world, x + 2, y + 0, z + 3, Blocks.stonebrick, 0, 3);
		this.setBlock(world, x + 3, y + 0, z + 3, Blocks.stonebrick, 0, 3);
		this.setBlock(world, x + 4, y + 0, z + 3, Blocks.stonebrick, 0, 3);
		this.setBlock(world, x + 5, y + 0, z + 3, Blocks.stonebrick, 0, 3);
		this.setBlock(world, x + 6, y + 0, z + 3, Blocks.stonebrick, 0, 3);
		this.setBlock(world, x + 7, y + 0, z + 3, Blocks.stonebrick, 0, 3);
		this.setBlock(world, x + 8, y + 0, z + 3, Blocks.stonebrick, 0, 3);
		this.setBlock(world, x + 9, y + 0, z + 3, Blocks.stonebrick, 0, 3);
		this.setBlock(world, x + 10, y + 0, z + 3, Blocks.stonebrick, 0, 3);
		this.setBlock(world, x + 11, y + 0, z + 3, Blocks.stonebrick, 0, 3);
		this.setBlock(world, x + 12, y + 0, z + 3, Blocks.stonebrick, 0, 3);
		this.setBlock(world, x + 13, y + 0, z + 3, Blocks.stonebrick, 0, 3);
		this.setBlock(world, x + 14, y + 0, z + 3, Blocks.stonebrick, 0, 3);
		this.setBlock(world, x + 15, y + 0, z + 3, Blocks.stonebrick, 0, 3);
		this.setBlock(world, x + 16, y + 0, z + 3, Blocks.stonebrick, 0, 3);
		this.setBlock(world, x + 17, y + 0, z + 3, Blocks.stonebrick, 0, 3);
		this.setBlock(world, x + 18, y + 0, z + 3, Blocks.stonebrick, 0, 3);
		this.setBlock(world, x + 19, y + 0, z + 3, Blocks.stonebrick, 0, 3);
		this.setBlock(world, x + 20, y + 0, z + 3, Blocks.stonebrick, 0, 3);
		this.setBlock(world, x + 21, y + 0, z + 3, Blocks.stonebrick, 0, 3);
		this.setBlock(world, x + 22, y + 0, z + 3, Blocks.stonebrick, 0, 3);
		this.setBlock(world, x + 23, y + 0, z + 3, Blocks.stonebrick, 0, 3);
		this.setBlock(world, x + 24, y + 0, z + 3, Blocks.stonebrick, 0, 3);
		this.setBlock(world, x + 25, y + 0, z + 3, Blocks.stonebrick, 0, 3);
		this.setBlock(world, x + 26, y + 0, z + 3, Blocks.stonebrick, 0, 3);
		this.setBlock(world, x + 27, y + 0, z + 3, Blocks.stonebrick, 0, 3);
		this.setBlock(world, x + 28, y + 0, z + 3, Blocks.stonebrick, 0, 3);
		this.setBlock(world, x + 29, y + 0, z + 3, Blocks.stonebrick, 0, 3);
		this.setBlock(world, x + 1, y + 0, z + 4, Blocks.stonebrick, 0, 3);
		this.setBlock(world, x + 2, y + 0, z + 4, Blocks.stonebrick, 0, 3);
		this.setBlock(world, x + 3, y + 0, z + 4, Blocks.stonebrick, 0, 3);
		this.setBlock(world, x + 4, y + 0, z + 4, Blocks.stonebrick, 0, 3);
		this.setBlock(world, x + 5, y + 0, z + 4, Blocks.stonebrick, 0, 3);
		this.setBlock(world, x + 6, y + 0, z + 4, Blocks.stonebrick, 0, 3);
		this.setBlock(world, x + 7, y + 0, z + 4, Blocks.stonebrick, 0, 3);
		this.setBlock(world, x + 8, y + 0, z + 4, Blocks.stonebrick, 0, 3);
		this.setBlock(world, x + 9, y + 0, z + 4, Blocks.stonebrick, 0, 3);
		this.setBlock(world, x + 10, y + 0, z + 4, Blocks.stonebrick, 0, 3);
		this.setBlock(world, x + 11, y + 0, z + 4, Blocks.stonebrick, 0, 3);
		this.setBlock(world, x + 12, y + 0, z + 4, Blocks.stonebrick, 0, 3);
		this.setBlock(world, x + 13, y + 0, z + 4, Blocks.stonebrick, 0, 3);
		this.setBlock(world, x + 14, y + 0, z + 4, Blocks.stonebrick, 0, 3);
		this.setBlock(world, x + 15, y + 0, z + 4, Blocks.stonebrick, 0, 3);
		this.setBlock(world, x + 16, y + 0, z + 4, Blocks.stonebrick, 0, 3);
		this.setBlock(world, x + 17, y + 0, z + 4, Blocks.stonebrick, 0, 3);
		this.setBlock(world, x + 18, y + 0, z + 4, Blocks.stonebrick, 0, 3);
		this.setBlock(world, x + 19, y + 0, z + 4, Blocks.stonebrick, 0, 3);
		this.setBlock(world, x + 20, y + 0, z + 4, Blocks.stonebrick, 0, 3);
		this.setBlock(world, x + 21, y + 0, z + 4, Blocks.stonebrick, 0, 3);
		this.setBlock(world, x + 22, y + 0, z + 4, Blocks.stonebrick, 0, 3);
		this.setBlock(world, x + 23, y + 0, z + 4, Blocks.stonebrick, 0, 3);
		this.setBlock(world, x + 24, y + 0, z + 4, Blocks.stonebrick, 0, 3);
		this.setBlock(world, x + 25, y + 0, z + 4, Blocks.stonebrick, 0, 3);
		this.setBlock(world, x + 26, y + 0, z + 4, Blocks.stonebrick, 0, 3);
		this.setBlock(world, x + 27, y + 0, z + 4, Blocks.stonebrick, 0, 3);
		this.setBlock(world, x + 28, y + 0, z + 4, Blocks.stonebrick, 0, 3);
		this.setBlock(world, x + 29, y + 0, z + 4, Blocks.stonebrick, 0, 3);
		this.setBlock(world, x + 1, y + 0, z + 5, Blocks.stonebrick, 0, 3);
		this.setBlock(world, x + 2, y + 0, z + 5, Blocks.stonebrick, 0, 3);
		this.setBlock(world, x + 3, y + 0, z + 5, Blocks.stonebrick, 0, 3);
		this.setBlock(world, x + 4, y + 0, z + 5, Blocks.stonebrick, 0, 3);
		this.setBlock(world, x + 5, y + 0, z + 5, Blocks.stonebrick, 0, 3);
		this.setBlock(world, x + 6, y + 0, z + 5, Blocks.stonebrick, 0, 3);
		this.setBlock(world, x + 7, y + 0, z + 5, Blocks.stonebrick, 0, 3);
		this.setBlock(world, x + 8, y + 0, z + 5, Blocks.stonebrick, 0, 3);
		this.setBlock(world, x + 9, y + 0, z + 5, Blocks.stonebrick, 0, 3);
		this.setBlock(world, x + 10, y + 0, z + 5, Blocks.stonebrick, 0, 3);
		this.setBlock(world, x + 11, y + 0, z + 5, Blocks.stonebrick, 0, 3);
		this.setBlock(world, x + 12, y + 0, z + 5, Blocks.stonebrick, 0, 3);
		this.setBlock(world, x + 13, y + 0, z + 5, Blocks.stonebrick, 0, 3);
		this.setBlock(world, x + 14, y + 0, z + 5, Blocks.stonebrick, 0, 3);
		this.setBlock(world, x + 15, y + 0, z + 5, Blocks.stonebrick, 0, 3);
		this.setBlock(world, x + 16, y + 0, z + 5, Blocks.stonebrick, 0, 3);
		this.setBlock(world, x + 17, y + 0, z + 5, Blocks.stonebrick, 0, 3);
		this.setBlock(world, x + 18, y + 0, z + 5, Blocks.stonebrick, 0, 3);
		this.setBlock(world, x + 19, y + 0, z + 5, Blocks.stonebrick, 0, 3);
		this.setBlock(world, x + 20, y + 0, z + 5, Blocks.stonebrick, 0, 3);
		this.setBlock(world, x + 21, y + 0, z + 5, Blocks.stonebrick, 0, 3);
		this.setBlock(world, x + 22, y + 0, z + 5, Blocks.stonebrick, 0, 3);
		this.setBlock(world, x + 23, y + 0, z + 5, Blocks.stonebrick, 0, 3);
		this.setBlock(world, x + 24, y + 0, z + 5, Blocks.stonebrick, 0, 3);
		this.setBlock(world, x + 25, y + 0, z + 5, Blocks.stonebrick, 0, 3);
		this.setBlock(world, x + 26, y + 0, z + 5, Blocks.stonebrick, 0, 3);
		this.setBlock(world, x + 27, y + 0, z + 5, Blocks.stonebrick, 0, 3);
		this.setBlock(world, x + 28, y + 0, z + 5, Blocks.stonebrick, 0, 3);
		this.setBlock(world, x + 29, y + 0, z + 5, Blocks.stonebrick, 0, 3);
		this.setBlock(world, x + 1, y + 0, z + 6, Blocks.stonebrick, 0, 3);
		this.setBlock(world, x + 2, y + 0, z + 6, Blocks.stonebrick, 0, 3);
		this.setBlock(world, x + 3, y + 0, z + 6, Blocks.stonebrick, 0, 3);
		this.setBlock(world, x + 4, y + 0, z + 6, Blocks.stonebrick, 0, 3);
		this.setBlock(world, x + 5, y + 0, z + 6, Blocks.stonebrick, 0, 3);
		this.setBlock(world, x + 6, y + 0, z + 6, Blocks.stonebrick, 0, 3);
		this.setBlock(world, x + 7, y + 0, z + 6, Blocks.stonebrick, 0, 3);
		this.setBlock(world, x + 8, y + 0, z + 6, Blocks.stonebrick, 0, 3);
		this.setBlock(world, x + 9, y + 0, z + 6, Blocks.stonebrick, 0, 3);
		this.setBlock(world, x + 10, y + 0, z + 6, Blocks.stonebrick, 0, 3);
		this.setBlock(world, x + 11, y + 0, z + 6, Blocks.stonebrick, 0, 3);
		this.setBlock(world, x + 12, y + 0, z + 6, Blocks.stonebrick, 0, 3);
		this.setBlock(world, x + 13, y + 0, z + 6, Blocks.stonebrick, 0, 3);
		this.setBlock(world, x + 14, y + 0, z + 6, Blocks.stonebrick, 0, 3);
		this.setBlock(world, x + 15, y + 0, z + 6, Blocks.stonebrick, 0, 3);
		this.setBlock(world, x + 16, y + 0, z + 6, Blocks.stonebrick, 0, 3);
		this.setBlock(world, x + 17, y + 0, z + 6, Blocks.stonebrick, 0, 3);
		this.setBlock(world, x + 18, y + 0, z + 6, Blocks.stonebrick, 0, 3);
		this.setBlock(world, x + 19, y + 0, z + 6, Blocks.stonebrick, 0, 3);
		this.setBlock(world, x + 20, y + 0, z + 6, Blocks.stonebrick, 0, 3);
		this.setBlock(world, x + 21, y + 0, z + 6, Blocks.stonebrick, 0, 3);
		this.setBlock(world, x + 22, y + 0, z + 6, Blocks.stonebrick, 0, 3);
		this.setBlock(world, x + 23, y + 0, z + 6, Blocks.stonebrick, 0, 3);
		this.setBlock(world, x + 24, y + 0, z + 6, Blocks.stonebrick, 0, 3);
		this.setBlock(world, x + 25, y + 0, z + 6, Blocks.stonebrick, 0, 3);
		this.setBlock(world, x + 26, y + 0, z + 6, Blocks.stonebrick, 0, 3);
		this.setBlock(world, x + 27, y + 0, z + 6, Blocks.stonebrick, 0, 3);
		this.setBlock(world, x + 28, y + 0, z + 6, Blocks.stonebrick, 0, 3);
		this.setBlock(world, x + 29, y + 0, z + 6, Blocks.stonebrick, 0, 3);
		this.setBlock(world, x + 1, y + 0, z + 7, Blocks.stonebrick, 0, 3);
		this.setBlock(world, x + 2, y + 0, z + 7, Blocks.stonebrick, 0, 3);
		this.setBlock(world, x + 3, y + 0, z + 7, Blocks.stonebrick, 0, 3);
		this.setBlock(world, x + 4, y + 0, z + 7, Blocks.stonebrick, 0, 3);
		this.setBlock(world, x + 5, y + 0, z + 7, Blocks.stonebrick, 0, 3);
		this.setBlock(world, x + 6, y + 0, z + 7, Blocks.stonebrick, 0, 3);
		this.setBlock(world, x + 7, y + 0, z + 7, Blocks.stonebrick, 0, 3);
		this.setBlock(world, x + 8, y + 0, z + 7, Blocks.stonebrick, 0, 3);
		this.setBlock(world, x + 9, y + 0, z + 7, Blocks.stonebrick, 0, 3);
		this.setBlock(world, x + 10, y + 0, z + 7, Blocks.stonebrick, 0, 3);
		this.setBlock(world, x + 11, y + 0, z + 7, Blocks.stonebrick, 0, 3);
		this.setBlock(world, x + 12, y + 0, z + 7, Blocks.stonebrick, 0, 3);
		this.setBlock(world, x + 13, y + 0, z + 7, Blocks.stonebrick, 0, 3);
		this.setBlock(world, x + 14, y + 0, z + 7, Blocks.stonebrick, 0, 3);
		this.setBlock(world, x + 15, y + 0, z + 7, Blocks.stonebrick, 0, 3);
		this.setBlock(world, x + 16, y + 0, z + 7, Blocks.stonebrick, 0, 3);
		this.setBlock(world, x + 17, y + 0, z + 7, Blocks.stonebrick, 0, 3);
		this.setBlock(world, x + 18, y + 0, z + 7, Blocks.stonebrick, 0, 3);
		this.setBlock(world, x + 19, y + 0, z + 7, Blocks.stonebrick, 0, 3);
		this.setBlock(world, x + 20, y + 0, z + 7, Blocks.stonebrick, 0, 3);
		this.setBlock(world, x + 21, y + 0, z + 7, Blocks.stonebrick, 0, 3);
		this.setBlock(world, x + 22, y + 0, z + 7, Blocks.stonebrick, 0, 3);
		this.setBlock(world, x + 23, y + 0, z + 7, Blocks.stonebrick, 0, 3);
		this.setBlock(world, x + 24, y + 0, z + 7, Blocks.stonebrick, 0, 3);
		this.setBlock(world, x + 25, y + 0, z + 7, Blocks.stonebrick, 0, 3);
		this.setBlock(world, x + 26, y + 0, z + 7, Blocks.stonebrick, 0, 3);
		this.setBlock(world, x + 27, y + 0, z + 7, Blocks.stonebrick, 0, 3);
		this.setBlock(world, x + 28, y + 0, z + 7, Blocks.stonebrick, 0, 3);
		this.setBlock(world, x + 29, y + 0, z + 7, Blocks.stonebrick, 0, 3);
		this.setBlock(world, x + 1, y + 0, z + 8, Blocks.stonebrick, 0, 3);
		this.setBlock(world, x + 2, y + 0, z + 8, Blocks.stonebrick, 0, 3);
		this.setBlock(world, x + 3, y + 0, z + 8, Blocks.stonebrick, 0, 3);
		this.setBlock(world, x + 4, y + 0, z + 8, Blocks.stonebrick, 0, 3);
		this.setBlock(world, x + 5, y + 0, z + 8, Blocks.stonebrick, 0, 3);
		this.setBlock(world, x + 6, y + 0, z + 8, Blocks.stonebrick, 0, 3);
		this.setBlock(world, x + 7, y + 0, z + 8, Blocks.stonebrick, 0, 3);
		this.setBlock(world, x + 8, y + 0, z + 8, Blocks.stonebrick, 0, 3);
		this.setBlock(world, x + 9, y + 0, z + 8, Blocks.stonebrick, 0, 3);
		this.setBlock(world, x + 10, y + 0, z + 8, Blocks.stonebrick, 0, 3);
		this.setBlock(world, x + 11, y + 0, z + 8, Blocks.stonebrick, 0, 3);
		this.setBlock(world, x + 12, y + 0, z + 8, Blocks.stonebrick, 0, 3);
		this.setBlock(world, x + 13, y + 0, z + 8, Blocks.stonebrick, 0, 3);
		this.setBlock(world, x + 14, y + 0, z + 8, Blocks.stonebrick, 0, 3);
		this.setBlock(world, x + 15, y + 0, z + 8, Blocks.stonebrick, 0, 3);
		this.setBlock(world, x + 16, y + 0, z + 8, Blocks.stonebrick, 0, 3);
		this.setBlock(world, x + 17, y + 0, z + 8, Blocks.stonebrick, 0, 3);
		this.setBlock(world, x + 18, y + 0, z + 8, Blocks.stonebrick, 0, 3);
		this.setBlock(world, x + 19, y + 0, z + 8, Blocks.stonebrick, 0, 3);
		this.setBlock(world, x + 20, y + 0, z + 8, Blocks.stonebrick, 0, 3);
		this.setBlock(world, x + 21, y + 0, z + 8, Blocks.stonebrick, 0, 3);
		this.setBlock(world, x + 22, y + 0, z + 8, Blocks.stonebrick, 0, 3);
		this.setBlock(world, x + 23, y + 0, z + 8, Blocks.stonebrick, 0, 3);
		this.setBlock(world, x + 24, y + 0, z + 8, Blocks.stonebrick, 0, 3);
		this.setBlock(world, x + 25, y + 0, z + 8, Blocks.stonebrick, 0, 3);
		this.setBlock(world, x + 26, y + 0, z + 8, Blocks.stonebrick, 0, 3);
		this.setBlock(world, x + 27, y + 0, z + 8, Blocks.stonebrick, 0, 3);
		this.setBlock(world, x + 28, y + 0, z + 8, Blocks.stonebrick, 0, 3);
		this.setBlock(world, x + 29, y + 0, z + 8, Blocks.stonebrick, 0, 3);
		this.setBlock(world, x + 1, y + 0, z + 9, Blocks.stonebrick, 0, 3);
		this.setBlock(world, x + 2, y + 0, z + 9, Blocks.stonebrick, 0, 3);
		this.setBlock(world, x + 3, y + 0, z + 9, Blocks.stonebrick, 0, 3);
		this.setBlock(world, x + 4, y + 0, z + 9, Blocks.stonebrick, 0, 3);
		this.setBlock(world, x + 5, y + 0, z + 9, Blocks.stonebrick, 0, 3);
		this.setBlock(world, x + 6, y + 0, z + 9, Blocks.stonebrick, 0, 3);
		this.setBlock(world, x + 7, y + 0, z + 9, Blocks.stonebrick, 0, 3);
		this.setBlock(world, x + 8, y + 0, z + 9, Blocks.stonebrick, 0, 3);
		this.setBlock(world, x + 9, y + 0, z + 9, Blocks.stonebrick, 0, 3);
		this.setBlock(world, x + 10, y + 0, z + 9, Blocks.stonebrick, 0, 3);
		this.setBlock(world, x + 11, y + 0, z + 9, Blocks.stonebrick, 0, 3);
		this.setBlock(world, x + 12, y + 0, z + 9, Blocks.stonebrick, 0, 3);
		this.setBlock(world, x + 13, y + 0, z + 9, Blocks.stonebrick, 0, 3);
		this.setBlock(world, x + 14, y + 0, z + 9, Blocks.stonebrick, 0, 3);
		this.setBlock(world, x + 15, y + 0, z + 9, Blocks.stonebrick, 0, 3);
		this.setBlock(world, x + 16, y + 0, z + 9, Blocks.stonebrick, 0, 3);
		this.setBlock(world, x + 17, y + 0, z + 9, Blocks.stonebrick, 0, 3);
		this.setBlock(world, x + 18, y + 0, z + 9, Blocks.stonebrick, 0, 3);
		this.setBlock(world, x + 19, y + 0, z + 9, Blocks.stonebrick, 0, 3);
		this.setBlock(world, x + 20, y + 0, z + 9, Blocks.stonebrick, 0, 3);
		this.setBlock(world, x + 21, y + 0, z + 9, Blocks.stonebrick, 0, 3);
		this.setBlock(world, x + 22, y + 0, z + 9, Blocks.stonebrick, 0, 3);
		this.setBlock(world, x + 23, y + 0, z + 9, Blocks.stonebrick, 0, 3);
		this.setBlock(world, x + 24, y + 0, z + 9, Blocks.stonebrick, 0, 3);
		this.setBlock(world, x + 25, y + 0, z + 9, Blocks.stonebrick, 0, 3);
		this.setBlock(world, x + 26, y + 0, z + 9, Blocks.stonebrick, 0, 3);
		this.setBlock(world, x + 27, y + 0, z + 9, Blocks.stonebrick, 0, 3);
		this.setBlock(world, x + 28, y + 0, z + 9, Blocks.stonebrick, 0, 3);
		this.setBlock(world, x + 29, y + 0, z + 9, Blocks.stonebrick, 0, 3);
		this.setBlock(world, x + 1, y + 0, z + 10, Blocks.stonebrick, 0, 3);
		this.setBlock(world, x + 2, y + 0, z + 10, Blocks.stonebrick, 0, 3);
		this.setBlock(world, x + 3, y + 0, z + 10, Blocks.stonebrick, 0, 3);
		this.setBlock(world, x + 4, y + 0, z + 10, Blocks.stonebrick, 0, 3);
		this.setBlock(world, x + 5, y + 0, z + 10, Blocks.stonebrick, 0, 3);
		this.setBlock(world, x + 6, y + 0, z + 10, Blocks.stonebrick, 0, 3);
		this.setBlock(world, x + 7, y + 0, z + 10, Blocks.stonebrick, 0, 3);
		this.setBlock(world, x + 8, y + 0, z + 10, Blocks.stonebrick, 0, 3);
		this.setBlock(world, x + 9, y + 0, z + 10, Blocks.stonebrick, 0, 3);
		this.setBlock(world, x + 10, y + 0, z + 10, Blocks.stonebrick, 0, 3);
		this.setBlock(world, x + 11, y + 0, z + 10, Blocks.stonebrick, 0, 3);
		this.setBlock(world, x + 12, y + 0, z + 10, Blocks.stonebrick, 0, 3);
		this.setBlock(world, x + 13, y + 0, z + 10, Blocks.stonebrick, 0, 3);
		this.setBlock(world, x + 14, y + 0, z + 10, Blocks.stonebrick, 0, 3);
		this.setBlock(world, x + 15, y + 0, z + 10, Blocks.stonebrick, 0, 3);
		this.setBlock(world, x + 16, y + 0, z + 10, Blocks.stonebrick, 0, 3);
		this.setBlock(world, x + 17, y + 0, z + 10, Blocks.stonebrick, 0, 3);
		this.setBlock(world, x + 18, y + 0, z + 10, Blocks.stonebrick, 0, 3);
		this.setBlock(world, x + 19, y + 0, z + 10, Blocks.stonebrick, 0, 3);
		this.setBlock(world, x + 20, y + 0, z + 10, Blocks.stonebrick, 0, 3);
		this.setBlock(world, x + 21, y + 0, z + 10, Blocks.stonebrick, 0, 3);
		this.setBlock(world, x + 22, y + 0, z + 10, Blocks.stonebrick, 0, 3);
		this.setBlock(world, x + 23, y + 0, z + 10, Blocks.stonebrick, 0, 3);
		this.setBlock(world, x + 24, y + 0, z + 10, Blocks.stonebrick, 0, 3);
		this.setBlock(world, x + 25, y + 0, z + 10, Blocks.stonebrick, 0, 3);
		this.setBlock(world, x + 26, y + 0, z + 10, Blocks.stonebrick, 0, 3);
		this.setBlock(world, x + 27, y + 0, z + 10, Blocks.stonebrick, 0, 3);
		this.setBlock(world, x + 28, y + 0, z + 10, Blocks.stonebrick, 0, 3);
		this.setBlock(world, x + 29, y + 0, z + 10, Blocks.stonebrick, 0, 3);
		this.setBlock(world, x + 1, y + 0, z + 11, Blocks.stonebrick, 0, 3);
		this.setBlock(world, x + 2, y + 0, z + 11, Blocks.stonebrick, 0, 3);
		this.setBlock(world, x + 3, y + 0, z + 11, Blocks.stonebrick, 0, 3);
		this.setBlock(world, x + 4, y + 0, z + 11, Blocks.stonebrick, 0, 3);
		this.setBlock(world, x + 5, y + 0, z + 11, Blocks.stonebrick, 0, 3);
		this.setBlock(world, x + 6, y + 0, z + 11, Blocks.stonebrick, 0, 3);
		this.setBlock(world, x + 7, y + 0, z + 11, Blocks.stonebrick, 0, 3);
		this.setBlock(world, x + 8, y + 0, z + 11, Blocks.stonebrick, 0, 3);
		this.setBlock(world, x + 9, y + 0, z + 11, Blocks.stonebrick, 0, 3);
		this.setBlock(world, x + 10, y + 0, z + 11, Blocks.stonebrick, 0, 3);
		this.setBlock(world, x + 11, y + 0, z + 11, Blocks.stonebrick, 0, 3);
		this.setBlock(world, x + 12, y + 0, z + 11, Blocks.stonebrick, 0, 3);
		this.setBlock(world, x + 13, y + 0, z + 11, Blocks.stonebrick, 0, 3);
		this.setBlock(world, x + 14, y + 0, z + 11, Blocks.stonebrick, 0, 3);
		this.setBlock(world, x + 15, y + 0, z + 11, Blocks.stonebrick, 0, 3);
		this.setBlock(world, x + 16, y + 0, z + 11, Blocks.stonebrick, 0, 3);
		this.setBlock(world, x + 17, y + 0, z + 11, Blocks.stonebrick, 0, 3);
		this.setBlock(world, x + 18, y + 0, z + 11, Blocks.stonebrick, 0, 3);
		this.setBlock(world, x + 19, y + 0, z + 11, Blocks.stonebrick, 0, 3);
		this.setBlock(world, x + 20, y + 0, z + 11, Blocks.stonebrick, 0, 3);
		this.setBlock(world, x + 21, y + 0, z + 11, Blocks.stonebrick, 0, 3);
		this.setBlock(world, x + 22, y + 0, z + 11, Blocks.stonebrick, 0, 3);
		this.setBlock(world, x + 23, y + 0, z + 11, Blocks.stonebrick, 0, 3);
		this.setBlock(world, x + 24, y + 0, z + 11, Blocks.stonebrick, 0, 3);
		this.setBlock(world, x + 25, y + 0, z + 11, Blocks.stonebrick, 0, 3);
		this.setBlock(world, x + 26, y + 0, z + 11, Blocks.stonebrick, 0, 3);
		this.setBlock(world, x + 27, y + 0, z + 11, Blocks.stonebrick, 0, 3);
		this.setBlock(world, x + 28, y + 0, z + 11, Blocks.stonebrick, 0, 3);
		this.setBlock(world, x + 29, y + 0, z + 11, Blocks.stonebrick, 0, 3);
		this.setBlock(world, x + 1, y + 0, z + 12, Blocks.stonebrick, 0, 3);
		this.setBlock(world, x + 2, y + 0, z + 12, Blocks.stonebrick, 0, 3);
		this.setBlock(world, x + 3, y + 0, z + 12, Blocks.stonebrick, 0, 3);
		this.setBlock(world, x + 4, y + 0, z + 12, Blocks.stonebrick, 0, 3);
		this.setBlock(world, x + 5, y + 0, z + 12, Blocks.stonebrick, 0, 3);
		this.setBlock(world, x + 6, y + 0, z + 12, Blocks.stonebrick, 0, 3);
		this.setBlock(world, x + 7, y + 0, z + 12, Blocks.stonebrick, 0, 3);
		this.setBlock(world, x + 8, y + 0, z + 12, Blocks.stonebrick, 0, 3);
		this.setBlock(world, x + 9, y + 0, z + 12, Blocks.stonebrick, 0, 3);
		this.setBlock(world, x + 10, y + 0, z + 12, Blocks.stonebrick, 0, 3);
		this.setBlock(world, x + 11, y + 0, z + 12, Blocks.stonebrick, 0, 3);
		this.setBlock(world, x + 12, y + 0, z + 12, Blocks.stonebrick, 0, 3);
		this.setBlock(world, x + 13, y + 0, z + 12, Blocks.stonebrick, 0, 3);
		this.setBlock(world, x + 14, y + 0, z + 12, Blocks.stonebrick, 0, 3);
		this.setBlock(world, x + 15, y + 0, z + 12, Blocks.stonebrick, 0, 3);
		this.setBlock(world, x + 16, y + 0, z + 12, Blocks.stonebrick, 0, 3);
		this.setBlock(world, x + 17, y + 0, z + 12, Blocks.stonebrick, 0, 3);
		this.setBlock(world, x + 18, y + 0, z + 12, Blocks.stonebrick, 0, 3);
		this.setBlock(world, x + 19, y + 0, z + 12, Blocks.stonebrick, 0, 3);
		this.setBlock(world, x + 20, y + 0, z + 12, Blocks.stonebrick, 0, 3);
		this.setBlock(world, x + 21, y + 0, z + 12, Blocks.stonebrick, 0, 3);
		this.setBlock(world, x + 22, y + 0, z + 12, Blocks.stonebrick, 0, 3);
		this.setBlock(world, x + 23, y + 0, z + 12, Blocks.stonebrick, 0, 3);
		this.setBlock(world, x + 24, y + 0, z + 12, Blocks.stonebrick, 0, 3);
		this.setBlock(world, x + 25, y + 0, z + 12, Blocks.stonebrick, 0, 3);
		this.setBlock(world, x + 26, y + 0, z + 12, Blocks.stonebrick, 0, 3);
		this.setBlock(world, x + 27, y + 0, z + 12, Blocks.stonebrick, 0, 3);
		this.setBlock(world, x + 28, y + 0, z + 12, Blocks.stonebrick, 0, 3);
		this.setBlock(world, x + 29, y + 0, z + 12, Blocks.stonebrick, 0, 3);
		this.setBlock(world, x + 1, y + 0, z + 13, Blocks.stonebrick, 0, 3);
		this.setBlock(world, x + 2, y + 0, z + 13, Blocks.stonebrick, 0, 3);
		this.setBlock(world, x + 3, y + 0, z + 13, Blocks.stonebrick, 0, 3);
		this.setBlock(world, x + 4, y + 0, z + 13, Blocks.stonebrick, 0, 3);
		this.setBlock(world, x + 5, y + 0, z + 13, Blocks.stonebrick, 0, 3);
		this.setBlock(world, x + 6, y + 0, z + 13, Blocks.stonebrick, 0, 3);
		this.setBlock(world, x + 7, y + 0, z + 13, Blocks.stonebrick, 0, 3);
		this.setBlock(world, x + 8, y + 0, z + 13, Blocks.stonebrick, 0, 3);
		this.setBlock(world, x + 9, y + 0, z + 13, Blocks.stonebrick, 0, 3);
		this.setBlock(world, x + 10, y + 0, z + 13, Blocks.stonebrick, 0, 3);
		this.setBlock(world, x + 11, y + 0, z + 13, Blocks.stonebrick, 0, 3);
		this.setBlock(world, x + 12, y + 0, z + 13, Blocks.stonebrick, 0, 3);
		this.setBlock(world, x + 13, y + 0, z + 13, Blocks.stonebrick, 0, 3);
		this.setBlock(world, x + 14, y + 0, z + 13, Blocks.stonebrick, 0, 3);
		this.setBlock(world, x + 15, y + 0, z + 13, Blocks.stonebrick, 0, 3);
		this.setBlock(world, x + 16, y + 0, z + 13, Blocks.stonebrick, 0, 3);
		this.setBlock(world, x + 17, y + 0, z + 13, Blocks.stonebrick, 0, 3);
		this.setBlock(world, x + 18, y + 0, z + 13, Blocks.stonebrick, 0, 3);
		this.setBlock(world, x + 19, y + 0, z + 13, Blocks.stonebrick, 0, 3);
		this.setBlock(world, x + 20, y + 0, z + 13, Blocks.stonebrick, 0, 3);
		this.setBlock(world, x + 21, y + 0, z + 13, Blocks.stonebrick, 0, 3);
		this.setBlock(world, x + 22, y + 0, z + 13, Blocks.stonebrick, 0, 3);
		this.setBlock(world, x + 23, y + 0, z + 13, Blocks.stonebrick, 0, 3);
		this.setBlock(world, x + 24, y + 0, z + 13, Blocks.stonebrick, 0, 3);
		this.setBlock(world, x + 25, y + 0, z + 13, Blocks.stonebrick, 0, 3);
		this.setBlock(world, x + 26, y + 0, z + 13, Blocks.stonebrick, 0, 3);
		this.setBlock(world, x + 27, y + 0, z + 13, Blocks.stonebrick, 0, 3);
		this.setBlock(world, x + 28, y + 0, z + 13, Blocks.stonebrick, 0, 3);
		this.setBlock(world, x + 29, y + 0, z + 13, Blocks.stonebrick, 0, 3);
		this.setBlock(world, x + 1, y + 0, z + 14, Blocks.stonebrick, 0, 3);
		this.setBlock(world, x + 2, y + 0, z + 14, Blocks.stonebrick, 0, 3);
		this.setBlock(world, x + 3, y + 0, z + 14, Blocks.stonebrick, 0, 3);
		this.setBlock(world, x + 4, y + 0, z + 14, Blocks.stonebrick, 0, 3);
		this.setBlock(world, x + 5, y + 0, z + 14, Blocks.stonebrick, 0, 3);
		this.setBlock(world, x + 6, y + 0, z + 14, Blocks.stonebrick, 0, 3);
		this.setBlock(world, x + 7, y + 0, z + 14, Blocks.stonebrick, 0, 3);
		this.setBlock(world, x + 8, y + 0, z + 14, Blocks.stonebrick, 0, 3);
		this.setBlock(world, x + 9, y + 0, z + 14, Blocks.stonebrick, 0, 3);
		this.setBlock(world, x + 10, y + 0, z + 14, Blocks.stonebrick, 0, 3);
		this.setBlock(world, x + 11, y + 0, z + 14, Blocks.stonebrick, 0, 3);
		this.setBlock(world, x + 12, y + 0, z + 14, Blocks.stonebrick, 0, 3);
		this.setBlock(world, x + 13, y + 0, z + 14, Blocks.stonebrick, 0, 3);
		this.setBlock(world, x + 14, y + 0, z + 14, Blocks.stonebrick, 0, 3);
		this.setBlock(world, x + 15, y + 0, z + 14, Blocks.stonebrick, 0, 3);
		this.setBlock(world, x + 16, y + 0, z + 14, Blocks.stonebrick, 0, 3);
		this.setBlock(world, x + 17, y + 0, z + 14, Blocks.stonebrick, 0, 3);
		this.setBlock(world, x + 18, y + 0, z + 14, Blocks.stonebrick, 0, 3);
		this.setBlock(world, x + 19, y + 0, z + 14, Blocks.stonebrick, 0, 3);
		this.setBlock(world, x + 20, y + 0, z + 14, Blocks.stonebrick, 0, 3);
		this.setBlock(world, x + 21, y + 0, z + 14, Blocks.stonebrick, 0, 3);
		this.setBlock(world, x + 22, y + 0, z + 14, Blocks.stonebrick, 0, 3);
		this.setBlock(world, x + 23, y + 0, z + 14, Blocks.stonebrick, 0, 3);
		this.setBlock(world, x + 24, y + 0, z + 14, Blocks.stonebrick, 0, 3);
		this.setBlock(world, x + 25, y + 0, z + 14, Blocks.stonebrick, 0, 3);
		this.setBlock(world, x + 26, y + 0, z + 14, Blocks.stonebrick, 0, 3);
		this.setBlock(world, x + 27, y + 0, z + 14, Blocks.stonebrick, 0, 3);
		this.setBlock(world, x + 28, y + 0, z + 14, Blocks.stonebrick, 0, 3);
		this.setBlock(world, x + 29, y + 0, z + 14, Blocks.stonebrick, 0, 3);
		this.setBlock(world, x + 1, y + 0, z + 15, Blocks.stonebrick, 0, 3);
		this.setBlock(world, x + 2, y + 0, z + 15, Blocks.stonebrick, 0, 3);
		this.setBlock(world, x + 3, y + 0, z + 15, Blocks.stonebrick, 0, 3);
		this.setBlock(world, x + 4, y + 0, z + 15, Blocks.stonebrick, 0, 3);
		this.setBlock(world, x + 5, y + 0, z + 15, Blocks.stonebrick, 0, 3);
		this.setBlock(world, x + 6, y + 0, z + 15, Blocks.stonebrick, 0, 3);
		this.setBlock(world, x + 7, y + 0, z + 15, Blocks.stonebrick, 0, 3);
		this.setBlock(world, x + 8, y + 0, z + 15, Blocks.stonebrick, 0, 3);
		this.setBlock(world, x + 9, y + 0, z + 15, Blocks.stonebrick, 0, 3);
		this.setBlock(world, x + 10, y + 0, z + 15, Blocks.stonebrick, 0, 3);
		this.setBlock(world, x + 11, y + 0, z + 15, Blocks.stonebrick, 0, 3);
		this.setBlock(world, x + 12, y + 0, z + 15, Blocks.stonebrick, 0, 3);
		this.setBlock(world, x + 13, y + 0, z + 15, Blocks.stonebrick, 0, 3);
		this.setBlock(world, x + 14, y + 0, z + 15, Blocks.stonebrick, 0, 3);
		this.setBlock(world, x + 15, y + 0, z + 15, Blocks.stonebrick, 0, 3);
		this.setBlock(world, x + 16, y + 0, z + 15, Blocks.stonebrick, 0, 3);
		this.setBlock(world, x + 17, y + 0, z + 15, Blocks.stonebrick, 0, 3);
		this.setBlock(world, x + 18, y + 0, z + 15, Blocks.stonebrick, 0, 3);
		this.setBlock(world, x + 19, y + 0, z + 15, Blocks.stonebrick, 0, 3);
		this.setBlock(world, x + 20, y + 0, z + 15, Blocks.stonebrick, 0, 3);
		this.setBlock(world, x + 21, y + 0, z + 15, Blocks.stonebrick, 0, 3);
		this.setBlock(world, x + 22, y + 0, z + 15, Blocks.stonebrick, 0, 3);
		this.setBlock(world, x + 23, y + 0, z + 15, Blocks.stonebrick, 0, 3);
		this.setBlock(world, x + 24, y + 0, z + 15, Blocks.stonebrick, 0, 3);
		this.setBlock(world, x + 25, y + 0, z + 15, Blocks.stonebrick, 0, 3);
		this.setBlock(world, x + 26, y + 0, z + 15, Blocks.stonebrick, 0, 3);
		this.setBlock(world, x + 27, y + 0, z + 15, Blocks.stonebrick, 0, 3);
		this.setBlock(world, x + 28, y + 0, z + 15, Blocks.stonebrick, 0, 3);
		this.setBlock(world, x + 29, y + 0, z + 15, Blocks.stonebrick, 0, 3);
		this.setBlock(world, x + 1, y + 0, z + 16, Blocks.stonebrick, 0, 3);
		this.setBlock(world, x + 2, y + 0, z + 16, Blocks.stonebrick, 0, 3);
		this.setBlock(world, x + 3, y + 0, z + 16, Blocks.stonebrick, 0, 3);
		this.setBlock(world, x + 4, y + 0, z + 16, Blocks.stonebrick, 0, 3);
		this.setBlock(world, x + 5, y + 0, z + 16, Blocks.stonebrick, 0, 3);
		this.setBlock(world, x + 6, y + 0, z + 16, Blocks.stonebrick, 0, 3);
		this.setBlock(world, x + 7, y + 0, z + 16, Blocks.stonebrick, 0, 3);
		this.setBlock(world, x + 8, y + 0, z + 16, Blocks.stonebrick, 0, 3);
		this.setBlock(world, x + 9, y + 0, z + 16, Blocks.stonebrick, 0, 3);
		this.setBlock(world, x + 10, y + 0, z + 16, Blocks.stonebrick, 0, 3);
		this.setBlock(world, x + 11, y + 0, z + 16, Blocks.stonebrick, 0, 3);
		this.setBlock(world, x + 12, y + 0, z + 16, Blocks.stonebrick, 0, 3);
		this.setBlock(world, x + 13, y + 0, z + 16, Blocks.stonebrick, 0, 3);
		this.setBlock(world, x + 14, y + 0, z + 16, Blocks.stonebrick, 0, 3);
		this.setBlock(world, x + 15, y + 0, z + 16, Blocks.stonebrick, 0, 3);
		this.setBlock(world, x + 16, y + 0, z + 16, Blocks.stonebrick, 0, 3);
		this.setBlock(world, x + 17, y + 0, z + 16, Blocks.stonebrick, 0, 3);
		this.setBlock(world, x + 18, y + 0, z + 16, Blocks.stonebrick, 0, 3);
		this.setBlock(world, x + 19, y + 0, z + 16, Blocks.stonebrick, 0, 3);
		this.setBlock(world, x + 20, y + 0, z + 16, Blocks.stonebrick, 0, 3);
		this.setBlock(world, x + 21, y + 0, z + 16, Blocks.stonebrick, 0, 3);
		this.setBlock(world, x + 22, y + 0, z + 16, Blocks.stonebrick, 0, 3);
		this.setBlock(world, x + 23, y + 0, z + 16, Blocks.stonebrick, 0, 3);
		this.setBlock(world, x + 24, y + 0, z + 16, Blocks.stonebrick, 0, 3);
		this.setBlock(world, x + 25, y + 0, z + 16, Blocks.stonebrick, 0, 3);
		this.setBlock(world, x + 26, y + 0, z + 16, Blocks.stonebrick, 0, 3);
		this.setBlock(world, x + 27, y + 0, z + 16, Blocks.stonebrick, 0, 3);
		this.setBlock(world, x + 28, y + 0, z + 16, Blocks.stonebrick, 0, 3);
		this.setBlock(world, x + 29, y + 0, z + 16, Blocks.stonebrick, 0, 3);
		this.setBlock(world, x + 1, y + 0, z + 17, Blocks.stonebrick, 0, 3);
		this.setBlock(world, x + 2, y + 0, z + 17, Blocks.stonebrick, 0, 3);
		this.setBlock(world, x + 3, y + 0, z + 17, Blocks.stonebrick, 0, 3);
		this.setBlock(world, x + 4, y + 0, z + 17, Blocks.stonebrick, 0, 3);
		this.setBlock(world, x + 5, y + 0, z + 17, Blocks.stonebrick, 0, 3);
		this.setBlock(world, x + 6, y + 0, z + 17, Blocks.stonebrick, 0, 3);
		this.setBlock(world, x + 7, y + 0, z + 17, Blocks.stonebrick, 0, 3);
		this.setBlock(world, x + 8, y + 0, z + 17, Blocks.stonebrick, 0, 3);
		this.setBlock(world, x + 9, y + 0, z + 17, Blocks.stonebrick, 0, 3);
		this.setBlock(world, x + 10, y + 0, z + 17, Blocks.stonebrick, 0, 3);
		this.setBlock(world, x + 11, y + 0, z + 17, Blocks.stonebrick, 0, 3);
		this.setBlock(world, x + 12, y + 0, z + 17, Blocks.stonebrick, 0, 3);
		this.setBlock(world, x + 14, y + 0, z + 17, Blocks.stonebrick, 0, 3);
		this.setBlock(world, x + 15, y + 0, z + 17, Blocks.stonebrick, 0, 3);
		this.setBlock(world, x + 16, y + 0, z + 17, Blocks.stonebrick, 0, 3);
		this.setBlock(world, x + 17, y + 0, z + 17, Blocks.stonebrick, 0, 3);
		this.setBlock(world, x + 18, y + 0, z + 17, Blocks.stonebrick, 0, 3);
		this.setBlock(world, x + 19, y + 0, z + 17, Blocks.stonebrick, 0, 3);
		this.setBlock(world, x + 20, y + 0, z + 17, Blocks.stonebrick, 0, 3);
		this.setBlock(world, x + 21, y + 0, z + 17, Blocks.stonebrick, 0, 3);
		this.setBlock(world, x + 22, y + 0, z + 17, Blocks.stonebrick, 0, 3);
		this.setBlock(world, x + 23, y + 0, z + 17, Blocks.stonebrick, 0, 3);
		this.setBlock(world, x + 24, y + 0, z + 17, Blocks.stonebrick, 0, 3);
		this.setBlock(world, x + 25, y + 0, z + 17, Blocks.stonebrick, 0, 3);
		this.setBlock(world, x + 26, y + 0, z + 17, Blocks.stonebrick, 0, 3);
		this.setBlock(world, x + 27, y + 0, z + 17, Blocks.stonebrick, 0, 3);
		this.setBlock(world, x + 28, y + 0, z + 17, Blocks.stonebrick, 0, 3);
		this.setBlock(world, x + 29, y + 0, z + 17, Blocks.stonebrick, 0, 3);
		this.setBlock(world, x + 1, y + 0, z + 18, Blocks.stonebrick, 0, 3);
		this.setBlock(world, x + 2, y + 0, z + 18, Blocks.stonebrick, 0, 3);
		this.setBlock(world, x + 3, y + 0, z + 18, Blocks.stonebrick, 0, 3);
		this.setBlock(world, x + 4, y + 0, z + 18, Blocks.stonebrick, 0, 3);
		this.setBlock(world, x + 5, y + 0, z + 18, Blocks.stonebrick, 0, 3);
		this.setBlock(world, x + 6, y + 0, z + 18, Blocks.stonebrick, 0, 3);
		this.setBlock(world, x + 7, y + 0, z + 18, Blocks.stonebrick, 0, 3);
		this.setBlock(world, x + 8, y + 0, z + 18, Blocks.stonebrick, 0, 3);
		this.setBlock(world, x + 9, y + 0, z + 18, Blocks.stonebrick, 0, 3);
		this.setBlock(world, x + 10, y + 0, z + 18, Blocks.stonebrick, 0, 3);
		this.setBlock(world, x + 11, y + 0, z + 18, Blocks.stonebrick, 0, 3);
		this.setBlock(world, x + 12, y + 0, z + 18, Blocks.stonebrick, 0, 3);
		this.setBlock(world, x + 13, y + 0, z + 18, Blocks.stonebrick, 0, 3);
		this.setBlock(world, x + 14, y + 0, z + 18, Blocks.stonebrick, 0, 3);
		this.setBlock(world, x + 15, y + 0, z + 18, Blocks.stonebrick, 0, 3);
		this.setBlock(world, x + 16, y + 0, z + 18, Blocks.stonebrick, 0, 3);
		this.setBlock(world, x + 17, y + 0, z + 18, Blocks.stonebrick, 0, 3);
		this.setBlock(world, x + 18, y + 0, z + 18, Blocks.stonebrick, 0, 3);
		this.setBlock(world, x + 19, y + 0, z + 18, Blocks.stonebrick, 0, 3);
		this.setBlock(world, x + 20, y + 0, z + 18, Blocks.stonebrick, 0, 3);
		this.setBlock(world, x + 21, y + 0, z + 18, Blocks.stonebrick, 0, 3);
		this.setBlock(world, x + 22, y + 0, z + 18, Blocks.stonebrick, 0, 3);
		this.setBlock(world, x + 23, y + 0, z + 18, Blocks.stonebrick, 0, 3);
		this.setBlock(world, x + 24, y + 0, z + 18, Blocks.stonebrick, 0, 3);
		this.setBlock(world, x + 25, y + 0, z + 18, Blocks.stonebrick, 0, 3);
		this.setBlock(world, x + 26, y + 0, z + 18, Blocks.stonebrick, 0, 3);
		this.setBlock(world, x + 27, y + 0, z + 18, Blocks.stonebrick, 0, 3);
		this.setBlock(world, x + 28, y + 0, z + 18, Blocks.stonebrick, 0, 3);
		this.setBlock(world, x + 29, y + 0, z + 18, Blocks.stonebrick, 0, 3);
		this.setBlock(world, x + 1, y + 0, z + 19, Blocks.stonebrick, 0, 3);
		this.setBlock(world, x + 2, y + 0, z + 19, Blocks.stonebrick, 0, 3);
		this.setBlock(world, x + 3, y + 0, z + 19, Blocks.stonebrick, 0, 3);
		this.setBlock(world, x + 4, y + 0, z + 19, Blocks.stonebrick, 0, 3);
		this.setBlock(world, x + 5, y + 0, z + 19, Blocks.stonebrick, 0, 3);
		this.setBlock(world, x + 6, y + 0, z + 19, Blocks.stonebrick, 0, 3);
		this.setBlock(world, x + 7, y + 0, z + 19, Blocks.stonebrick, 0, 3);
		this.setBlock(world, x + 8, y + 0, z + 19, Blocks.stonebrick, 0, 3);
		this.setBlock(world, x + 9, y + 0, z + 19, Blocks.stonebrick, 0, 3);
		this.setBlock(world, x + 10, y + 0, z + 19, Blocks.stonebrick, 0, 3);
		this.setBlock(world, x + 11, y + 0, z + 19, Blocks.stonebrick, 0, 3);
		this.setBlock(world, x + 12, y + 0, z + 19, Blocks.stonebrick, 0, 3);
		this.setBlock(world, x + 13, y + 0, z + 19, Blocks.stonebrick, 0, 3);
		this.setBlock(world, x + 14, y + 0, z + 19, Blocks.stonebrick, 0, 3);
		this.setBlock(world, x + 15, y + 0, z + 19, Blocks.stonebrick, 0, 3);
		this.setBlock(world, x + 16, y + 0, z + 19, Blocks.stonebrick, 0, 3);
		this.setBlock(world, x + 17, y + 0, z + 19, Blocks.stonebrick, 0, 3);
		this.setBlock(world, x + 18, y + 0, z + 19, Blocks.stonebrick, 0, 3);
		this.setBlock(world, x + 19, y + 0, z + 19, Blocks.stonebrick, 0, 3);
		this.setBlock(world, x + 20, y + 0, z + 19, Blocks.stonebrick, 0, 3);
		this.setBlock(world, x + 21, y + 0, z + 19, Blocks.stonebrick, 0, 3);
		this.setBlock(world, x + 22, y + 0, z + 19, Blocks.stonebrick, 0, 3);
		this.setBlock(world, x + 23, y + 0, z + 19, Blocks.stonebrick, 0, 3);
		this.setBlock(world, x + 24, y + 0, z + 19, Blocks.stonebrick, 0, 3);
		this.setBlock(world, x + 25, y + 0, z + 19, Blocks.stonebrick, 0, 3);
		this.setBlock(world, x + 26, y + 0, z + 19, Blocks.stonebrick, 0, 3);
		this.setBlock(world, x + 27, y + 0, z + 19, Blocks.stonebrick, 0, 3);
		this.setBlock(world, x + 28, y + 0, z + 19, Blocks.stonebrick, 0, 3);
		this.setBlock(world, x + 29, y + 0, z + 19, Blocks.stonebrick, 0, 3);
		this.setBlock(world, x + 1, y + 0, z + 20, Blocks.stonebrick, 0, 3);
		this.setBlock(world, x + 2, y + 0, z + 20, Blocks.stonebrick, 0, 3);
		this.setBlock(world, x + 3, y + 0, z + 20, Blocks.stonebrick, 0, 3);
		this.setBlock(world, x + 4, y + 0, z + 20, Blocks.stonebrick, 0, 3);
		this.setBlock(world, x + 5, y + 0, z + 20, Blocks.stonebrick, 0, 3);
		this.setBlock(world, x + 6, y + 0, z + 20, Blocks.stonebrick, 0, 3);
		this.setBlock(world, x + 7, y + 0, z + 20, Blocks.stonebrick, 0, 3);
		this.setBlock(world, x + 8, y + 0, z + 20, Blocks.stonebrick, 0, 3);
		this.setBlock(world, x + 9, y + 0, z + 20, Blocks.stonebrick, 0, 3);
		this.setBlock(world, x + 10, y + 0, z + 20, Blocks.stonebrick, 0, 3);
		this.setBlock(world, x + 11, y + 0, z + 20, Blocks.stonebrick, 0, 3);
		this.setBlock(world, x + 12, y + 0, z + 20, Blocks.stonebrick, 0, 3);
		this.setBlock(world, x + 13, y + 0, z + 20, Blocks.stonebrick, 0, 3);
		this.setBlock(world, x + 14, y + 0, z + 20, Blocks.stonebrick, 0, 3);
		this.setBlock(world, x + 15, y + 0, z + 20, Blocks.stonebrick, 0, 3);
		this.setBlock(world, x + 16, y + 0, z + 20, Blocks.stonebrick, 0, 3);
		this.setBlock(world, x + 17, y + 0, z + 20, Blocks.stonebrick, 0, 3);
		this.setBlock(world, x + 18, y + 0, z + 20, Blocks.stonebrick, 0, 3);
		this.setBlock(world, x + 19, y + 0, z + 20, Blocks.stonebrick, 0, 3);
		this.setBlock(world, x + 20, y + 0, z + 20, Blocks.stonebrick, 0, 3);
		this.setBlock(world, x + 21, y + 0, z + 20, Blocks.stonebrick, 0, 3);
		this.setBlock(world, x + 22, y + 0, z + 20, Blocks.stonebrick, 0, 3);
		this.setBlock(world, x + 23, y + 0, z + 20, Blocks.stonebrick, 0, 3);
		this.setBlock(world, x + 24, y + 0, z + 20, Blocks.stonebrick, 0, 3);
		this.setBlock(world, x + 25, y + 0, z + 20, Blocks.stonebrick, 0, 3);
		this.setBlock(world, x + 26, y + 0, z + 20, Blocks.stonebrick, 0, 3);
		this.setBlock(world, x + 27, y + 0, z + 20, Blocks.stonebrick, 0, 3);
		this.setBlock(world, x + 28, y + 0, z + 20, Blocks.stonebrick, 0, 3);
		this.setBlock(world, x + 29, y + 0, z + 20, Blocks.stonebrick, 0, 3);
		this.setBlock(world, x + 1, y + 0, z + 21, Blocks.stonebrick, 0, 3);
		this.setBlock(world, x + 2, y + 0, z + 21, Blocks.stonebrick, 0, 3);
		this.setBlock(world, x + 3, y + 0, z + 21, Blocks.stonebrick, 0, 3);
		this.setBlock(world, x + 4, y + 0, z + 21, Blocks.stonebrick, 0, 3);
		this.setBlock(world, x + 5, y + 0, z + 21, Blocks.stonebrick, 0, 3);
		this.setBlock(world, x + 6, y + 0, z + 21, Blocks.stonebrick, 0, 3);
		this.setBlock(world, x + 7, y + 0, z + 21, Blocks.stonebrick, 0, 3);
		this.setBlock(world, x + 8, y + 0, z + 21, Blocks.stonebrick, 0, 3);
		this.setBlock(world, x + 9, y + 0, z + 21, Blocks.stonebrick, 0, 3);
		this.setBlock(world, x + 10, y + 0, z + 21, Blocks.stonebrick, 0, 3);
		this.setBlock(world, x + 11, y + 0, z + 21, Blocks.stonebrick, 0, 3);
		this.setBlock(world, x + 12, y + 0, z + 21, Blocks.stonebrick, 0, 3);
		this.setBlock(world, x + 13, y + 0, z + 21, Blocks.stonebrick, 0, 3);
		this.setBlock(world, x + 14, y + 0, z + 21, Blocks.stonebrick, 0, 3);
		this.setBlock(world, x + 15, y + 0, z + 21, Blocks.stonebrick, 0, 3);
		this.setBlock(world, x + 16, y + 0, z + 21, Blocks.stonebrick, 0, 3);
		this.setBlock(world, x + 17, y + 0, z + 21, Blocks.stonebrick, 0, 3);
		this.setBlock(world, x + 18, y + 0, z + 21, Blocks.stonebrick, 0, 3);
		this.setBlock(world, x + 19, y + 0, z + 21, Blocks.stonebrick, 0, 3);
		this.setBlock(world, x + 20, y + 0, z + 21, Blocks.stonebrick, 0, 3);
		this.setBlock(world, x + 21, y + 0, z + 21, Blocks.stonebrick, 0, 3);
		this.setBlock(world, x + 22, y + 0, z + 21, Blocks.stonebrick, 0, 3);
		this.setBlock(world, x + 23, y + 0, z + 21, Blocks.stonebrick, 0, 3);
		this.setBlock(world, x + 24, y + 0, z + 21, Blocks.stonebrick, 0, 3);
		this.setBlock(world, x + 25, y + 0, z + 21, Blocks.stonebrick, 0, 3);
		this.setBlock(world, x + 26, y + 0, z + 21, Blocks.stonebrick, 0, 3);
		this.setBlock(world, x + 27, y + 0, z + 21, Blocks.stonebrick, 0, 3);
		this.setBlock(world, x + 28, y + 0, z + 21, Blocks.stonebrick, 0, 3);
		this.setBlock(world, x + 29, y + 0, z + 21, Blocks.stonebrick, 0, 3);
		this.setBlock(world, x + 1, y + 0, z + 22, Blocks.stonebrick, 0, 3);
		this.setBlock(world, x + 2, y + 0, z + 22, Blocks.stonebrick, 0, 3);
		this.setBlock(world, x + 3, y + 0, z + 22, Blocks.stonebrick, 0, 3);
		this.setBlock(world, x + 4, y + 0, z + 22, Blocks.stonebrick, 0, 3);
		this.setBlock(world, x + 5, y + 0, z + 22, Blocks.stonebrick, 0, 3);
		this.setBlock(world, x + 6, y + 0, z + 22, Blocks.stonebrick, 0, 3);
		this.setBlock(world, x + 7, y + 0, z + 22, Blocks.stonebrick, 0, 3);
		this.setBlock(world, x + 8, y + 0, z + 22, Blocks.stonebrick, 0, 3);
		this.setBlock(world, x + 9, y + 0, z + 22, Blocks.stonebrick, 0, 3);
		this.setBlock(world, x + 10, y + 0, z + 22, Blocks.stonebrick, 0, 3);
		this.setBlock(world, x + 11, y + 0, z + 22, Blocks.stonebrick, 0, 3);
		this.setBlock(world, x + 12, y + 0, z + 22, Blocks.stonebrick, 0, 3);
		this.setBlock(world, x + 13, y + 0, z + 22, Blocks.stonebrick, 0, 3);
		this.setBlock(world, x + 14, y + 0, z + 22, Blocks.stonebrick, 0, 3);
		this.setBlock(world, x + 15, y + 0, z + 22, Blocks.stonebrick, 0, 3);
		this.setBlock(world, x + 16, y + 0, z + 22, Blocks.stonebrick, 0, 3);
		this.setBlock(world, x + 17, y + 0, z + 22, Blocks.stonebrick, 0, 3);
		this.setBlock(world, x + 18, y + 0, z + 22, Blocks.stonebrick, 0, 3);
		this.setBlock(world, x + 19, y + 0, z + 22, Blocks.stonebrick, 0, 3);
		this.setBlock(world, x + 20, y + 0, z + 22, Blocks.stonebrick, 0, 3);
		this.setBlock(world, x + 21, y + 0, z + 22, Blocks.stonebrick, 0, 3);
		this.setBlock(world, x + 22, y + 0, z + 22, Blocks.stonebrick, 0, 3);
		this.setBlock(world, x + 23, y + 0, z + 22, Blocks.stonebrick, 0, 3);
		this.setBlock(world, x + 24, y + 0, z + 22, Blocks.stonebrick, 0, 3);
		this.setBlock(world, x + 25, y + 0, z + 22, Blocks.stonebrick, 0, 3);
		this.setBlock(world, x + 26, y + 0, z + 22, Blocks.stonebrick, 0, 3);
		this.setBlock(world, x + 27, y + 0, z + 22, Blocks.stonebrick, 0, 3);
		this.setBlock(world, x + 28, y + 0, z + 22, Blocks.stonebrick, 0, 3);
		this.setBlock(world, x + 29, y + 0, z + 22, Blocks.stonebrick, 0, 3);
		this.setBlock(world, x + 1, y + 0, z + 23, Blocks.stonebrick, 0, 3);
		this.setBlock(world, x + 2, y + 0, z + 23, Blocks.stonebrick, 0, 3);
		this.setBlock(world, x + 3, y + 0, z + 23, Blocks.stonebrick, 0, 3);
		this.setBlock(world, x + 4, y + 0, z + 23, Blocks.stonebrick, 0, 3);
		this.setBlock(world, x + 5, y + 0, z + 23, Blocks.stonebrick, 0, 3);
		this.setBlock(world, x + 6, y + 0, z + 23, Blocks.stonebrick, 0, 3);
		this.setBlock(world, x + 7, y + 0, z + 23, Blocks.stonebrick, 0, 3);
		this.setBlock(world, x + 8, y + 0, z + 23, Blocks.stonebrick, 0, 3);
		this.setBlock(world, x + 9, y + 0, z + 23, Blocks.stonebrick, 0, 3);
		this.setBlock(world, x + 10, y + 0, z + 23, Blocks.stonebrick, 0, 3);
		this.setBlock(world, x + 11, y + 0, z + 23, Blocks.stonebrick, 0, 3);
		this.setBlock(world, x + 12, y + 0, z + 23, Blocks.stonebrick, 0, 3);
		this.setBlock(world, x + 13, y + 0, z + 23, Blocks.stonebrick, 0, 3);
		this.setBlock(world, x + 14, y + 0, z + 23, Blocks.stonebrick, 0, 3);
		this.setBlock(world, x + 15, y + 0, z + 23, Blocks.stonebrick, 0, 3);
		this.setBlock(world, x + 16, y + 0, z + 23, Blocks.stonebrick, 0, 3);
		this.setBlock(world, x + 17, y + 0, z + 23, Blocks.stonebrick, 0, 3);
		this.setBlock(world, x + 18, y + 0, z + 23, Blocks.stonebrick, 0, 3);
		this.setBlock(world, x + 19, y + 0, z + 23, Blocks.stonebrick, 0, 3);
		this.setBlock(world, x + 20, y + 0, z + 23, Blocks.stonebrick, 0, 3);
		this.setBlock(world, x + 21, y + 0, z + 23, Blocks.stonebrick, 0, 3);
		this.setBlock(world, x + 22, y + 0, z + 23, Blocks.stonebrick, 0, 3);
		this.setBlock(world, x + 23, y + 0, z + 23, Blocks.stonebrick, 0, 3);
		this.setBlock(world, x + 24, y + 0, z + 23, Blocks.stonebrick, 0, 3);
		this.setBlock(world, x + 25, y + 0, z + 23, Blocks.stonebrick, 0, 3);
		this.setBlock(world, x + 26, y + 0, z + 23, Blocks.stonebrick, 0, 3);
		this.setBlock(world, x + 27, y + 0, z + 23, Blocks.stonebrick, 0, 3);
		this.setBlock(world, x + 28, y + 0, z + 23, Blocks.stonebrick, 0, 3);
		this.setBlock(world, x + 29, y + 0, z + 23, Blocks.stonebrick, 0, 3);
		this.setBlock(world, x + 1, y + 0, z + 24, Blocks.stonebrick, 0, 3);
		this.setBlock(world, x + 2, y + 0, z + 24, Blocks.stonebrick, 0, 3);
		this.setBlock(world, x + 3, y + 0, z + 24, Blocks.stonebrick, 0, 3);
		this.setBlock(world, x + 4, y + 0, z + 24, Blocks.stonebrick, 0, 3);
		this.setBlock(world, x + 5, y + 0, z + 24, Blocks.stonebrick, 0, 3);
		this.setBlock(world, x + 6, y + 0, z + 24, Blocks.stonebrick, 0, 3);
		this.setBlock(world, x + 7, y + 0, z + 24, Blocks.stonebrick, 0, 3);
		this.setBlock(world, x + 8, y + 0, z + 24, Blocks.stonebrick, 0, 3);
		this.setBlock(world, x + 9, y + 0, z + 24, Blocks.stonebrick, 0, 3);
		this.setBlock(world, x + 10, y + 0, z + 24, Blocks.stonebrick, 0, 3);
		this.setBlock(world, x + 11, y + 0, z + 24, Blocks.stonebrick, 0, 3);
		this.setBlock(world, x + 12, y + 0, z + 24, Blocks.stonebrick, 0, 3);
		this.setBlock(world, x + 13, y + 0, z + 24, Blocks.stonebrick, 0, 3);
		this.setBlock(world, x + 14, y + 0, z + 24, Blocks.stonebrick, 0, 3);
		this.setBlock(world, x + 15, y + 0, z + 24, Blocks.stonebrick, 0, 3);
		this.setBlock(world, x + 16, y + 0, z + 24, Blocks.stonebrick, 0, 3);
		this.setBlock(world, x + 17, y + 0, z + 24, Blocks.stonebrick, 0, 3);
		this.setBlock(world, x + 18, y + 0, z + 24, Blocks.stonebrick, 0, 3);
		this.setBlock(world, x + 19, y + 0, z + 24, Blocks.stonebrick, 0, 3);
		this.setBlock(world, x + 20, y + 0, z + 24, Blocks.stonebrick, 0, 3);
		this.setBlock(world, x + 21, y + 0, z + 24, Blocks.stonebrick, 0, 3);
		this.setBlock(world, x + 22, y + 0, z + 24, Blocks.stonebrick, 0, 3);
		this.setBlock(world, x + 23, y + 0, z + 24, Blocks.stonebrick, 0, 3);
		this.setBlock(world, x + 24, y + 0, z + 24, Blocks.stonebrick, 0, 3);
		this.setBlock(world, x + 25, y + 0, z + 24, Blocks.stonebrick, 0, 3);
		this.setBlock(world, x + 26, y + 0, z + 24, Blocks.stonebrick, 0, 3);
		this.setBlock(world, x + 27, y + 0, z + 24, Blocks.stonebrick, 0, 3);
		this.setBlock(world, x + 28, y + 0, z + 24, Blocks.stonebrick, 0, 3);
		this.setBlock(world, x + 29, y + 0, z + 24, Blocks.stonebrick, 0, 3);
		this.setBlock(world, x + 1, y + 0, z + 25, Blocks.stonebrick, 0, 3);
		this.setBlock(world, x + 2, y + 0, z + 25, Blocks.stonebrick, 0, 3);
		this.setBlock(world, x + 3, y + 0, z + 25, Blocks.stonebrick, 0, 3);
		this.setBlock(world, x + 4, y + 0, z + 25, Blocks.stonebrick, 0, 3);
		this.setBlock(world, x + 5, y + 0, z + 25, Blocks.stonebrick, 0, 3);
		this.setBlock(world, x + 6, y + 0, z + 25, Blocks.stonebrick, 0, 3);
		this.setBlock(world, x + 7, y + 0, z + 25, Blocks.stonebrick, 0, 3);
		this.setBlock(world, x + 8, y + 0, z + 25, Blocks.stonebrick, 0, 3);
		this.setBlock(world, x + 9, y + 0, z + 25, Blocks.stonebrick, 0, 3);
		this.setBlock(world, x + 10, y + 0, z + 25, Blocks.stonebrick, 0, 3);
		this.setBlock(world, x + 11, y + 0, z + 25, Blocks.stonebrick, 0, 3);
		this.setBlock(world, x + 12, y + 0, z + 25, Blocks.stonebrick, 0, 3);
		this.setBlock(world, x + 13, y + 0, z + 25, Blocks.stonebrick, 0, 3);
		this.setBlock(world, x + 14, y + 0, z + 25, Blocks.stonebrick, 0, 3);
		this.setBlock(world, x + 15, y + 0, z + 25, Blocks.stonebrick, 0, 3);
		this.setBlock(world, x + 16, y + 0, z + 25, Blocks.stonebrick, 0, 3);
		this.setBlock(world, x + 17, y + 0, z + 25, Blocks.stonebrick, 0, 3);
		this.setBlock(world, x + 18, y + 0, z + 25, Blocks.stonebrick, 0, 3);
		this.setBlock(world, x + 19, y + 0, z + 25, Blocks.stonebrick, 0, 3);
		this.setBlock(world, x + 20, y + 0, z + 25, Blocks.stonebrick, 0, 3);
		this.setBlock(world, x + 21, y + 0, z + 25, Blocks.stonebrick, 0, 3);
		this.setBlock(world, x + 22, y + 0, z + 25, Blocks.stonebrick, 0, 3);
		this.setBlock(world, x + 23, y + 0, z + 25, Blocks.stonebrick, 0, 3);
		this.setBlock(world, x + 24, y + 0, z + 25, Blocks.stonebrick, 0, 3);
		this.setBlock(world, x + 25, y + 0, z + 25, Blocks.stonebrick, 0, 3);
		this.setBlock(world, x + 26, y + 0, z + 25, Blocks.stonebrick, 0, 3);
		this.setBlock(world, x + 27, y + 0, z + 25, Blocks.stonebrick, 0, 3);
		this.setBlock(world, x + 28, y + 0, z + 25, Blocks.stonebrick, 0, 3);
		this.setBlock(world, x + 29, y + 0, z + 25, Blocks.stonebrick, 0, 3);
		this.setBlock(world, x + 1, y + 0, z + 26, Blocks.stonebrick, 0, 3);
		this.setBlock(world, x + 2, y + 0, z + 26, Blocks.stonebrick, 0, 3);
		this.setBlock(world, x + 3, y + 0, z + 26, Blocks.stonebrick, 0, 3);
		this.setBlock(world, x + 4, y + 0, z + 26, Blocks.stonebrick, 0, 3);
		this.setBlock(world, x + 5, y + 0, z + 26, Blocks.stonebrick, 0, 3);
		this.setBlock(world, x + 6, y + 0, z + 26, Blocks.stonebrick, 0, 3);
		this.setBlock(world, x + 7, y + 0, z + 26, Blocks.stonebrick, 0, 3);
		this.setBlock(world, x + 8, y + 0, z + 26, Blocks.stonebrick, 0, 3);
		this.setBlock(world, x + 9, y + 0, z + 26, Blocks.stonebrick, 0, 3);
		this.setBlock(world, x + 10, y + 0, z + 26, Blocks.stonebrick, 0, 3);
		this.setBlock(world, x + 11, y + 0, z + 26, Blocks.stonebrick, 0, 3);
		this.setBlock(world, x + 12, y + 0, z + 26, Blocks.stonebrick, 0, 3);
		this.setBlock(world, x + 13, y + 0, z + 26, Blocks.stonebrick, 0, 3);
		this.setBlock(world, x + 14, y + 0, z + 26, Blocks.stonebrick, 0, 3);
		this.setBlock(world, x + 15, y + 0, z + 26, Blocks.stonebrick, 0, 3);
		this.setBlock(world, x + 16, y + 0, z + 26, Blocks.stonebrick, 0, 3);
		this.setBlock(world, x + 17, y + 0, z + 26, Blocks.stonebrick, 0, 3);
		this.setBlock(world, x + 18, y + 0, z + 26, Blocks.stonebrick, 0, 3);
		this.setBlock(world, x + 19, y + 0, z + 26, Blocks.stonebrick, 0, 3);
		this.setBlock(world, x + 20, y + 0, z + 26, Blocks.stonebrick, 0, 3);
		this.setBlock(world, x + 21, y + 0, z + 26, Blocks.stonebrick, 0, 3);
		this.setBlock(world, x + 22, y + 0, z + 26, Blocks.stonebrick, 0, 3);
		this.setBlock(world, x + 23, y + 0, z + 26, Blocks.stonebrick, 0, 3);
		this.setBlock(world, x + 24, y + 0, z + 26, Blocks.stonebrick, 0, 3);
		this.setBlock(world, x + 25, y + 0, z + 26, Blocks.stonebrick, 0, 3);
		this.setBlock(world, x + 26, y + 0, z + 26, Blocks.stonebrick, 0, 3);
		this.setBlock(world, x + 27, y + 0, z + 26, Blocks.stonebrick, 0, 3);
		this.setBlock(world, x + 28, y + 0, z + 26, Blocks.stonebrick, 0, 3);
		this.setBlock(world, x + 29, y + 0, z + 26, Blocks.stonebrick, 0, 3);
		this.setBlock(world, x + 1, y + 0, z + 27, Blocks.stonebrick, 0, 3);
		this.setBlock(world, x + 2, y + 0, z + 27, Blocks.stonebrick, 0, 3);
		this.setBlock(world, x + 3, y + 0, z + 27, Blocks.stonebrick, 0, 3);
		this.setBlock(world, x + 4, y + 0, z + 27, Blocks.stonebrick, 0, 3);
		this.setBlock(world, x + 5, y + 0, z + 27, Blocks.stonebrick, 0, 3);
		this.setBlock(world, x + 6, y + 0, z + 27, Blocks.stonebrick, 0, 3);
		this.setBlock(world, x + 7, y + 0, z + 27, Blocks.stonebrick, 0, 3);
		this.setBlock(world, x + 8, y + 0, z + 27, Blocks.stonebrick, 0, 3);
		this.setBlock(world, x + 9, y + 0, z + 27, Blocks.stonebrick, 0, 3);
		this.setBlock(world, x + 10, y + 0, z + 27, Blocks.stonebrick, 0, 3);
		this.setBlock(world, x + 11, y + 0, z + 27, Blocks.stonebrick, 0, 3);
		this.setBlock(world, x + 12, y + 0, z + 27, Blocks.stonebrick, 0, 3);
		this.setBlock(world, x + 13, y + 0, z + 27, Blocks.stonebrick, 0, 3);
		this.setBlock(world, x + 14, y + 0, z + 27, Blocks.stonebrick, 0, 3);
		this.setBlock(world, x + 15, y + 0, z + 27, Blocks.stonebrick, 0, 3);
		this.setBlock(world, x + 16, y + 0, z + 27, Blocks.stonebrick, 0, 3);
		this.setBlock(world, x + 17, y + 0, z + 27, Blocks.stonebrick, 0, 3);
		this.setBlock(world, x + 18, y + 0, z + 27, Blocks.stonebrick, 0, 3);
		this.setBlock(world, x + 19, y + 0, z + 27, Blocks.stonebrick, 0, 3);
		this.setBlock(world, x + 20, y + 0, z + 27, Blocks.stonebrick, 0, 3);
		this.setBlock(world, x + 21, y + 0, z + 27, Blocks.stonebrick, 0, 3);
		this.setBlock(world, x + 22, y + 0, z + 27, Blocks.stonebrick, 0, 3);
		this.setBlock(world, x + 23, y + 0, z + 27, Blocks.stonebrick, 0, 3);
		this.setBlock(world, x + 24, y + 0, z + 27, Blocks.stonebrick, 0, 3);
		this.setBlock(world, x + 25, y + 0, z + 27, Blocks.stonebrick, 0, 3);
		this.setBlock(world, x + 26, y + 0, z + 27, Blocks.stonebrick, 0, 3);
		this.setBlock(world, x + 27, y + 0, z + 27, Blocks.stonebrick, 0, 3);
		this.setBlock(world, x + 28, y + 0, z + 27, Blocks.stonebrick, 0, 3);
		this.setBlock(world, x + 29, y + 0, z + 27, Blocks.stonebrick, 0, 3);
		this.setBlock(world, x + 1, y + 0, z + 28, Blocks.stonebrick, 0, 3);
		this.setBlock(world, x + 2, y + 0, z + 28, Blocks.stonebrick, 0, 3);
		this.setBlock(world, x + 3, y + 0, z + 28, Blocks.stonebrick, 0, 3);
		this.setBlock(world, x + 4, y + 0, z + 28, Blocks.stonebrick, 0, 3);
		this.setBlock(world, x + 5, y + 0, z + 28, Blocks.stonebrick, 0, 3);
		this.setBlock(world, x + 6, y + 0, z + 28, Blocks.stonebrick, 0, 3);
		this.setBlock(world, x + 7, y + 0, z + 28, Blocks.stonebrick, 0, 3);
		this.setBlock(world, x + 8, y + 0, z + 28, Blocks.stonebrick, 0, 3);
		this.setBlock(world, x + 9, y + 0, z + 28, Blocks.stonebrick, 0, 3);
		this.setBlock(world, x + 10, y + 0, z + 28, Blocks.stonebrick, 0, 3);
		this.setBlock(world, x + 11, y + 0, z + 28, Blocks.stonebrick, 0, 3);
		this.setBlock(world, x + 12, y + 0, z + 28, Blocks.stonebrick, 0, 3);
		this.setBlock(world, x + 13, y + 0, z + 28, Blocks.stonebrick, 0, 3);
		this.setBlock(world, x + 14, y + 0, z + 28, Blocks.stonebrick, 0, 3);
		this.setBlock(world, x + 15, y + 0, z + 28, Blocks.stonebrick, 0, 3);
		this.setBlock(world, x + 16, y + 0, z + 28, Blocks.stonebrick, 0, 3);
		this.setBlock(world, x + 17, y + 0, z + 28, Blocks.stonebrick, 0, 3);
		this.setBlock(world, x + 18, y + 0, z + 28, Blocks.stonebrick, 0, 3);
		this.setBlock(world, x + 19, y + 0, z + 28, Blocks.stonebrick, 0, 3);
		this.setBlock(world, x + 20, y + 0, z + 28, Blocks.stonebrick, 0, 3);
		this.setBlock(world, x + 21, y + 0, z + 28, Blocks.stonebrick, 0, 3);
		this.setBlock(world, x + 22, y + 0, z + 28, Blocks.stonebrick, 0, 3);
		this.setBlock(world, x + 23, y + 0, z + 28, Blocks.stonebrick, 0, 3);
		this.setBlock(world, x + 24, y + 0, z + 28, Blocks.stonebrick, 0, 3);
		this.setBlock(world, x + 25, y + 0, z + 28, Blocks.stonebrick, 0, 3);
		this.setBlock(world, x + 26, y + 0, z + 28, Blocks.stonebrick, 0, 3);
		this.setBlock(world, x + 27, y + 0, z + 28, Blocks.stonebrick, 0, 3);
		this.setBlock(world, x + 28, y + 0, z + 28, Blocks.stonebrick, 0, 3);
		this.setBlock(world, x + 29, y + 0, z + 28, Blocks.stonebrick, 0, 3);
		this.setBlock(world, x + 1, y + 0, z + 29, Blocks.stonebrick, 0, 3);
		this.setBlock(world, x + 2, y + 0, z + 29, Blocks.stonebrick, 0, 3);
		this.setBlock(world, x + 3, y + 0, z + 29, Blocks.stonebrick, 0, 3);
		this.setBlock(world, x + 4, y + 0, z + 29, Blocks.stonebrick, 0, 3);
		this.setBlock(world, x + 5, y + 0, z + 29, Blocks.stonebrick, 0, 3);
		this.setBlock(world, x + 6, y + 0, z + 29, Blocks.stonebrick, 0, 3);
		this.setBlock(world, x + 7, y + 0, z + 29, Blocks.stonebrick, 0, 3);
		this.setBlock(world, x + 8, y + 0, z + 29, Blocks.stonebrick, 0, 3);
		this.setBlock(world, x + 9, y + 0, z + 29, Blocks.stonebrick, 0, 3);
		this.setBlock(world, x + 10, y + 0, z + 29, Blocks.stonebrick, 0, 3);
		this.setBlock(world, x + 11, y + 0, z + 29, Blocks.stonebrick, 0, 3);
		this.setBlock(world, x + 12, y + 0, z + 29, Blocks.stonebrick, 0, 3);
		this.setBlock(world, x + 13, y + 0, z + 29, Blocks.stonebrick, 0, 3);
		this.setBlock(world, x + 14, y + 0, z + 29, Blocks.stonebrick, 0, 3);
		this.setBlock(world, x + 15, y + 0, z + 29, Blocks.stonebrick, 0, 3);
		this.setBlock(world, x + 16, y + 0, z + 29, Blocks.stonebrick, 0, 3);
		this.setBlock(world, x + 17, y + 0, z + 29, Blocks.stonebrick, 0, 3);
		this.setBlock(world, x + 18, y + 0, z + 29, Blocks.stonebrick, 0, 3);
		this.setBlock(world, x + 19, y + 0, z + 29, Blocks.stonebrick, 0, 3);
		this.setBlock(world, x + 20, y + 0, z + 29, Blocks.stonebrick, 0, 3);
		this.setBlock(world, x + 21, y + 0, z + 29, Blocks.stonebrick, 0, 3);
		this.setBlock(world, x + 22, y + 0, z + 29, Blocks.stonebrick, 0, 3);
		this.setBlock(world, x + 23, y + 0, z + 29, Blocks.stonebrick, 0, 3);
		this.setBlock(world, x + 24, y + 0, z + 29, Blocks.stonebrick, 0, 3);
		this.setBlock(world, x + 25, y + 0, z + 29, Blocks.stonebrick, 0, 3);
		this.setBlock(world, x + 26, y + 0, z + 29, Blocks.stonebrick, 0, 3);
		this.setBlock(world, x + 27, y + 0, z + 29, Blocks.stonebrick, 0, 3);
		this.setBlock(world, x + 28, y + 0, z + 29, Blocks.stonebrick, 0, 3);
		this.setBlock(world, x + 29, y + 0, z + 29, Blocks.stonebrick, 0, 3);
		this.setBlock(world, x + 1, y + 1, z + 1, Blocks.stonebrick, 0, 3);
		this.setBlock(world, x + 2, y + 1, z + 1, Blocks.stonebrick, 0, 3);
		this.setBlock(world, x + 3, y + 1, z + 1, Blocks.stonebrick, 0, 3);
		this.setBlock(world, x + 4, y + 1, z + 1, Blocks.stonebrick, 0, 3);
		this.setBlock(world, x + 5, y + 1, z + 1, Blocks.stonebrick, 0, 3);
		this.setBlock(world, x + 6, y + 1, z + 1, Blocks.stonebrick, 0, 3);
		this.setBlock(world, x + 7, y + 1, z + 1, Blocks.stonebrick, 0, 3);
		this.setBlock(world, x + 8, y + 1, z + 1, Blocks.stonebrick, 0, 3);
		this.setBlock(world, x + 9, y + 1, z + 1, Blocks.stonebrick, 0, 3);
		this.setBlock(world, x + 10, y + 1, z + 1, Blocks.stonebrick, 0, 3);
		this.setBlock(world, x + 11, y + 1, z + 1, Blocks.stonebrick, 0, 3);
		this.setBlock(world, x + 12, y + 1, z + 1, Blocks.stonebrick, 0, 3);
		this.setBlock(world, x + 13, y + 1, z + 1, Blocks.stonebrick, 0, 3);
		this.setBlock(world, x + 14, y + 1, z + 1, Blocks.stonebrick, 0, 3);
		this.setBlock(world, x + 15, y + 1, z + 1, Blocks.stonebrick, 0, 3);
		this.setBlock(world, x + 16, y + 1, z + 1, Blocks.stonebrick, 0, 3);
		this.setBlock(world, x + 17, y + 1, z + 1, Blocks.stonebrick, 0, 3);
		this.setBlock(world, x + 18, y + 1, z + 1, Blocks.stonebrick, 0, 3);
		this.setBlock(world, x + 19, y + 1, z + 1, Blocks.stonebrick, 0, 3);
		this.setBlock(world, x + 20, y + 1, z + 1, Blocks.stonebrick, 0, 3);
		this.setBlock(world, x + 21, y + 1, z + 1, Blocks.stonebrick, 0, 3);
		this.setBlock(world, x + 22, y + 1, z + 1, Blocks.stonebrick, 0, 3);
		this.setBlock(world, x + 23, y + 1, z + 1, Blocks.stonebrick, 0, 3);
		this.setBlock(world, x + 24, y + 1, z + 1, Blocks.stonebrick, 0, 3);
		this.setBlock(world, x + 25, y + 1, z + 1, Blocks.stonebrick, 0, 3);
		this.setBlock(world, x + 26, y + 1, z + 1, Blocks.stonebrick, 0, 3);
		this.setBlock(world, x + 27, y + 1, z + 1, Blocks.stonebrick, 0, 3);
		this.setBlock(world, x + 28, y + 1, z + 1, Blocks.stonebrick, 0, 3);
		this.setBlock(world, x + 29, y + 1, z + 1, Blocks.stonebrick, 0, 3);
		this.setBlock(world, x + 1, y + 1, z + 2, Blocks.stonebrick, 0, 3);
		this.setBlock(world, x + 29, y + 1, z + 2, Blocks.stonebrick, 0, 3);
		this.setBlock(world, x + 1, y + 1, z + 3, Blocks.stonebrick, 0, 3);
		this.setBlock(world, x + 29, y + 1, z + 3, Blocks.stonebrick, 0, 3);
		this.setBlock(world, x + 1, y + 1, z + 4, Blocks.stonebrick, 0, 3);
		this.setBlock(world, x + 29, y + 1, z + 4, Blocks.stonebrick, 0, 3);
		this.setBlock(world, x + 1, y + 1, z + 5, Blocks.stonebrick, 0, 3);
		this.setBlock(world, x + 29, y + 1, z + 5, Blocks.stonebrick, 0, 3);
		this.setBlock(world, x + 1, y + 1, z + 6, Blocks.stonebrick, 0, 3);
		this.setBlock(world, x + 29, y + 1, z + 6, Blocks.stonebrick, 0, 3);
		this.setBlock(world, x + 1, y + 1, z + 7, Blocks.stonebrick, 0, 3);
		this.setBlock(world, x + 29, y + 1, z + 7, Blocks.stonebrick, 0, 3);
		this.setBlock(world, x + 1, y + 1, z + 8, Blocks.stonebrick, 0, 3);
		this.setBlock(world, x + 29, y + 1, z + 8, Blocks.stonebrick, 0, 3);
		this.setBlock(world, x + 1, y + 1, z + 9, Blocks.stonebrick, 0, 3);
		this.setBlock(world, x + 29, y + 1, z + 9, Blocks.stonebrick, 0, 3);
		this.setBlock(world, x + 1, y + 1, z + 10, Blocks.stonebrick, 0, 3);
		this.setBlock(world, x + 2, y + 1, z + 10, Blocks.stone_brick_stairs, 2, 3);
		this.setBlock(world, x + 29, y + 1, z + 10, Blocks.stonebrick, 0, 3);
		this.setBlock(world, x + 1, y + 1, z + 11, Blocks.stonebrick, 0, 3);
		this.setBlock(world, x + 2, y + 1, z + 11, Blocks.stonebrick, 0, 3);
		this.setBlock(world, x + 5, y + 1, z + 11, Blocks.cobblestone_wall, 0, 3);
		this.setBlock(world, x + 29, y + 1, z + 11, Blocks.stonebrick, 0, 3);
		this.setBlock(world, x + 1, y + 1, z + 12, Blocks.stonebrick, 0, 3);
		this.setBlock(world, x + 2, y + 1, z + 12, Blocks.stonebrick, 0, 3);
		this.setBlock(world, x + 12, y + 1, z + 12, Blocks.stonebrick, 0, 3);
		this.setBlock(world, x + 13, y + 1, z + 12, Blocks.stonebrick, 0, 3);
		this.setBlock(world, x + 14, y + 1, z + 12, Blocks.stonebrick, 0, 3);
		this.setBlock(world, x + 15, y + 1, z + 12, Blocks.stonebrick, 0, 3);
		this.setBlock(world, x + 16, y + 1, z + 12, Blocks.stonebrick, 0, 3);
		this.setBlock(world, x + 17, y + 1, z + 12, Blocks.stonebrick, 0, 3);
		this.setBlock(world, x + 18, y + 1, z + 12, Blocks.stonebrick, 0, 3);
		this.setBlock(world, x + 29, y + 1, z + 12, Blocks.stonebrick, 0, 3);
		this.setBlock(world, x + 1, y + 1, z + 13, Blocks.stonebrick, 0, 3);
		this.setBlock(world, x + 2, y + 1, z + 13, Blocks.stonebrick, 0, 3);
		this.setBlock(world, x + 12, y + 1, z + 13, Blocks.stonebrick, 0, 3);
		this.setBlock(world, x + 16, y + 1, z + 14, Blocks.redstone_wire, 0, 3);
		this.setBlock(world, x + 15, y + 1, z + 14, Blocks.redstone_wire, 0, 3);
		this.setBlock(world, x + 14, y + 1, z + 13, Blocks.redstone_wire, 0, 3);
		this.setBlock(world, x + 16, y + 1, z + 13, Blocks.redstone_wire, 0, 3);
		this.setBlock(world, x + 13, y + 2, z + 13, Blocks.skull, 3, 3);
        TileEntity tileentity1 = world.getTileEntity(new BlockPos(x + 13, y + 2, z + 13));
        if (tileentity1 instanceof TileEntitySkull)
        {
            ((TileEntitySkull)tileentity1).setSkullRotation(15);
        }
		this.setBlock(world, x + 17, y + 2, z + 13, Blocks.skull, 3, 3);
        TileEntity tileentity2 = world.getTileEntity(new BlockPos(x + 17, y + 2, z + 13));
        if (tileentity2 instanceof TileEntitySkull)
        {
        	((TileEntitySkull)tileentity1).setSkullRotation(-15);
            ((TileEntitySkull)tileentity2).setType(3);
        }
		this.setBlock(world, x + 15, y + 1, z + 13, Blocks.mob_spawner, 0, 3);
        TileEntity tileentity3 = world.getTileEntity(new BlockPos(x + 15, y + 1, z + 13));
        if (tileentity3 instanceof TileEntityMobSpawner)
        {
            ((TileEntityMobSpawner)tileentity3).getSpawnerBaseLogic().setEntityName(setRandomMob(rand));
        }
		this.setBlock(world, x + 18, y + 1, z + 13, Blocks.stonebrick, 0, 3);
		this.setBlock(world, x + 29, y + 1, z + 13, Blocks.stonebrick, 0, 3);
		this.setBlock(world, x + 1, y + 1, z + 14, Blocks.stonebrick, 0, 3);
		this.setBlock(world, x + 2, y + 1, z + 14, Blocks.stonebrick, 0, 3);
		this.setBlock(world, x + 12, y + 1, z + 14, Blocks.stonebrick, 0, 3);
		this.setBlock(world, x + 18, y + 1, z + 14, Blocks.stonebrick, 0, 3);
		this.setBlock(world, x + 29, y + 1, z + 14, Blocks.stonebrick, 0, 3);
		this.setBlock(world, x + 1, y + 1, z + 15, Blocks.stonebrick, 0, 3);
		this.setBlock(world, x + 2, y + 1, z + 15, Blocks.stonebrick, 0, 3);
		this.setBlock(world, x + 12, y + 1, z + 15, Blocks.stonebrick, 0, 3);
		this.setBlock(world, x + 18, y + 1, z + 15, Blocks.stonebrick, 0, 3);
		this.setBlock(world, x + 29, y + 1, z + 15, Blocks.stonebrick, 0, 3);
		this.setBlock(world, x + 1, y + 1, z + 16, Blocks.stonebrick, 0, 3);
		this.setBlock(world, x + 2, y + 1, z + 16, Blocks.stonebrick, 0, 3);
		this.setBlock(world, x + 12, y + 1, z + 16, Blocks.stonebrick, 0, 3);
		this.setBlock(world, x + 13, y + 2, z + 15, Blocks.stone_button, 1, 3);
		this.setBlock(world, x + 13, y + 1, z + 16, Blocks.iron_door, 1, 3);
		this.setBlock(world, x + 14, y + 1, z + 16, Blocks.stonebrick, 0, 3);
		this.setBlock(world, x + 16, y + 1, z + 16, Blocks.stonebrick, 0, 3);
		this.setBlock(world, x + 18, y + 1, z + 16, Blocks.stonebrick, 0, 3);
		this.setBlock(world, x + 29, y + 1, z + 16, Blocks.stonebrick, 0, 3);
		this.setBlock(world, x + 1, y + 1, z + 17, Blocks.stonebrick, 0, 3);
		this.setBlock(world, x + 2, y + 1, z + 17, Blocks.stonebrick, 0, 3);
		this.setBlock(world, x + 12, y + 1, z + 17, Blocks.stonebrick, 0, 3);
		this.setBlock(world, x + 13, y + 1, z + 17, Blocks.trapdoor, 4, 3);
		this.setBlock(world, x + 13, y, z + 17, Blocks.ladder, 2, 3);
		this.generate_entrance(world, rand, x + 13, y, z + 17);
		this.setBlock(world, x + 13, y + 2, z + 17, Blocks.stone_button, 4, 3);
		this.setBlock(world, x + 14, y + 1, z + 17, Blocks.stonebrick, 0, 3);
		this.setBlock(world, x + 16, y + 1, z + 17, Blocks.stonebrick, 0, 3);
		this.generateChest(FORTRESS_MAIN, world, rand, x + 17, y + 1, z + 17, Blocks.chest, 2, 3);
		this.setBlock(world, x + 18, y + 1, z + 17, Blocks.stonebrick, 0, 3);
		this.setBlock(world, x + 29, y + 1, z + 17, Blocks.stonebrick, 0, 3);
		this.setBlock(world, x + 1, y + 1, z + 18, Blocks.stonebrick, 0, 3);
		this.setBlock(world, x + 2, y + 1, z + 18, Blocks.stonebrick, 0, 3);
		this.setBlock(world, x + 5, y + 1, z + 18, Blocks.cobblestone_wall, 0, 3);
		this.setBlock(world, x + 12, y + 1, z + 18, Blocks.stonebrick, 0, 3);
		this.setBlock(world, x + 13, y + 1, z + 18, Blocks.stonebrick, 0, 3);
		this.setBlock(world, x + 14, y + 1, z + 18, Blocks.stonebrick, 0, 3);
		this.setBlock(world, x + 16, y + 1, z + 18, Blocks.stonebrick, 0, 3);
		this.setBlock(world, x + 17, y + 1, z + 18, Blocks.stonebrick, 0, 3);
		this.setBlock(world, x + 18, y + 1, z + 18, Blocks.stonebrick, 0, 3);
		this.setBlock(world, x + 29, y + 1, z + 18, Blocks.stonebrick, 0, 3);
		this.setBlock(world, x + 1, y + 1, z + 19, Blocks.stonebrick, 0, 3);
		this.setBlock(world, x + 2, y + 1, z + 19, Blocks.stonebrick, 0, 3);
		this.setBlock(world, x + 29, y + 1, z + 19, Blocks.stonebrick, 0, 3);
		this.setBlock(world, x + 1, y + 1, z + 20, Blocks.stonebrick, 0, 3);
		this.setBlock(world, x + 2, y + 1, z + 20, Blocks.stone_brick_stairs, 3, 3);
		this.setBlock(world, x + 29, y + 1, z + 20, Blocks.stonebrick, 0, 3);
		this.setBlock(world, x + 1, y + 1, z + 21, Blocks.stonebrick, 0, 3);
		this.setBlock(world, x + 29, y + 1, z + 21, Blocks.stonebrick, 0, 3);
		this.setBlock(world, x + 1, y + 1, z + 22, Blocks.stonebrick, 0, 3);
		this.setBlock(world, x + 29, y + 1, z + 22, Blocks.stonebrick, 0, 3);
		this.setBlock(world, x + 1, y + 1, z + 23, Blocks.stonebrick, 0, 3);
		this.setBlock(world, x + 29, y + 1, z + 23, Blocks.stonebrick, 0, 3);
		this.setBlock(world, x + 1, y + 1, z + 24, Blocks.stonebrick, 0, 3);
		this.setBlock(world, x + 29, y + 1, z + 24, Blocks.stonebrick, 0, 3);
		this.setBlock(world, x + 1, y + 1, z + 25, Blocks.stonebrick, 0, 3);
		this.setBlock(world, x + 29, y + 1, z + 25, Blocks.stonebrick, 0, 3);
		this.setBlock(world, x + 1, y + 1, z + 26, Blocks.stonebrick, 0, 3);
		this.setBlock(world, x + 29, y + 1, z + 26, Blocks.stonebrick, 0, 3);
		this.setBlock(world, x + 1, y + 1, z + 27, Blocks.stonebrick, 0, 3);
		this.setBlock(world, x + 29, y + 1, z + 27, Blocks.stonebrick, 0, 3);
		this.setBlock(world, x + 1, y + 1, z + 28, Blocks.stonebrick, 0, 3);
		this.setBlock(world, x + 29, y + 1, z + 28, Blocks.stonebrick, 0, 3);
		this.setBlock(world, x + 1, y + 1, z + 29, Blocks.stonebrick, 0, 3);
		this.setBlock(world, x + 2, y + 1, z + 29, Blocks.stonebrick, 0, 3);
		this.setBlock(world, x + 3, y + 1, z + 29, Blocks.stonebrick, 0, 3);
		this.setBlock(world, x + 4, y + 1, z + 29, Blocks.stonebrick, 0, 3);
		this.setBlock(world, x + 5, y + 1, z + 29, Blocks.stonebrick, 0, 3);
		this.setBlock(world, x + 6, y + 1, z + 29, Blocks.stonebrick, 0, 3);
		this.setBlock(world, x + 7, y + 1, z + 29, Blocks.stonebrick, 0, 3);
		this.setBlock(world, x + 8, y + 1, z + 29, Blocks.stonebrick, 0, 3);
		this.setBlock(world, x + 9, y + 1, z + 29, Blocks.stonebrick, 0, 3);
		this.setBlock(world, x + 10, y + 1, z + 29, Blocks.stonebrick, 0, 3);
		this.setBlock(world, x + 11, y + 1, z + 29, Blocks.stonebrick, 0, 3);
		this.setBlock(world, x + 12, y + 1, z + 29, Blocks.stonebrick, 0, 3);
		this.setBlock(world, x + 18, y + 1, z + 29, Blocks.stonebrick, 0, 3);
		this.setBlock(world, x + 19, y + 1, z + 29, Blocks.stonebrick, 0, 3);
		this.setBlock(world, x + 20, y + 1, z + 29, Blocks.stonebrick, 0, 3);
		this.setBlock(world, x + 21, y + 1, z + 29, Blocks.stonebrick, 0, 3);
		this.setBlock(world, x + 22, y + 1, z + 29, Blocks.stonebrick, 0, 3);
		this.setBlock(world, x + 23, y + 1, z + 29, Blocks.stonebrick, 0, 3);
		this.setBlock(world, x + 24, y + 1, z + 29, Blocks.stonebrick, 0, 3);
		this.setBlock(world, x + 25, y + 1, z + 29, Blocks.stonebrick, 0, 3);
		this.setBlock(world, x + 26, y + 1, z + 29, Blocks.stonebrick, 0, 3);
		this.setBlock(world, x + 27, y + 1, z + 29, Blocks.stonebrick, 0, 3);
		this.setBlock(world, x + 28, y + 1, z + 29, Blocks.stonebrick, 0, 3);
		this.setBlock(world, x + 29, y + 1, z + 29, Blocks.stonebrick, 0, 3);
		this.setBlock(world, x + 1, y + 2, z + 1, Blocks.stonebrick, 0, 3);
		this.setBlock(world, x + 2, y + 2, z + 1, Blocks.stonebrick, 0, 3);
		this.setBlock(world, x + 3, y + 2, z + 1, Blocks.stonebrick, 0, 3);
		this.setBlock(world, x + 4, y + 2, z + 1, Blocks.stonebrick, 0, 3);
		this.setBlock(world, x + 5, y + 2, z + 1, Blocks.stonebrick, 0, 3);
		this.setBlock(world, x + 6, y + 2, z + 1, Blocks.stonebrick, 0, 3);

		this.generate_r00(world, rand, x, y, z);

		return true;

	}
	
	public boolean generate_r00(World world, Random rand, int x, int y, int z)
	{
	this.setBlock(world, x + 7, y + 2, z + 1, Blocks.stonebrick, 0, 3);
	this.setBlock(world, x + 8, y + 2, z + 1, Blocks.stonebrick, 0, 3);
	this.setBlock(world, x + 9, y + 2, z + 1, Blocks.stonebrick, 0, 3);
	this.setBlock(world, x + 10, y + 2, z + 1, Blocks.stonebrick, 0, 3);
	this.setBlock(world, x + 11, y + 2, z + 1, Blocks.stonebrick, 0, 3);
	this.setBlock(world, x + 12, y + 2, z + 1, Blocks.stonebrick, 0, 3);
	this.setBlock(world, x + 13, y + 2, z + 1, Blocks.stonebrick, 0, 3);
	this.setBlock(world, x + 14, y + 2, z + 1, Blocks.stonebrick, 0, 3);
	this.setBlock(world, x + 15, y + 2, z + 1, Blocks.stonebrick, 0, 3);
	this.setBlock(world, x + 16, y + 2, z + 1, Blocks.stonebrick, 0, 3);
	this.setBlock(world, x + 17, y + 2, z + 1, Blocks.stonebrick, 0, 3);
	this.setBlock(world, x + 18, y + 2, z + 1, Blocks.stonebrick, 0, 3);
	this.setBlock(world, x + 19, y + 2, z + 1, Blocks.stonebrick, 0, 3);
	this.setBlock(world, x + 20, y + 2, z + 1, Blocks.stonebrick, 0, 3);
	this.setBlock(world, x + 21, y + 2, z + 1, Blocks.stonebrick, 0, 3);
	this.setBlock(world, x + 22, y + 2, z + 1, Blocks.stonebrick, 0, 3);
	this.setBlock(world, x + 23, y + 2, z + 1, Blocks.stonebrick, 0, 3);
	this.setBlock(world, x + 24, y + 2, z + 1, Blocks.stonebrick, 0, 3);
	this.setBlock(world, x + 25, y + 2, z + 1, Blocks.stonebrick, 0, 3);
	this.setBlock(world, x + 26, y + 2, z + 1, Blocks.stonebrick, 0, 3);
	this.setBlock(world, x + 27, y + 2, z + 1, Blocks.stonebrick, 0, 3);
	this.setBlock(world, x + 28, y + 2, z + 1, Blocks.stonebrick, 0, 3);
	this.setBlock(world, x + 29, y + 2, z + 1, Blocks.stonebrick, 0, 3);
	this.setBlock(world, x + 1, y + 2, z + 2, Blocks.stonebrick, 0, 3);
	this.setBlock(world, x + 29, y + 2, z + 2, Blocks.stonebrick, 0, 3);
	this.setBlock(world, x + 1, y + 2, z + 3, Blocks.stonebrick, 0, 3);
	this.setBlock(world, x + 29, y + 2, z + 3, Blocks.stonebrick, 0, 3);
	this.setBlock(world, x + 1, y + 2, z + 4, Blocks.stonebrick, 0, 3);
	this.setBlock(world, x + 29, y + 2, z + 4, Blocks.stonebrick, 0, 3);
	this.setBlock(world, x + 1, y + 2, z + 5, Blocks.stonebrick, 0, 3);
	this.setBlock(world, x + 29, y + 2, z + 5, Blocks.stonebrick, 0, 3);
	this.setBlock(world, x + 1, y + 2, z + 6, Blocks.stonebrick, 0, 3);
	this.setBlock(world, x + 29, y + 2, z + 6, Blocks.stonebrick, 0, 3);
	this.setBlock(world, x + 1, y + 2, z + 7, Blocks.stonebrick, 0, 3);
	this.setBlock(world, x + 29, y + 2, z + 7, Blocks.stonebrick, 0, 3);
	this.setBlock(world, x + 1, y + 2, z + 8, Blocks.stonebrick, 0, 3);
	this.setBlock(world, x + 29, y + 2, z + 8, Blocks.stonebrick, 0, 3);
	this.setBlock(world, x + 1, y + 2, z + 9, Blocks.stonebrick, 0, 3);
	this.setBlock(world, x + 29, y + 2, z + 9, Blocks.stonebrick, 0, 3);
	this.setBlock(world, x + 1, y + 2, z + 10, Blocks.stonebrick, 0, 3);
	this.setBlock(world, x + 29, y + 2, z + 10, Blocks.stonebrick, 0, 3);
	this.setBlock(world, x + 1, y + 2, z + 11, Blocks.stonebrick, 0, 3);
	this.setBlock(world, x + 2, y + 2, z + 11, Blocks.stone_brick_stairs, 2, 3);
	this.setBlock(world, x + 5, y + 2, z + 11, Blocks.cobblestone_wall, 0, 3);
	this.setBlock(world, x + 29, y + 2, z + 11, Blocks.stonebrick, 0, 3);
	this.setBlock(world, x + 1, y + 2, z + 12, Blocks.stonebrick, 0, 3);
	this.setBlock(world, x + 2, y + 2, z + 12, Blocks.stonebrick, 0, 3);
	this.setBlock(world, x + 12, y + 2, z + 12, Blocks.stonebrick, 0, 3);
	this.setBlock(world, x + 13, y + 2, z + 12, Blocks.stonebrick, 0, 3);
	this.setBlock(world, x + 14, y + 2, z + 12, Blocks.stonebrick, 0, 3);
	this.setBlock(world, x + 15, y + 2, z + 12, Blocks.stonebrick, 0, 3);
	this.setBlock(world, x + 16, y + 2, z + 12, Blocks.stonebrick, 0, 3);
	this.setBlock(world, x + 17, y + 2, z + 12, Blocks.stonebrick, 0, 3);
	this.setBlock(world, x + 18, y + 2, z + 12, Blocks.stonebrick, 0, 3);
	this.setBlock(world, x + 29, y + 2, z + 12, Blocks.stonebrick, 0, 3);
	this.setBlock(world, x + 1, y + 2, z + 13, Blocks.stonebrick, 0, 3);
	this.setBlock(world, x + 2, y + 2, z + 13, Blocks.stonebrick, 0, 3);
	this.setBlock(world, x + 12, y + 2, z + 13, Blocks.stonebrick, 0, 3);
	this.setBlock(world, x + 18, y + 2, z + 13, Blocks.stonebrick, 0, 3);
	this.setBlock(world, x + 29, y + 2, z + 13, Blocks.stonebrick, 0, 3);
	this.setBlock(world, x + 1, y + 2, z + 14, Blocks.stonebrick, 0, 3);
	this.setBlock(world, x + 2, y + 2, z + 14, Blocks.stonebrick, 0, 3);
	this.setBlock(world, x + 12, y + 2, z + 14, Blocks.stonebrick, 0, 3);
	this.setBlock(world, x + 18, y + 2, z + 14, Blocks.stonebrick, 0, 3);
	this.setBlock(world, x + 29, y + 2, z + 14, Blocks.stonebrick, 0, 3);
	this.setBlock(world, x + 1, y + 2, z + 15, Blocks.stonebrick, 0, 3);
	this.setBlock(world, x + 2, y + 2, z + 15, Blocks.stonebrick, 0, 3);
	this.setBlock(world, x + 12, y + 2, z + 15, Blocks.stonebrick, 0, 3);
	this.setBlock(world, x + 18, y + 2, z + 15, Blocks.stonebrick, 0, 3);
	this.setBlock(world, x + 29, y + 2, z + 15, Blocks.stonebrick, 0, 3);
	this.setBlock(world, x + 1, y + 2, z + 16, Blocks.stonebrick, 0, 3);
	this.setBlock(world, x + 2, y + 2, z + 16, Blocks.stonebrick, 0, 3);
	this.setBlock(world, x + 12, y + 2, z + 16, Blocks.stonebrick, 0, 3);
	this.setBlock(world, x + 13, y + 2, z + 16, Blocks.iron_door, 8, 3);
	this.setBlock(world, x + 14, y + 2, z + 16, Blocks.stonebrick, 0, 3);
	this.setBlock(world, x + 16, y + 2, z + 16, Blocks.stonebrick, 0, 3);
	this.setBlock(world, x + 18, y + 2, z + 16, Blocks.stonebrick, 0, 3);
	this.setBlock(world, x + 29, y + 2, z + 16, Blocks.stonebrick, 0, 3);
	this.setBlock(world, x + 1, y + 2, z + 17, Blocks.stonebrick, 0, 3);
	this.setBlock(world, x + 2, y + 2, z + 17, Blocks.stonebrick, 0, 3);
	this.setBlock(world, x + 12, y + 2, z + 17, Blocks.stonebrick, 0, 3);
	this.setBlock(world, x + 14, y + 2, z + 17, Blocks.stonebrick, 0, 3);
	this.setBlock(world, x + 16, y + 2, z + 17, Blocks.stonebrick, 0, 3);
	this.setBlock(world, x + 18, y + 2, z + 17, Blocks.stonebrick, 0, 3);
	this.setBlock(world, x + 29, y + 2, z + 17, Blocks.stonebrick, 0, 3);
	this.setBlock(world, x + 1, y + 2, z + 18, Blocks.stonebrick, 0, 3);
	this.setBlock(world, x + 2, y + 2, z + 18, Blocks.stonebrick, 0, 3);
	this.setBlock(world, x + 5, y + 2, z + 18, Blocks.cobblestone_wall, 0, 3);
	this.setBlock(world, x + 12, y + 2, z + 18, Blocks.stonebrick, 0, 3);
	this.setBlock(world, x + 13, y + 2, z + 18, Blocks.stonebrick, 0, 3);
	this.setBlock(world, x + 14, y + 2, z + 18, Blocks.stonebrick, 0, 3);
	this.setBlock(world, x + 16, y + 2, z + 18, Blocks.stonebrick, 0, 3);
	this.setBlock(world, x + 17, y + 2, z + 18, Blocks.stonebrick, 0, 3);
	this.setBlock(world, x + 18, y + 2, z + 18, Blocks.stonebrick, 0, 3);
	this.setBlock(world, x + 29, y + 2, z + 18, Blocks.stonebrick, 0, 3);
	this.setBlock(world, x + 1, y + 2, z + 19, Blocks.stonebrick, 0, 3);
	this.setBlock(world, x + 2, y + 2, z + 19, Blocks.stone_brick_stairs, 3, 3);
	this.setBlock(world, x + 29, y + 2, z + 19, Blocks.stonebrick, 0, 3);
	this.setBlock(world, x + 1, y + 2, z + 20, Blocks.stonebrick, 0, 3);
	this.setBlock(world, x + 29, y + 2, z + 20, Blocks.stonebrick, 0, 3);
	this.setBlock(world, x + 1, y + 2, z + 21, Blocks.stonebrick, 0, 3);
	this.setBlock(world, x + 29, y + 2, z + 21, Blocks.stonebrick, 0, 3);
	this.setBlock(world, x + 1, y + 2, z + 22, Blocks.stonebrick, 0, 3);
	this.setBlock(world, x + 29, y + 2, z + 22, Blocks.stonebrick, 0, 3);
	this.setBlock(world, x + 1, y + 2, z + 23, Blocks.stonebrick, 0, 3);
	this.setBlock(world, x + 29, y + 2, z + 23, Blocks.stonebrick, 0, 3);
	this.setBlock(world, x + 1, y + 2, z + 24, Blocks.stonebrick, 0, 3);
	this.setBlock(world, x + 29, y + 2, z + 24, Blocks.stonebrick, 0, 3);
	this.setBlock(world, x + 1, y + 2, z + 25, Blocks.stonebrick, 0, 3);
	this.setBlock(world, x + 29, y + 2, z + 25, Blocks.stonebrick, 0, 3);
	this.setBlock(world, x + 1, y + 2, z + 26, Blocks.stonebrick, 0, 3);
	this.setBlock(world, x + 29, y + 2, z + 26, Blocks.stonebrick, 0, 3);
	this.setBlock(world, x + 1, y + 2, z + 27, Blocks.stonebrick, 0, 3);
	this.setBlock(world, x + 29, y + 2, z + 27, Blocks.stonebrick, 0, 3);
	this.setBlock(world, x + 1, y + 2, z + 28, Blocks.stonebrick, 0, 3);
	this.setBlock(world, x + 29, y + 2, z + 28, Blocks.stonebrick, 0, 3);
	this.setBlock(world, x + 1, y + 2, z + 29, Blocks.stonebrick, 0, 3);
	this.setBlock(world, x + 2, y + 2, z + 29, Blocks.stonebrick, 0, 3);
	this.setBlock(world, x + 3, y + 2, z + 29, Blocks.stonebrick, 0, 3);
	this.setBlock(world, x + 4, y + 2, z + 29, Blocks.stonebrick, 0, 3);
	this.setBlock(world, x + 5, y + 2, z + 29, Blocks.stonebrick, 0, 3);
	this.setBlock(world, x + 6, y + 2, z + 29, Blocks.stonebrick, 0, 3);
	this.setBlock(world, x + 7, y + 2, z + 29, Blocks.stonebrick, 0, 3);
	this.setBlock(world, x + 8, y + 2, z + 29, Blocks.stonebrick, 0, 3);
	this.setBlock(world, x + 9, y + 2, z + 29, Blocks.stonebrick, 0, 3);
	this.setBlock(world, x + 10, y + 2, z + 29, Blocks.stonebrick, 0, 3);
	this.setBlock(world, x + 11, y + 2, z + 29, Blocks.stonebrick, 0, 3);
	this.setBlock(world, x + 12, y + 2, z + 29, Blocks.stonebrick, 0, 3);
	this.setBlock(world, x + 18, y + 2, z + 29, Blocks.stonebrick, 0, 3);
	this.setBlock(world, x + 19, y + 2, z + 29, Blocks.stonebrick, 0, 3);
	this.setBlock(world, x + 20, y + 2, z + 29, Blocks.stonebrick, 0, 3);
	this.setBlock(world, x + 21, y + 2, z + 29, Blocks.stonebrick, 0, 3);
	this.setBlock(world, x + 22, y + 2, z + 29, Blocks.stonebrick, 0, 3);
	this.setBlock(world, x + 23, y + 2, z + 29, Blocks.stonebrick, 0, 3);
	this.setBlock(world, x + 24, y + 2, z + 29, Blocks.stonebrick, 0, 3);
	this.setBlock(world, x + 25, y + 2, z + 29, Blocks.stonebrick, 0, 3);
	this.setBlock(world, x + 26, y + 2, z + 29, Blocks.stonebrick, 0, 3);
	this.setBlock(world, x + 27, y + 2, z + 29, Blocks.stonebrick, 0, 3);
	this.setBlock(world, x + 28, y + 2, z + 29, Blocks.stonebrick, 0, 3);
	this.setBlock(world, x + 29, y + 2, z + 29, Blocks.stonebrick, 0, 3);
	this.setBlock(world, x + 1, y + 3, z + 1, Blocks.stonebrick, 0, 3);
	this.setBlock(world, x + 2, y + 3, z + 1, Blocks.stonebrick, 0, 3);
	this.setBlock(world, x + 3, y + 3, z + 1, Blocks.stonebrick, 0, 3);
	this.setBlock(world, x + 4, y + 3, z + 1, Blocks.stonebrick, 0, 3);
	this.setBlock(world, x + 5, y + 3, z + 1, Blocks.stonebrick, 0, 3);
	this.setBlock(world, x + 6, y + 3, z + 1, Blocks.stonebrick, 0, 3);
	this.setBlock(world, x + 7, y + 3, z + 1, Blocks.stonebrick, 0, 3);
	this.setBlock(world, x + 8, y + 3, z + 1, Blocks.stonebrick, 0, 3);
	this.setBlock(world, x + 9, y + 3, z + 1, Blocks.stonebrick, 0, 3);
	this.setBlock(world, x + 10, y + 3, z + 1, Blocks.stonebrick, 0, 3);
	this.setBlock(world, x + 11, y + 3, z + 1, Blocks.stonebrick, 0, 3);
	this.setBlock(world, x + 12, y + 3, z + 1, Blocks.stonebrick, 0, 3);
	this.setBlock(world, x + 13, y + 3, z + 1, Blocks.stonebrick, 0, 3);
	this.setBlock(world, x + 14, y + 3, z + 1, Blocks.stonebrick, 0, 3);
	this.setBlock(world, x + 15, y + 3, z + 1, Blocks.stonebrick, 0, 3);
	this.setBlock(world, x + 16, y + 3, z + 1, Blocks.stonebrick, 0, 3);
	this.setBlock(world, x + 17, y + 3, z + 1, Blocks.stonebrick, 0, 3);
	this.setBlock(world, x + 18, y + 3, z + 1, Blocks.stonebrick, 0, 3);
	this.setBlock(world, x + 19, y + 3, z + 1, Blocks.stonebrick, 0, 3);
	this.setBlock(world, x + 20, y + 3, z + 1, Blocks.stonebrick, 0, 3);
	this.setBlock(world, x + 21, y + 3, z + 1, Blocks.stonebrick, 0, 3);
	this.setBlock(world, x + 22, y + 3, z + 1, Blocks.stonebrick, 0, 3);
	this.setBlock(world, x + 23, y + 3, z + 1, Blocks.stonebrick, 0, 3);
	this.setBlock(world, x + 24, y + 3, z + 1, Blocks.stonebrick, 0, 3);
	this.setBlock(world, x + 25, y + 3, z + 1, Blocks.stonebrick, 0, 3);
	this.setBlock(world, x + 26, y + 3, z + 1, Blocks.stonebrick, 0, 3);
	this.setBlock(world, x + 27, y + 3, z + 1, Blocks.stonebrick, 0, 3);
	this.setBlock(world, x + 28, y + 3, z + 1, Blocks.stonebrick, 0, 3);
	this.setBlock(world, x + 29, y + 3, z + 1, Blocks.stonebrick, 0, 3);
	this.setBlock(world, x + 1, y + 3, z + 2, Blocks.stonebrick, 0, 3);
	this.setBlock(world, x + 29, y + 3, z + 2, Blocks.stonebrick, 0, 3);
	this.setBlock(world, x + 1, y + 3, z + 3, Blocks.stonebrick, 0, 3);
	this.setBlock(world, x + 29, y + 3, z + 3, Blocks.stonebrick, 0, 3);
	this.setBlock(world, x + 1, y + 3, z + 4, Blocks.stonebrick, 0, 3);
	this.setBlock(world, x + 29, y + 3, z + 4, Blocks.stonebrick, 0, 3);
	this.setBlock(world, x + 1, y + 3, z + 5, Blocks.stonebrick, 0, 3);
	this.setBlock(world, x + 29, y + 3, z + 5, Blocks.stonebrick, 0, 3);
	this.setBlock(world, x + 1, y + 3, z + 6, Blocks.stonebrick, 0, 3);
	this.setBlock(world, x + 29, y + 3, z + 6, Blocks.stonebrick, 0, 3);
	this.setBlock(world, x + 1, y + 3, z + 7, Blocks.stonebrick, 0, 3);
	this.setBlock(world, x + 29, y + 3, z + 7, Blocks.stonebrick, 0, 3);
	this.setBlock(world, x + 1, y + 3, z + 8, Blocks.stonebrick, 0, 3);
	this.setBlock(world, x + 29, y + 3, z + 8, Blocks.stonebrick, 0, 3);
	this.setBlock(world, x + 1, y + 3, z + 9, Blocks.stonebrick, 0, 3);
	this.setBlock(world, x + 29, y + 3, z + 9, Blocks.stonebrick, 0, 3);
	this.setBlock(world, x + 1, y + 3, z + 10, Blocks.stonebrick, 0, 3);
	this.setBlock(world, x + 29, y + 3, z + 10, Blocks.stonebrick, 0, 3);
	this.setBlock(world, x + 1, y + 3, z + 11, Blocks.stonebrick, 0, 3);
	this.setBlock(world, x + 5, y + 3, z + 11, Blocks.cobblestone_wall, 0, 3);
	this.setBlock(world, x + 29, y + 3, z + 11, Blocks.stonebrick, 0, 3);
	this.setBlock(world, x + 1, y + 3, z + 12, Blocks.stonebrick, 0, 3);
	this.setBlock(world, x + 2, y + 3, z + 12, Blocks.stone_brick_stairs, 2, 3);
	this.setBlock(world, x + 12, y + 3, z + 12, Blocks.stonebrick, 0, 3);
	this.setBlock(world, x + 13, y + 3, z + 12, Blocks.stonebrick, 0, 3);
	this.setBlock(world, x + 14, y + 3, z + 12, Blocks.stonebrick, 0, 3);
	this.setBlock(world, x + 15, y + 3, z + 12, Blocks.stonebrick, 0, 3);
	this.setBlock(world, x + 16, y + 3, z + 12, Blocks.stonebrick, 0, 3);
	this.setBlock(world, x + 17, y + 3, z + 12, Blocks.stonebrick, 0, 3);
	this.setBlock(world, x + 18, y + 3, z + 12, Blocks.stonebrick, 0, 3);
	this.setBlock(world, x + 29, y + 3, z + 12, Blocks.stonebrick, 0, 3);
	this.setBlock(world, x + 1, y + 3, z + 13, Blocks.stonebrick, 0, 3);
	this.setBlock(world, x + 2, y + 3, z + 13, Blocks.stonebrick, 0, 3);
	this.setBlock(world, x + 12, y + 3, z + 13, Blocks.stonebrick, 0, 3);
	this.setBlock(world, x + 18, y + 3, z + 13, Blocks.stonebrick, 0, 3);
	this.setBlock(world, x + 29, y + 3, z + 13, Blocks.stonebrick, 0, 3);
	this.setBlock(world, x + 1, y + 3, z + 14, Blocks.stonebrick, 0, 3);
	this.setBlock(world, x + 2, y + 3, z + 14, Blocks.stonebrick, 0, 3);
	this.setBlock(world, x + 12, y + 3, z + 14, Blocks.stonebrick, 0, 3);
	this.setBlock(world, x + 18, y + 3, z + 14, Blocks.stonebrick, 0, 3);
	this.setBlock(world, x + 29, y + 3, z + 14, Blocks.stonebrick, 0, 3);
	this.setBlock(world, x + 1, y + 3, z + 15, Blocks.stonebrick, 0, 3);
	this.setBlock(world, x + 2, y + 3, z + 15, Blocks.stonebrick, 0, 3);
	this.setBlock(world, x + 12, y + 3, z + 15, Blocks.stonebrick, 0, 3);
	this.setBlock(world, x + 18, y + 3, z + 15, Blocks.stonebrick, 0, 3);
	this.setBlock(world, x + 29, y + 3, z + 15, Blocks.stonebrick, 0, 3);
	this.setBlock(world, x + 1, y + 3, z + 16, Blocks.stonebrick, 0, 3);
	this.setBlock(world, x + 2, y + 3, z + 16, Blocks.stonebrick, 0, 3);
	this.setBlock(world, x + 12, y + 3, z + 16, Blocks.stonebrick, 0, 3);
	this.setBlock(world, x + 13, y + 3, z + 16, Blocks.stonebrick, 0, 3);
	this.setBlock(world, x + 14, y + 3, z + 16, Blocks.stonebrick, 0, 3);
	this.setBlock(world, x + 15, y + 3, z + 16, Blocks.stonebrick, 0, 3);
	this.setBlock(world, x + 16, y + 3, z + 16, Blocks.stonebrick, 0, 3);
	this.setBlock(world, x + 17, y + 3, z + 16, Blocks.stonebrick, 0, 3);
	this.setBlock(world, x + 18, y + 3, z + 16, Blocks.stonebrick, 0, 3);
	this.setBlock(world, x + 29, y + 3, z + 16, Blocks.stonebrick, 0, 3);
	this.setBlock(world, x + 1, y + 3, z + 17, Blocks.stonebrick, 0, 3);
	this.setBlock(world, x + 2, y + 3, z + 17, Blocks.stonebrick, 0, 3);
	this.setBlock(world, x + 12, y + 3, z + 17, Blocks.stonebrick, 0, 3);
	this.setBlock(world, x + 13, y + 3, z + 17, Blocks.stonebrick, 0, 3);
	this.setBlock(world, x + 14, y + 3, z + 17, Blocks.stonebrick, 0, 3);
	this.setBlock(world, x + 15, y + 3, z + 17, Blocks.stonebrick, 0, 3);
	this.setBlock(world, x + 16, y + 3, z + 17, Blocks.stonebrick, 0, 3);
	this.setBlock(world, x + 17, y + 3, z + 17, Blocks.stonebrick, 0, 3);
	this.setBlock(world, x + 18, y + 3, z + 17, Blocks.stonebrick, 0, 3);
	this.setBlock(world, x + 29, y + 3, z + 17, Blocks.stonebrick, 0, 3);
	this.setBlock(world, x + 1, y + 3, z + 18, Blocks.stonebrick, 0, 3);
	this.setBlock(world, x + 2, y + 3, z + 18, Blocks.stone_brick_stairs, 3, 3);
	this.setBlock(world, x + 5, y + 3, z + 18, Blocks.cobblestone_wall, 0, 3);
	this.setBlock(world, x + 12, y + 3, z + 18, Blocks.stonebrick, 0, 3);
	this.setBlock(world, x + 13, y + 3, z + 18, Blocks.stonebrick, 0, 3);
	this.setBlock(world, x + 14, y + 3, z + 18, Blocks.stonebrick, 0, 3);
	this.setBlock(world, x + 15, y + 3, z + 18, Blocks.stonebrick, 0, 3);
	this.setBlock(world, x + 16, y + 3, z + 18, Blocks.stonebrick, 0, 3);
	this.setBlock(world, x + 17, y + 3, z + 18, Blocks.stonebrick, 0, 3);
	this.setBlock(world, x + 18, y + 3, z + 18, Blocks.stonebrick, 0, 3);
	this.setBlock(world, x + 29, y + 3, z + 18, Blocks.stonebrick, 0, 3);
	this.setBlock(world, x + 1, y + 3, z + 19, Blocks.stonebrick, 0, 3);
	this.setBlock(world, x + 29, y + 3, z + 19, Blocks.stonebrick, 0, 3);
	this.setBlock(world, x + 1, y + 3, z + 20, Blocks.stonebrick, 0, 3);
	this.setBlock(world, x + 29, y + 3, z + 20, Blocks.stonebrick, 0, 3);
	this.setBlock(world, x + 1, y + 3, z + 21, Blocks.stonebrick, 0, 3);
	this.setBlock(world, x + 29, y + 3, z + 21, Blocks.stonebrick, 0, 3);
	this.setBlock(world, x + 1, y + 3, z + 22, Blocks.stonebrick, 0, 3);
